File: A1.vms
VAMAS Surface Chemical Analysis Standard Data Transfer Format 1988 May 4
Not Specified
Kratos Axis
Not Specified
/d=/data/20170705/2017006144/A1.dset
3
Casa Info Follows
0
SourceAnalyserAngle: Not Specified
MAP
REGULAR
4
2
32768
32768
1
Etch Time
s
0
0
0
0
4
wide/2
Not Specified
2017
7
4
10
44
32
0
25
Casa Info Follows
1
Calib M = 283.074 A = 284.6 BE ADD
8
annot text peak Data 1200.16 2067 RGB(0,0,0) Font(14,18,0,0,Times New Roman) Vertical
C 1s
annot text peak Data 1089.89 569 RGB(0,0,0) Font(14,18,0,0,Times New Roman) Vertical
N 1s
annot text peak Data 510.164 1921 RGB(0,0,0) Font(14,18,0,0,Times New Roman) Vertical
O KLL
annot text peak Data 954.164 3706 RGB(0,0,0) Font(14,18,0,0,Times New Roman) Vertical
O 1s
annot text peak Data 642 1329 RGB(0,0,0) Font(14,18,0,0,Times New Roman) Vertical
F KLL
annot text peak Data 799.164 4212 RGB(0,0,0) Font(14,18,0,0,Times New Roman) Vertical
F 1s
annot text peak Data 1255.16 114 RGB(0,0,0) Font(14,18,0,0,Times New Roman) Vertical
S 2s
annot text peak Data 1318.16 159 RGB(0,0,0) Font(14,18,0,0,Times New Roman) Vertical
S 2p
0
0
   XPS     Spectrum    Lens Mode:Hybrid   Resolution:Pass energy 80    Iris(Aper):slot(Slot)
   Acqn. Time(s): 110        Sweeps: 1        Anode:Mono(Al (Mono))(150 W)   Step(meV): 1000.0
   Dwell Time(ms): 100        Charge Neutraliser :On   Acquired On :17/07/04 10:44:32
XPS
59
-3
0
Mono(Al (Mono))
1486.69
150
1e+037
1e+037
6000
6000
1e+037
1e+037
FAT
80
1e+037
-4.45
0
1e+037
1e+037
1e+037
1e+037
Wide
None
-1
Kinetic Energy
eV
386.69
1
2
Intensity
d
Transmission
d
pulse counting
0.1
0
1e+037
0
5
8.48115
1566
1549
1551
1505
1540
1571
1525
1579
1563
1541
1587
1562
1575
1603
1613
1581
1488
1507
1554
1558
1526
1505
1517
1531
1559
1520
1517
1519
1581
1584
1607
1592
1534
1585
1638
1605
1582
1613
1600
1587
1559
1595
1557
1639
1621
1659
1628
1600
1574
1528
1566
1611
1583
1634
1612
1598
1587
1565
1590
1574
1593
1562
1619
1651
1694
1675
1628
1652
1683
1655
1642
1569
1650
1628
1611
1669
1701
1693
1682
1679
1670
1715
1707
1675
1647
1648
1698
1667
1713
1736
1726
1728
1688
1749
1710
1751
1745
1760
1742
1770
1820
1775
1783
1815
1803
1692
1672
1697
1690
1630
1653
1677
1655
1626
1613
1615
1636
1644
1658
1665
1755
1823
1800
1860
1888
1921
1897
1874
1851
1740
1719
1699
1630
1571
1491
1440
1379
1339
1283
1282
1263
1273
1273
1252
1316
1260
1245
1258
1245
1297
1333
1265
1209
1267
1244
1235
1258
1270
1243
1299
1293
1278
1297
1286
1283
1272
1285
1251
1274
1254
1295
1257
1238
1261
1372
1277
1333
1298
1325
1235
1294
1322
1282
1266
1311
1295
1322
1287
1325
1354
1289
1346
1344
1347
1320
1360
1367
1322
1327
1353
1356
1379
1325
1355
1357
1335
1324
1356
1407
1351
1335
1333
1372
1317
1346
1359
1378
1380
1383
1349
1379
1426
1417
1405
1404
1419
1398
1394
1426
1405
1396
1365
1426
1384
1348
1427
1489
1452
1501
1563
1546
1588
1574
1540
1569
1512
1492
1450
1450
1470
1407
1480
1369
1424
1381
1372
1329
1346
1366
1398
1419
1405
1446
1488
1524
1627
1780
1882
1959
1925
1881
1732
1691
1600
1530
1521
1380
1367
1328
1272
1233
1212
1204
1180
1173
1131
1125
1173
1176
1117
1127
1131
1107
1206
1141
1120
1147
1147
1129
1193
1154
1114
1201
1164
1137
1180
1166
1182
1132
1157
1194
1162
1202
1181
1185
1139
1208
1178
1185
1163
1148
1236
1249
1184
1141
1183
1175
1166
1216
1172
1192
1193
1206
1201
1151
1209
1210
1217
1211
1212
1206
1224
1179
1278
1225
1197
1207
1222
1237
1198
1229
1253
1256
1233
1210
1272
1224
1228
1224
1184
1259
1264
1216
1183
1220
1209
1236
1250
1199
1197
1213
1225
1235
1253
1244
1232
1256
1274
1224
1255
1297
1277
1298
1304
1335
1303
1297
1308
1306
1272
1247
1282
1252
1308
1234
1242
1199
1171
1168
1150
1143
1124
1086
1127
1105
1080
1068
1071
1018
1108
1223
1524
2333
3733
4212
2385
1292
1064
1021
972
931
986
935
949
982
1005
998
974
971
953
988
987
988
1018
990
1005
984
978
977
989
980
1003
1023
992
1005
1010
987
997
978
1017
1015
1059
1053
996
973
1038
1044
1001
1001
998
985
1018
977
990
993
1001
1009
1046
1001
1030
986
997
1008
1044
993
1009
1028
1048
1044
1039
1009
1062
1013
1025
1023
1012
989
997
991
1014
993
1027
1025
981
1011
1054
991
1052
1079
1026
1067
1000
1025
981
1013
1004
1020
1017
997
1014
1027
1075
960
973
1012
1014
959
1005
1011
1011
1011
1055
1027
1008
1030
981
1030
996
1075
1057
1002
1042
1035
1003
1039
1049
970
1008
1021
1031
1039
1013
1080
1111
1044
1095
1106
1109
1053
998
1022
958
950
944
875
844
815
834
764
741
691
685
676
684
643
715
893
1295
2424
3706
3556
1961
882
560
548
525
498
480
493
497
486
496
476
536
522
507
490
490
449
465
476
479
467
473
490
512
498
504
489
481
530
501
478
495
480
542
502
512
521
504
496
506
523
524
507
493
524
496
481
509
481
518
500
513
501
516
544
517
505
497
539
525
535
492
459
525
540
506
518
533
500
481
524
558
512
502
486
476
515
509
522
492
470
524
531
522
543
497
496
519
490
516
535
482
522
542
532
518
506
498
519
577
550
519
540
569
555
561
527
523
510
499
502
502
551
560
563
531
510
530
550
540
528
537
548
563
521
524
547
608
647
588
560
543
569
551
539
538
546
517
525
548
533
541
561
544
541
521
497
522
530
526
539
524
543
551
543
563
580
575
564
552
549
549
583
544
501
569
533
528
543
567
592
597
605
581
559
537
568
557
587
588
570
573
597
582
584
599
584
571
608
555
553
557
593
554
569
553
578
582
597
574
606
598
576
559
601
590
559
592
620
599
623
615
619
648
636
631
659
677
621
616
627
603
572
582
550
550
497
484
425
447
442
357
317
315
317
268
285
332
451
702
1244
1570
1561
2067
1913
1615
1182
429
116
106
102
82
99
92
77
69
88
102
96
95
104
97
86
89
79
81
85
79
87
86
84
100
89
87
76
89
77
87
85
79
86
97
76
79
87
82
83
91
83
99
104
82
82
84
93
102
87
129
114
108
87
95
74
80
86
90
87
80
75
77
88
87
78
77
76
76
79
93
76
69
76
85
89
89
90
81
86
88
83
98
97
103
77
77
77
92
96
88
92
83
85
86
84
76
81
74
89
77
82
74
74
65
71
70
64
68
71
84
71
98
129
159
141
119
81
90
75
73
69
68
60
65
77
65
79
80
99
87
99
70
56
71
69
64
60
68
60
92
63
70
61
66
74
60
74
71
87
68
69
70
70
58
54
55
65
69
69
57
73
64
83
78
89
68
68
72
85
83
67
67
59
76
69
88
80
68
81
80
80
93
76
75
65
78
82
75
73
76
88
67
73
87
68
82
90
77
84
92
80
95
72
83
69
73
86
96
81
76
79
71
74
75
79
74
83
79
78
89
80
93
99
79
94
101
81
71
69
85
84
81
77
77
83
82
79
81
81
64
73
65
76
70
80
95
117
132
172
172
108
93
90
102
118
97
98
129
92
67
58
55
50
65
63
87
81
64
73
64
63
64
72
65
42
52
32
33
23
15
5
8.94051
F 1s/5
Not Specified
2017
7
4
12
37
14
0
9
Casa Info Follows
1
Calib M = 283.074 A = 284.6 BE ADD
0
0
0
   XPS     Spectrum    Lens Mode:Hybrid   Resolution:Pass energy 40    Iris(Aper):slot(Slot)
   Acqn. Time(s): 121        Sweeps: 2        Anode:Mono(Al (Mono))(150 W)   Step(meV): 50.0
   Dwell Time(ms): 150        Charge Neutraliser :On   Acquired On :17/07/04 12:37:14
XPS
59
-3
0
Mono(Al (Mono))
1486.69
150
1e+037
1e+037
6000
6000
1e+037
1e+037
FAT
40
1e+037
-4.45
0
1e+037
1e+037
1e+037
1e+037
F
1s
-1
Kinetic Energy
eV
790.64
0.05
2
Intensity
d
Transmission
d
pulse counting
0.15
2
0
1e+037
1e+037
1e+037
0
806
1078
6241
3.41724
3.42712
1225
3.42712
1259
3.4271
1261
3.42707
1200
3.42705
1215
3.42702
1266
3.427
1267
3.42698
1241
3.42695
1180
3.42693
1229
3.4269
1208
3.42688
1240
3.42686
1242
3.42683
1228
3.42681
1247
3.42678
1231
3.42676
1260
3.42674
1232
3.42671
1234
3.42669
1256
3.42667
1316
3.42664
1218
3.42662
1241
3.42659
1210
3.42657
1217
3.42655
1197
3.42652
1202
3.4265
1203
3.42647
1245
3.42645
1250
3.42643
1213
3.4264
1232
3.42638
1205
3.42636
1160
3.42633
1168
3.42631
1153
3.42628
1206
3.42626
1215
3.42624
1208
3.42621
1224
3.42619
1191
3.42616
1250
3.42614
1230
3.42612
1137
3.42609
1248
3.42607
1229
3.42605
1224
3.42602
1227
3.426
1231
3.42597
1193
3.42595
1207
3.42593
1134
3.4259
1165
3.42588
1194
3.42585
1251
3.42583
1246
3.42581
1222
3.42578
1161
3.42576
1219
3.42573
1248
3.42571
1219
3.42569
1175
3.42566
1230
3.42564
1201
3.42562
1237
3.42559
1234
3.42557
1215
3.42554
1185
3.42552
1255
3.4255
1216
3.42547
1232
3.42545
1237
3.42542
1225
3.4254
1255
3.42538
1213
3.42535
1183
3.42533
1211
3.42531
1235
3.42528
1242
3.42526
1243
3.42523
1244
3.42521
1209
3.42519
1171
3.42516
1239
3.42514
1202
3.42511
1218
3.42509
1236
3.42507
1258
3.42504
1239
3.42502
1226
3.425
1201
3.42497
1179
3.42495
1244
3.42492
1261
3.4249
1241
3.42488
1300
3.42485
1280
3.42483
1227
3.4248
1227
3.42478
1210
3.42476
1277
3.42473
1277
3.42471
1266
3.42469
1278
3.42466
1359
3.42464
1294
3.42461
1296
3.42459
1290
3.42457
1277
3.42454
1312
3.42452
1307
3.42449
1303
3.42447
1296
3.42445
1345
3.42442
1274
3.4244
1316
3.42437
1302
3.42435
1370
3.42433
1272
3.4243
1328
3.42428
1361
3.42426
1427
3.42423
1394
3.42421
1409
3.42418
1428
3.42416
1402
3.42414
1421
3.42411
1442
3.42409
1446
3.42406
1449
3.42404
1439
3.42402
1470
3.42399
1553
3.42397
1538
3.42395
1628
3.42392
1620
3.4239
1616
3.42387
1607
3.42385
1671
3.42383
1657
3.4238
1738
3.42378
1674
3.42375
1782
3.42373
1773
3.42371
1838
3.42368
1916
3.42366
1930
3.42364
1907
3.42361
2008
3.42359
2014
3.42356
2130
3.42354
2123
3.42352
2211
3.42349
2272
3.42347
2301
3.42344
2339
3.42342
2398
3.4234
2343
3.42337
2536
3.42335
2625
3.42333
2663
3.4233
2739
3.42328
2799
3.42325
2897
3.42323
2981
3.42321
3044
3.42318
3229
3.42316
3386
3.42313
3472
3.42311
3628
3.42309
3743
3.42306
3894
3.42304
4021
3.42301
4100
3.42299
4375
3.42297
4497
3.42294
4666
3.42292
4805
3.4229
5017
3.42287
5141
3.42285
5264
3.42282
5302
3.4228
5622
3.42278
5672
3.42275
5742
3.42273
5980
3.4227
6121
3.42268
6117
3.42266
6189
3.42263
6174
3.42261
6154
3.42259
6241
3.42256
6211
3.42254
5991
3.42251
5964
3.42249
5877
3.42247
5861
3.42244
5580
3.42242
5463
3.42239
5370
3.42237
5141
3.42235
5056
3.42232
4790
3.4223
4662
3.42228
4292
3.42225
4151
3.42223
3949
3.4222
3801
3.42218
3606
3.42216
3422
3.42213
3184
3.42211
3013
3.42208
2783
3.42206
2725
3.42204
2591
3.42201
2456
3.42199
2379
3.42196
2254
3.42194
2095
3.42192
2050
3.42189
1906
3.42187
1862
3.42185
1856
3.42182
1752
3.4218
1778
3.42177
1703
3.42175
1571
3.42173
1574
3.4217
1559
3.42168
1534
3.42165
1460
3.42163
1430
3.42161
1372
3.42158
1395
3.42156
1455
3.42154
1373
3.42151
1316
3.42149
1324
3.42146
1337
3.42144
1298
3.42142
1320
3.42139
1317
3.42137
1319
3.42134
1262
3.42132
1267
3.4213
1307
3.42127
1298
3.42125
1248
3.42123
1238
3.4212
1249
3.42118
1227
3.42115
1270
3.42113
1203
3.42111
1217
3.42108
1238
3.42106
1224
3.42103
1199
3.42101
1176
3.42099
1190
3.42096
1189
3.42094
1200
3.42091
1206
3.42089
1257
3.42087
1231
3.42084
1240
3.42082
1254
3.4208
1198
3.42077
1221
3.42075
1214
3.42072
1202
3.4207
1202
3.42068
1164
3.42065
1217
3.42063
1188
3.4206
1173
3.42058
1253
3.42056
1194
3.42053
1152
3.42051
1175
3.42049
1200
3.42046
1172
3.42044
1165
3.42041
1161
3.42039
1183
3.42037
1219
3.42034
1134
3.42032
1166
3.42029
1143
3.42027
1136
3.42025
1146
3.42022
1143
3.4202
1132
3.42018
1119
3.42015
1221
3.42013
1152
3.4201
1183
3.42008
1155
3.42006
1171
3.42003
1114
3.42001
1167
3.41998
1201
3.41996
1136
3.41994
1183
3.41991
1141
3.41989
1177
3.41986
1148
3.41984
1182
3.41982
1178
3.41979
1172
3.41977
1182
3.41975
1135
3.41972
1106
3.4197
1134
3.41967
1157
3.41965
1194
3.41963
1117
3.4196
1171
3.41958
1171
3.41955
1177
3.41953
1228
3.41951
1173
3.41948
1182
3.41946
1160
3.41944
1203
3.41941
1078
3.41939
1182
3.41936
1139
3.41934
1152
3.41932
1201
3.41929
1127
3.41927
1143
3.41924
1226
3.41922
1160
3.4192
1168
3.41917
1162
3.41915
1139
3.41913
1138
3.4191
1146
3.41908
1156
3.41905
1171
3.41903
1191
3.41901
1197
3.41898
1150
3.41896
1170
3.41893
1152
3.41891
1136
3.41889
1160
3.41886
1141
3.41884
1170
3.41881
1186
3.41879
1123
3.41877
1145
3.41874
1206
3.41872
1202
3.4187
1142
3.41867
1123
3.41865
1141
3.41862
1169
3.4186
1186
3.41858
1191
3.41855
1141
3.41853
1212
3.4185
1169
3.41848
1155
3.41846
1205
3.41843
1156
3.41841
1125
3.41839
1168
3.41836
1186
3.41834
1164
3.41831
1182
3.41829
1150
3.41827
1128
3.41824
1154
3.41822
1167
3.41819
1184
3.41817
1176
3.41815
1134
3.41812
1115
3.4181
1168
3.41808
1160
3.41805
1176
3.41803
1147
3.418
1166
3.41798
1195
3.41796
1185
3.41793
1141
3.4179
1153
3.41786
1106
3.41781
1159
3.41777
1187
3.41773
1243
3.41769
1167
3.41765
1191
3.41761
1178
3.41757
1176
3.41753
1193
3.41748
1207
3.41744
1214
3.4174
1169
3.41736
1147
3.41732
1173
3.41728
1164
3.41724
O 1s/6
Not Specified
2017
7
4
12
37
14
0
9
Casa Info Follows
1
Calib M = 283.074 A = 284.6 BE ADD
0
0
0
   XPS     Spectrum    Lens Mode:Hybrid   Resolution:Pass energy 40    Iris(Aper):slot(Slot)
   Acqn. Time(s): 162        Sweeps: 3        Anode:Mono(Al (Mono))(150 W)   Step(meV): 50.0
   Dwell Time(ms): 150        Charge Neutraliser :On   Acquired On :17/07/04 12:37:14
XPS
59
-3
0
Mono(Al (Mono))
1486.69
150
1e+037
1e+037
6000
6000
1e+037
1e+037
FAT
40
1e+037
-4.45
0
1e+037
1e+037
1e+037
1e+037
O
1s
-1
Kinetic Energy
eV
946.69
0.05
2
Intensity
d
Transmission
d
pulse counting
0.15
3
0
1e+037
1e+037
1e+037
0
722
766
8524
3.32569
3.34183
1225
3.34183
1229
3.34178
1209
3.34174
1193
3.34169
1171
3.34165
1199
3.3416
1294
3.34156
1284
3.34151
1215
3.34147
1178
3.34142
1191
3.34138
1178
3.34133
1167
3.34129
1146
3.34124
1131
3.3412
1193
3.34115
1222
3.34111
1124
3.34107
1105
3.34102
1088
3.34098
1072
3.34093
1167
3.34089
1155
3.34084
1168
3.3408
1124
3.34075
1140
3.34071
1128
3.34066
1180
3.34062
1214
3.34057
1163
3.34053
1150
3.34048
1177
3.34044
1182
3.34039
1103
3.34035
1133
3.3403
1185
3.34026
1146
3.34021
1164
3.34017
1132
3.34012
1147
3.34008
1131
3.34003
1132
3.33999
1122
3.33994
1109
3.3399
1127
3.33985
1145
3.33981
1115
3.33976
1078
3.33972
1091
3.33968
1143
3.33963
1118
3.33959
1149
3.33954
1134
3.3395
1087
3.33945
1073
3.33941
1117
3.33936
1146
3.33932
1100
3.33927
1155
3.33923
1133
3.33918
1176
3.33914
1113
3.33909
1156
3.33905
1158
3.339
1163
3.33896
1151
3.33891
1094
3.33887
1168
3.33882
1192
3.33878
1189
3.33873
1115
3.33869
1150
3.33864
1137
3.3386
1136
3.33855
1137
3.33851
1157
3.33846
1135
3.33842
1065
3.33837
1145
3.33833
1141
3.33829
1134
3.33824
1116
3.3382
1100
3.33815
1144
3.33811
1151
3.33806
1138
3.33802
1161
3.33797
1193
3.33793
1159
3.33788
1131
3.33784
1082
3.33779
1116
3.33775
1158
3.3377
1104
3.33766
1156
3.33761
1175
3.33757
1165
3.33752
1157
3.33748
1183
3.33743
1200
3.33739
1203
3.33734
1155
3.3373
1169
3.33725
1180
3.33721
1159
3.33716
1193
3.33712
1201
3.33707
1250
3.33703
1198
3.33698
1205
3.33694
1247
3.3369
1229
3.33685
1287
3.33681
1261
3.33676
1336
3.33672
1344
3.33667
1310
3.33663
1341
3.33658
1350
3.33654
1371
3.33649
1389
3.33645
1426
3.3364
1421
3.33636
1476
3.33631
1475
3.33627
1503
3.33622
1506
3.33618
1570
3.33613
1622
3.33609
1638
3.33604
1648
3.336
1767
3.33595
1690
3.33591
1783
3.33586
1816
3.33582
1841
3.33577
1928
3.33573
1958
3.33568
2032
3.33564
2138
3.3356
2130
3.33555
2286
3.33551
2320
3.33546
2378
3.33542
2479
3.33537
2506
3.33533
2694
3.33528
2794
3.33524
2775
3.33519
2978
3.33515
3089
3.3351
3146
3.33506
3339
3.33501
3444
3.33497
3525
3.33492
3697
3.33488
3914
3.33483
4123
3.33479
4313
3.33474
4416
3.3347
4516
3.33465
4660
3.33461
4938
3.33456
5231
3.33452
5369
3.33447
5581
3.33443
5789
3.33438
6055
3.33434
6265
3.33429
6474
3.33425
6782
3.33421
6796
3.33416
7076
3.33412
7275
3.33407
7534
3.33403
7670
3.33398
7811
3.33394
7972
3.33389
8323
3.33385
8372
3.3338
8343
3.33376
8503
3.33371
8350
3.33367
8389
3.33362
8524
3.33358
8512
3.33353
8420
3.33349
8340
3.33344
8123
3.3334
8010
3.33335
7891
3.33331
7650
3.33326
7473
3.33322
7282
3.33317
7193
3.33313
6872
3.33308
6697
3.33304
6526
3.33299
6252
3.33295
5993
3.3329
5707
3.33286
5596
3.33282
5448
3.33277
5235
3.33273
5051
3.33268
4777
3.33264
4619
3.33259
4282
3.33255
4111
3.3325
4065
3.33246
3887
3.33241
3798
3.33237
3557
3.33232
3272
3.33228
3265
3.33223
3026
3.33219
2949
3.33214
2779
3.3321
2674
3.33205
2499
3.33201
2306
3.33196
2351
3.33192
2153
3.33187
2087
3.33183
1922
3.33178
1875
3.33174
1883
3.33169
1724
3.33165
1611
3.3316
1528
3.33156
1470
3.33151
1490
3.33147
1365
3.33143
1340
3.33138
1294
3.33134
1238
3.33129
1229
3.33125
1173
3.3312
1134
3.33116
1140
3.33111
1103
3.33107
1072
3.33102
1037
3.33098
1019
3.33093
1015
3.33089
1001
3.33084
964
3.3308
943
3.33075
927
3.33071
967
3.33066
965
3.33062
918
3.33057
899
3.33053
888
3.33048
893
3.33044
945
3.33039
937
3.33035
923
3.3303
864
3.33026
918
3.33021
952
3.33017
892
3.33012
877
3.33008
901
3.33004
910
3.32999
909
3.32995
947
3.3299
919
3.32986
883
3.32981
863
3.32977
876
3.32972
910
3.32968
888
3.32963
891
3.32959
887
3.32954
892
3.3295
909
3.32945
884
3.32941
849
3.32936
914
3.32932
883
3.32927
847
3.32923
857
3.32918
889
3.32914
872
3.32909
888
3.32905
829
3.329
851
3.32896
871
3.32891
829
3.32887
848
3.32882
856
3.32878
841
3.32873
875
3.32869
933
3.32865
905
3.3286
889
3.32856
881
3.32851
832
3.32847
872
3.32842
856
3.32838
890
3.32833
897
3.32829
888
3.32824
886
3.3282
880
3.32815
859
3.32811
847
3.32806
864
3.32802
888
3.32797
829
3.32793
851
3.32788
854
3.32784
839
3.32779
839
3.32775
845
3.3277
869
3.32766
885
3.32761
825
3.32757
885
3.32752
888
3.32748
873
3.32743
856
3.32739
858
3.32735
840
3.3273
872
3.32726
854
3.32721
859
3.32717
897
3.32712
889
3.32708
829
3.32703
902
3.32699
823
3.32694
803
3.3269
851
3.32685
878
3.32681
841
3.32676
823
3.32672
858
3.32667
892
3.32663
881
3.32658
841
3.32654
843
3.32649
856
3.32645
766
3.3264
834
3.32636
811
3.32631
883
3.32627
806
3.32622
837
3.32618
824
3.32613
852
3.32609
850
3.32604
850
3.326
800
3.32596
851
3.32591
834
3.32587
851
3.32582
872
3.32578
892
3.32573
878
3.32569
C 1s/7
Not Specified
2017
7
4
12
37
14
0
9
Casa Info Follows
1
Calib M = 283.074 A = 284.6 BE ADD
0
0
0
   XPS     Spectrum    Lens Mode:Hybrid   Resolution:Pass energy 40    Iris(Aper):slot(Slot)
   Acqn. Time(s): 138        Sweeps: 2        Anode:Mono(Al (Mono))(150 W)   Step(meV): 50.0
   Dwell Time(ms): 150        Charge Neutraliser :On   Acquired On :17/07/04 12:37:14
XPS
59
-3
0
Mono(Al (Mono))
1486.69
150
1e+037
1e+037
6000
6000
1e+037
1e+037
FAT
40
1e+037
-4.45
0
1e+037
1e+037
1e+037
1e+037
C
1s
-1
Kinetic Energy
eV
1190.19
0.05
2
Intensity
d
Transmission
d
pulse counting
0.15
2
0
1e+037
1e+037
1e+037
0
922
81
3003
3.16755
3.19198
398
3.16755
376
3.1676
379
3.16765
382
3.16771
388
3.16776
403
3.16781
370
3.16787
361
3.16792
396
3.16797
409
3.16802
347
3.16808
365
3.16813
367
3.16818
384
3.16824
358
3.16829
385
3.16834
379
3.1684
365
3.16845
398
3.1685
379
3.16856
371
3.16861
360
3.16866
349
3.16871
357
3.16877
343
3.16882
343
3.16887
352
3.16893
364
3.16898
340
3.16903
336
3.16909
337
3.16914
343
3.16919
378
3.16925
378
3.1693
359
3.16935
344
3.16941
345
3.16946
310
3.16951
299
3.16956
357
3.16962
350
3.16967
335
3.16972
339
3.16978
351
3.16983
347
3.16988
352
3.16994
329
3.16999
379
3.17004
347
3.1701
310
3.17015
365
3.1702
341
3.17025
343
3.17031
328
3.17036
308
3.17041
336
3.17047
309
3.17052
313
3.17057
330
3.17063
314
3.17068
300
3.17073
320
3.17079
344
3.17084
311
3.17089
317
3.17095
322
3.171
311
3.17105
336
3.1711
343
3.17116
316
3.17121
304
3.17126
338
3.17132
306
3.17137
318
3.17142
293
3.17148
319
3.17153
285
3.17158
289
3.17164
320
3.17169
329
3.17174
291
3.17179
300
3.17185
322
3.1719
309
3.17195
314
3.17201
293
3.17206
306
3.17211
296
3.17217
315
3.17222
295
3.17227
317
3.17233
312
3.17238
304
3.17243
320
3.17249
345
3.17254
357
3.17259
339
3.17264
289
3.1727
317
3.17275
327
3.1728
329
3.17286
330
3.17291
331
3.17296
344
3.17302
338
3.17307
347
3.17312
330
3.17318
354
3.17323
344
3.17328
329
3.17334
327
3.17339
359
3.17344
352
3.17349
356
3.17355
373
3.1736
388
3.17365
361
3.17371
384
3.17376
410
3.17381
384
3.17387
398
3.17392
429
3.17397
427
3.17403
422
3.17408
463
3.17413
456
3.17418
468
3.17424
467
3.17429
512
3.17434
519
3.1744
539
3.17445
532
3.1745
520
3.17456
571
3.17461
601
3.17466
579
3.17472
606
3.17477
569
3.17482
576
3.17488
600
3.17493
619
3.17498
644
3.17503
663
3.17509
636
3.17514
597
3.17519
655
3.17525
644
3.1753
700
3.17535
690
3.17541
732
3.17546
732
3.17551
754
3.17557
789
3.17562
859
3.17567
863
3.17572
874
3.17578
912
3.17583
972
3.17588
994
3.17594
1083
3.17599
1120
3.17604
1161
3.1761
1247
3.17615
1308
3.1762
1397
3.17626
1458
3.17631
1456
3.17636
1610
3.17642
1639
3.17647
1740
3.17652
1831
3.17657
1890
3.17663
1950
3.17668
1921
3.17673
2009
3.17679
1973
3.17684
2015
3.17689
2031
3.17695
2052
3.177
2038
3.17705
2029
3.17711
1964
3.17716
1905
3.17721
1869
3.17726
1776
3.17732
1721
3.17737
1723
3.17742
1686
3.17748
1628
3.17753
1529
3.17758
1529
3.17764
1543
3.17769
1504
3.17774
1511
3.1778
1447
3.17785
1475
3.1779
1422
3.17796
1460
3.17801
1481
3.17806
1415
3.17811
1378
3.17817
1433
3.17822
1390
3.17827
1415
3.17833
1429
3.17838
1459
3.17843
1459
3.17849
1566
3.17854
1563
3.17859
1638
3.17865
1669
3.1787
1731
3.17875
1771
3.17881
1835
3.17886
1938
3.17891
2046
3.17896
2093
3.17902
2142
3.17907
2222
3.17912
2264
3.17918
2489
3.17923
2595
3.17928
2613
3.17934
2718
3.17939
2764
3.17944
2819
3.1795
2902
3.17955
3000
3.1796
2998
3.17965
2994
3.17971
3002
3.17976
3003
3.17981
2879
3.17987
2935
3.17992
2856
3.17997
2760
3.18003
2719
3.18008
2608
3.18013
2634
3.18019
2460
3.18024
2416
3.18029
2302
3.18035
2208
3.1804
2106
3.18045
2083
3.1805
2019
3.18056
1981
3.18061
1928
3.18066
1895
3.18072
1855
3.18077
1890
3.18082
1885
3.18088
1902
3.18093
1909
3.18098
1849
3.18104
1896
3.18109
1968
3.18114
1935
3.1812
1942
3.18125
2057
3.1813
2117
3.18135
2150
3.18141
2162
3.18146
2225
3.18151
2156
3.18157
2228
3.18162
2276
3.18167
2367
3.18173
2288
3.18178
2240
3.18183
2176
3.18189
2187
3.18194
2193
3.18199
2226
3.18204
2219
3.1821
2156
3.18215
2054
3.1822
2036
3.18226
1932
3.18231
1869
3.18236
1831
3.18242
1813
3.18247
1673
3.18252
1670
3.18258
1531
3.18263
1450
3.18268
1385
3.18274
1327
3.18279
1205
3.18284
1141
3.18289
1051
3.18295
998
3.183
917
3.18305
823
3.18311
770
3.18316
673
3.18321
609
3.18327
593
3.18332
496
3.18337
478
3.18343
406
3.18348
383
3.18353
383
3.18358
324
3.18364
317
3.18369
298
3.18374
239
3.1838
225
3.18385
211
3.1839
162
3.18396
208
3.18401
168
3.18406
155
3.18412
175
3.18417
151
3.18422
166
3.18428
143
3.18433
139
3.18438
133
3.18443
136
3.18449
135
3.18454
149
3.18459
137
3.18465
130
3.1847
129
3.18475
125
3.18481
128
3.18486
127
3.18491
120
3.18497
108
3.18502
117
3.18507
128
3.18512
100
3.18518
105
3.18523
123
3.18528
112
3.18534
117
3.18539
106
3.18544
98
3.1855
112
3.18555
110
3.1856
101
3.18566
125
3.18571
113
3.18576
109
3.18582
101
3.18587
104
3.18592
114
3.18597
123
3.18603
118
3.18608
99
3.18613
104
3.18619
113
3.18624
111
3.18629
98
3.18635
128
3.1864
82
3.18645
82
3.18651
101
3.18656
102
3.18661
109
3.18667
117
3.18672
113
3.18677
103
3.18682
115
3.18688
105
3.18693
100
3.18698
108
3.18704
108
3.18709
91
3.18714
87
3.1872
107
3.18725
100
3.1873
97
3.18736
102
3.18741
114
3.18746
110
3.18751
99
3.18757
104
3.18762
105
3.18767
106
3.18773
113
3.18778
96
3.18783
85
3.18789
131
3.18794
109
3.18799
97
3.18805
103
3.1881
87
3.18815
124
3.18821
100
3.18826
106
3.18831
109
3.18836
106
3.18842
121
3.18847
109
3.18852
90
3.18858
103
3.18863
126
3.18868
100
3.18874
107
3.18879
112
3.18884
104
3.1889
110
3.18895
116
3.189
97
3.18905
97
3.18911
95
3.18916
99
3.18921
87
3.18927
103
3.18932
109
3.18937
110
3.18943
104
3.18948
99
3.18953
111
3.18959
106
3.18964
103
3.18969
108
3.18975
103
3.1898
100
3.18985
110
3.1899
103
3.18996
95
3.19001
93
3.19006
88
3.19012
95
3.19017
107
3.19022
113
3.19028
115
3.19033
96
3.19038
103
3.19044
98
3.19049
98
3.19054
81
3.19059
96
3.19065
103
3.1907
98
3.19075
110
3.19081
108
3.19086
105
3.19091
101
3.19097
109
3.19102
102
3.19107
100
3.19113
103
3.19118
99
3.19123
92
3.19129
102
3.19134
100
3.19139
95
3.19144
90
3.1915
99
3.19155
88
3.1916
95
3.19166
93
3.19171
103
3.19176
107
3.19182
89
3.19187
88
3.19192
114
3.19198
end of experiment