File: A2.vms
VAMAS Surface Chemical Analysis Standard Data Transfer Format 1988 May 4
Not Specified
Kratos Axis
Not Specified
/d=/data/20170705/2017006144/A2.dset
3
Casa Info Follows
0
SourceAnalyserAngle: Not Specified
MAP
REGULAR
4
2
32768
32768
1
Etch Time
s
0
0
0
0
4
wide/2
Not Specified
2017
7
4
10
47
6
0
23
Casa Info Follows
1
Calib M = 283.291 A = 284.6 BE ADD
7
annot text peak Data 1197.38 1551 RGB(0,0,0) Font(14,18,0,0,Times New Roman) Vertical
C 1s
annot text peak Data 509.381 1864 RGB(0,0,0) Font(14,18,0,0,Times New Roman) Vertical
O KLL
annot text peak Data 954.381 2618 RGB(0,0,0) Font(14,18,0,0,Times New Roman) Vertical
O 1s
annot text peak Data 642 1405 RGB(0,0,0) Font(14,18,0,0,Times New Roman) Vertical
F KLL
annot text peak Data 799.381 4720 RGB(0,0,0) Font(14,18,0,0,Times New Roman) Vertical
F 1s
annot text peak Data 1257.69 79 RGB(0,0,0) Font(14,18,0,0,Times New Roman) Vertical
S 2s
annot text peak Data 1319.38 121 RGB(0,0,0) Font(14,18,0,0,Times New Roman) Vertical
S 2p
0
0
   XPS     Spectrum    Lens Mode:Hybrid   Resolution:Pass energy 80    Iris(Aper):slot(Slot)
   Acqn. Time(s): 110        Sweeps: 1        Anode:Mono(Al (Mono))(150 W)   Step(meV): 1000.0
   Dwell Time(ms): 100        Charge Neutraliser :On   Acquired On :17/07/04 10:47:06
XPS
68
-2
0
Mono(Al (Mono))
1486.69
150
1e+037
1e+037
6000
6000
1e+037
1e+037
FAT
80
1e+037
-4.45
0
1e+037
1e+037
1e+037
1e+037
Wide
None
-1
Kinetic Energy
eV
386.69
1
2
Intensity
d
Transmission
d
pulse counting
0.1
0
1e+037
0
0
8.48115
1552
1525
1510
1521
1529
1499
1449
1532
1477
1485
1550
1543
1520
1590
1531
1499
1535
1486
1469
1550
1495
1554
1521
1587
1525
1518
1536
1522
1512
1507
1570
1555
1550
1565
1488
1541
1628
1540
1529
1596
1630
1519
1531
1551
1623
1576
1629
1689
1580
1554
1547
1592
1617
1584
1555
1555
1549
1560
1634
1653
1606
1617
1620
1598
1612
1645
1614
1641
1629
1608
1607
1621
1640
1608
1638
1631
1636
1601
1639
1652
1644
1690
1685
1640
1611
1681
1707
1674
1680
1621
1651
1696
1689
1626
1635
1659
1724
1715
1814
1723
1685
1777
1755
1651
1723
1727
1744
1666
1722
1693
1668
1646
1611
1617
1608
1576
1616
1686
1680
1679
1682
1693
1784
1829
1864
1839
1793
1789
1769
1696
1677
1595
1612
1529
1431
1433
1427
1374
1368
1377
1361
1368
1302
1339
1392
1351
1379
1323
1340
1319
1361
1378
1371
1313
1352
1389
1369
1343
1392
1358
1401
1387
1390
1374
1341
1341
1332
1348
1393
1366
1339
1349
1373
1435
1425
1366
1374
1370
1361
1403
1395
1389
1393
1405
1394
1417
1379
1423
1429
1402
1394
1422
1439
1392
1489
1422
1431
1377
1426
1453
1496
1446
1420
1483
1496
1482
1460
1439
1465
1476
1467
1486
1538
1513
1525
1524
1419
1485
1475
1531
1567
1504
1568
1593
1563
1523
1484
1514
1496
1485
1526
1503
1560
1471
1548
1583
1582
1598
1676
1677
1672
1800
1732
1648
1634
1642
1613
1642
1578
1585
1650
1564
1511
1490
1433
1444
1405
1407
1432
1510
1517
1495
1579
1641
1796
1948
2152
2232
2343
2352
2185
2031
1917
1791
1636
1579
1567
1499
1365
1384
1228
1247
1203
1156
1092
1165
1135
1156
1165
1166
1085
1116
1109
1076
1103
1158
1117
1131
1145
1135
1079
1147
1175
1126
1085
1093
1146
1110
1110
1079
1108
1121
1143
1173
1149
1154
1147
1146
1138
1152
1125
1127
1159
1163
1170
1136
1152
1138
1202
1180
1149
1126
1128
1178
1176
1187
1159
1120
1119
1144
1211
1155
1110
1120
1158
1228
1181
1153
1149
1139
1182
1148
1166
1233
1241
1219
1214
1186
1174
1187
1135
1128
1176
1201
1157
1196
1211
1227
1173
1191
1152
1144
1156
1176
1175
1238
1239
1305
1236
1214
1301
1319
1266
1273
1244
1225
1283
1250
1222
1259
1240
1231
1182
1233
1197
1146
1194
1110
1056
1061
969
987
976
982
943
906
905
916
948
1084
1440
2035
2965
4649
4720
2392
1082
878
842
794
775
796
847
784
762
800
813
825
808
792
837
848
827
782
776
793
809
838
801
825
798
794
850
762
794
851
808
810
831
836
829
845
848
855
845
825
817
809
828
821
821
804
832
827
847
836
808
812
794
793
805
806
848
851
806
802
749
818
791
839
846
838
829
775
831
838
816
793
821
778
831
791
817
820
824
836
844
792
776
802
823
840
782
805
815
815
835
817
804
829
795
779
819
847
832
838
834
809
787
807
846
816
854
837
774
815
793
826
750
809
827
806
804
821
807
809
820
800
788
749
843
853
818
823
845
859
825
822
850
782
750
716
707
728
693
656
638
636
606
565
541
505
510
542
554
722
994
1377
2038
2618
2140
1190
596
444
411
398
401
388
414
394
408
398
392
406
395
394
396
419
404
418
420
408
401
401
385
374
402
436
389
395
372
387
404
423
414
409
400
431
412
391
402
407
395
383
391
424
419
386
398
380
399
396
403
420
426
390
392
435
416
410
416
403
423
372
426
446
434
420
399
412
390
395
447
446
382
431
418
435
459
419
412
408
383
433
451
407
436
428
410
413
424
441
428
425
412
406
397
424
408
413
421
432
419
424
406
412
421
413
429
411
399
435
432
430
425
421
411
403
405
436
402
401
441
461
462
437
439
429
428
482
489
468
449
434
438
426
446
453
436
406
407
423
404
382
437
423
437
436
445
436
408
423
478
424
420
385
403
445
462
466
481
465
501
462
463
449
443
454
466
443
431
465
465
421
493
460
461
458
446
467
435
428
481
465
468
468
447
456
495
472
430
448
484
443
508
500
470
490
447
440
472
458
456
460
481
472
471
495
498
490
518
517
482
525
492
519
496
510
508
514
459
483
472
449
472
455
415
397
391
376
350
324
303
290
263
250
243
239
296
448
599
934
1551
1539
1346
1389
1112
903
579
236
102
69
81
71
86
69
81
81
70
80
83
73
84
76
64
78
74
71
62
71
77
83
64
64
80
87
88
63
81
71
75
75
68
77
70
74
68
70
68
59
65
70
79
70
73
90
86
92
99
94
114
95
79
84
66
61
81
62
90
66
72
81
73
75
76
72
76
65
66
68
70
70
80
65
61
73
63
63
73
70
85
96
92
77
66
68
61
75
85
69
76
78
76
68
67
67
52
71
68
63
74
74
56
56
52
66
72
54
80
69
76
92
109
112
121
71
61
69
63
66
48
68
61
75
64
60
49
57
71
68
64
72
47
68
86
63
59
66
55
55
66
70
64
62
69
63
75
66
59
65
63
64
57
57
62
66
81
61
52
62
57
62
83
60
69
66
77
57
51
55
44
60
53
64
62
79
80
72
68
66
67
75
60
60
63
60
65
61
63
73
63
70
76
76
60
62
82
52
82
80
66
55
64
69
69
81
76
66
50
77
78
73
60
60
61
85
77
84
78
62
65
74
74
74
81
74
74
72
72
77
87
76
71
67
64
66
64
53
60
66
50
63
65
77
77
97
126
157
171
150
110
86
73
92
88
74
81
62
49
66
60
48
56
57
59
83
83
75
72
56
55
55
58
44
29
31
20
16
8
4
0
8.94051
F 1s/5
Not Specified
2017
7
4
12
47
15
0
9
Casa Info Follows
1
Calib M = 283.291 A = 284.6 BE ADD
0
0
0
   XPS     Spectrum    Lens Mode:Hybrid   Resolution:Pass energy 40    Iris(Aper):slot(Slot)
   Acqn. Time(s): 121        Sweeps: 2        Anode:Mono(Al (Mono))(150 W)   Step(meV): 50.0
   Dwell Time(ms): 150        Charge Neutraliser :On   Acquired On :17/07/04 12:47:15
XPS
68
-2
0
Mono(Al (Mono))
1486.69
150
1e+037
1e+037
6000
6000
1e+037
1e+037
FAT
40
1e+037
-4.45
0
1e+037
1e+037
1e+037
1e+037
F
1s
-1
Kinetic Energy
eV
790.64
0.05
2
Intensity
d
Transmission
d
pulse counting
0.15
2
0
1e+037
1e+037
1e+037
0
806
856
7218
3.41724
3.42712
1064
3.42712
1065
3.4271
1035
3.42707
1031
3.42705
1017
3.42702
1064
3.427
1020
3.42698
1038
3.42695
1075
3.42693
1005
3.4269
1047
3.42688
1044
3.42686
1039
3.42683
1053
3.42681
1062
3.42678
1008
3.42676
1003
3.42674
1010
3.42671
1063
3.42669
1054
3.42667
1031
3.42664
1024
3.42662
1040
3.42659
1014
3.42657
1063
3.42655
1037
3.42652
1023
3.4265
1043
3.42647
1040
3.42645
1030
3.42643
967
3.4264
1040
3.42638
1051
3.42636
1006
3.42633
987
3.42631
1023
3.42628
1032
3.42626
1037
3.42624
1041
3.42621
1002
3.42619
985
3.42616
1019
3.42614
1003
3.42612
1048
3.42609
1061
3.42607
1041
3.42605
1028
3.42602
994
3.426
1051
3.42597
1002
3.42595
999
3.42593
1030
3.4259
1012
3.42588
993
3.42585
1006
3.42583
1075
3.42581
1014
3.42578
1029
3.42576
1013
3.42573
1024
3.42571
1054
3.42569
1026
3.42566
1014
3.42564
1034
3.42562
1048
3.42559
1017
3.42557
1006
3.42554
1053
3.42552
1028
3.4255
1081
3.42547
1038
3.42545
1031
3.42542
996
3.4254
1045
3.42538
1063
3.42535
1105
3.42533
1092
3.42531
1057
3.42528
1104
3.42526
1104
3.42523
1055
3.42521
1104
3.42519
1097
3.42516
1145
3.42514
1166
3.42511
1201
3.42509
1218
3.42507
1234
3.42504
1172
3.42502
1141
3.425
1187
3.42497
1186
3.42495
1234
3.42492
1243
3.4249
1286
3.42488
1294
3.42485
1309
3.42483
1302
3.4248
1325
3.42478
1329
3.42476
1346
3.42473
1357
3.42471
1401
3.42469
1386
3.42466
1381
3.42464
1439
3.42461
1497
3.42459
1515
3.42457
1542
3.42454
1516
3.42452
1563
3.42449
1579
3.42447
1544
3.42445
1599
3.42442
1574
3.4244
1554
3.42437
1546
3.42435
1635
3.42433
1695
3.4243
1713
3.42428
1699
3.42426
1725
3.42423
1716
3.42421
1746
3.42418
1800
3.42416
1857
3.42414
1802
3.42411
1873
3.42409
1952
3.42406
1965
3.42404
1953
3.42402
2038
3.42399
2064
3.42397
2092
3.42395
2082
3.42392
2117
3.4239
2155
3.42387
2222
3.42385
2210
3.42383
2274
3.4238
2300
3.42378
2374
3.42375
2465
3.42373
2404
3.42371
2504
3.42368
2583
3.42366
2624
3.42364
2607
3.42361
2597
3.42359
2697
3.42356
2760
3.42354
2815
3.42352
2927
3.42349
3003
3.42347
3098
3.42344
3073
3.42342
3178
3.4234
3385
3.42337
3433
3.42335
3508
3.42333
3531
3.4233
3632
3.42328
3842
3.42325
3885
3.42323
4114
3.42321
4303
3.42318
4376
3.42316
4465
3.42313
4651
3.42311
4713
3.42309
4960
3.42306
5112
3.42304
5260
3.42301
5561
3.42299
5609
3.42297
5821
3.42294
6133
3.42292
6130
3.4229
6323
3.42287
6449
3.42285
6618
3.42282
6688
3.4228
6896
3.42278
7081
3.42275
7131
3.42273
7154
3.4227
7218
3.42268
7181
3.42266
7172
3.42263
7128
3.42261
7144
3.42259
6943
3.42256
6899
3.42254
6745
3.42251
6735
3.42249
6619
3.42247
6286
3.42244
5983
3.42242
5800
3.42239
5475
3.42237
5179
3.42235
5031
3.42232
4813
3.4223
4447
3.42228
4257
3.42225
3975
3.42223
3750
3.4222
3530
3.42218
3262
3.42216
3044
3.42213
2870
3.42211
2727
3.42208
2576
3.42206
2470
3.42204
2306
3.42201
2227
3.42199
2049
3.42196
1931
3.42194
1848
3.42192
1776
3.42189
1636
3.42187
1660
3.42185
1620
3.42182
1523
3.4218
1447
3.42177
1398
3.42175
1406
3.42173
1354
3.4217
1265
3.42168
1249
3.42165
1238
3.42163
1192
3.42161
1193
3.42158
1194
3.42156
1145
3.42154
1106
3.42151
1165
3.42149
1157
3.42146
1155
3.42144
1088
3.42142
1030
3.42139
1071
3.42137
1072
3.42134
1074
3.42132
1072
3.4213
1067
3.42127
1063
3.42125
1076
3.42123
1004
3.4212
987
3.42118
981
3.42115
1020
3.42113
986
3.42111
977
3.42108
995
3.42106
982
3.42103
1001
3.42101
971
3.42099
974
3.42096
1011
3.42094
997
3.42091
964
3.42089
1006
3.42087
984
3.42084
976
3.42082
977
3.4208
952
3.42077
950
3.42075
946
3.42072
935
3.4207
963
3.42068
948
3.42065
965
3.42063
962
3.4206
918
3.42058
941
3.42056
995
3.42053
982
3.42051
965
3.42049
944
3.42046
986
3.42044
928
3.42041
956
3.42039
931
3.42037
962
3.42034
962
3.42032
930
3.42029
947
3.42027
950
3.42025
908
3.42022
951
3.4202
915
3.42018
921
3.42015
969
3.42013
973
3.4201
910
3.42008
947
3.42006
946
3.42003
913
3.42001
893
3.41998
908
3.41996
972
3.41994
958
3.41991
921
3.41989
922
3.41986
965
3.41984
979
3.41982
926
3.41979
948
3.41977
919
3.41975
940
3.41972
945
3.4197
953
3.41967
937
3.41965
926
3.41963
943
3.4196
920
3.41958
932
3.41955
971
3.41953
954
3.41951
894
3.41948
967
3.41946
973
3.41944
957
3.41941
968
3.41939
919
3.41936
959
3.41934
993
3.41932
956
3.41929
884
3.41927
970
3.41924
940
3.41922
951
3.4192
917
3.41917
935
3.41915
972
3.41913
989
3.4191
913
3.41908
908
3.41905
964
3.41903
951
3.41901
856
3.41898
868
3.41896
883
3.41893
933
3.41891
909
3.41889
906
3.41886
938
3.41884
965
3.41881
942
3.41879
976
3.41877
894
3.41874
937
3.41872
915
3.4187
875
3.41867
938
3.41865
937
3.41862
928
3.4186
971
3.41858
941
3.41855
933
3.41853
958
3.4185
950
3.41848
950
3.41846
924
3.41843
963
3.41841
1015
3.41839
929
3.41836
953
3.41834
909
3.41831
908
3.41829
928
3.41827
909
3.41824
963
3.41822
946
3.41819
909
3.41817
956
3.41815
960
3.41812
928
3.4181
936
3.41808
908
3.41805
890
3.41803
951
3.418
903
3.41798
937
3.41796
942
3.41793
918
3.4179
918
3.41786
959
3.41781
907
3.41777
931
3.41773
954
3.41769
909
3.41765
874
3.41761
911
3.41757
934
3.41753
910
3.41748
872
3.41744
891
3.4174
962
3.41736
935
3.41732
933
3.41728
942
3.41724
O 1s/6
Not Specified
2017
7
4
12
47
15
0
9
Casa Info Follows
1
Calib M = 283.291 A = 284.6 BE ADD
0
0
0
   XPS     Spectrum    Lens Mode:Hybrid   Resolution:Pass energy 40    Iris(Aper):slot(Slot)
   Acqn. Time(s): 162        Sweeps: 3        Anode:Mono(Al (Mono))(150 W)   Step(meV): 50.0
   Dwell Time(ms): 150        Charge Neutraliser :On   Acquired On :17/07/04 12:47:15
XPS
68
-2
0
Mono(Al (Mono))
1486.69
150
1e+037
1e+037
6000
6000
1e+037
1e+037
FAT
40
1e+037
-4.45
0
1e+037
1e+037
1e+037
1e+037
O
1s
-1
Kinetic Energy
eV
946.69
0.05
2
Intensity
d
Transmission
d
pulse counting
0.15
3
0
1e+037
1e+037
1e+037
0
722
611
5145
3.32569
3.34183
943
3.34183
838
3.34178
861
3.34174
874
3.34169
904
3.34165
854
3.3416
906
3.34156
888
3.34151
925
3.34147
928
3.34142
911
3.34138
918
3.34133
893
3.34129
908
3.34124
892
3.3412
877
3.34115
878
3.34111
865
3.34107
831
3.34102
907
3.34098
842
3.34093
897
3.34089
880
3.34084
903
3.3408
870
3.34075
851
3.34071
837
3.34066
839
3.34062
821
3.34057
886
3.34053
946
3.34048
886
3.34044
850
3.34039
877
3.34035
844
3.3403
908
3.34026
873
3.34021
867
3.34017
859
3.34012
849
3.34008
810
3.34003
890
3.33999
865
3.33994
871
3.3399
831
3.33985
899
3.33981
876
3.33976
863
3.33972
882
3.33968
869
3.33963
882
3.33959
895
3.33954
870
3.3395
874
3.33945
894
3.33941
875
3.33936
898
3.33932
837
3.33927
898
3.33923
869
3.33918
942
3.33914
931
3.33909
897
3.33905
927
3.339
914
3.33896
914
3.33891
892
3.33887
999
3.33882
956
3.33878
919
3.33873
963
3.33869
1018
3.33864
990
3.3386
1028
3.33855
1033
3.33851
1064
3.33846
1086
3.33842
1082
3.33837
1064
3.33833
1106
3.33829
1117
3.33824
1133
3.3382
1216
3.33815
1218
3.33811
1191
3.33806
1149
3.33802
1198
3.33797
1211
3.33793
1236
3.33788
1268
3.33784
1295
3.33779
1358
3.33775
1355
3.3377
1334
3.33766
1346
3.33761
1348
3.33757
1384
3.33752
1345
3.33748
1397
3.33743
1475
3.33739
1536
3.33734
1475
3.3373
1463
3.33725
1586
3.33721
1530
3.33716
1519
3.33712
1518
3.33707
1597
3.33703
1587
3.33698
1594
3.33694
1637
3.3369
1633
3.33685
1669
3.33681
1677
3.33676
1671
3.33672
1679
3.33667
1633
3.33663
1639
3.33658
1678
3.33654
1743
3.33649
1763
3.33645
1740
3.3364
1811
3.33636
1846
3.33631
1910
3.33627
1845
3.33622
1862
3.33618
1906
3.33613
1925
3.33609
1938
3.33604
2034
3.336
2060
3.33595
2067
3.33591
2084
3.33586
2122
3.33582
2141
3.33577
2236
3.33573
2279
3.33568
2272
3.33564
2367
3.3356
2400
3.33555
2489
3.33551
2495
3.33546
2554
3.33542
2677
3.33537
2715
3.33533
2686
3.33528
2808
3.33524
2896
3.33519
2993
3.33515
3061
3.3351
3186
3.33506
3179
3.33501
3262
3.33497
3401
3.33492
3517
3.33488
3538
3.33483
3736
3.33479
3800
3.33474
3916
3.3347
4006
3.33465
4065
3.33461
4215
3.33456
4325
3.33452
4411
3.33447
4432
3.33443
4567
3.33438
4729
3.33434
4648
3.33429
4793
3.33425
4829
3.33421
4937
3.33416
5002
3.33412
5089
3.33407
5145
3.33403
5089
3.33398
5031
3.33394
5082
3.33389
4984
3.33385
4944
3.3338
4920
3.33376
4904
3.33371
4837
3.33367
4808
3.33362
4667
3.33358
4673
3.33353
4492
3.33349
4252
3.33344
4276
3.3334
4162
3.33335
4085
3.33331
3961
3.33326
3921
3.33322
3734
3.33317
3605
3.33313
3399
3.33308
3341
3.33304
3178
3.33299
3094
3.33295
2929
3.3329
2886
3.33286
2782
3.33282
2733
3.33277
2598
3.33273
2458
3.33268
2383
3.33264
2219
3.33259
2154
3.33255
2067
3.3325
2065
3.33246
1949
3.33241
1826
3.33237
1725
3.33232
1742
3.33228
1595
3.33223
1543
3.33219
1500
3.33214
1403
3.3321
1360
3.33205
1264
3.33201
1214
3.33196
1212
3.33192
1137
3.33187
1117
3.33183
1097
3.33178
1053
3.33174
1012
3.33169
1006
3.33165
948
3.3316
923
3.33156
868
3.33151
829
3.33147
838
3.33143
820
3.33138
799
3.33134
775
3.33129
762
3.33125
760
3.3312
721
3.33116
738
3.33111
774
3.33107
759
3.33102
808
3.33098
730
3.33093
696
3.33089
781
3.33084
728
3.3308
661
3.33075
718
3.33071
709
3.33066
708
3.33062
682
3.33057
750
3.33053
718
3.33048
686
3.33044
697
3.33039
653
3.33035
734
3.3303
699
3.33026
680
3.33021
704
3.33017
717
3.33012
668
3.33008
696
3.33004
684
3.32999
657
3.32995
658
3.3299
701
3.32986
663
3.32981
697
3.32977
681
3.32972
665
3.32968
637
3.32963
649
3.32959
667
3.32954
648
3.3295
681
3.32945
683
3.32941
721
3.32936
681
3.32932
674
3.32927
665
3.32923
703
3.32918
665
3.32914
677
3.32909
662
3.32905
690
3.329
690
3.32896
655
3.32891
686
3.32887
691
3.32882
688
3.32878
694
3.32873
684
3.32869
673
3.32865
670
3.3286
653
3.32856
653
3.32851
649
3.32847
687
3.32842
729
3.32838
676
3.32833
677
3.32829
632
3.32824
668
3.3282
647
3.32815
641
3.32811
657
3.32806
648
3.32802
655
3.32797
675
3.32793
688
3.32788
681
3.32784
687
3.32779
611
3.32775
693
3.3277
675
3.32766
687
3.32761
708
3.32757
659
3.32752
659
3.32748
635
3.32743
662
3.32739
637
3.32735
634
3.3273
668
3.32726
676
3.32721
666
3.32717
644
3.32712
631
3.32708
649
3.32703
700
3.32699
682
3.32694
713
3.3269
728
3.32685
657
3.32681
706
3.32676
688
3.32672
714
3.32667
660
3.32663
686
3.32658
707
3.32654
686
3.32649
721
3.32645
662
3.3264
663
3.32636
656
3.32631
673
3.32627
724
3.32622
667
3.32618
686
3.32613
696
3.32609
683
3.32604
677
3.326
651
3.32596
662
3.32591
637
3.32587
673
3.32582
656
3.32578
656
3.32573
680
3.32569
C 1s/7
Not Specified
2017
7
4
12
47
15
0
9
Casa Info Follows
1
Calib M = 283.291 A = 284.6 BE ADD
0
0
0
   XPS     Spectrum    Lens Mode:Hybrid   Resolution:Pass energy 40    Iris(Aper):slot(Slot)
   Acqn. Time(s): 138        Sweeps: 2        Anode:Mono(Al (Mono))(150 W)   Step(meV): 50.0
   Dwell Time(ms): 150        Charge Neutraliser :On   Acquired On :17/07/04 12:47:15
XPS
68
-2
0
Mono(Al (Mono))
1486.69
150
1e+037
1e+037
6000
6000
1e+037
1e+037
FAT
40
1e+037
-4.45
0
1e+037
1e+037
1e+037
1e+037
C
1s
-1
Kinetic Energy
eV
1190.19
0.05
2
Intensity
d
Transmission
d
pulse counting
0.15
2
0
1e+037
1e+037
1e+037
0
922
64
2206
3.16755
3.19198
301
3.16755
293
3.1676
268
3.16765
269
3.16771
260
3.16776
246
3.16781
247
3.16787
258
3.16792
289
3.16797
273
3.16802
283
3.16808
268
3.16813
264
3.16818
282
3.16824
247
3.16829
280
3.16834
264
3.1684
250
3.16845
273
3.1685
267
3.16856
247
3.16861
262
3.16866
267
3.16871
262
3.16877
252
3.16882
263
3.16887
253
3.16893
247
3.16898
294
3.16903
262
3.16909
254
3.16914
256
3.16919
246
3.16925
264
3.1693
260
3.16935
252
3.16941
235
3.16946
268
3.16951
269
3.16956
242
3.16962
235
3.16967
261
3.16972
263
3.16978
270
3.16983
258
3.16988
268
3.16994
238
3.16999
240
3.17004
226
3.1701
238
3.17015
260
3.1702
262
3.17025
277
3.17031
243
3.17036
258
3.17041
257
3.17047
243
3.17052
258
3.17057
275
3.17063
235
3.17068
251
3.17073
254
3.17079
270
3.17084
251
3.17089
270
3.17095
281
3.171
275
3.17105
306
3.1711
297
3.17116
312
3.17121
286
3.17126
310
3.17132
295
3.17137
350
3.17142
345
3.17148
343
3.17153
316
3.17158
370
3.17164
361
3.17169
344
3.17174
379
3.17179
375
3.17185
372
3.1719
395
3.17195
364
3.17201
380
3.17206
368
3.17211
373
3.17217
396
3.17222
432
3.17227
410
3.17233
387
3.17238
387
3.17243
411
3.17249
415
3.17254
388
3.17259
431
3.17264
404
3.1727
425
3.17275
432
3.1728
457
3.17286
419
3.17291
444
3.17296
448
3.17302
439
3.17307
418
3.17312
458
3.17318
451
3.17323
475
3.17328
505
3.17334
481
3.17339
523
3.17344
524
3.17349
493
3.17355
500
3.1736
509
3.17365
502
3.17371
546
3.17376
552
3.17381
593
3.17387
593
3.17392
572
3.17397
601
3.17403
626
3.17408
644
3.17413
636
3.17418
654
3.17424
735
3.17429
698
3.17434
704
3.1744
755
3.17445
796
3.1745
834
3.17456
816
3.17461
869
3.17466
894
3.17472
870
3.17477
949
3.17482
919
3.17488
963
3.17493
1019
3.17498
1087
3.17503
1019
3.17509
1053
3.17514
1061
3.17519
1131
3.17525
1198
3.1753
1154
3.17535
1222
3.17541
1236
3.17546
1306
3.17551
1274
3.17557
1315
3.17562
1321
3.17567
1403
3.17572
1404
3.17578
1440
3.17583
1501
3.17588
1600
3.17594
1600
3.17599
1656
3.17604
1774
3.1761
1732
3.17615
1830
3.1762
1895
3.17626
1913
3.17631
1904
3.17636
2001
3.17642
2081
3.17647
2124
3.17652
2148
3.17657
2206
3.17663
2158
3.17668
2159
3.17673
2179
3.17679
2157
3.17684
2106
3.17689
2041
3.17695
1999
3.177
1944
3.17705
1853
3.17711
1849
3.17716
1793
3.17721
1712
3.17726
1646
3.17732
1564
3.17737
1512
3.17742
1405
3.17748
1414
3.17753
1399
3.17758
1339
3.17764
1289
3.17769
1294
3.17774
1281
3.1778
1323
3.17785
1236
3.1779
1227
3.17796
1220
3.17801
1282
3.17806
1244
3.17811
1272
3.17817
1244
3.17822
1250
3.17827
1259
3.17833
1286
3.17838
1276
3.17843
1286
3.17849
1326
3.17854
1335
3.17859
1412
3.17865
1459
3.1787
1471
3.17875
1436
3.17881
1511
3.17886
1555
3.17891
1545
3.17896
1575
3.17902
1628
3.17907
1644
3.17912
1686
3.17918
1709
3.17923
1651
3.17928
1671
3.17934
1682
3.17939
1692
3.17944
1623
3.1795
1650
3.17955
1680
3.1796
1626
3.17965
1585
3.17971
1512
3.17976
1466
3.17981
1425
3.17987
1396
3.17992
1361
3.17997
1327
3.18003
1329
3.18008
1291
3.18013
1240
3.18019
1207
3.18024
1144
3.18029
1107
3.18035
1104
3.1804
1079
3.18045
1080
3.1805
1050
3.18056
1045
3.18061
1017
3.18066
1058
3.18072
1055
3.18077
1047
3.18082
1092
3.18088
1089
3.18093
1072
3.18098
1067
3.18104
1051
3.18109
1057
3.18114
1099
3.1812
1066
3.18125
1047
3.1813
1096
3.18135
1116
3.18141
1070
3.18146
1160
3.18151
1094
3.18157
1078
3.18162
1073
3.18167
1126
3.18173
1088
3.18178
1103
3.18183
1043
3.18189
964
3.18194
926
3.18199
932
3.18204
903
3.1821
892
3.18215
839
3.1822
835
3.18226
777
3.18231
720
3.18236
699
3.18242
660
3.18247
633
3.18252
576
3.18258
546
3.18263
512
3.18268
506
3.18274
492
3.18279
452
3.18284
418
3.18289
384
3.18295
344
3.183
320
3.18305
291
3.18311
257
3.18316
240
3.18321
224
3.18327
220
3.18332
199
3.18337
188
3.18343
178
3.18348
168
3.18353
154
3.18358
135
3.18364
133
3.18369
120
3.18374
134
3.1838
122
3.18385
111
3.1839
99
3.18396
115
3.18401
93
3.18406
114
3.18412
90
3.18417
108
3.18422
92
3.18428
111
3.18433
96
3.18438
92
3.18443
109
3.18449
102
3.18454
83
3.18459
92
3.18465
86
3.1847
102
3.18475
96
3.18481
68
3.18486
87
3.18491
91
3.18497
88
3.18502
96
3.18507
102
3.18512
85
3.18518
86
3.18523
84
3.18528
88
3.18534
97
3.18539
88
3.18544
107
3.1855
79
3.18555
90
3.1856
98
3.18566
88
3.18571
92
3.18576
85
3.18582
85
3.18587
86
3.18592
74
3.18597
91
3.18603
79
3.18608
83
3.18613
87
3.18619
85
3.18624
88
3.18629
85
3.18635
68
3.1864
81
3.18645
96
3.18651
92
3.18656
81
3.18661
86
3.18667
90
3.18672
79
3.18677
86
3.18682
77
3.18688
99
3.18693
80
3.18698
87
3.18704
81
3.18709
84
3.18714
95
3.1872
79
3.18725
95
3.1873
91
3.18736
88
3.18741
79
3.18746
70
3.18751
73
3.18757
83
3.18762
75
3.18767
85
3.18773
97
3.18778
82
3.18783
81
3.18789
73
3.18794
88
3.18799
105
3.18805
70
3.1881
70
3.18815
89
3.18821
94
3.18826
88
3.18831
95
3.18836
88
3.18842
88
3.18847
64
3.18852
81
3.18858
74
3.18863
72
3.18868
79
3.18874
95
3.18879
84
3.18884
87
3.1889
85
3.18895
88
3.189
94
3.18905
76
3.18911
69
3.18916
86
3.18921
93
3.18927
81
3.18932
77
3.18937
88
3.18943
85
3.18948
76
3.18953
82
3.18959
89
3.18964
76
3.18969
92
3.18975
94
3.1898
85
3.18985
71
3.1899
82
3.18996
74
3.19001
75
3.19006
89
3.19012
86
3.19017
87
3.19022
95
3.19028
86
3.19033
86
3.19038
86
3.19044
72
3.19049
83
3.19054
88
3.19059
88
3.19065
85
3.1907
95
3.19075
99
3.19081
80
3.19086
83
3.19091
84
3.19097
91
3.19102
90
3.19107
89
3.19113
82
3.19118
87
3.19123
77
3.19129
87
3.19134
88
3.19139
89
3.19144
83
3.1915
76
3.19155
76
3.1916
91
3.19166
69
3.19171
85
3.19176
67
3.19182
91
3.19187
84
3.19192
83
3.19198
end of experiment