File: A3.vms
VAMAS Surface Chemical Analysis Standard Data Transfer Format 1988 May 4
Not Specified
Kratos Axis
Not Specified
/d=/data/20170705/2017006144/A3.dset
3
Casa Info Follows
0
SourceAnalyserAngle: Not Specified
MAP
REGULAR
4
2
32768
32768
1
Etch Time
s
0
0
0
0
4
wide/2
Not Specified
2017
7
4
10
49
38
0
21
Casa Info Follows
1
Calib M = 283.183 A = 284.6 BE ADD
6
annot text peak Data 1197.27 2850 RGB(0,0,0) Font(14,18,0,0,Times New Roman) Vertical
C 1s
annot text peak Data 505 2437 RGB(0,0,0) Font(14,18,0,0,Times New Roman) Vertical
O KLL
annot text peak Data 954.273 1654 RGB(0,0,0) Font(14,18,0,0,Times New Roman) Vertical
O 1s
annot text peak Data 642 2165 RGB(0,0,0) Font(14,18,0,0,Times New Roman) Vertical
F KLL
annot text peak Data 798.273 10167 RGB(0,0,0) Font(14,18,0,0,Times New Roman) Vertical
F 1s
annot text peak Data 1453.27 385 RGB(0,0,0) Font(14,18,0,0,Times New Roman) Vertical
F 2s
0
0
   XPS     Spectrum    Lens Mode:Hybrid   Resolution:Pass energy 80    Iris(Aper):slot(Slot)
   Acqn. Time(s): 110        Sweeps: 1        Anode:Mono(Al (Mono))(150 W)   Step(meV): 1000.0
   Dwell Time(ms): 100        Charge Neutraliser :On   Acquired On :17/07/04 10:49:38
XPS
77
-3
0
Mono(Al (Mono))
1486.69
150
1e+037
1e+037
6000
6000
1e+037
1e+037
FAT
80
1e+037
-4.45
0
1e+037
1e+037
1e+037
1e+037
Wide
None
-1
Kinetic Energy
eV
386.69
1
2
Intensity
d
Transmission
d
pulse counting
0.1
0
1e+037
0
4
8.48115
2045
2017
2112
2083
2123
2128
2126
2073
2073
2126
2148
2101
2167
2169
2124
2134
2138
2151
2087
2115
2104
2099
2102
2173
2080
2108
2122
2114
2115
2156
2114
2187
2144
2135
2079
2122
2107
2151
2153
2128
2160
2172
2154
2145
2105
2099
2202
2128
2184
2217
2179
2128
2135
2178
2178
2170
2155
2168
2195
2215
2211
2228
2214
2239
2233
2280
2235
2210
2278
2298
2302
2251
2203
2221
2212
2250
2243
2250
2231
2253
2284
2231
2228
2214
2252
2163
2235
2302
2238
2215
2282
2264
2246
2302
2297
2306
2348
2305
2269
2334
2353
2335
2318
2354
2367
2340
2327
2310
2243
2328
2398
2275
2332
2292
2287
2298
2290
2309
2352
2437
2388
2374
2369
2327
2435
2453
2484
2359
2412
2377
2378
2333
2334
2310
2200
2174
2185
2198
2211
2173
2184
2251
2198
2238
2191
2185
2169
2207
2200
2212
2208
2177
2172
2182
2222
2198
2178
2195
2234
2217
2189
2199
2227
2235
2234
2201
2237
2256
2217
2255
2192
2215
2257
2328
2204
2242
2243
2183
2280
2324
2243
2319
2282
2279
2255
2341
2255
2229
2273
2360
2249
2239
2278
2285
2295
2275
2254
2317
2309
2292
2300
2359
2391
2327
2372
2310
2364
2319
2343
2322
2384
2420
2359
2362
2406
2429
2405
2434
2544
2490
2489
2549
2542
2561
2536
2471
2409
2344
2426
2396
2342
2395
2421
2426
2418
2408
2473
2563
2694
2763
2788
2847
2799
2853
2750
2702
2602
2632
2607
2526
2502
2443
2315
2241
2179
2144
2165
2102
2161
2188
2253
2327
2370
2512
2835
3181
3420
3688
3980
3934
3700
3378
3118
2884
2597
2460
2259
2126
2030
1859
1822
1683
1548
1551
1488
1504
1435
1459
1435
1499
1492
1483
1443
1434
1444
1474
1476
1446
1416
1461
1483
1460
1417
1451
1463
1490
1465
1433
1476
1487
1454
1456
1449
1472
1459
1416
1466
1463
1459
1448
1429
1467
1440
1420
1493
1474
1464
1494
1453
1480
1470
1476
1464
1475
1461
1442
1529
1466
1498
1542
1545
1448
1434
1506
1474
1494
1521
1530
1500
1483
1515
1525
1508
1539
1551
1516
1530
1519
1538
1503
1476
1492
1476
1436
1489
1480
1488
1498
1474
1485
1466
1456
1453
1465
1489
1540
1559
1524
1578
1662
1670
1657
1617
1617
1590
1613
1592
1580
1576
1587
1545
1508
1487
1469
1432
1393
1288
1226
1194
1100
1083
1072
1005
904
819
824
739
733
822
957
1360
2583
5701
10167
9401
3754
1146
706
642
563
573
578
530
541
521
525
563
551
544
555
544
558
532
499
540
561
536
550
532
513
526
551
541
557
500
533
506
518
551
548
537
585
570
532
565
577
557
590
550
561
559
570
569
546
538
548
578
590
540
525
540
577
543
550
568
538
576
551
591
545
566
560
553
529
571
540
549
571
577
535
530
545
535
546
586
542
549
589
555
556
624
567
577
600
615
601
571
574
606
608
548
570
587
570
564
589
566
575
599
556
576
626
593
585
569
558
587
594
596
582
586
588
524
572
591
613
648
631
611
615
589
582
613
643
627
614
660
638
631
581
574
574
587
560
548
524
533
514
481
493
470
474
480
510
508
543
614
918
1334
1654
1341
818
526
428
434
424
437
426
383
389
416
427
415
436
429
411
425
373
430
424
397
408
410
457
433
418
408
421
412
459
423
420
428
447
423
417
438
449
404
402
432
438
418
417
450
464
428
433
457
427
426
468
466
423
434
438
444
441
448
449
459
446
433
476
452
452
463
453
451
471
466
454
442
444
461
431
414
469
421
447
446
410
447
439
437
457
452
447
443
422
437
462
474
453
447
464
483
511
441
409
441
477
461
466
475
466
446
464
444
440
508
467
472
460
518
481
473
477
475
450
459
462
480
481
492
456
486
489
515
532
498
495
490
475
487
516
458
453
476
451
496
487
503
466
464
441
497
491
474
488
497
460
465
461
484
464
478
499
463
489
529
515
511
535
534
486
465
469
482
489
514
525
538
512
507
497
461
495
509
519
536
519
530
506
466
488
470
501
536
536
509
527
507
504
506
502
519
520
513
512
519
537
513
516
530
584
547
540
546
599
597
565
567
575
589
562
597
567
573
546
547
531
510
476
501
445
449
424
409
395
379
340
317
284
234
246
237
229
293
448
849
1606
2850
2405
1101
916
856
768
487
198
121
106
111
85
96
104
112
91
98
102
113
98
100
85
96
84
86
78
94
108
90
104
97
81
91
92
81
96
116
96
83
86
105
99
85
72
78
90
96
89
101
91
69
89
94
91
93
104
113
114
103
100
99
102
86
76
118
107
97
101
97
78
88
85
94
78
99
109
105
82
82
104
95
81
95
77
84
95
94
90
98
106
93
115
93
95
102
111
91
98
89
85
93
100
96
109
114
72
79
78
105
97
84
94
92
95
93
97
97
94
105
116
123
126
131
92
92
102
91
92
85
96
86
105
101
89
72
82
85
104
88
78
83
91
101
94
102
95
83
85
89
95
92
101
97
96
89
100
91
83
96
88
82
90
89
91
84
104
95
74
74
88
92
109
97
97
111
94
104
100
101
109
107
111
109
121
88
99
108
114
118
119
105
83
106
91
92
90
101
107
106
107
98
103
107
86
97
104
112
108
106
114
88
100
93
96
100
90
109
106
97
110
117
119
127
112
124
126
117
106
124
117
102
107
114
115
111
116
101
106
93
91
107
96
91
87
94
81
87
70
79
91
78
91
110
183
261
345
385
344
224
151
122
106
84
76
61
72
73
68
67
81
83
83
68
74
91
112
106
102
98
108
133
83
47
45
24
21
9
4
4
8.94051
F 1s/5
Not Specified
2017
7
4
12
57
15
0
9
Casa Info Follows
1
Calib M = 283.183 A = 284.6 BE ADD
0
0
0
   XPS     Spectrum    Lens Mode:Hybrid   Resolution:Pass energy 40    Iris(Aper):slot(Slot)
   Acqn. Time(s): 121        Sweeps: 2        Anode:Mono(Al (Mono))(150 W)   Step(meV): 50.0
   Dwell Time(ms): 150        Charge Neutraliser :On   Acquired On :17/07/04 12:57:15
XPS
77
-3
0
Mono(Al (Mono))
1486.69
150
1e+037
1e+037
6000
6000
1e+037
1e+037
FAT
40
1e+037
-4.45
0
1e+037
1e+037
1e+037
1e+037
F
1s
-1
Kinetic Energy
eV
790.64
0.05
2
Intensity
d
Transmission
d
pulse counting
0.15
2
0
1e+037
1e+037
1e+037
0
806
576
15890
3.41724
3.42712
905
3.42712
929
3.4271
960
3.42707
916
3.42705
868
3.42702
914
3.427
895
3.42698
897
3.42695
863
3.42693
915
3.4269
890
3.42688
886
3.42686
861
3.42683
834
3.42681
892
3.42678
865
3.42676
856
3.42674
896
3.42671
860
3.42669
813
3.42667
870
3.42664
802
3.42662
796
3.42659
816
3.42657
836
3.42655
840
3.42652
835
3.4265
826
3.42647
809
3.42645
855
3.42643
858
3.4264
801
3.42638
826
3.42636
788
3.42633
852
3.42631
815
3.42628
825
3.42626
852
3.42624
862
3.42621
826
3.42619
801
3.42616
795
3.42614
827
3.42612
857
3.42609
809
3.42607
761
3.42605
796
3.42602
847
3.426
874
3.42597
866
3.42595
846
3.42593
831
3.4259
814
3.42588
811
3.42585
763
3.42583
801
3.42581
819
3.42578
793
3.42576
815
3.42573
837
3.42571
857
3.42569
866
3.42566
833
3.42564
812
3.42562
890
3.42559
825
3.42557
849
3.42554
854
3.42552
826
3.4255
889
3.42547
802
3.42545
846
3.42542
814
3.4254
879
3.42538
856
3.42535
848
3.42533
816
3.42531
819
3.42528
858
3.42526
832
3.42523
862
3.42521
873
3.42519
848
3.42516
884
3.42514
921
3.42511
903
3.42509
933
3.42507
915
3.42504
911
3.42502
874
3.425
904
3.42497
924
3.42495
879
3.42492
947
3.4249
945
3.42488
980
3.42485
956
3.42483
1011
3.4248
956
3.42478
951
3.42476
999
3.42473
1013
3.42471
1013
3.42469
994
3.42466
1050
3.42464
1078
3.42461
1088
3.42459
1102
3.42457
1122
3.42454
1154
3.42452
1160
3.42449
1207
3.42447
1225
3.42445
1310
3.42442
1350
3.4244
1267
3.42437
1374
3.42435
1417
3.42433
1411
3.4243
1459
3.42428
1454
3.42426
1531
3.42423
1621
3.42421
1557
3.42418
1646
3.42416
1682
3.42414
1686
3.42411
1798
3.42409
1862
3.42406
1890
3.42404
1945
3.42402
2033
3.42399
2112
3.42397
2202
3.42395
2222
3.42392
2351
3.4239
2517
3.42387
2556
3.42385
2570
3.42383
2729
3.4238
2784
3.42378
2880
3.42375
3018
3.42373
3146
3.42371
3243
3.42368
3478
3.42366
3598
3.42364
3747
3.42361
3832
3.42359
3936
3.42356
4161
3.42354
4350
3.42352
4506
3.42349
4804
3.42347
4872
3.42344
5006
3.42342
5270
3.4234
5529
3.42337
5881
3.42335
6277
3.42333
6416
3.4233
6721
3.42328
7120
3.42325
7480
3.42323
7875
3.42321
8110
3.42318
8448
3.42316
8923
3.42313
9301
3.42311
9934
3.42309
10331
3.42306
10884
3.42304
11215
3.42301
11751
3.42299
12251
3.42297
12681
3.42294
13223
3.42292
13619
3.4229
13853
3.42287
14359
3.42285
14556
3.42282
15073
3.4228
15258
3.42278
15418
3.42275
15529
3.42273
15809
3.4227
15890
3.42268
15799
3.42266
15623
3.42263
15539
3.42261
15504
3.42259
15189
3.42256
14832
3.42254
14450
3.42251
13941
3.42249
13417
3.42247
12996
3.42244
12324
3.42242
11816
3.42239
11333
3.42237
10590
3.42235
10034
3.42232
9472
3.4223
8845
3.42228
8218
3.42225
7675
3.42223
7175
3.4222
6663
3.42218
6215
3.42216
5751
3.42213
5212
3.42211
4822
3.42208
4488
3.42206
4167
3.42204
3756
3.42201
3362
3.42199
3210
3.42196
2973
3.42194
2782
3.42192
2476
3.42189
2323
3.42187
2173
3.42185
2100
3.42182
1889
3.4218
1808
3.42177
1721
3.42175
1619
3.42173
1490
3.4217
1430
3.42168
1351
3.42165
1348
3.42163
1317
3.42161
1276
3.42158
1219
3.42156
1225
3.42154
1141
3.42151
1134
3.42149
1086
3.42146
1023
3.42144
999
3.42142
997
3.42139
988
3.42137
918
3.42134
944
3.42132
924
3.4213
874
3.42127
882
3.42125
884
3.42123
879
3.4212
851
3.42118
865
3.42115
807
3.42113
774
3.42111
791
3.42108
839
3.42106
764
3.42103
773
3.42101
754
3.42099
763
3.42096
799
3.42094
765
3.42091
744
3.42089
774
3.42087
763
3.42084
736
3.42082
729
3.4208
722
3.42077
736
3.42075
701
3.42072
720
3.4207
729
3.42068
703
3.42065
717
3.42063
709
3.4206
699
3.42058
693
3.42056
704
3.42053
718
3.42051
694
3.42049
687
3.42046
725
3.42044
674
3.42041
683
3.42039
651
3.42037
672
3.42034
687
3.42032
658
3.42029
645
3.42027
690
3.42025
688
3.42022
677
3.4202
642
3.42018
703
3.42015
690
3.42013
659
3.4201
657
3.42008
707
3.42006
664
3.42003
649
3.42001
643
3.41998
683
3.41996
662
3.41994
663
3.41991
629
3.41989
651
3.41986
626
3.41984
666
3.41982
650
3.41979
636
3.41977
627
3.41975
629
3.41972
651
3.4197
621
3.41967
616
3.41965
668
3.41963
628
3.4196
644
3.41958
657
3.41955
656
3.41953
650
3.41951
629
3.41948
635
3.41946
622
3.41944
627
3.41941
634
3.41939
596
3.41936
667
3.41934
628
3.41932
678
3.41929
642
3.41927
624
3.41924
672
3.41922
659
3.4192
620
3.41917
665
3.41915
605
3.41913
634
3.4191
629
3.41908
611
3.41905
610
3.41903
635
3.41901
616
3.41898
617
3.41896
645
3.41893
660
3.41891
631
3.41889
654
3.41886
650
3.41884
656
3.41881
648
3.41879
652
3.41877
599
3.41874
631
3.41872
661
3.4187
651
3.41867
612
3.41865
617
3.41862
596
3.4186
661
3.41858
617
3.41855
595
3.41853
603
3.4185
617
3.41848
662
3.41846
647
3.41843
618
3.41841
621
3.41839
634
3.41836
626
3.41834
609
3.41831
617
3.41829
653
3.41827
643
3.41824
631
3.41822
664
3.41819
671
3.41817
640
3.41815
621
3.41812
644
3.4181
615
3.41808
649
3.41805
650
3.41803
628
3.418
623
3.41798
616
3.41796
610
3.41793
624
3.4179
627
3.41786
609
3.41781
652
3.41777
576
3.41773
615
3.41769
614
3.41765
610
3.41761
598
3.41757
583
3.41753
613
3.41748
620
3.41744
648
3.4174
612
3.41736
628
3.41732
643
3.41728
642
3.41724
O 1s/6
Not Specified
2017
7
4
12
57
15
0
9
Casa Info Follows
1
Calib M = 283.183 A = 284.6 BE ADD
0
0
0
   XPS     Spectrum    Lens Mode:Hybrid   Resolution:Pass energy 40    Iris(Aper):slot(Slot)
   Acqn. Time(s): 162        Sweeps: 3        Anode:Mono(Al (Mono))(150 W)   Step(meV): 50.0
   Dwell Time(ms): 150        Charge Neutraliser :On   Acquired On :17/07/04 12:57:15
XPS
77
-3
0
Mono(Al (Mono))
1486.69
150
1e+037
1e+037
6000
6000
1e+037
1e+037
FAT
40
1e+037
-4.45
0
1e+037
1e+037
1e+037
1e+037
O
1s
-1
Kinetic Energy
eV
946.69
0.05
2
Intensity
d
Transmission
d
pulse counting
0.15
3
0
1e+037
1e+037
1e+037
0
722
626
3192
3.32569
3.34183
840
3.34183
830
3.34178
782
3.34174
787
3.34169
835
3.34165
824
3.3416
786
3.34156
822
3.34151
830
3.34147
846
3.34142
856
3.34138
786
3.34133
807
3.34129
786
3.34124
800
3.3412
774
3.34115
762
3.34111
783
3.34107
800
3.34102
792
3.34098
879
3.34093
797
3.34089
814
3.34084
782
3.3408
795
3.34075
798
3.34071
800
3.34066
832
3.34062
764
3.34057
789
3.34053
808
3.34048
773
3.34044
825
3.34039
771
3.34035
788
3.3403
748
3.34026
820
3.34021
793
3.34017
797
3.34012
819
3.34008
815
3.34003
732
3.33999
799
3.33994
784
3.3399
792
3.33985
813
3.33981
824
3.33976
815
3.33972
807
3.33968
763
3.33963
795
3.33959
810
3.33954
789
3.3395
839
3.33945
842
3.33941
802
3.33936
802
3.33932
823
3.33927
803
3.33923
810
3.33918
797
3.33914
818
3.33909
817
3.33905
778
3.339
841
3.33896
772
3.33891
786
3.33887
811
3.33882
732
3.33878
793
3.33873
839
3.33869
775
3.33864
794
3.3386
846
3.33855
819
3.33851
837
3.33846
815
3.33842
799
3.33837
811
3.33833
774
3.33829
805
3.33824
824
3.3382
805
3.33815
784
3.33811
811
3.33806
821
3.33802
809
3.33797
809
3.33793
827
3.33788
815
3.33784
828
3.33779
810
3.33775
861
3.3377
850
3.33766
860
3.33761
847
3.33757
828
3.33752
877
3.33748
864
3.33743
838
3.33739
864
3.33734
867
3.3373
886
3.33725
872
3.33721
910
3.33716
925
3.33712
921
3.33707
916
3.33703
949
3.33698
939
3.33694
930
3.3369
946
3.33685
955
3.33681
966
3.33676
1002
3.33672
982
3.33667
1034
3.33663
1025
3.33658
1060
3.33654
1008
3.33649
1042
3.33645
1112
3.3364
1099
3.33636
1165
3.33631
1175
3.33627
1135
3.33622
1175
3.33618
1170
3.33613
1222
3.33609
1218
3.33604
1205
3.336
1272
3.33595
1289
3.33591
1313
3.33586
1328
3.33582
1365
3.33577
1422
3.33573
1453
3.33568
1464
3.33564
1514
3.3356
1534
3.33555
1588
3.33551
1583
3.33546
1630
3.33542
1657
3.33537
1729
3.33533
1798
3.33528
1891
3.33524
1893
3.33519
1953
3.33515
2022
3.3351
2088
3.33506
2133
3.33501
2203
3.33497
2237
3.33492
2227
3.33488
2267
3.33483
2435
3.33479
2485
3.33474
2536
3.3347
2639
3.33465
2728
3.33461
2765
3.33456
2889
3.33452
2839
3.33447
2841
3.33443
2978
3.33438
2961
3.33434
2970
3.33429
3106
3.33425
3177
3.33421
3125
3.33416
3118
3.33412
3133
3.33407
3141
3.33403
3192
3.33398
3144
3.33394
3067
3.33389
3109
3.33385
3149
3.3338
3111
3.33376
3023
3.33371
3018
3.33367
3011
3.33362
2910
3.33358
2882
3.33353
2872
3.33349
2745
3.33344
2740
3.3334
2688
3.33335
2628
3.33331
2565
3.33326
2452
3.33322
2410
3.33317
2400
3.33313
2316
3.33308
2163
3.33304
2209
3.33299
2169
3.33295
2106
3.3329
2030
3.33286
1947
3.33282
1936
3.33277
1869
3.33273
1846
3.33268
1774
3.33264
1763
3.33259
1638
3.33255
1580
3.3325
1514
3.33246
1488
3.33241
1439
3.33237
1391
3.33232
1343
3.33228
1337
3.33223
1292
3.33219
1268
3.33214
1187
3.3321
1164
3.33205
1102
3.33201
1116
3.33196
1064
3.33192
1001
3.33187
969
3.33183
986
3.33178
942
3.33174
942
3.33169
902
3.33165
863
3.3316
879
3.33156
834
3.33151
846
3.33147
875
3.33143
863
3.33138
828
3.33134
772
3.33129
769
3.33125
817
3.3312
749
3.33116
814
3.33111
765
3.33107
817
3.33102
800
3.33098
743
3.33093
745
3.33089
732
3.33084
749
3.3308
778
3.33075
764
3.33071
736
3.33066
697
3.33062
779
3.33057
726
3.33053
749
3.33048
724
3.33044
728
3.33039
721
3.33035
684
3.3303
791
3.33026
754
3.33021
721
3.33017
690
3.33012
687
3.33008
716
3.33004
733
3.32999
708
3.32995
731
3.3299
671
3.32986
686
3.32981
696
3.32977
714
3.32972
714
3.32968
669
3.32963
720
3.32959
712
3.32954
714
3.3295
722
3.32945
735
3.32941
711
3.32936
734
3.32932
715
3.32927
720
3.32923
744
3.32918
727
3.32914
729
3.32909
721
3.32905
695
3.329
683
3.32896
731
3.32891
707
3.32887
696
3.32882
666
3.32878
699
3.32873
680
3.32869
727
3.32865
724
3.3286
707
3.32856
706
3.32851
669
3.32847
661
3.32842
689
3.32838
718
3.32833
708
3.32829
716
3.32824
729
3.3282
721
3.32815
741
3.32811
729
3.32806
713
3.32802
667
3.32797
688
3.32793
741
3.32788
707
3.32784
749
3.32779
729
3.32775
697
3.3277
787
3.32766
720
3.32761
732
3.32757
690
3.32752
715
3.32748
703
3.32743
683
3.32739
708
3.32735
677
3.3273
691
3.32726
706
3.32721
703
3.32717
658
3.32712
696
3.32708
712
3.32703
678
3.32699
688
3.32694
703
3.3269
691
3.32685
701
3.32681
704
3.32676
701
3.32672
715
3.32667
693
3.32663
664
3.32658
713
3.32654
679
3.32649
641
3.32645
626
3.3264
709
3.32636
691
3.32631
705
3.32627
719
3.32622
703
3.32618
635
3.32613
701
3.32609
688
3.32604
651
3.326
719
3.32596
711
3.32591
705
3.32587
753
3.32582
698
3.32578
719
3.32573
686
3.32569
C 1s/7
Not Specified
2017
7
4
12
57
15
0
9
Casa Info Follows
1
Calib M = 283.183 A = 284.6 BE ADD
0
0
0
   XPS     Spectrum    Lens Mode:Hybrid   Resolution:Pass energy 40    Iris(Aper):slot(Slot)
   Acqn. Time(s): 138        Sweeps: 2        Anode:Mono(Al (Mono))(150 W)   Step(meV): 50.0
   Dwell Time(ms): 150        Charge Neutraliser :On   Acquired On :17/07/04 12:57:15
XPS
77
-3
0
Mono(Al (Mono))
1486.69
150
1e+037
1e+037
6000
6000
1e+037
1e+037
FAT
40
1e+037
-4.45
0
1e+037
1e+037
1e+037
1e+037
C
1s
-1
Kinetic Energy
eV
1190.19
0.05
2
Intensity
d
Transmission
d
pulse counting
0.15
2
0
1e+037
1e+037
1e+037
0
922
81
4685
3.16755
3.19198
286
3.16755
249
3.1676
283
3.16765
274
3.16771
277
3.16776
263
3.16781
299
3.16787
269
3.16792
259
3.16797
267
3.16802
283
3.16808
259
3.16813
268
3.16818
248
3.16824
252
3.16829
241
3.16834
253
3.1684
226
3.16845
260
3.1685
258
3.16856
272
3.16861
240
3.16866
253
3.16871
266
3.16877
231
3.16882
253
3.16887
238
3.16893
257
3.16898
247
3.16903
258
3.16909
259
3.16914
240
3.16919
231
3.16925
242
3.1693
259
3.16935
253
3.16941
239
3.16946
245
3.16951
246
3.16956
239
3.16962
261
3.16967
242
3.16972
243
3.16978
257
3.16983
236
3.16988
255
3.16994
258
3.16999
235
3.17004
243
3.1701
228
3.17015
237
3.1702
239
3.17025
231
3.17031
251
3.17036
255
3.17041
249
3.17047
239
3.17052
233
3.17057
240
3.17063
216
3.17068
256
3.17073
242
3.17079
242
3.17084
227
3.17089
229
3.17095
237
3.171
255
3.17105
246
3.1711
263
3.17116
244
3.17121
224
3.17126
257
3.17132
228
3.17137
225
3.17142
254
3.17148
244
3.17153
268
3.17158
271
3.17164
253
3.17169
249
3.17174
269
3.17179
266
3.17185
267
3.1719
280
3.17195
274
3.17201
270
3.17206
277
3.17211
287
3.17217
265
3.17222
287
3.17227
312
3.17233
301
3.17238
312
3.17243
286
3.17249
326
3.17254
327
3.17259
303
3.17264
302
3.1727
339
3.17275
335
3.1728
331
3.17286
354
3.17291
355
3.17296
367
3.17302
352
3.17307
384
3.17312
383
3.17318
426
3.17323
413
3.17328
452
3.17334
480
3.17339
444
3.17344
488
3.17349
487
3.17355
509
3.1736
555
3.17365
557
3.17371
593
3.17376
608
3.17381
690
3.17387
679
3.17392
720
3.17397
746
3.17403
792
3.17408
810
3.17413
825
3.17418
880
3.17424
860
3.17429
911
3.17434
956
3.1744
968
3.17445
970
3.1745
1040
3.17456
1030
3.17461
1025
3.17466
1022
3.17472
1090
3.17477
1141
3.17482
1155
3.17488
1184
3.17493
1208
3.17498
1228
3.17503
1263
3.17509
1303
3.17514
1323
3.17519
1329
3.17525
1341
3.1753
1432
3.17535
1451
3.17541
1603
3.17546
1661
3.17551
1679
3.17557
1740
3.17562
1875
3.17567
2015
3.17572
2150
3.17578
2223
3.17583
2321
3.17588
2486
3.17594
2643
3.17599
2892
3.17604
3080
3.1761
3285
3.17615
3425
3.1762
3673
3.17626
3783
3.17631
3969
3.17636
4106
3.17642
4302
3.17647
4455
3.17652
4556
3.17657
4550
3.17663
4670
3.17668
4685
3.17673
4596
3.17679
4574
3.17684
4493
3.17689
4464
3.17695
4218
3.177
3994
3.17705
3826
3.17711
3631
3.17716
3342
3.17721
3108
3.17726
2956
3.17732
2741
3.17737
2562
3.17742
2317
3.17748
2109
3.17753
1957
3.17758
1757
3.17764
1656
3.17769
1486
3.17774
1402
3.1778
1371
3.17785
1231
3.1779
1186
3.17796
1131
3.17801
1051
3.17806
980
3.17811
999
3.17817
943
3.17822
911
3.17827
914
3.17833
975
3.17838
959
3.17843
991
3.17849
1002
3.17854
1026
3.17859
965
3.17865
965
3.1787
994
3.17875
1014
3.17881
1041
3.17886
1027
3.17891
1068
3.17896
1085
3.17902
1062
3.17907
1044
3.17912
1119
3.17918
1104
3.17923
1136
3.17928
1106
3.17934
1139
3.17939
1138
3.17944
1124
3.1795
1075
3.17955
1071
3.1796
1040
3.17965
980
3.17971
1033
3.17976
1005
3.17981
996
3.17987
1010
3.17992
941
3.17997
963
3.18003
934
3.18008
892
3.18013
882
3.18019
890
3.18024
848
3.18029
834
3.18035
850
3.1804
855
3.18045
813
3.1805
806
3.18056
872
3.18061
842
3.18066
822
3.18072
779
3.18077
810
3.18082
849
3.18088
861
3.18093
843
3.18098
823
3.18104
885
3.18109
911
3.18114
883
3.1812
864
3.18125
852
3.1813
893
3.18135
809
3.18141
837
3.18146
859
3.18151
894
3.18157
868
3.18162
847
3.18167
809
3.18173
820
3.18178
887
3.18183
883
3.18189
809
3.18194
770
3.18199
767
3.18204
782
3.1821
821
3.18215
761
3.1822
754
3.18226
697
3.18231
671
3.18236
630
3.18242
639
3.18247
653
3.18252
582
3.18258
567
3.18263
496
3.18268
528
3.18274
454
3.18279
433
3.18284
379
3.18289
358
3.18295
337
3.183
348
3.18305
328
3.18311
296
3.18316
257
3.18321
234
3.18327
232
3.18332
230
3.18337
191
3.18343
194
3.18348
179
3.18353
182
3.18358
158
3.18364
165
3.18369
180
3.18374
157
3.1838
148
3.18385
130
3.1839
136
3.18396
124
3.18401
128
3.18406
139
3.18412
127
3.18417
124
3.18422
110
3.18428
109
3.18433
116
3.18438
113
3.18443
109
3.18449
116
3.18454
102
3.18459
120
3.18465
127
3.1847
120
3.18475
96
3.18481
115
3.18486
125
3.18491
98
3.18497
104
3.18502
128
3.18507
120
3.18512
104
3.18518
110
3.18523
110
3.18528
108
3.18534
90
3.18539
115
3.18544
115
3.1855
104
3.18555
107
3.1856
108
3.18566
118
3.18571
120
3.18576
125
3.18582
116
3.18587
121
3.18592
114
3.18597
101
3.18603
98
3.18608
121
3.18613
116
3.18619
92
3.18624
91
3.18629
107
3.18635
105
3.1864
124
3.18645
100
3.18651
106
3.18656
125
3.18661
95
3.18667
91
3.18672
98
3.18677
102
3.18682
106
3.18688
105
3.18693
104
3.18698
112
3.18704
106
3.18709
108
3.18714
108
3.1872
90
3.18725
91
3.1873
100
3.18736
112
3.18741
111
3.18746
99
3.18751
114
3.18757
98
3.18762
115
3.18767
107
3.18773
91
3.18778
93
3.18783
103
3.18789
99
3.18794
96
3.18799
87
3.18805
89
3.1881
111
3.18815
105
3.18821
97
3.18826
104
3.18831
96
3.18836
116
3.18842
94
3.18847
105
3.18852
91
3.18858
108
3.18863
95
3.18868
108
3.18874
100
3.18879
116
3.18884
98
3.1889
122
3.18895
104
3.189
106
3.18905
97
3.18911
106
3.18916
108
3.18921
109
3.18927
92
3.18932
100
3.18937
116
3.18943
123
3.18948
112
3.18953
92
3.18959
122
3.18964
103
3.18969
105
3.18975
105
3.1898
115
3.18985
105
3.1899
81
3.18996
82
3.19001
111
3.19006
108
3.19012
120
3.19017
107
3.19022
107
3.19028
104
3.19033
122
3.19038
104
3.19044
112
3.19049
112
3.19054
100
3.19059
118
3.19065
90
3.1907
89
3.19075
90
3.19081
103
3.19086
104
3.19091
109
3.19097
118
3.19102
98
3.19107
113
3.19113
96
3.19118
106
3.19123
89
3.19129
106
3.19134
108
3.19139
109
3.19144
110
3.1915
88
3.19155
103
3.1916
100
3.19166
110
3.19171
103
3.19176
104
3.19182
91
3.19187
99
3.19192
97
3.19198
end of experiment