File: A4.vms
VAMAS Surface Chemical Analysis Standard Data Transfer Format 1988 May 4
Not Specified
Kratos Axis
Not Specified
/d=/data/20170705/2017006144/A4.dset
3
Casa Info Follows
0
SourceAnalyserAngle: Not Specified
MAP
REGULAR
4
2
32768
32768
1
Etch Time
s
0
0
0
0
4
wide/2
Not Specified
2017
7
4
10
52
10
0
29
Casa Info Follows
1
Calib M = 282.884 A = 284.6 BE ADD
10
annot text peak Data 1201.97 1078 RGB(0,0,0) Font(14,18,0,0,Times New Roman) Vertical
C 1s
annot text peak Data 510.974 2398 RGB(0,0,0) Font(14,18,0,0,Times New Roman) Vertical
O KLL
annot text peak Data 954.974 1807 RGB(0,0,0) Font(14,18,0,0,Times New Roman) Vertical
O 1s
annot text peak Data 642 1998 RGB(0,0,0) Font(14,18,0,0,Times New Roman) Vertical
F KLL
annot text peak Data 798.974 6416 RGB(0,0,0) Font(14,18,0,0,Times New Roman) Vertical
F 1s
annot text peak Data 1217.97 228 RGB(0,0,0) Font(14,18,0,0,Times New Roman) Vertical
Cl 2s
annot text peak Data 1288.97 264 RGB(0,0,0) Font(14,18,0,0,Times New Roman) Vertical
Cl 2p
annot text peak Data 1254.97 179 RGB(0,0,0) Font(14,18,0,0,Times New Roman) Vertical
S 2s
annot text peak Data 1317.97 165 RGB(0,0,0) Font(14,18,0,0,Times New Roman) Vertical
S 2p
annot text peak Data 1452.97 261 RGB(0,0,0) Font(14,18,0,0,Times New Roman) Vertical
F 2s
0
0
   XPS     Spectrum    Lens Mode:Hybrid   Resolution:Pass energy 80    Iris(Aper):slot(Slot)
   Acqn. Time(s): 110        Sweeps: 1        Anode:Mono(Al (Mono))(150 W)   Step(meV): 1000.0
   Dwell Time(ms): 100        Charge Neutraliser :On   Acquired On :17/07/04 10:52:10
XPS
84
-3
0
Mono(Al (Mono))
1486.69
150
1e+037
1e+037
6000
6000
1e+037
1e+037
FAT
80
1e+037
-4.45
0
1e+037
1e+037
1e+037
1e+037
Wide
None
-1
Kinetic Energy
eV
386.69
1
2
Intensity
d
Transmission
d
pulse counting
0.1
0
1e+037
0
7
8.48115
2027
1975
1956
1971
2051
2135
2111
2032
2005
2086
2122
2058
2045
2027
2107
2042
2000
2027
1977
2077
2014
2028
1965
1977
2052
2049
2053
2057
2029
2090
2107
2040
2048
2097
2017
2057
2067
2128
2044
2066
2108
2085
2086
2091
2086
2137
2170
2143
2110
2075
2120
2102
2081
2126
2112
2106
2183
2108
2077
2126
2124
2139
2169
2158
2126
2092
2173
2138
2085
2096
2118
2162
2172
2149
2159
2188
2257
2189
2175
2202
2213
2160
2163
2215
2204
2244
2230
2173
2200
2234
2238
2248
2175
2215
2190
2176
2311
2332
2290
2250
2233
2265
2288
2283
2291
2276
2242
2280
2292
2235
2211
2151
2223
2141
2154
2191
2242
2190
2230
2290
2299
2312
2271
2357
2347
2368
2398
2385
2293
2327
2297
2251
2158
2184
2099
2130
2098
2089
2158
2115
2054
2031
2085
2028
2080
2086
2061
2038
2073
2102
2094
2119
2097
2105
2046
2042
2064
2015
2122
2130
2138
2114
2162
2055
2085
2055
2027
2063
2077
2074
2073
2124
2124
2098
2135
2076
2076
2041
2098
2064
2078
2086
2072
2094
2105
2106
2094
2143
2142
2102
2111
2154
2159
2109
2084
2121
2111
2140
2130
2110
2112
2166
2158
2128
2154
2146
2099
2128
2166
2108
2177
2151
2108
2086
2048
2086
2071
2084
2077
2045
2088
2176
2229
2248
2129
2058
2056
2070
2177
2162
2092
2076
2037
2026
1972
2127
2110
2225
2268
2293
2335
2358
2314
2277
2311
2222
2204
2150
2116
2079
2070
2129
2035
2005
2034
1938
1920
1998
1883
1882
1918
1971
1986
2030
2163
2316
2477
2643
2767
2845
2806
2649
2495
2219
2124
1922
1887
1806
1745
1587
1532
1462
1465
1488
1458
1444
1407
1417
1388
1386
1375
1373
1438
1374
1399
1416
1370
1417
1398
1390
1349
1443
1425
1402
1391
1408
1375
1363
1400
1399
1374
1385
1357
1439
1451
1434
1421
1480
1360
1403
1420
1405
1385
1368
1371
1361
1398
1403
1443
1400
1391
1356
1344
1364
1430
1362
1366
1359
1378
1332
1359
1334
1409
1400
1377
1450
1351
1377
1334
1378
1347
1369
1373
1356
1349
1359
1408
1391
1399
1393
1395
1409
1377
1319
1347
1355
1356
1351
1307
1300
1366
1379
1382
1359
1394
1356
1397
1419
1442
1426
1366
1371
1333
1379
1427
1425
1420
1327
1395
1457
1421
1399
1373
1256
1179
1164
1108
1001
994
951
1000
921
848
809
789
766
695
687
701
764
827
1270
2557
5307
6416
3423
1209
774
655
619
633
613
556
593
585
578
598
608
593
584
580
557
596
570
561
565
563
591
566
561
581
586
599
579
600
620
625
569
628
606
563
594
580
608
620
599
587
611
606
629
631
584
599
571
602
589
563
561
591
584
581
593
592
585
569
576
589
551
590
577
583
587
572
595
612
566
588
616
628
626
588
601
601
569
585
605
624
581
599
613
568
583
620
588
584
614
611
609
626
590
602
599
626
602
636
631
651
640
607
630
644
620
619
637
629
664
658
625
558
551
631
630
621
600
625
618
606
594
635
628
605
622
616
629
664
643
639
629
605
635
642
621
602
567
563
555
549
526
505
491
471
473
485
474
508
547
551
709
1056
1559
1807
1382
651
460
417
402
386
404
365
398
390
385
386
394
385
376
391
399
399
397
375
376
401
381
370
422
411
368
391
425
418
410
408
384
401
402
353
402
393
364
382
374
391
397
406
391
414
404
412
409
420
403
376
402
388
357
387
395
419
398
400
405
433
404
401
408
408
419
412
445
433
430
404
423
416
443
422
436
419
419
432
401
407
418
412
431
407
400
402
401
414
432
417
426
425
403
422
420
436
387
399
445
442
423
438
417
464
421
436
413
435
433
440
428
443
425
411
399
448
447
430
417
431
433
418
430
430
423
438
461
477
491
459
443
426
433
432
431
447
443
471
453
419
434
456
455
434
434
443
438
444
416
421
461
468
452
464
484
503
453
458
453
425
450
498
495
441
451
472
443
467
446
447
433
445
469
435
458
477
457
451
479
461
455
463
455
488
488
515
457
448
497
504
478
492
478
484
493
483
474
514
515
468
519
513
494
487
495
472
495
500
526
562
531
517
508
530
545
561
517
484
478
487
480
460
444
472
457
412
392
387
385
388
369
324
288
271
274
286
386
570
941
1749
1833
984
806
903
1078
843
314
172
129
151
151
130
149
145
150
132
136
174
193
214
228
196
163
142
147
145
128
132
139
143
119
113
146
130
140
138
126
142
147
130
141
134
140
129
128
142
124
132
143
130
146
135
136
145
140
163
177
179
142
133
125
109
132
148
132
135
136
148
137
130
174
166
133
129
121
121
119
114
109
111
135
119
112
129
132
113
128
134
173
240
262
264
161
121
91
93
102
101
94
112
96
99
104
93
98
111
91
96
99
102
104
109
100
93
105
120
101
103
122
150
165
157
104
98
123
114
111
98
93
97
93
114
114
104
105
97
103
131
118
113
112
121
115
112
94
104
94
95
113
106
101
106
110
114
121
122
104
115
115
107
112
111
110
101
105
113
112
85
98
119
105
113
101
105
105
107
105
115
115
96
110
124
123
129
113
125
111
109
114
125
108
108
121
114
117
110
117
100
104
114
114
113
103
90
109
116
113
113
107
104
100
111
101
109
118
103
111
121
98
109
90
106
94
102
118
108
109
107
110
132
131
110
155
140
124
96
104
86
98
76
84
110
77
81
82
79
75
63
78
86
74
92
105
145
198
261
203
160
107
92
77
72
62
79
72
65
80
61
65
54
57
57
62
75
89
80
78
77
79
76
66
60
35
46
38
22
11
7
8.94051
F 1s/5
Not Specified
2017
7
4
13
7
17
0
9
Casa Info Follows
1
Calib M = 282.884 A = 284.6 BE ADD
0
0
0
   XPS     Spectrum    Lens Mode:Hybrid   Resolution:Pass energy 40    Iris(Aper):slot(Slot)
   Acqn. Time(s): 121        Sweeps: 2        Anode:Mono(Al (Mono))(150 W)   Step(meV): 50.0
   Dwell Time(ms): 150        Charge Neutraliser :On   Acquired On :17/07/04 13:07:17
XPS
84
-3
0
Mono(Al (Mono))
1486.69
150
1e+037
1e+037
6000
6000
1e+037
1e+037
FAT
40
1e+037
-4.45
0
1e+037
1e+037
1e+037
1e+037
F
1s
-1
Kinetic Energy
eV
790.64
0.05
2
Intensity
d
Transmission
d
pulse counting
0.15
2
0
1e+037
1e+037
1e+037
0
806
629
9902
3.41724
3.42712
940
3.42712
877
3.4271
870
3.42707
896
3.42705
917
3.42702
888
3.427
896
3.42698
903
3.42695
911
3.42693
892
3.4269
896
3.42688
878
3.42686
940
3.42683
866
3.42681
878
3.42678
876
3.42676
834
3.42674
815
3.42671
817
3.42669
819
3.42667
794
3.42664
808
3.42662
844
3.42659
851
3.42657
855
3.42655
854
3.42652
819
3.4265
840
3.42647
826
3.42645
803
3.42643
816
3.4264
820
3.42638
792
3.42636
817
3.42633
816
3.42631
822
3.42628
831
3.42626
840
3.42624
855
3.42621
821
3.42619
795
3.42616
802
3.42614
815
3.42612
825
3.42609
806
3.42607
800
3.42605
834
3.42602
798
3.426
824
3.42597
808
3.42595
814
3.42593
816
3.4259
817
3.42588
815
3.42585
795
3.42583
833
3.42581
795
3.42578
822
3.42576
798
3.42573
796
3.42571
782
3.42569
841
3.42566
802
3.42564
826
3.42562
839
3.42559
863
3.42557
799
3.42554
755
3.42552
830
3.4255
816
3.42547
807
3.42545
844
3.42542
873
3.4254
836
3.42538
798
3.42535
842
3.42533
804
3.42531
823
3.42528
843
3.42526
816
3.42523
816
3.42521
814
3.42519
809
3.42516
796
3.42514
816
3.42511
836
3.42509
776
3.42507
805
3.42504
829
3.42502
824
3.425
801
3.42497
847
3.42495
844
3.42492
827
3.4249
851
3.42488
798
3.42485
804
3.42483
797
3.4248
821
3.42478
850
3.42476
841
3.42473
809
3.42471
879
3.42469
807
3.42466
855
3.42464
849
3.42461
833
3.42459
888
3.42457
860
3.42454
848
3.42452
823
3.42449
866
3.42447
840
3.42445
868
3.42442
884
3.4244
896
3.42437
916
3.42435
885
3.42433
926
3.4243
923
3.42428
934
3.42426
933
3.42423
928
3.42421
934
3.42418
979
3.42416
969
3.42414
1003
3.42411
971
3.42409
1019
3.42406
1021
3.42404
996
3.42402
1037
3.42399
986
3.42397
1025
3.42395
1089
3.42392
1140
3.4239
1146
3.42387
1220
3.42385
1170
3.42383
1217
3.4238
1271
3.42378
1340
3.42375
1318
3.42373
1375
3.42371
1491
3.42368
1498
3.42366
1573
3.42364
1629
3.42361
1676
3.42359
1807
3.42356
1866
3.42354
1911
3.42352
1994
3.42349
2143
3.42347
2215
3.42344
2373
3.42342
2552
3.4234
2668
3.42337
2775
3.42335
2949
3.42333
3157
3.4233
3232
3.42328
3454
3.42325
3755
3.42323
3788
3.42321
4105
3.42318
4352
3.42316
4648
3.42313
4860
3.42311
5043
3.42309
5284
3.42306
5629
3.42304
5929
3.42301
6281
3.42299
6533
3.42297
6830
3.42294
7196
3.42292
7574
3.4229
7737
3.42287
7947
3.42285
8427
3.42282
8720
3.4228
8881
3.42278
9103
3.42275
9377
3.42273
9445
3.4227
9554
3.42268
9615
3.42266
9899
3.42263
9902
3.42261
9692
3.42259
9710
3.42256
9716
3.42254
9698
3.42251
9460
3.42249
9295
3.42247
8967
3.42244
8898
3.42242
8637
3.42239
8288
3.42237
8113
3.42235
7704
3.42232
7248
3.4223
6842
3.42228
6623
3.42225
6225
3.42223
5887
3.4222
5493
3.42218
5182
3.42216
4864
3.42213
4533
3.42211
4246
3.42208
3951
3.42206
3658
3.42204
3405
3.42201
3156
3.42199
3040
3.42196
2816
3.42194
2485
3.42192
2291
3.42189
2187
3.42187
2093
3.42185
1971
3.42182
1827
3.4218
1739
3.42177
1685
3.42175
1560
3.42173
1432
3.4217
1366
3.42168
1324
3.42165
1232
3.42163
1212
3.42161
1191
3.42158
1098
3.42156
1074
3.42154
1054
3.42151
1055
3.42149
1023
3.42146
1014
3.42144
1012
3.42142
993
3.42139
959
3.42137
897
3.42134
898
3.42132
906
3.4213
906
3.42127
877
3.42125
924
3.42123
854
3.4212
914
3.42118
843
3.42115
855
3.42113
850
3.42111
884
3.42108
866
3.42106
908
3.42103
831
3.42101
891
3.42099
879
3.42096
868
3.42094
841
3.42091
875
3.42089
872
3.42087
848
3.42084
819
3.42082
839
3.4208
849
3.42077
825
3.42075
844
3.42072
842
3.4207
842
3.42068
820
3.42065
785
3.42063
835
3.4206
748
3.42058
836
3.42056
831
3.42053
811
3.42051
847
3.42049
800
3.42046
776
3.42044
795
3.42041
798
3.42039
767
3.42037
760
3.42034
756
3.42032
744
3.42029
789
3.42027
771
3.42025
758
3.42022
761
3.4202
745
3.42018
760
3.42015
752
3.42013
731
3.4201
730
3.42008
697
3.42006
709
3.42003
738
3.42001
767
3.41998
714
3.41996
707
3.41994
671
3.41991
724
3.41989
700
3.41986
707
3.41984
672
3.41982
704
3.41979
711
3.41977
698
3.41975
720
3.41972
701
3.4197
707
3.41967
713
3.41965
705
3.41963
712
3.4196
705
3.41958
693
3.41955
715
3.41953
746
3.41951
750
3.41948
696
3.41946
718
3.41944
711
3.41941
689
3.41939
705
3.41936
687
3.41934
653
3.41932
710
3.41929
682
3.41927
703
3.41924
704
3.41922
667
3.4192
716
3.41917
672
3.41915
711
3.41913
693
3.4191
688
3.41908
665
3.41905
671
3.41903
685
3.41901
641
3.41898
698
3.41896
719
3.41893
709
3.41891
753
3.41889
675
3.41886
663
3.41884
725
3.41881
715
3.41879
739
3.41877
701
3.41874
688
3.41872
702
3.4187
671
3.41867
658
3.41865
662
3.41862
691
3.4186
686
3.41858
669
3.41855
670
3.41853
684
3.4185
700
3.41848
722
3.41846
662
3.41843
707
3.41841
669
3.41839
699
3.41836
722
3.41834
686
3.41831
658
3.41829
713
3.41827
695
3.41824
692
3.41822
694
3.41819
682
3.41817
695
3.41815
686
3.41812
672
3.4181
675
3.41808
646
3.41805
669
3.41803
706
3.418
676
3.41798
679
3.41796
739
3.41793
686
3.4179
700
3.41786
670
3.41781
647
3.41777
659
3.41773
629
3.41769
704
3.41765
699
3.41761
683
3.41757
694
3.41753
723
3.41748
688
3.41744
696
3.4174
691
3.41736
715
3.41732
703
3.41728
717
3.41724
O 1s/6
Not Specified
2017
7
4
13
7
17
0
9
Casa Info Follows
1
Calib M = 282.884 A = 284.6 BE ADD
0
0
0
   XPS     Spectrum    Lens Mode:Hybrid   Resolution:Pass energy 40    Iris(Aper):slot(Slot)
   Acqn. Time(s): 162        Sweeps: 3        Anode:Mono(Al (Mono))(150 W)   Step(meV): 50.0
   Dwell Time(ms): 150        Charge Neutraliser :On   Acquired On :17/07/04 13:07:17
XPS
84
-3
0
Mono(Al (Mono))
1486.69
150
1e+037
1e+037
6000
6000
1e+037
1e+037
FAT
40
1e+037
-4.45
0
1e+037
1e+037
1e+037
1e+037
O
1s
-1
Kinetic Energy
eV
946.69
0.05
2
Intensity
d
Transmission
d
pulse counting
0.15
3
0
1e+037
1e+037
1e+037
0
722
650
3628
3.32569
3.34183
844
3.34183
894
3.34178
854
3.34174
858
3.34169
877
3.34165
854
3.3416
860
3.34156
894
3.34151
882
3.34147
873
3.34142
861
3.34138
874
3.34133
835
3.34129
882
3.34124
855
3.3412
839
3.34115
862
3.34111
898
3.34107
910
3.34102
852
3.34098
808
3.34093
843
3.34089
847
3.34084
862
3.3408
814
3.34075
859
3.34071
876
3.34066
822
3.34062
854
3.34057
864
3.34053
881
3.34048
858
3.34044
837
3.34039
826
3.34035
812
3.3403
857
3.34026
847
3.34021
873
3.34017
777
3.34012
843
3.34008
866
3.34003
826
3.33999
779
3.33994
839
3.3399
834
3.33985
825
3.33981
825
3.33976
818
3.33972
825
3.33968
822
3.33963
829
3.33959
845
3.33954
817
3.3395
873
3.33945
818
3.33941
815
3.33936
789
3.33932
824
3.33927
841
3.33923
850
3.33918
839
3.33914
883
3.33909
881
3.33905
810
3.339
834
3.33896
801
3.33891
857
3.33887
838
3.33882
867
3.33878
823
3.33873
843
3.33869
847
3.33864
799
3.3386
828
3.33855
840
3.33851
863
3.33846
879
3.33842
901
3.33837
879
3.33833
891
3.33829
854
3.33824
864
3.3382
803
3.33815
824
3.33811
855
3.33806
838
3.33802
855
3.33797
866
3.33793
853
3.33788
860
3.33784
883
3.33779
885
3.33775
889
3.3377
886
3.33766
867
3.33761
864
3.33757
840
3.33752
845
3.33748
860
3.33743
920
3.33739
861
3.33734
861
3.3373
878
3.33725
899
3.33721
870
3.33716
881
3.33712
900
3.33707
942
3.33703
898
3.33698
918
3.33694
883
3.3369
933
3.33685
922
3.33681
902
3.33676
913
3.33672
889
3.33667
914
3.33663
942
3.33658
988
3.33654
994
3.33649
933
3.33645
1006
3.3364
1022
3.33636
1006
3.33631
952
3.33627
989
3.33622
1018
3.33618
1056
3.33613
1016
3.33609
1108
3.33604
1103
3.336
1045
3.33595
1100
3.33591
1116
3.33586
1165
3.33582
1151
3.33577
1130
3.33573
1150
3.33568
1177
3.33564
1231
3.3356
1305
3.33555
1289
3.33551
1331
3.33546
1356
3.33542
1396
3.33537
1402
3.33533
1444
3.33528
1511
3.33524
1498
3.33519
1598
3.33515
1645
3.3351
1687
3.33506
1792
3.33501
1735
3.33497
1780
3.33492
1875
3.33488
1916
3.33483
2025
3.33479
1994
3.33474
1980
3.3347
2116
3.33465
2161
3.33461
2231
3.33456
2310
3.33452
2382
3.33447
2444
3.33443
2619
3.33438
2609
3.33434
2662
3.33429
2605
3.33425
2687
3.33421
2719
3.33416
2798
3.33412
2839
3.33407
2982
3.33403
2938
3.33398
2907
3.33394
3059
3.33389
3124
3.33385
3088
3.3338
3122
3.33376
3233
3.33371
3245
3.33367
3139
3.33362
3244
3.33358
3268
3.33353
3309
3.33349
3380
3.33344
3490
3.3334
3533
3.33335
3567
3.33331
3511
3.33326
3570
3.33322
3532
3.33317
3576
3.33313
3544
3.33308
3628
3.33304
3479
3.33299
3490
3.33295
3566
3.3329
3542
3.33286
3498
3.33282
3401
3.33277
3350
3.33273
3230
3.33268
3168
3.33264
3079
3.33259
2981
3.33255
2968
3.3325
2839
3.33246
2726
3.33241
2625
3.33237
2540
3.33232
2519
3.33228
2346
3.33223
2196
3.33219
2080
3.33214
2044
3.3321
1953
3.33205
1767
3.33201
1713
3.33196
1670
3.33192
1528
3.33187
1490
3.33183
1418
3.33178
1324
3.33174
1311
3.33169
1249
3.33165
1231
3.3316
1198
3.33156
1168
3.33151
1117
3.33147
1031
3.33143
1003
3.33138
1016
3.33134
994
3.33129
993
3.33125
948
3.3312
912
3.33116
925
3.33111
903
3.33107
900
3.33102
835
3.33098
827
3.33093
849
3.33089
834
3.33084
829
3.3308
786
3.33075
819
3.33071
830
3.33066
812
3.33062
816
3.33057
800
3.33053
782
3.33048
750
3.33044
755
3.33039
761
3.33035
787
3.3303
760
3.33026
707
3.33021
710
3.33017
721
3.33012
738
3.33008
709
3.33004
710
3.32999
695
3.32995
705
3.3299
705
3.32986
721
3.32981
685
3.32977
710
3.32972
708
3.32968
709
3.32963
702
3.32959
703
3.32954
674
3.3295
690
3.32945
715
3.32941
680
3.32936
726
3.32932
734
3.32927
704
3.32923
702
3.32918
716
3.32914
705
3.32909
684
3.32905
721
3.329
691
3.32896
726
3.32891
707
3.32887
686
3.32882
652
3.32878
689
3.32873
694
3.32869
737
3.32865
703
3.3286
723
3.32856
680
3.32851
672
3.32847
701
3.32842
650
3.32838
668
3.32833
659
3.32829
686
3.32824
713
3.3282
716
3.32815
701
3.32811
700
3.32806
679
3.32802
674
3.32797
679
3.32793
693
3.32788
666
3.32784
696
3.32779
672
3.32775
712
3.3277
678
3.32766
655
3.32761
705
3.32757
679
3.32752
682
3.32748
694
3.32743
686
3.32739
697
3.32735
712
3.3273
694
3.32726
676
3.32721
679
3.32717
699
3.32712
697
3.32708
677
3.32703
668
3.32699
663
3.32694
668
3.3269
710
3.32685
720
3.32681
706
3.32676
694
3.32672
687
3.32667
703
3.32663
707
3.32658
669
3.32654
712
3.32649
717
3.32645
698
3.3264
670
3.32636
681
3.32631
698
3.32627
696
3.32622
691
3.32618
696
3.32613
690
3.32609
679
3.32604
661
3.326
695
3.32596
687
3.32591
677
3.32587
671
3.32582
703
3.32578
722
3.32573
657
3.32569
C 1s/7
Not Specified
2017
7
4
13
7
17
0
9
Casa Info Follows
1
Calib M = 282.884 A = 284.6 BE ADD
0
0
0
   XPS     Spectrum    Lens Mode:Hybrid   Resolution:Pass energy 40    Iris(Aper):slot(Slot)
   Acqn. Time(s): 138        Sweeps: 2        Anode:Mono(Al (Mono))(150 W)   Step(meV): 50.0
   Dwell Time(ms): 150        Charge Neutraliser :On   Acquired On :17/07/04 13:07:17
XPS
84
-3
0
Mono(Al (Mono))
1486.69
150
1e+037
1e+037
6000
6000
1e+037
1e+037
FAT
40
1e+037
-4.45
0
1e+037
1e+037
1e+037
1e+037
C
1s
-1
Kinetic Energy
eV
1190.19
0.05
2
Intensity
d
Transmission
d
pulse counting
0.15
2
0
1e+037
1e+037
1e+037
0
922
139
3122
3.16755
3.19198
355
3.16755
375
3.1676
326
3.16765
315
3.16771
321
3.16776
327
3.16781
338
3.16787
340
3.16792
310
3.16797
336
3.16802
352
3.16808
344
3.16813
338
3.16818
349
3.16824
335
3.16829
323
3.16834
309
3.1684
342
3.16845
334
3.1685
344
3.16856
351
3.16861
294
3.16866
328
3.16871
344
3.16877
340
3.16882
337
3.16887
345
3.16893
318
3.16898
355
3.16903
332
3.16909
323
3.16914
330
3.16919
331
3.16925
296
3.1693
307
3.16935
283
3.16941
306
3.16946
300
3.16951
321
3.16956
318
3.16962
310
3.16967
288
3.16972
317
3.16978
313
3.16983
345
3.16988
295
3.16994
329
3.16999
316
3.17004
333
3.1701
321
3.17015
299
3.1702
316
3.17025
287
3.17031
293
3.17036
303
3.17041
317
3.17047
307
3.17052
329
3.17057
313
3.17063
300
3.17068
310
3.17073
308
3.17079
313
3.17084
304
3.17089
304
3.17095
318
3.171
334
3.17105
275
3.1711
292
3.17116
299
3.17121
310
3.17126
328
3.17132
289
3.17137
281
3.17142
313
3.17148
339
3.17153
312
3.17158
323
3.17164
313
3.17169
308
3.17174
313
3.17179
304
3.17185
319
3.1719
337
3.17195
348
3.17201
319
3.17206
327
3.17211
309
3.17217
320
3.17222
337
3.17227
308
3.17233
365
3.17238
317
3.17243
322
3.17249
317
3.17254
320
3.17259
330
3.17264
341
3.1727
331
3.17275
332
3.1728
298
3.17286
340
3.17291
316
3.17296
359
3.17302
370
3.17307
338
3.17312
334
3.17318
357
3.17323
335
3.17328
364
3.17334
379
3.17339
393
3.17344
384
3.17349
381
3.17355
427
3.1736
384
3.17365
427
3.17371
438
3.17376
459
3.17381
450
3.17387
464
3.17392
502
3.17397
477
3.17403
517
3.17408
520
3.17413
540
3.17418
555
3.17424
577
3.17429
595
3.17434
592
3.1744
642
3.17445
634
3.1745
640
3.17456
649
3.17461
682
3.17466
696
3.17472
681
3.17477
711
3.17482
739
3.17488
728
3.17493
756
3.17498
781
3.17503
797
3.17509
784
3.17514
827
3.17519
850
3.17525
913
3.1753
985
3.17535
985
3.17541
973
3.17546
1064
3.17551
1101
3.17557
1113
3.17562
1158
3.17567
1267
3.17572
1277
3.17578
1281
3.17583
1422
3.17588
1534
3.17594
1631
3.17599
1745
3.17604
1806
3.1761
2036
3.17615
2169
3.1762
2247
3.17626
2365
3.17631
2514
3.17636
2580
3.17642
2673
3.17647
2711
3.17652
2822
3.17657
2920
3.17663
3046
3.17668
3077
3.17673
3064
3.17679
3122
3.17684
3114
3.17689
3078
3.17695
3027
3.177
3001
3.17705
2919
3.17711
2762
3.17716
2735
3.17721
2561
3.17726
2370
3.17732
2240
3.17737
2192
3.17742
2101
3.17748
1928
3.17753
1807
3.17758
1664
3.17764
1620
3.17769
1492
3.17774
1416
3.1778
1348
3.17785
1243
3.1779
1180
3.17796
1084
3.17801
1073
3.17806
976
3.17811
922
3.17817
944
3.17822
867
3.17827
872
3.17833
868
3.17838
798
3.17843
834
3.17849
771
3.17854
733
3.17859
794
3.17865
831
3.1787
832
3.17875
801
3.17881
788
3.17886
827
3.17891
826
3.17896
820
3.17902
882
3.17907
840
3.17912
838
3.17918
875
3.17923
906
3.17928
906
3.17934
920
3.17939
975
3.17944
939
3.1795
971
3.17955
977
3.1796
1022
3.17965
978
3.17971
926
3.17976
1011
3.17981
997
3.17987
1025
3.17992
968
3.17997
1004
3.18003
1029
3.18008
1048
3.18013
978
3.18019
1014
3.18024
1002
3.18029
1011
3.18035
1017
3.1804
1039
3.18045
1021
3.1805
1066
3.18056
1083
3.18061
1003
3.18066
1029
3.18072
1106
3.18077
1150
3.18082
1104
3.18088
1079
3.18093
1139
3.18098
1134
3.18104
1163
3.18109
1177
3.18114
1239
3.1812
1230
3.18125
1325
3.1813
1368
3.18135
1322
3.18141
1339
3.18146
1442
3.18151
1454
3.18157
1454
3.18162
1502
3.18167
1582
3.18173
1588
3.18178
1648
3.18183
1603
3.18189
1606
3.18194
1623
3.18199
1604
3.18204
1596
3.1821
1554
3.18215
1582
3.1822
1511
3.18226
1494
3.18231
1405
3.18236
1340
3.18242
1261
3.18247
1176
3.18252
1172
3.18258
1072
3.18263
993
3.18268
891
3.18274
823
3.18279
764
3.18284
704
3.18289
646
3.18295
573
3.183
566
3.18305
490
3.18311
451
3.18316
436
3.18321
415
3.18327
377
3.18332
320
3.18337
305
3.18343
283
3.18348
264
3.18353
251
3.18358
239
3.18364
233
3.18369
226
3.18374
197
3.1838
210
3.18385
207
3.1839
191
3.18396
207
3.18401
186
3.18406
219
3.18412
188
3.18417
193
3.18422
197
3.18428
184
3.18433
179
3.18438
183
3.18443
164
3.18449
188
3.18454
168
3.18459
178
3.18465
191
3.1847
174
3.18475
179
3.18481
174
3.18486
162
3.18491
167
3.18497
183
3.18502
174
3.18507
173
3.18512
158
3.18518
152
3.18523
182
3.18528
167
3.18534
179
3.18539
170
3.18544
185
3.1855
172
3.18555
168
3.1856
184
3.18566
179
3.18571
180
3.18576
183
3.18582
185
3.18587
178
3.18592
185
3.18597
179
3.18603
165
3.18608
166
3.18613
150
3.18619
195
3.18624
177
3.18629
159
3.18635
166
3.1864
148
3.18645
144
3.18651
163
3.18656
148
3.18661
168
3.18667
167
3.18672
173
3.18677
174
3.18682
163
3.18688
183
3.18693
167
3.18698
170
3.18704
190
3.18709
190
3.18714
183
3.1872
159
3.18725
175
3.1873
148
3.18736
169
3.18741
173
3.18746
175
3.18751
160
3.18757
173
3.18762
167
3.18767
150
3.18773
149
3.18778
186
3.18783
188
3.18789
169
3.18794
168
3.18799
168
3.18805
162
3.1881
167
3.18815
172
3.18821
175
3.18826
174
3.18831
193
3.18836
175
3.18842
164
3.18847
139
3.18852
164
3.18858
164
3.18863
168
3.18868
163
3.18874
157
3.18879
153
3.18884
153
3.1889
166
3.18895
170
3.189
149
3.18905
145
3.18911
154
3.18916
156
3.18921
171
3.18927
168
3.18932
161
3.18937
177
3.18943
159
3.18948
178
3.18953
155
3.18959
164
3.18964
175
3.18969
154
3.18975
139
3.1898
147
3.18985
162
3.1899
140
3.18996
181
3.19001
160
3.19006
161
3.19012
151
3.19017
167
3.19022
158
3.19028
149
3.19033
152
3.19038
156
3.19044
163
3.19049
149
3.19054
162
3.19059
159
3.19065
163
3.1907
151
3.19075
162
3.19081
188
3.19086
157
3.19091
167
3.19097
167
3.19102
172
3.19107
166
3.19113
170
3.19118
166
3.19123
165
3.19129
162
3.19134
187
3.19139
161
3.19144
170
3.1915
159
3.19155
191
3.1916
169
3.19166
168
3.19171
142
3.19176
165
3.19182
190
3.19187
145
3.19192
151
3.19198
end of experiment