File: A5.vms
VAMAS Surface Chemical Analysis Standard Data Transfer Format 1988 May 4
Not Specified
Kratos Axis
Not Specified
/d=/data/20170705/2017006144/A5.dset
3
Casa Info Follows
0
SourceAnalyserAngle: Not Specified
MAP
REGULAR
4
2
32768
32768
1
Etch Time
s
0
0
0
0
4
wide/2
Not Specified
2017
7
4
10
54
41
0
21
Casa Info Follows
1
Calib M = 283.101 A = 284.6 BE ADD
6
annot text peak Data 1202.19 1529 RGB(0,0,0) Font(14,18,0,0,Times New Roman) Vertical
C 1s
annot text peak Data 505 2847 RGB(0,0,0) Font(14,18,0,0,Times New Roman) Vertical
O KLL
annot text peak Data 954.191 1478 RGB(0,0,0) Font(14,18,0,0,Times New Roman) Vertical
O 1s
annot text peak Data 642 2561 RGB(0,0,0) Font(14,18,0,0,Times New Roman) Vertical
F KLL
annot text peak Data 798.191 9817 RGB(0,0,0) Font(14,18,0,0,Times New Roman) Vertical
F 1s
annot text peak Data 1453.19 390 RGB(0,0,0) Font(14,18,0,0,Times New Roman) Vertical
F 2s
0
0
   XPS     Spectrum    Lens Mode:Hybrid   Resolution:Pass energy 80    Iris(Aper):slot(Slot)
   Acqn. Time(s): 110        Sweeps: 1        Anode:Mono(Al (Mono))(150 W)   Step(meV): 1000.0
   Dwell Time(ms): 100        Charge Neutraliser :On   Acquired On :17/07/04 10:54:41
XPS
93
-3
0
Mono(Al (Mono))
1486.69
150
1e+037
1e+037
6000
6000
1e+037
1e+037
FAT
80
1e+037
-4.45
0
1e+037
1e+037
1e+037
1e+037
Wide
None
-1
Kinetic Energy
eV
386.69
1
2
Intensity
d
Transmission
d
pulse counting
0.1
0
1e+037
0
2
8.48115
2462
2596
2553
2505
2515
2563
2519
2550
2565
2568
2583
2528
2538
2623
2640
2526
2472
2529
2553
2591
2573
2528
2486
2515
2590
2543
2582
2559
2563
2543
2533
2579
2600
2553
2670
2561
2580
2565
2569
2585
2589
2589
2584
2621
2611
2566
2537
2545
2549
2498
2594
2638
2665
2594
2545
2567
2652
2630
2585
2619
2682
2656
2663
2689
2730
2659
2625
2657
2702
2679
2616
2621
2616
2691
2670
2647
2703
2670
2627
2750
2728
2673
2684
2600
2709
2747
2677
2696
2747
2719
2704
2705
2672
2781
2771
2652
2836
2780
2782
2788
2694
2765
2739
2732
2766
2734
2747
2682
2695
2714
2746
2752
2803
2802
2787
2695
2808
2722
2860
2847
2765
2815
2879
2867
2896
2901
2856
2842
2878
2798
2792
2835
2745
2762
2665
2700
2699
2732
2659
2622
2599
2648
2675
2664
2706
2609
2618
2626
2691
2694
2660
2728
2739
2772
2700
2651
2689
2663
2661
2702
2618
2722
2629
2643
2624
2651
2734
2770
2761
2651
2648
2765
2768
2740
2749
2771
2727
2675
2689
2724
2698
2762
2724
2714
2698
2753
2766
2834
2731
2826
2819
2787
2788
2840
2783
2728
2670
2741
2845
2774
2769
2754
2791
2788
2738
2710
2802
2834
2805
2782
2789
2828
2753
2811
2857
2839
2929
2907
2754
2895
2870
2889
2953
2972
3004
2965
2927
2834
2855
2804
2787
2774
2837
2812
2873
2880
2898
2929
3076
3239
3222
3231
3203
3102
2972
3003
3032
2956
2886
2814
2856
2877
2732
2684
2607
2577
2561
2528
2538
2501
2525
2577
2690
2823
3043
3308
3563
3960
4213
4178
3863
3518
3315
2972
2807
2587
2412
2268
2162
2065
1924
1897
1850
1828
1828
1799
1745
1716
1757
1717
1707
1759
1719
1725
1709
1734
1707
1751
1712
1671
1746
1741
1714
1707
1646
1728
1674
1689
1676
1743
1754
1710
1657
1676
1685
1722
1758
1763
1684
1739
1757
1687
1661
1738
1715
1717
1725
1735
1763
1703
1769
1692
1755
1684
1707
1698
1754
1686
1781
1709
1709
1680
1706
1753
1714
1725
1743
1768
1740
1723
1731
1728
1727
1735
1733
1789
1808
1760
1703
1750
1782
1699
1697
1718
1768
1841
1768
1775
1711
1652
1667
1648
1645
1697
1696
1704
1700
1718
1799
1844
1842
1888
1893
1840
1790
1813
1776
1735
1758
1820
1806
1769
1787
1749
1686
1585
1531
1421
1309
1276
1235
1171
1100
992
884
830
747
777
837
1004
1529
3011
6278
9817
8060
3105
1095
695
627
619
634
610
600
590
568
555
568
591
578
606
584
615
626
627
573
602
596
607
616
585
588
591
572
584
655
599
611
596
587
619
629
622
596
583
590
606
598
639
591
629
650
637
627
595
624
589
596
630
640
627
620
639
577
567
618
595
600
589
622
643
660
609
623
629
622
638
606
617
597
635
626
632
625
662
625
647
656
611
600
588
624
641
658
629
613
656
654
657
664
605
635
615
636
659
662
651
654
633
669
635
635
646
650
686
636
645
659
586
622
629
663
658
650
628
657
659
626
632
667
639
656
673
666
660
658
646
684
661
651
676
667
611
618
634
636
616
589
590
571
587
556
551
558
583
562
601
751
1033
1438
1478
1128
691
559
512
513
473
533
524
503
528
516
509
521
496
496
517
478
472
497
502
509
487
509
514
507
499
521
523
515
486
505
495
505
499
511
495
485
496
522
569
512
523
493
496
464
505
486
514
500
494
508
517
477
517
514
523
525
525
520
517
552
521
510
525
574
523
507
518
536
529
544
546
555
563
536
529
517
524
540
546
525
558
526
517
522
518
497
554
520
523
547
570
542
522
546
542
502
528
555
529
557
578
606
551
537
526
576
560
542
539
513
523
523
517
514
543
547
560
507
503
529
531
537
566
586
556
550
556
581
587
580
556
570
602
574
569
529
539
565
543
564
584
545
605
543
560
542
540
540
539
565
576
588
573
579
585
566
596
572
601
573
591
543
536
544
582
591
580
593
567
609
625
591
560
594
568
584
590
615
585
586
583
623
625
606
631
584
618
630
673
617
599
618
596
602
585
636
616
656
602
632
625
616
628
639
666
668
635
651
700
690
678
679
665
676
643
674
643
666
658
652
676
644
617
602
548
555
534
534
502
449
427
416
364
344
267
246
260
371
615
1089
1981
2842
1953
1098
1051
1256
1529
992
294
142
124
94
107
102
105
97
97
103
115
101
126
99
107
103
97
117
114
97
102
96
106
102
97
93
99
99
91
88
105
107
108
120
112
96
111
104
93
103
115
101
113
104
90
81
100
106
113
124
130
119
108
111
111
102
108
110
94
98
116
114
92
121
107
106
97
107
97
116
101
94
104
98
108
99
114
116
109
91
107
117
118
128
107
111
97
112
97
106
104
103
106
89
91
111
106
116
106
113
111
110
116
96
94
108
107
93
97
117
103
129
132
134
142
109
106
97
106
104
108
116
107
109
99
115
107
137
136
140
120
139
115
106
95
105
114
113
109
109
118
99
103
128
110
111
98
112
115
104
95
117
109
115
115
109
108
103
107
108
130
127
104
117
125
105
120
120
112
132
122
103
106
121
125
111
106
121
126
130
116
135
135
125
125
109
121
115
127
107
116
128
112
144
118
118
129
113
116
134
132
125
120
128
122
113
119
112
138
131
110
104
111
121
114
121
143
151
151
128
130
126
127
133
141
121
125
125
138
112
120
119
120
117
121
113
106
77
96
98
88
107
97
103
123
155
223
307
385
390
283
174
132
104
72
68
66
67
68
73
83
90
78
73
80
97
88
112
114
108
110
95
110
110
76
42
44
20
13
3
5
2
8.94051
F 1s/5
Not Specified
2017
7
4
13
17
14
0
9
Casa Info Follows
1
Calib M = 283.101 A = 284.6 BE ADD
0
0
0
   XPS     Spectrum    Lens Mode:Hybrid   Resolution:Pass energy 40    Iris(Aper):slot(Slot)
   Acqn. Time(s): 121        Sweeps: 2        Anode:Mono(Al (Mono))(150 W)   Step(meV): 50.0
   Dwell Time(ms): 150        Charge Neutraliser :On   Acquired On :17/07/04 13:17:14
XPS
93
-3
0
Mono(Al (Mono))
1486.69
150
1e+037
1e+037
6000
6000
1e+037
1e+037
FAT
40
1e+037
-4.45
0
1e+037
1e+037
1e+037
1e+037
F
1s
-1
Kinetic Energy
eV
790.64
0.05
2
Intensity
d
Transmission
d
pulse counting
0.15
2
0
1e+037
1e+037
1e+037
0
806
650
14744
3.41724
3.42712
1003
3.42712
1073
3.4271
1033
3.42707
978
3.42705
986
3.42702
993
3.427
962
3.42698
992
3.42695
981
3.42693
1023
3.4269
963
3.42688
964
3.42686
988
3.42683
966
3.42681
945
3.42678
938
3.42676
929
3.42674
964
3.42671
947
3.42669
960
3.42667
946
3.42664
924
3.42662
898
3.42659
929
3.42657
926
3.42655
941
3.42652
948
3.4265
891
3.42647
934
3.42645
916
3.42643
915
3.4264
914
3.42638
910
3.42636
891
3.42633
903
3.42631
875
3.42628
837
3.42626
906
3.42624
931
3.42621
880
3.42619
858
3.42616
850
3.42614
863
3.42612
870
3.42609
887
3.42607
855
3.42605
902
3.42602
855
3.426
892
3.42597
865
3.42595
846
3.42593
911
3.4259
892
3.42588
860
3.42585
874
3.42583
873
3.42581
896
3.42578
955
3.42576
925
3.42573
887
3.42571
895
3.42569
911
3.42566
894
3.42564
894
3.42562
911
3.42559
889
3.42557
910
3.42554
887
3.42552
949
3.4255
896
3.42547
928
3.42545
913
3.42542
931
3.4254
918
3.42538
922
3.42535
910
3.42533
928
3.42531
893
3.42528
971
3.42526
949
3.42523
961
3.42521
978
3.42519
943
3.42516
929
3.42514
967
3.42511
1003
3.42509
951
3.42507
956
3.42504
961
3.42502
1010
3.425
1009
3.42497
1044
3.42495
1041
3.42492
1014
3.4249
1070
3.42488
1063
3.42485
1082
3.42483
1051
3.4248
1073
3.42478
1107
3.42476
1171
3.42473
1164
3.42471
1148
3.42469
1080
3.42466
1172
3.42464
1189
3.42461
1183
3.42459
1257
3.42457
1304
3.42454
1256
3.42452
1272
3.42449
1318
3.42447
1427
3.42445
1412
3.42442
1456
3.4244
1527
3.42437
1489
3.42435
1492
3.42433
1574
3.4243
1626
3.42428
1672
3.42426
1701
3.42423
1749
3.42421
1883
3.42418
1817
3.42416
1931
3.42414
1967
3.42411
2047
3.42409
2114
3.42406
2198
3.42404
2154
3.42402
2207
3.42399
2446
3.42397
2453
3.42395
2565
3.42392
2673
3.4239
2670
3.42387
2862
3.42385
2992
3.42383
3168
3.4238
3343
3.42378
3380
3.42375
3493
3.42373
3587
3.42371
3746
3.42368
3932
3.42366
4095
3.42364
4317
3.42361
4528
3.42359
4781
3.42356
4955
3.42354
5212
3.42352
5423
3.42349
5703
3.42347
6148
3.42344
6435
3.42342
6639
3.4234
6884
3.42337
7320
3.42335
7562
3.42333
8120
3.4233
8515
3.42328
8809
3.42325
9182
3.42323
9571
3.42321
10024
3.42318
10395
3.42316
10985
3.42313
11184
3.42311
11403
3.42309
11827
3.42306
12280
3.42304
12841
3.42301
13058
3.42299
13252
3.42297
13683
3.42294
14051
3.42292
14085
3.4229
14316
3.42287
14599
3.42285
14643
3.42282
14744
3.4228
14472
3.42278
14708
3.42275
14590
3.42273
14636
3.4227
14154
3.42268
14011
3.42266
13675
3.42263
13450
3.42261
12979
3.42259
12510
3.42256
12228
3.42254
11696
3.42251
11346
3.42249
10806
3.42247
10194
3.42244
9542
3.42242
9092
3.42239
8669
3.42237
8125
3.42235
7773
3.42232
7122
3.4223
6622
3.42228
6119
3.42225
5789
3.42223
5345
3.4222
4939
3.42218
4523
3.42216
4281
3.42213
3952
3.42211
3671
3.42208
3425
3.42206
3202
3.42204
2959
3.42201
2712
3.42199
2522
3.42196
2347
3.42194
2234
3.42192
2139
3.42189
1977
3.42187
1840
3.42185
1800
3.42182
1724
3.4218
1591
3.42177
1492
3.42175
1450
3.42173
1413
3.4217
1379
3.42168
1308
3.42165
1248
3.42163
1211
3.42161
1132
3.42158
1097
3.42156
1054
3.42154
1085
3.42151
1026
3.42149
970
3.42146
1017
3.42144
984
3.42142
983
3.42139
921
3.42137
944
3.42134
946
3.42132
945
3.4213
886
3.42127
893
3.42125
912
3.42123
861
3.4212
870
3.42118
858
3.42115
792
3.42113
844
3.42111
870
3.42108
825
3.42106
857
3.42103
833
3.42101
826
3.42099
816
3.42096
866
3.42094
846
3.42091
797
3.42089
780
3.42087
793
3.42084
784
3.42082
791
3.4208
811
3.42077
787
3.42075
753
3.42072
769
3.4207
734
3.42068
723
3.42065
797
3.42063
734
3.4206
771
3.42058
775
3.42056
746
3.42053
722
3.42051
727
3.42049
778
3.42046
745
3.42044
745
3.42041
752
3.42039
742
3.42037
729
3.42034
706
3.42032
727
3.42029
725
3.42027
720
3.42025
701
3.42022
747
3.4202
728
3.42018
735
3.42015
760
3.42013
722
3.4201
740
3.42008
750
3.42006
736
3.42003
777
3.42001
751
3.41998
769
3.41996
739
3.41994
723
3.41991
726
3.41989
720
3.41986
716
3.41984
687
3.41982
733
3.41979
740
3.41977
717
3.41975
697
3.41972
717
3.4197
680
3.41967
691
3.41965
685
3.41963
650
3.4196
701
3.41958
737
3.41955
724
3.41953
721
3.41951
736
3.41948
724
3.41946
720
3.41944
695
3.41941
714
3.41939
754
3.41936
726
3.41934
694
3.41932
716
3.41929
733
3.41927
727
3.41924
696
3.41922
676
3.4192
734
3.41917
719
3.41915
713
3.41913
662
3.4191
720
3.41908
706
3.41905
725
3.41903
717
3.41901
754
3.41898
735
3.41896
714
3.41893
686
3.41891
672
3.41889
743
3.41886
711
3.41884
742
3.41881
752
3.41879
685
3.41877
748
3.41874
714
3.41872
728
3.4187
739
3.41867
710
3.41865
692
3.41862
684
3.4186
697
3.41858
693
3.41855
691
3.41853
688
3.4185
740
3.41848
718
3.41846
687
3.41843
710
3.41841
684
3.41839
679
3.41836
718
3.41834
682
3.41831
709
3.41829
673
3.41827
697
3.41824
724
3.41822
709
3.41819
702
3.41817
751
3.41815
729
3.41812
682
3.4181
677
3.41808
744
3.41805
707
3.41803
666
3.418
680
3.41798
695
3.41796
700
3.41793
680
3.4179
712
3.41786
716
3.41781
679
3.41777
711
3.41773
691
3.41769
716
3.41765
672
3.41761
701
3.41757
685
3.41753
722
3.41748
705
3.41744
662
3.4174
679
3.41736
684
3.41732
719
3.41728
718
3.41724
O 1s/6
Not Specified
2017
7
4
13
17
14
0
9
Casa Info Follows
1
Calib M = 283.101 A = 284.6 BE ADD
0
0
0
   XPS     Spectrum    Lens Mode:Hybrid   Resolution:Pass energy 40    Iris(Aper):slot(Slot)
   Acqn. Time(s): 162        Sweeps: 3        Anode:Mono(Al (Mono))(150 W)   Step(meV): 50.0
   Dwell Time(ms): 150        Charge Neutraliser :On   Acquired On :17/07/04 13:17:14
XPS
93
-3
0
Mono(Al (Mono))
1486.69
150
1e+037
1e+037
6000
6000
1e+037
1e+037
FAT
40
1e+037
-4.45
0
1e+037
1e+037
1e+037
1e+037
O
1s
-1
Kinetic Energy
eV
946.69
0.05
2
Intensity
d
Transmission
d
pulse counting
0.15
3
0
1e+037
1e+037
1e+037
0
722
752
2953
3.32569
3.34183
948
3.34183
972
3.34178
975
3.34174
972
3.34169
919
3.34165
943
3.3416
950
3.34156
944
3.34151
947
3.34147
931
3.34142
942
3.34138
949
3.34133
957
3.34129
997
3.34124
936
3.3412
934
3.34115
888
3.34111
907
3.34107
933
3.34102
949
3.34098
943
3.34093
954
3.34089
951
3.34084
903
3.3408
914
3.34075
936
3.34071
916
3.34066
926
3.34062
890
3.34057
942
3.34053
942
3.34048
923
3.34044
914
3.34039
882
3.34035
961
3.3403
920
3.34026
932
3.34021
917
3.34017
956
3.34012
949
3.34008
906
3.34003
923
3.33999
968
3.33994
919
3.3399
969
3.33985
939
3.33981
925
3.33976
943
3.33972
941
3.33968
935
3.33963
955
3.33959
943
3.33954
977
3.3395
1011
3.33945
928
3.33941
981
3.33936
964
3.33932
955
3.33927
951
3.33923
939
3.33918
932
3.33914
921
3.33909
905
3.33905
940
3.339
942
3.33896
950
3.33891
985
3.33887
937
3.33882
971
3.33878
985
3.33873
961
3.33869
951
3.33864
932
3.3386
1011
3.33855
1014
3.33851
961
3.33846
975
3.33842
1010
3.33837
917
3.33833
962
3.33829
940
3.33824
982
3.3382
978
3.33815
935
3.33811
954
3.33806
1005
3.33802
985
3.33797
992
3.33793
1021
3.33788
1045
3.33784
999
3.33779
1010
3.33775
1019
3.3377
1014
3.33766
1019
3.33761
1025
3.33757
999
3.33752
1046
3.33748
1025
3.33743
1049
3.33739
1050
3.33734
1078
3.3373
1084
3.33725
1096
3.33721
1090
3.33716
1075
3.33712
1107
3.33707
1108
3.33703
1138
3.33698
1138
3.33694
1159
3.3369
1163
3.33685
1162
3.33681
1178
3.33676
1201
3.33672
1284
3.33667
1300
3.33663
1219
3.33658
1305
3.33654
1304
3.33649
1321
3.33645
1253
3.3364
1321
3.33636
1402
3.33631
1400
3.33627
1466
3.33622
1463
3.33618
1510
3.33613
1490
3.33609
1465
3.33604
1543
3.336
1572
3.33595
1598
3.33591
1662
3.33586
1701
3.33582
1682
3.33577
1812
3.33573
1817
3.33568
1848
3.33564
1810
3.3356
1932
3.33555
1976
3.33551
2047
3.33546
2031
3.33542
2183
3.33537
2188
3.33533
2202
3.33528
2284
3.33524
2241
3.33519
2285
3.33515
2407
3.3351
2445
3.33506
2475
3.33501
2555
3.33497
2545
3.33492
2592
3.33488
2669
3.33483
2762
3.33479
2726
3.33474
2701
3.3347
2799
3.33465
2846
3.33461
2911
3.33456
2897
3.33452
2866
3.33447
2943
3.33443
2905
3.33438
2845
3.33434
2953
3.33429
2902
3.33425
2911
3.33421
2934
3.33416
2910
3.33412
2928
3.33407
2836
3.33403
2720
3.33398
2767
3.33394
2707
3.33389
2730
3.33385
2659
3.3338
2606
3.33376
2537
3.33371
2557
3.33367
2523
3.33362
2544
3.33358
2503
3.33353
2384
3.33349
2240
3.33344
2262
3.3334
2287
3.33335
2246
3.33331
2127
3.33326
2132
3.33322
2104
3.33317
2104
3.33313
1983
3.33308
1916
3.33304
1871
3.33299
1777
3.33295
1735
3.3329
1751
3.33286
1679
3.33282
1620
3.33277
1581
3.33273
1550
3.33268
1525
3.33264
1469
3.33259
1461
3.33255
1405
3.3325
1314
3.33246
1295
3.33241
1298
3.33237
1246
3.33232
1221
3.33228
1170
3.33223
1115
3.33219
1156
3.33214
1090
3.3321
1085
3.33205
1034
3.33201
1036
3.33196
1040
3.33192
1026
3.33187
1004
3.33183
945
3.33178
966
3.33174
988
3.33169
971
3.33165
910
3.3316
901
3.33156
901
3.33151
897
3.33147
877
3.33143
886
3.33138
916
3.33134
955
3.33129
868
3.33125
890
3.3312
900
3.33116
863
3.33111
881
3.33107
915
3.33102
922
3.33098
897
3.33093
872
3.33089
879
3.33084
881
3.3308
884
3.33075
892
3.33071
903
3.33066
852
3.33062
887
3.33057
880
3.33053
873
3.33048
892
3.33044
894
3.33039
836
3.33035
894
3.3303
897
3.33026
895
3.33021
864
3.33017
859
3.33012
827
3.33008
819
3.33004
863
3.32999
860
3.32995
843
3.3299
827
3.32986
846
3.32981
835
3.32977
847
3.32972
875
3.32968
854
3.32963
941
3.32959
870
3.32954
861
3.3295
835
3.32945
860
3.32941
880
3.32936
817
3.32932
752
3.32927
875
3.32923
852
3.32918
819
3.32914
893
3.32909
899
3.32905
841
3.329
818
3.32896
865
3.32891
869
3.32887
871
3.32882
849
3.32878
855
3.32873
830
3.32869
829
3.32865
822
3.3286
897
3.32856
886
3.32851
844
3.32847
847
3.32842
826
3.32838
846
3.32833
862
3.32829
844
3.32824
913
3.3282
819
3.32815
841
3.32811
810
3.32806
880
3.32802
851
3.32797
845
3.32793
852
3.32788
842
3.32784
850
3.32779
892
3.32775
846
3.3277
862
3.32766
856
3.32761
849
3.32757
882
3.32752
877
3.32748
868
3.32743
854
3.32739
887
3.32735
869
3.3273
866
3.32726
884
3.32721
884
3.32717
873
3.32712
852
3.32708
813
3.32703
876
3.32699
843
3.32694
835
3.3269
839
3.32685
792
3.32681
861
3.32676
839
3.32672
827
3.32667
851
3.32663
851
3.32658
839
3.32654
860
3.32649
860
3.32645
835
3.3264
859
3.32636
844
3.32631
844
3.32627
802
3.32622
850
3.32618
799
3.32613
837
3.32609
839
3.32604
804
3.326
849
3.32596
885
3.32591
869
3.32587
815
3.32582
840
3.32578
834
3.32573
836
3.32569
C 1s/7
Not Specified
2017
7
4
13
17
14
0
9
Casa Info Follows
1
Calib M = 283.101 A = 284.6 BE ADD
0
0
0
   XPS     Spectrum    Lens Mode:Hybrid   Resolution:Pass energy 40    Iris(Aper):slot(Slot)
   Acqn. Time(s): 138        Sweeps: 2        Anode:Mono(Al (Mono))(150 W)   Step(meV): 50.0
   Dwell Time(ms): 150        Charge Neutraliser :On   Acquired On :17/07/04 13:17:14
XPS
93
-3
0
Mono(Al (Mono))
1486.69
150
1e+037
1e+037
6000
6000
1e+037
1e+037
FAT
40
1e+037
-4.45
0
1e+037
1e+037
1e+037
1e+037
C
1s
-1
Kinetic Energy
eV
1190.19
0.05
2
Intensity
d
Transmission
d
pulse counting
0.15
2
0
1e+037
1e+037
1e+037
0
922
95
4124
3.16755
3.19198
360
3.16755
340
3.1676
327
3.16765
328
3.16771
312
3.16776
343
3.16781
323
3.16787
338
3.16792
325
3.16797
317
3.16802
313
3.16808
296
3.16813
318
3.16818
320
3.16824
329
3.16829
313
3.16834
316
3.1684
297
3.16845
303
3.1685
324
3.16856
322
3.16861
319
3.16866
301
3.16871
298
3.16877
340
3.16882
320
3.16887
287
3.16893
282
3.16898
281
3.16903
282
3.16909
294
3.16914
309
3.16919
319
3.16925
300
3.1693
279
3.16935
292
3.16941
305
3.16946
290
3.16951
308
3.16956
311
3.16962
318
3.16967
301
3.16972
271
3.16978
295
3.16983
296
3.16988
282
3.16994
280
3.16999
292
3.17004
318
3.1701
291
3.17015
275
3.1702
286
3.17025
304
3.17031
270
3.17036
273
3.17041
286
3.17047
280
3.17052
297
3.17057
314
3.17063
286
3.17068
284
3.17073
270
3.17079
277
3.17084
304
3.17089
294
3.17095
272
3.171
294
3.17105
283
3.1711
290
3.17116
317
3.17121
275
3.17126
275
3.17132
270
3.17137
296
3.17142
328
3.17148
323
3.17153
314
3.17158
318
3.17164
323
3.17169
293
3.17174
308
3.17179
337
3.17185
338
3.1719
357
3.17195
336
3.17201
356
3.17206
337
3.17211
357
3.17217
350
3.17222
376
3.17227
377
3.17233
426
3.17238
427
3.17243
388
3.17249
397
3.17254
418
3.17259
419
3.17264
460
3.1727
499
3.17275
459
3.1728
481
3.17286
518
3.17291
542
3.17296
520
3.17302
577
3.17307
613
3.17312
601
3.17318
659
3.17323
633
3.17328
652
3.17334
689
3.17339
737
3.17344
789
3.17349
792
3.17355
778
3.1736
818
3.17365
843
3.17371
843
3.17376
940
3.17381
940
3.17387
976
3.17392
1007
3.17397
1043
3.17403
1051
3.17408
1128
3.17413
1098
3.17418
1191
3.17424
1208
3.17429
1251
3.17434
1301
3.1744
1260
3.17445
1362
3.1745
1410
3.17456
1408
3.17461
1460
3.17466
1506
3.17472
1571
3.17477
1608
3.17482
1665
3.17488
1771
3.17493
1763
3.17498
1811
3.17503
1904
3.17509
2006
3.17514
1994
3.17519
2190
3.17525
2330
3.1753
2389
3.17535
2467
3.17541
2612
3.17546
2597
3.17551
2822
3.17557
2883
3.17562
2999
3.17567
3194
3.17572
3280
3.17578
3397
3.17583
3526
3.17588
3735
3.17594
3773
3.17599
3887
3.17604
3947
3.1761
3928
3.17615
4013
3.1762
4015
3.17626
4124
3.17631
4039
3.17636
3985
3.17642
3926
3.17647
3849
3.17652
3687
3.17657
3593
3.17663
3596
3.17668
3458
3.17673
3253
3.17679
3050
3.17684
2913
3.17689
2793
3.17695
2702
3.177
2613
3.17705
2405
3.17711
2223
3.17716
2109
3.17721
2002
3.17726
1846
3.17732
1734
3.17737
1617
3.17742
1550
3.17748
1467
3.17753
1387
3.17758
1354
3.17764
1292
3.17769
1204
3.17774
1200
3.1778
1143
3.17785
1137
3.1779
1102
3.17796
1095
3.17801
1011
3.17806
1015
3.17811
1009
3.17817
1022
3.17822
993
3.17827
1037
3.17833
1037
3.17838
1072
3.17843
1040
3.17849
1021
3.17854
1060
3.17859
1075
3.17865
1041
3.1787
1042
3.17875
1039
3.17881
1078
3.17886
1053
3.17891
1072
3.17896
1025
3.17902
1064
3.17907
1066
3.17912
1053
3.17918
1076
3.17923
1084
3.17928
1096
3.17934
1085
3.17939
1074
3.17944
1035
3.1795
1127
3.17955
1106
3.1796
1122
3.17965
1123
3.17971
1079
3.17976
1068
3.17981
1117
3.17987
1152
3.17992
1192
3.17997
1196
3.18003
1215
3.18008
1283
3.18013
1285
3.18019
1239
3.18024
1272
3.18029
1270
3.18035
1275
3.1804
1343
3.18045
1373
3.1805
1500
3.18056
1424
3.18061
1463
3.18066
1457
3.18072
1543
3.18077
1553
3.18082
1587
3.18088
1632
3.18093
1667
3.18098
1702
3.18104
1718
3.18109
1775
3.18114
1801
3.1812
1817
3.18125
1810
3.1813
1855
3.18135
1809
3.18141
1860
3.18146
1893
3.18151
1957
3.18157
1985
3.18162
1888
3.18167
1978
3.18173
1961
3.18178
1968
3.18183
1903
3.18189
1827
3.18194
1803
3.18199
1810
3.18204
1797
3.1821
1712
3.18215
1630
3.1822
1560
3.18226
1487
3.18231
1412
3.18236
1358
3.18242
1275
3.18247
1208
3.18252
1087
3.18258
1034
3.18263
963
3.18268
866
3.18274
778
3.18279
751
3.18284
738
3.18289
645
3.18295
625
3.183
513
3.18305
481
3.18311
445
3.18316
401
3.18321
376
3.18327
349
3.18332
304
3.18337
254
3.18343
240
3.18348
235
3.18353
241
3.18358
207
3.18364
232
3.18369
170
3.18374
201
3.1838
174
3.18385
178
3.1839
165
3.18396
159
3.18401
159
3.18406
148
3.18412
164
3.18417
139
3.18422
143
3.18428
158
3.18433
168
3.18438
146
3.18443
153
3.18449
121
3.18454
138
3.18459
151
3.18465
141
3.1847
139
3.18475
125
3.18481
133
3.18486
137
3.18491
129
3.18497
116
3.18502
121
3.18507
135
3.18512
132
3.18518
118
3.18523
127
3.18528
99
3.18534
118
3.18539
115
3.18544
122
3.1855
137
3.18555
124
3.1856
125
3.18566
110
3.18571
118
3.18576
121
3.18582
114
3.18587
129
3.18592
120
3.18597
128
3.18603
121
3.18608
117
3.18613
107
3.18619
142
3.18624
140
3.18629
122
3.18635
108
3.1864
119
3.18645
124
3.18651
117
3.18656
118
3.18661
122
3.18667
112
3.18672
114
3.18677
115
3.18682
112
3.18688
129
3.18693
131
3.18698
129
3.18704
139
3.18709
108
3.18714
116
3.1872
118
3.18725
118
3.1873
145
3.18736
125
3.18741
110
3.18746
111
3.18751
99
3.18757
129
3.18762
132
3.18767
123
3.18773
114
3.18778
105
3.18783
124
3.18789
135
3.18794
113
3.18799
114
3.18805
114
3.1881
116
3.18815
120
3.18821
113
3.18826
116
3.18831
103
3.18836
95
3.18842
105
3.18847
126
3.18852
123
3.18858
114
3.18863
119
3.18868
126
3.18874
118
3.18879
101
3.18884
128
3.1889
118
3.18895
118
3.189
123
3.18905
117
3.18911
129
3.18916
106
3.18921
122
3.18927
104
3.18932
135
3.18937
123
3.18943
103
3.18948
127
3.18953
118
3.18959
105
3.18964
120
3.18969
116
3.18975
119
3.1898
118
3.18985
113
3.1899
113
3.18996
104
3.19001
114
3.19006
132
3.19012
112
3.19017
129
3.19022
96
3.19028
123
3.19033
116
3.19038
118
3.19044
135
3.19049
133
3.19054
119
3.19059
122
3.19065
123
3.1907
134
3.19075
112
3.19081
137
3.19086
136
3.19091
115
3.19097
126
3.19102
127
3.19107
116
3.19113
108
3.19118
123
3.19123
107
3.19129
111
3.19134
120
3.19139
109
3.19144
118
3.1915
116
3.19155
136
3.1916
127
3.19166
134
3.19171
106
3.19176
117
3.19182
128
3.19187
113
3.19192
113
3.19198
end of experiment