File: B1.vms
VAMAS Surface Chemical Analysis Standard Data Transfer Format 1988 May 4
Not Specified
Kratos Axis
Not Specified
/d=/data/20170705/2017006144/B1.dset
3
Casa Info Follows
0
SourceAnalyserAngle: Not Specified
MAP
REGULAR
4
2
32768
32768
1
Etch Time
s
0
0
0
0
4
wide/2
Not Specified
2017
7
4
10
57
24
0
25
Casa Info Follows
1
Calib M = 283.02 A = 284.6 BE ADD
8
annot text peak Data 1197.11 1798 RGB(0,0,0) Font(14,18,0,0,Times New Roman) Vertical
C 1s
annot text peak Data 642 1602 RGB(0,0,0) Font(14,18,0,0,Times New Roman) Vertical
F KLL
annot text peak Data 799.11 6179 RGB(0,0,0) Font(14,18,0,0,Times New Roman) Vertical
F 1s
annot text peak Data 510.11 1960 RGB(0,0,0) Font(14,18,0,0,Times New Roman) Vertical
O KLL
annot text peak Data 954.11 1636 RGB(0,0,0) Font(14,18,0,0,Times New Roman) Vertical
O 1s
annot text peak Data 1254.11 117 RGB(0,0,0) Font(14,18,0,0,Times New Roman) Vertical
S 2s
annot text peak Data 1318.11 129 RGB(0,0,0) Font(14,18,0,0,Times New Roman) Vertical
S 2p
annot text peak Data 1453.11 273 RGB(0,0,0) Font(14,18,0,0,Times New Roman) Vertical
F 2s
0
0
   XPS     Spectrum    Lens Mode:Hybrid   Resolution:Pass energy 80    Iris(Aper):slot(Slot)
   Acqn. Time(s): 110        Sweeps: 1        Anode:Mono(Al (Mono))(150 W)   Step(meV): 1000.0
   Dwell Time(ms): 100        Charge Neutraliser :On   Acquired On :17/07/04 10:57:24
XPS
99
6
0
Mono(Al (Mono))
1486.69
150
1e+037
1e+037
6000
6000
1e+037
1e+037
FAT
80
1e+037
-4.45
0
1e+037
1e+037
1e+037
1e+037
Wide
None
-1
Kinetic Energy
eV
386.69
1
2
Intensity
d
Transmission
d
pulse counting
0.1
0
1e+037
0
3
8.48115
1647
1638
1617
1614
1691
1644
1678
1622
1733
1707
1683
1633
1613
1640
1638
1673
1650
1605
1658
1620
1689
1611
1656
1636
1688
1646
1592
1643
1737
1660
1634
1654
1651
1686
1710
1781
1716
1648
1690
1690
1695
1686
1699
1706
1695
1781
1751
1731
1693
1695
1715
1742
1686
1714
1762
1717
1723
1721
1720
1705
1706
1697
1684
1682
1634
1704
1746
1754
1695
1782
1704
1763
1738
1763
1710
1707
1790
1726
1762
1778
1745
1700
1762
1709
1721
1765
1794
1764
1709
1797
1791
1760
1809
1851
1872
1811
1758
1834
1806
1812
1825
1799
1795
1899
1858
1822
1870
1850
1785
1792
1719
1732
1820
1826
1770
1731
1739
1745
1802
1809
1851
1885
1874
1924
1961
1960
1867
1871
1885
1871
1868
1807
1783
1690
1699
1669
1730
1724
1649
1638
1615
1546
1609
1684
1692
1648
1633
1662
1685
1625
1640
1669
1643
1559
1628
1710
1655
1695
1671
1670
1691
1673
1686
1681
1655
1697
1698
1648
1659
1733
1699
1683
1671
1736
1640
1660
1711
1654
1643
1678
1706
1692
1698
1723
1642
1647
1747
1730
1739
1718
1758
1770
1688
1679
1715
1748
1763
1722
1688
1725
1735
1696
1710
1730
1693
1764
1736
1759
1778
1773
1771
1738
1748
1788
1731
1817
1828
1771
1834
1842
1840
1897
1866
1871
1827
1860
1798
1781
1815
1820
1737
1798
1832
1819
1830
1796
1853
1934
1971
2008
2069
2120
2098
2086
2019
1962
1872
1835
1867
1866
1794
1723
1741
1712
1627
1624
1602
1614
1633
1615
1661
1630
1793
1877
2058
2260
2513
2610
2788
2725
2625
2442
2247
2054
1975
1745
1660
1523
1487
1424
1349
1287
1273
1215
1183
1176
1166
1195
1141
1112
1107
1099
1113
1116
1172
1179
1108
1133
1111
1094
1119
1150
1154
1108
1134
1113
1178
1135
1138
1205
1138
1124
1156
1132
1139
1149
1160
1177
1114
1129
1147
1137
1125
1176
1174
1187
1180
1157
1119
1189
1136
1147
1174
1185
1116
1115
1090
1168
1172
1177
1179
1127
1186
1205
1153
1143
1157
1176
1189
1160
1149
1179
1171
1212
1193
1168
1177
1157
1135
1152
1193
1206
1176
1196
1150
1160
1155
1126
1122
1117
1132
1151
1181
1141
1147
1153
1212
1216
1235
1295
1265
1304
1267
1275
1269
1257
1206
1204
1204
1238
1235
1187
1213
1191
1073
1035
1028
992
964
900
845
865
812
745
724
669
650
692
775
953
1300
1993
3405
6038
6179
2846
1024
647
571
548
538
538
525
504
547
555
536
530
553
572
524
534
530
548
517
529
508
500
512
509
512
501
539
545
564
504
543
542
553
565
544
545
526
535
547
550
586
575
559
536
508
578
540
547
521
534
536
555
543
520
544
541
544
524
561
554
583
539
542
560
543
573
564
562
552
585
607
555
562
530
540
554
557
577
582
570
549
550
562
566
572
547
551
579
548
519
551
578
621
576
588
534
563
534
553
547
570
573
578
589
564
553
565
580
592
539
556
577
568
550
557
530
556
547
547
570
542
548
597
586
592
626
572
641
611
622
570
596
580
594
576
560
573
551
525
479
498
472
453
445
433
419
432
432
423
507
635
779
1233
1636
1472
907
516
372
373
359
393
356
365
347
366
358
337
353
370
370
335
339
353
326
328
345
371
355
349
353
365
351
373
367
368
369
354
372
367
363
385
349
369
362
382
352
357
374
356
357
354
348
376
357
337
361
363
372
401
391
350
336
358
364
352
354
361
378
380
376
345
369
355
379
356
329
349
364
361
392
388
352
371
355
367
347
377
354
365
389
399
397
342
371
405
368
378
370
366
347
372
402
346
352
362
363
366
370
392
389
361
408
390
399
401
397
406
359
378
401
381
381
371
376
348
346
392
348
375
370
400
408
421
417
469
423
413
395
395
361
370
391
407
383
374
386
372
368
390
384
398
435
381
383
418
396
383
443
398
397
375
390
364
373
394
383
420
409
377
382
385
373
397
404
411
395
429
410
381
421
424
414
405
399
406
445
412
406
410
412
436
415
398
403
416
440
436
438
404
436
402
427
431
420
435
453
424
410
398
412
433
419
451
505
467
458
448
475
467
460
459
452
450
471
439
461
446
395
399
387
367
379
375
349
304
302
320
277
262
231
233
219
272
427
683
1055
1798
1576
942
939
864
805
558
214
98
97
77
78
72
77
88
103
94
80
92
80
76
73
71
78
97
97
84
98
85
97
90
100
95
70
77
102
94
98
77
81
84
78
82
83
81
83
86
85
78
65
81
85
85
83
68
90
122
117
105
113
107
86
82
78
88
79
84
88
85
96
73
72
88
77
69
82
71
74
83
73
69
76
73
62
80
82
73
81
90
95
96
96
75
72
73
82
100
77
55
78
78
80
85
83
76
75
62
69
73
72
80
62
73
73
65
74
65
73
77
80
128
129
118
106
72
57
57
63
57
68
78
80
75
62
70
69
69
68
64
70
69
72
72
65
73
66
71
85
69
64
81
71
66
68
91
70
76
71
92
65
73
70
76
78
83
81
67
84
86
67
67
61
64
81
72
76
68
70
71
84
76
67
81
67
84
72
67
65
79
80
83
105
78
69
66
79
90
93
81
70
72
82
69
76
94
76
72
85
93
74
82
76
67
77
73
91
80
61
79
82
103
81
72
85
96
87
81
80
82
83
86
95
80
97
93
95
78
89
82
89
90
74
74
59
72
67
56
70
68
64
65
77
92
137
187
233
273
241
155
97
82
63
74
73
82
63
58
55
61
66
59
55
58
70
70
88
68
73
79
83
92
67
55
40
30
12
8
5
3
8.94051
F 1s/5
Not Specified
2017
7
4
13
27
27
0
9
Casa Info Follows
1
Calib M = 283.02 A = 284.6 BE ADD
0
0
0
   XPS     Spectrum    Lens Mode:Hybrid   Resolution:Pass energy 40    Iris(Aper):slot(Slot)
   Acqn. Time(s): 121        Sweeps: 2        Anode:Mono(Al (Mono))(150 W)   Step(meV): 50.0
   Dwell Time(ms): 150        Charge Neutraliser :On   Acquired On :17/07/04 13:27:27
XPS
99
6
0
Mono(Al (Mono))
1486.69
150
1e+037
1e+037
6000
6000
1e+037
1e+037
FAT
40
1e+037
-4.45
0
1e+037
1e+037
1e+037
1e+037
F
1s
-1
Kinetic Energy
eV
790.64
0.05
2
Intensity
d
Transmission
d
pulse counting
0.15
2
0
1e+037
1e+037
1e+037
0
806
560
10177
3.41724
3.42712
842
3.42712
829
3.4271
809
3.42707
778
3.42705
786
3.42702
792
3.427
811
3.42698
789
3.42695
777
3.42693
860
3.4269
747
3.42688
752
3.42686
787
3.42683
768
3.42681
782
3.42678
780
3.42676
775
3.42674
741
3.42671
776
3.42669
746
3.42667
728
3.42664
801
3.42662
773
3.42659
796
3.42657
787
3.42655
755
3.42652
800
3.4265
741
3.42647
748
3.42645
700
3.42643
755
3.4264
787
3.42638
796
3.42636
768
3.42633
764
3.42631
755
3.42628
739
3.42626
769
3.42624
742
3.42621
707
3.42619
698
3.42616
709
3.42614
771
3.42612
722
3.42609
761
3.42607
765
3.42605
755
3.42602
777
3.426
792
3.42597
720
3.42595
776
3.42593
779
3.4259
748
3.42588
750
3.42585
716
3.42583
736
3.42581
772
3.42578
764
3.42576
756
3.42573
782
3.42571
763
3.42569
802
3.42566
815
3.42564
781
3.42562
788
3.42559
802
3.42557
786
3.42554
838
3.42552
781
3.4255
767
3.42547
834
3.42545
843
3.42542
831
3.4254
798
3.42538
818
3.42535
830
3.42533
850
3.42531
830
3.42528
772
3.42526
835
3.42523
807
3.42521
818
3.42519
883
3.42516
861
3.42514
882
3.42511
902
3.42509
854
3.42507
866
3.42504
847
3.42502
921
3.425
920
3.42497
937
3.42495
934
3.42492
906
3.4249
906
3.42488
929
3.42485
913
3.42483
992
3.4248
991
3.42478
978
3.42476
971
3.42473
1024
3.42471
1013
3.42469
1012
3.42466
1038
3.42464
1150
3.42461
1120
3.42459
1144
3.42457
1106
3.42454
1155
3.42452
1217
3.42449
1201
3.42447
1250
3.42445
1256
3.42442
1269
3.4244
1259
3.42437
1278
3.42435
1330
3.42433
1355
3.4243
1362
3.42428
1389
3.42426
1440
3.42423
1467
3.42421
1489
3.42418
1468
3.42416
1615
3.42414
1603
3.42411
1733
3.42409
1666
3.42406
1707
3.42404
1723
3.42402
1789
3.42399
1823
3.42397
1874
3.42395
1935
3.42392
2021
3.4239
2023
3.42387
2049
3.42385
2103
3.42383
2101
3.4238
2188
3.42378
2270
3.42375
2289
3.42373
2392
3.42371
2502
3.42368
2416
3.42366
2528
3.42364
2612
3.42361
2630
3.42359
2733
3.42356
2849
3.42354
2891
3.42352
2961
3.42349
3151
3.42347
3202
3.42344
3354
3.42342
3476
3.4234
3608
3.42337
3708
3.42335
3851
3.42333
4063
3.4233
4241
3.42328
4451
3.42325
4642
3.42323
4671
3.42321
4876
3.42318
5110
3.42316
5400
3.42313
5573
3.42311
5955
3.42309
6161
3.42306
6507
3.42304
6603
3.42301
6945
3.42299
7262
3.42297
7538
3.42294
7940
3.42292
8164
3.4229
8307
3.42287
8530
3.42285
8729
3.42282
9124
3.4228
9342
3.42278
9489
3.42275
9693
3.42273
9677
3.4227
9885
3.42268
10095
3.42266
10058
3.42263
10177
3.42261
9778
3.42259
9860
3.42256
9685
3.42254
9679
3.42251
9228
3.42249
9099
3.42247
8733
3.42244
8618
3.42242
8295
3.42239
7827
3.42237
7533
3.42235
7076
3.42232
6634
3.4223
6278
3.42228
6048
3.42225
5602
3.42223
5207
3.4222
4794
3.42218
4496
3.42216
4396
3.42213
4018
3.42211
3607
3.42208
3318
3.42206
2967
3.42204
2808
3.42201
2562
3.42199
2447
3.42196
2295
3.42194
2141
3.42192
1961
3.42189
1864
3.42187
1708
3.42185
1627
3.42182
1564
3.4218
1453
3.42177
1383
3.42175
1278
3.42173
1278
3.4217
1184
3.42168
1161
3.42165
1121
3.42163
1087
3.42161
1048
3.42158
1011
3.42156
1034
3.42154
955
3.42151
928
3.42149
918
3.42146
885
3.42144
897
3.42142
845
3.42139
843
3.42137
847
3.42134
845
3.42132
824
3.4213
803
3.42127
803
3.42125
817
3.42123
756
3.4212
738
3.42118
740
3.42115
738
3.42113
734
3.42111
749
3.42108
751
3.42106
731
3.42103
740
3.42101
730
3.42099
742
3.42096
744
3.42094
742
3.42091
734
3.42089
703
3.42087
705
3.42084
722
3.42082
721
3.4208
670
3.42077
717
3.42075
680
3.42072
661
3.4207
677
3.42068
669
3.42065
664
3.42063
695
3.4206
671
3.42058
687
3.42056
630
3.42053
661
3.42051
651
3.42049
624
3.42046
683
3.42044
678
3.42041
667
3.42039
671
3.42037
621
3.42034
620
3.42032
649
3.42029
682
3.42027
663
3.42025
669
3.42022
640
3.4202
665
3.42018
659
3.42015
634
3.42013
634
3.4201
635
3.42008
654
3.42006
677
3.42003
639
3.42001
634
3.41998
681
3.41996
660
3.41994
634
3.41991
641
3.41989
631
3.41986
598
3.41984
601
3.41982
654
3.41979
676
3.41977
658
3.41975
608
3.41972
636
3.4197
650
3.41967
652
3.41965
620
3.41963
609
3.4196
616
3.41958
603
3.41955
622
3.41953
656
3.41951
585
3.41948
634
3.41946
636
3.41944
620
3.41941
632
3.41939
652
3.41936
644
3.41934
660
3.41932
623
3.41929
644
3.41927
631
3.41924
638
3.41922
638
3.4192
621
3.41917
599
3.41915
602
3.41913
584
3.4191
618
3.41908
624
3.41905
560
3.41903
604
3.41901
577
3.41898
640
3.41896
629
3.41893
603
3.41891
589
3.41889
632
3.41886
639
3.41884
573
3.41881
597
3.41879
631
3.41877
624
3.41874
602
3.41872
593
3.4187
599
3.41867
608
3.41865
631
3.41862
678
3.4186
620
3.41858
608
3.41855
640
3.41853
644
3.4185
615
3.41848
632
3.41846
632
3.41843
647
3.41841
630
3.41839
627
3.41836
610
3.41834
618
3.41831
649
3.41829
685
3.41827
647
3.41824
622
3.41822
589
3.41819
594
3.41817
618
3.41815
632
3.41812
588
3.4181
669
3.41808
636
3.41805
612
3.41803
640
3.418
604
3.41798
626
3.41796
599
3.41793
615
3.4179
596
3.41786
600
3.41781
613
3.41777
614
3.41773
603
3.41769
608
3.41765
636
3.41761
621
3.41757
597
3.41753
621
3.41748
628
3.41744
633
3.4174
618
3.41736
620
3.41732
616
3.41728
615
3.41724
O 1s/6
Not Specified
2017
7
4
13
27
27
0
9
Casa Info Follows
1
Calib M = 283.02 A = 284.6 BE ADD
0
0
0
   XPS     Spectrum    Lens Mode:Hybrid   Resolution:Pass energy 40    Iris(Aper):slot(Slot)
   Acqn. Time(s): 162        Sweeps: 3        Anode:Mono(Al (Mono))(150 W)   Step(meV): 50.0
   Dwell Time(ms): 150        Charge Neutraliser :On   Acquired On :17/07/04 13:27:27
XPS
99
6
0
Mono(Al (Mono))
1486.69
150
1e+037
1e+037
6000
6000
1e+037
1e+037
FAT
40
1e+037
-4.45
0
1e+037
1e+037
1e+037
1e+037
O
1s
-1
Kinetic Energy
eV
946.69
0.05
2
Intensity
d
Transmission
d
pulse counting
0.15
3
0
1e+037
1e+037
1e+037
0
722
540
3382
3.32569
3.34183
694
3.34183
739
3.34178
727
3.34174
735
3.34169
709
3.34165
699
3.3416
723
3.34156
718
3.34151
708
3.34147
717
3.34142
701
3.34138
695
3.34133
693
3.34129
706
3.34124
686
3.3412
708
3.34115
727
3.34111
708
3.34107
756
3.34102
729
3.34098
719
3.34093
718
3.34089
668
3.34084
735
3.3408
687
3.34075
677
3.34071
660
3.34066
698
3.34062
747
3.34057
685
3.34053
718
3.34048
709
3.34044
678
3.34039
679
3.34035
688
3.3403
688
3.34026
691
3.34021
705
3.34017
692
3.34012
696
3.34008
733
3.34003
700
3.33999
694
3.33994
704
3.3399
731
3.33985
691
3.33981
700
3.33976
676
3.33972
697
3.33968
687
3.33963
722
3.33959
694
3.33954
677
3.3395
695
3.33945
692
3.33941
720
3.33936
717
3.33932
760
3.33927
708
3.33923
751
3.33918
730
3.33914
717
3.33909
719
3.33905
711
3.339
715
3.33896
747
3.33891
732
3.33887
716
3.33882
753
3.33878
750
3.33873
724
3.33869
675
3.33864
774
3.3386
717
3.33855
713
3.33851
729
3.33846
741
3.33842
746
3.33837
742
3.33833
765
3.33829
749
3.33824
775
3.3382
774
3.33815
773
3.33811
760
3.33806
758
3.33802
755
3.33797
693
3.33793
738
3.33788
750
3.33784
740
3.33779
779
3.33775
773
3.3377
778
3.33766
807
3.33761
781
3.33757
747
3.33752
820
3.33748
782
3.33743
806
3.33739
790
3.33734
750
3.3373
836
3.33725
827
3.33721
796
3.33716
830
3.33712
844
3.33707
835
3.33703
848
3.33698
875
3.33694
896
3.3369
917
3.33685
872
3.33681
880
3.33676
952
3.33672
1003
3.33667
923
3.33663
923
3.33658
910
3.33654
937
3.33649
990
3.33645
967
3.3364
984
3.33636
1013
3.33631
1032
3.33627
1048
3.33622
1047
3.33618
1116
3.33613
1076
3.33609
1112
3.33604
1147
3.336
1161
3.33595
1119
3.33591
1170
3.33586
1215
3.33582
1202
3.33577
1234
3.33573
1248
3.33568
1279
3.33564
1307
3.3356
1341
3.33555
1334
3.33551
1362
3.33546
1372
3.33542
1412
3.33537
1491
3.33533
1514
3.33528
1617
3.33524
1539
3.33519
1623
3.33515
1637
3.3351
1723
3.33506
1827
3.33501
1827
3.33497
1844
3.33492
1895
3.33488
1966
3.33483
2049
3.33479
2033
3.33474
2074
3.3347
2161
3.33465
2325
3.33461
2405
3.33456
2372
3.33452
2467
3.33447
2558
3.33443
2589
3.33438
2688
3.33434
2782
3.33429
2862
3.33425
2835
3.33421
2896
3.33416
3032
3.33412
3086
3.33407
3158
3.33403
3166
3.33398
3227
3.33394
3378
3.33389
3303
3.33385
3361
3.3338
3339
3.33376
3382
3.33371
3291
3.33367
3278
3.33362
3303
3.33358
3226
3.33353
3218
3.33349
3225
3.33344
3250
3.3334
3178
3.33335
3155
3.33331
3054
3.33326
3032
3.33322
2931
3.33317
2892
3.33313
2820
3.33308
2788
3.33304
2626
3.33299
2608
3.33295
2582
3.3329
2463
3.33286
2431
3.33282
2383
3.33277
2243
3.33273
2171
3.33268
2161
3.33264
2030
3.33259
1942
3.33255
1982
3.3325
1856
3.33246
1789
3.33241
1764
3.33237
1727
3.33232
1656
3.33228
1517
3.33223
1501
3.33219
1445
3.33214
1390
3.3321
1299
3.33205
1288
3.33201
1186
3.33196
1148
3.33192
1101
3.33187
1025
3.33183
1025
3.33178
939
3.33174
919
3.33169
895
3.33165
862
3.3316
863
3.33156
827
3.33151
842
3.33147
777
3.33143
773
3.33138
734
3.33134
729
3.33129
694
3.33125
736
3.3312
701
3.33116
664
3.33111
682
3.33107
668
3.33102
649
3.33098
641
3.33093
649
3.33089
621
3.33084
648
3.3308
658
3.33075
642
3.33071
635
3.33066
592
3.33062
632
3.33057
631
3.33053
621
3.33048
629
3.33044
613
3.33039
620
3.33035
612
3.3303
628
3.33026
604
3.33021
593
3.33017
625
3.33012
587
3.33008
638
3.33004
627
3.32999
615
3.32995
606
3.3299
637
3.32986
604
3.32981
580
3.32977
631
3.32972
635
3.32968
636
3.32963
614
3.32959
612
3.32954
621
3.3295
608
3.32945
612
3.32941
601
3.32936
574
3.32932
567
3.32927
568
3.32923
594
3.32918
621
3.32914
610
3.32909
587
3.32905
570
3.329
590
3.32896
590
3.32891
589
3.32887
569
3.32882
594
3.32878
593
3.32873
552
3.32869
604
3.32865
621
3.3286
608
3.32856
600
3.32851
597
3.32847
602
3.32842
599
3.32838
622
3.32833
586
3.32829
610
3.32824
585
3.3282
602
3.32815
548
3.32811
571
3.32806
597
3.32802
619
3.32797
596
3.32793
623
3.32788
637
3.32784
586
3.32779
602
3.32775
606
3.3277
622
3.32766
595
3.32761
591
3.32757
572
3.32752
575
3.32748
595
3.32743
581
3.32739
605
3.32735
588
3.3273
601
3.32726
576
3.32721
571
3.32717
582
3.32712
590
3.32708
575
3.32703
612
3.32699
599
3.32694
601
3.3269
599
3.32685
609
3.32681
570
3.32676
579
3.32672
554
3.32667
589
3.32663
613
3.32658
599
3.32654
582
3.32649
626
3.32645
540
3.3264
577
3.32636
567
3.32631
546
3.32627
560
3.32622
600
3.32618
626
3.32613
609
3.32609
576
3.32604
577
3.326
604
3.32596
613
3.32591
566
3.32587
611
3.32582
609
3.32578
611
3.32573
577
3.32569
C 1s/7
Not Specified
2017
7
4
13
27
27
0
9
Casa Info Follows
1
Calib M = 283.02 A = 284.6 BE ADD
0
0
0
   XPS     Spectrum    Lens Mode:Hybrid   Resolution:Pass energy 40    Iris(Aper):slot(Slot)
   Acqn. Time(s): 138        Sweeps: 2        Anode:Mono(Al (Mono))(150 W)   Step(meV): 50.0
   Dwell Time(ms): 150        Charge Neutraliser :On   Acquired On :17/07/04 13:27:27
XPS
99
6
0
Mono(Al (Mono))
1486.69
150
1e+037
1e+037
6000
6000
1e+037
1e+037
FAT
40
1e+037
-4.45
0
1e+037
1e+037
1e+037
1e+037
C
1s
-1
Kinetic Energy
eV
1190.19
0.05
2
Intensity
d
Transmission
d
pulse counting
0.15
2
0
1e+037
1e+037
1e+037
0
922
65
2921
3.16755
3.19198
245
3.16755
240
3.1676
208
3.16765
228
3.16771
236
3.16776
253
3.16781
239
3.16787
234
3.16792
231
3.16797
242
3.16802
235
3.16808
230
3.16813
225
3.16818
221
3.16824
239
3.16829
216
3.16834
235
3.1684
246
3.16845
227
3.1685
223
3.16856
200
3.16861
231
3.16866
220
3.16871
217
3.16877
231
3.16882
226
3.16887
223
3.16893
251
3.16898
256
3.16903
213
3.16909
222
3.16914
230
3.16919
209
3.16925
222
3.1693
210
3.16935
217
3.16941
198
3.16946
237
3.16951
220
3.16956
215
3.16962
233
3.16967
218
3.16972
206
3.16978
187
3.16983
218
3.16988
243
3.16994
224
3.16999
215
3.17004
198
3.1701
222
3.17015
234
3.1702
228
3.17025
217
3.17031
231
3.17036
228
3.17041
203
3.17047
220
3.17052
229
3.17057
233
3.17063
241
3.17068
225
3.17073
220
3.17079
247
3.17084
249
3.17089
244
3.17095
230
3.171
247
3.17105
206
3.1711
210
3.17116
234
3.17121
240
3.17126
276
3.17132
243
3.17137
251
3.17142
234
3.17148
260
3.17153
234
3.17158
221
3.17164
263
3.17169
252
3.17174
244
3.17179
256
3.17185
263
3.1719
254
3.17195
258
3.17201
279
3.17206
271
3.17211
267
3.17217
270
3.17222
294
3.17227
317
3.17233
319
3.17238
310
3.17243
305
3.17249
300
3.17254
328
3.17259
331
3.17264
331
3.1727
344
3.17275
354
3.1728
355
3.17286
340
3.17291
345
3.17296
335
3.17302
386
3.17307
372
3.17312
394
3.17318
421
3.17323
420
3.17328
435
3.17334
463
3.17339
489
3.17344
467
3.17349
483
3.17355
476
3.1736
479
3.17365
518
3.17371
519
3.17376
527
3.17381
607
3.17387
608
3.17392
587
3.17397
610
3.17403
635
3.17408
641
3.17413
630
3.17418
686
3.17424
686
3.17429
698
3.17434
728
3.1744
756
3.17445
744
3.1745
718
3.17456
753
3.17461
787
3.17466
731
3.17472
798
3.17477
795
3.17482
831
3.17488
843
3.17493
866
3.17498
820
3.17503
821
3.17509
834
3.17514
906
3.17519
937
3.17525
876
3.1753
868
3.17535
933
3.17541
995
3.17546
1063
3.17551
1065
3.17557
1096
3.17562
1163
3.17567
1257
3.17572
1266
3.17578
1372
3.17583
1374
3.17588
1489
3.17594
1610
3.17599
1676
3.17604
1702
3.1761
1901
3.17615
1958
3.1762
2134
3.17626
2196
3.17631
2337
3.17636
2431
3.17642
2535
3.17647
2661
3.17652
2678
3.17657
2818
3.17663
2921
3.17668
2855
3.17673
2791
3.17679
2839
3.17684
2890
3.17689
2824
3.17695
2787
3.177
2664
3.17705
2530
3.17711
2375
3.17716
2250
3.17721
2136
3.17726
1982
3.17732
1870
3.17737
1713
3.17742
1653
3.17748
1501
3.17753
1384
3.17758
1322
3.17764
1210
3.17769
1103
3.17774
1070
3.1778
986
3.17785
991
3.1779
907
3.17796
905
3.17801
823
3.17806
819
3.17811
794
3.17817
800
3.17822
804
3.17827
798
3.17833
757
3.17838
775
3.17843
763
3.17849
831
3.17854
789
3.17859
768
3.17865
796
3.1787
832
3.17875
822
3.17881
866
3.17886
904
3.17891
901
3.17896
970
3.17902
959
3.17907
1034
3.17912
1061
3.17918
990
3.17923
1063
3.17928
1099
3.17934
1109
3.17939
1101
3.17944
1171
3.1795
1170
3.17955
1192
3.1796
1212
3.17965
1178
3.17971
1201
3.17976
1152
3.17981
1151
3.17987
1124
3.17992
1072
3.17997
1077
3.18003
1069
3.18008
1065
3.18013
1026
3.18019
957
3.18024
949
3.18029
906
3.18035
942
3.1804
923
3.18045
916
3.1805
883
3.18056
848
3.18061
781
3.18066
846
3.18072
835
3.18077
794
3.18082
818
3.18088
875
3.18093
790
3.18098
823
3.18104
827
3.18109
853
3.18114
866
3.1812
886
3.18125
872
3.1813
885
3.18135
926
3.18141
926
3.18146
887
3.18151
963
3.18157
956
3.18162
947
3.18167
983
3.18173
1018
3.18178
993
3.18183
966
3.18189
962
3.18194
951
3.18199
941
3.18204
966
3.1821
881
3.18215
894
3.1822
931
3.18226
840
3.18231
816
3.18236
815
3.18242
744
3.18247
788
3.18252
697
3.18258
660
3.18263
641
3.18268
584
3.18274
560
3.18279
551
3.18284
487
3.18289
451
3.18295
446
3.183
377
3.18305
333
3.18311
336
3.18316
333
3.18321
279
3.18327
240
3.18332
235
3.18337
222
3.18343
197
3.18348
190
3.18353
185
3.18358
160
3.18364
177
3.18369
129
3.18374
141
3.1838
133
3.18385
126
3.1839
126
3.18396
122
3.18401
125
3.18406
111
3.18412
119
3.18417
103
3.18422
116
3.18428
112
3.18433
113
3.18438
104
3.18443
106
3.18449
111
3.18454
130
3.18459
102
3.18465
101
3.1847
110
3.18475
105
3.18481
87
3.18486
99
3.18491
113
3.18497
101
3.18502
109
3.18507
122
3.18512
108
3.18518
91
3.18523
84
3.18528
85
3.18534
105
3.18539
86
3.18544
99
3.1855
95
3.18555
98
3.1856
87
3.18566
74
3.18571
83
3.18576
90
3.18582
78
3.18587
102
3.18592
106
3.18597
88
3.18603
91
3.18608
89
3.18613
91
3.18619
100
3.18624
90
3.18629
87
3.18635
80
3.1864
80
3.18645
90
3.18651
92
3.18656
96
3.18661
99
3.18667
83
3.18672
92
3.18677
91
3.18682
110
3.18688
89
3.18693
80
3.18698
96
3.18704
101
3.18709
95
3.18714
96
3.1872
85
3.18725
100
3.1873
79
3.18736
86
3.18741
91
3.18746
88
3.18751
110
3.18757
108
3.18762
99
3.18767
80
3.18773
79
3.18778
88
3.18783
97
3.18789
85
3.18794
86
3.18799
83
3.18805
76
3.1881
95
3.18815
82
3.18821
80
3.18826
108
3.18831
104
3.18836
85
3.18842
89
3.18847
94
3.18852
76
3.18858
84
3.18863
86
3.18868
86
3.18874
76
3.18879
102
3.18884
86
3.1889
74
3.18895
73
3.189
90
3.18905
107
3.18911
83
3.18916
79
3.18921
75
3.18927
74
3.18932
86
3.18937
103
3.18943
82
3.18948
87
3.18953
91
3.18959
80
3.18964
101
3.18969
81
3.18975
84
3.1898
94
3.18985
92
3.1899
86
3.18996
87
3.19001
90
3.19006
100
3.19012
94
3.19017
74
3.19022
73
3.19028
102
3.19033
109
3.19038
93
3.19044
84
3.19049
106
3.19054
93
3.19059
91
3.19065
80
3.1907
94
3.19075
87
3.19081
91
3.19086
88
3.19091
78
3.19097
93
3.19102
82
3.19107
84
3.19113
92
3.19118
76
3.19123
65
3.19129
96
3.19134
98
3.19139
91
3.19144
93
3.1915
102
3.19155
82
3.1916
101
3.19166
90
3.19171
89
3.19176
92
3.19182
92
3.19187
86
3.19192
99
3.19198
end of experiment