File: B2.vms
VAMAS Surface Chemical Analysis Standard Data Transfer Format 1988 May 4
Not Specified
Kratos Axis
Not Specified
/d=/data/20170705/2017006144/B2.dset
3
Casa Info Follows
0
SourceAnalyserAngle: Not Specified
MAP
REGULAR
4
2
32768
32768
1
Etch Time
s
0
0
0
0
4
wide/2
Not Specified
2017
7
4
10
59
57
0
21
Casa Info Follows
1
Calib M = 282.722 A = 284.6 BE ADD
6
annot text peak Data 1201.81 2416 RGB(0,0,0) Font(14,18,0,0,Times New Roman) Vertical
C 1s
annot text peak Data 505 2773 RGB(0,0,0) Font(14,18,0,0,Times New Roman) Vertical
O KLL
annot text peak Data 953.812 2568 RGB(0,0,0) Font(14,18,0,0,Times New Roman) Vertical
O 1s
annot text peak Data 642 2517 RGB(0,0,0) Font(14,18,0,0,Times New Roman) Vertical
F KLL
annot text peak Data 798.812 10224 RGB(0,0,0) Font(14,18,0,0,Times New Roman) Vertical
F 1s
annot text peak Data 1452.81 419 RGB(0,0,0) Font(14,18,0,0,Times New Roman) Vertical
F 2s
0
0
   XPS     Spectrum    Lens Mode:Hybrid   Resolution:Pass energy 80    Iris(Aper):slot(Slot)
   Acqn. Time(s): 110        Sweeps: 1        Anode:Mono(Al (Mono))(150 W)   Step(meV): 1000.0
   Dwell Time(ms): 100        Charge Neutraliser :On   Acquired On :17/07/04 10:59:57
XPS
90
6
0
Mono(Al (Mono))
1486.69
150
1e+037
1e+037
6000
6000
1e+037
1e+037
FAT
80
1e+037
-4.45
0
1e+037
1e+037
1e+037
1e+037
Wide
None
-1
Kinetic Energy
eV
386.69
1
2
Intensity
d
Transmission
d
pulse counting
0.1
0
1e+037
0
1
8.48115
2536
2581
2592
2596
2486
2588
2541
2564
2559
2644
2627
2590
2564
2601
2554
2623
2539
2567
2500
2482
2558
2487
2504
2467
2538
2583
2556
2505
2504
2636
2570
2605
2610
2490
2509
2553
2615
2646
2685
2626
2615
2605
2687
2638
2700
2623
2611
2598
2709
2568
2574
2621
2596
2600
2593
2640
2707
2727
2616
2633
2696
2654
2617
2648
2760
2673
2675
2645
2638
2632
2697
2725
2700
2658
2718
2721
2683
2745
2831
2760
2746
2736
2761
2709
2728
2713
2723
2770
2760
2747
2733
2718
2832
2733
2685
2755
2711
2776
2777
2771
2822
2778
2843
2747
2761
2853
2784
2761
2803
2756
2762
2782
2748
2685
2736
2688
2715
2766
2768
2785
2773
2829
2896
2847
2927
2887
2813
2825
2857
2767
2841
2787
2777
2729
2600
2608
2678
2642
2628
2572
2592
2600
2604
2531
2504
2625
2599
2643
2576
2524
2593
2626
2559
2548
2584
2561
2502
2550
2581
2539
2520
2620
2646
2556
2565
2638
2606
2680
2644
2590
2631
2616
2566
2602
2618
2616
2564
2622
2604
2634
2591
2618
2635
2673
2674
2745
2675
2731
2648
2735
2691
2646
2693
2671
2706
2675
2703
2640
2630
2659
2713
2691
2692
2744
2719
2732
2649
2777
2785
2687
2741
2739
2706
2709
2791
2809
2866
2836
2754
2846
2882
2872
2981
2976
2938
2882
2804
2727
2819
2706
2665
2717
2794
2709
2698
2877
2891
2892
3016
3091
3100
3191
3118
3158
3093
3078
2999
3008
2994
2936
2809
2756
2676
2649
2641
2610
2555
2517
2443
2485
2426
2548
2613
2701
2883
3152
3443
3650
4021
4134
3886
3550
3354
3085
2848
2658
2595
2450
2242
2174
2175
1967
1981
1883
1838
1889
1869
1848
1796
1886
1792
1819
1804
1767
1785
1812
1859
1820
1787
1756
1763
1848
1811
1830
1847
1813
1852
1862
1828
1811
1848
1836
1717
1791
1796
1841
1876
1834
1784
1851
1859
1810
1794
1822
1885
1897
1796
1817
1802
1823
1821
1860
1821
1811
1830
1912
1854
1808
1824
1786
1797
1861
1857
1857
1811
1864
1875
1886
1846
1899
1921
1878
1897
1837
1812
1839
1859
1883
1859
1815
1871
1907
1902
1911
1916
1936
1844
1858
1896
1839
1876
1848
1816
1769
1847
1874
1853
1943
1947
1993
1993
1958
1988
1967
1969
1924
1956
1915
1887
1930
1876
1897
1809
1850
1803
1768
1656
1603
1553
1551
1532
1420
1331
1237
1215
1140
1080
1021
1044
1091
1300
2002
4590
9589
10224
4419
1547
1026
933
897
835
871
827
867
840
875
879
847
849
868
845
891
879
844
803
876
831
852
834
825
835
829
844
872
827
834
826
840
876
886
844
891
888
878
872
845
879
881
888
874
858
880
882
897
863
886
860
881
902
856
861
882
866
923
910
886
898
916
845
885
910
865
846
902
888
970
919
882
867
923
881
897
889
869
883
847
886
902
924
883
886
861
856
883
889
868
872
890
919
915
887
904
915
910
873
869
879
907
972
919
915
905
884
858
866
859
851
937
965
917
866
878
866
916
912
861
869
851
836
869
823
945
912
972
945
954
986
941
916
908
909
893
877
881
818
801
809
797
788
748
722
728
668
673
724
719
801
1041
1717
2568
2326
1370
794
652
599
618
638
617
581
620
616
608
614
604
621
574
635
604
609
609
605
614
590
613
596
622
615
571
602
599
623
582
596
614
609
636
633
624
615
610
629
634
614
616
640
621
559
605
631
676
634
645
666
639
615
636
640
608
577
618
651
643
659
652
656
622
637
654
645
631
614
646
630
623
642
597
610
628
629
623
640
663
688
640
669
688
679
667
640
651
661
680
679
663
698
663
641
633
649
642
658
646
692
670
658
680
633
661
667
672
649
639
664
633
659
683
678
701
680
636
639
671
683
692
722
711
669
680
704
712
797
755
706
698
721
715
703
654
709
706
691
731
691
701
706
693
715
659
724
681
691
739
694
722
711
723
730
755
700
755
690
692
755
737
741
753
792
748
693
715
701
715
752
754
740
722
724
739
735
729
720
745
739
777
758
740
742
765
749
746
755
741
780
776
753
742
780
777
768
763
735
769
808
802
804
744
817
788
816
800
826
846
809
821
823
820
816
803
863
832
764
819
795
794
814
770
697
716
691
623
628
590
560
495
428
402
356
318
338
464
773
1578
3113
2568
1352
1427
1633
2416
2043
603
201
147
149
139
138
124
130
135
137
133
137
118
131
136
116
130
118
135
137
139
143
113
115
131
124
131
127
125
127
127
118
119
130
120
114
130
133
115
124
122
127
135
143
111
121
137
128
130
165
154
156
148
131
118
121
127
137
123
130
129
131
127
143
126
111
109
118
138
123
121
128
108
103
101
129
125
123
114
125
125
131
133
137
122
121
130
125
116
129
127
139
136
97
112
140
113
110
129
124
121
115
123
108
113
121
115
131
116
117
124
117
147
151
188
166
152
131
115
106
113
128
97
115
113
117
122
122
127
131
142
145
138
128
120
137
96
124
140
126
127
133
121
122
132
144
140
117
108
131
119
113
111
116
120
132
127
124
147
142
120
111
121
129
130
122
141
140
141
142
124
113
138
119
137
136
125
123
115
131
147
140
126
140
143
146
139
144
136
137
124
138
135
135
136
133
117
136
140
137
139
135
141
156
134
132
142
140
133
136
118
130
140
141
147
134
117
132
130
136
134
141
123
151
132
134
121
127
114
121
136
131
130
138
130
121
129
115
130
117
107
105
107
124
122
120
175
258
385
419
337
226
172
139
102
109
97
89
93
76
77
101
96
91
98
100
85
101
118
128
123
111
113
136
90
64
51
35
28
15
10
1
8.94051
F 1s/5
Not Specified
2017
7
4
13
37
28
0
9
Casa Info Follows
1
Calib M = 282.722 A = 284.6 BE ADD
0
0
0
   XPS     Spectrum    Lens Mode:Hybrid   Resolution:Pass energy 40    Iris(Aper):slot(Slot)
   Acqn. Time(s): 121        Sweeps: 2        Anode:Mono(Al (Mono))(150 W)   Step(meV): 50.0
   Dwell Time(ms): 150        Charge Neutraliser :On   Acquired On :17/07/04 13:37:28
XPS
90
6
0
Mono(Al (Mono))
1486.69
150
1e+037
1e+037
6000
6000
1e+037
1e+037
FAT
40
1e+037
-4.45
0
1e+037
1e+037
1e+037
1e+037
F
1s
-1
Kinetic Energy
eV
790.64
0.05
2
Intensity
d
Transmission
d
pulse counting
0.15
2
0
1e+037
1e+037
1e+037
0
806
921
16959
3.41724
3.42712
1353
3.42712
1384
3.4271
1358
3.42707
1337
3.42705
1321
3.42702
1223
3.427
1283
3.42698
1270
3.42695
1284
3.42693
1248
3.4269
1253
3.42688
1220
3.42686
1237
3.42683
1215
3.42681
1243
3.42678
1223
3.42676
1220
3.42674
1249
3.42671
1184
3.42669
1210
3.42667
1218
3.42664
1211
3.42662
1223
3.42659
1182
3.42657
1168
3.42655
1198
3.42652
1212
3.4265
1210
3.42647
1172
3.42645
1158
3.42643
1162
3.4264
1151
3.42638
1190
3.42636
1161
3.42633
1129
3.42631
1191
3.42628
1148
3.42626
1145
3.42624
1166
3.42621
1185
3.42619
1187
3.42616
1136
3.42614
1163
3.42612
1160
3.42609
1187
3.42607
1190
3.42605
1132
3.42602
1157
3.426
1169
3.42597
1158
3.42595
1180
3.42593
1207
3.4259
1117
3.42588
1140
3.42585
1179
3.42583
1122
3.42581
1164
3.42578
1174
3.42576
1111
3.42573
1163
3.42571
1178
3.42569
1115
3.42566
1135
3.42564
1105
3.42562
1087
3.42559
1176
3.42557
1202
3.42554
1110
3.42552
1167
3.4255
1193
3.42547
1199
3.42545
1163
3.42542
1179
3.4254
1167
3.42538
1126
3.42535
1146
3.42533
1153
3.42531
1144
3.42528
1172
3.42526
1182
3.42523
1158
3.42521
1166
3.42519
1174
3.42516
1199
3.42514
1179
3.42511
1173
3.42509
1156
3.42507
1116
3.42504
1155
3.42502
1221
3.425
1235
3.42497
1195
3.42495
1171
3.42492
1185
3.4249
1196
3.42488
1224
3.42485
1206
3.42483
1214
3.4248
1186
3.42478
1223
3.42476
1139
3.42473
1209
3.42471
1189
3.42469
1169
3.42466
1257
3.42464
1264
3.42461
1231
3.42459
1208
3.42457
1219
3.42454
1257
3.42452
1271
3.42449
1264
3.42447
1294
3.42445
1252
3.42442
1283
3.4244
1284
3.42437
1344
3.42435
1309
3.42433
1375
3.4243
1264
3.42428
1277
3.42426
1324
3.42423
1288
3.42421
1300
3.42418
1302
3.42416
1333
3.42414
1390
3.42411
1432
3.42409
1420
3.42406
1466
3.42404
1459
3.42402
1458
3.42399
1491
3.42397
1488
3.42395
1537
3.42392
1626
3.4239
1637
3.42387
1663
3.42385
1733
3.42383
1762
3.4238
1854
3.42378
1905
3.42375
2043
3.42373
2099
3.42371
2091
3.42368
2241
3.42366
2341
3.42364
2472
3.42361
2659
3.42359
2724
3.42356
2831
3.42354
3020
3.42352
3199
3.42349
3508
3.42347
3679
3.42344
3817
3.42342
3996
3.4234
4361
3.42337
4656
3.42335
4894
3.42333
5148
3.4233
5503
3.42328
5862
3.42325
6174
3.42323
6813
3.42321
7149
3.42318
7480
3.42316
7943
3.42313
8431
3.42311
8966
3.42309
9549
3.42306
9947
3.42304
10547
3.42301
11047
3.42299
11542
3.42297
12401
3.42294
12829
3.42292
13339
3.4229
13998
3.42287
14350
3.42285
14769
3.42282
15362
3.4228
15825
3.42278
16198
3.42275
16345
3.42273
16677
3.4227
16747
3.42268
16959
3.42266
16787
3.42263
16886
3.42261
16631
3.42259
16504
3.42256
16351
3.42254
15977
3.42251
15561
3.42249
15194
3.42247
14718
3.42244
14057
3.42242
13246
3.42239
12701
3.42237
12147
3.42235
11455
3.42232
10759
3.4223
10015
3.42228
9357
3.42225
8738
3.42223
8264
3.4222
7525
3.42218
6973
3.42216
6381
3.42213
5882
3.42211
5510
3.42208
5017
3.42206
4618
3.42204
4271
3.42201
4091
3.42199
3764
3.42196
3465
3.42194
3259
3.42192
2958
3.42189
2790
3.42187
2634
3.42185
2458
3.42182
2280
3.4218
2261
3.42177
2103
3.42175
1940
3.42173
1917
3.4217
1865
3.42168
1830
3.42165
1731
3.42163
1668
3.42161
1583
3.42158
1595
3.42156
1481
3.42154
1475
3.42151
1452
3.42149
1450
3.42146
1405
3.42144
1350
3.42142
1370
3.42139
1331
3.42137
1256
3.42134
1337
3.42132
1241
3.4213
1191
3.42127
1248
3.42125
1193
3.42123
1175
3.4212
1146
3.42118
1173
3.42115
1158
3.42113
1173
3.42111
1150
3.42108
1173
3.42106
1120
3.42103
1110
3.42101
1119
3.42099
1122
3.42096
1151
3.42094
1091
3.42091
1102
3.42089
1076
3.42087
1108
3.42084
1053
3.42082
1038
3.4208
1110
3.42077
1087
3.42075
1048
3.42072
1069
3.4207
1119
3.42068
1065
3.42065
1114
3.42063
1054
3.4206
1061
3.42058
1082
3.42056
1043
3.42053
1080
3.42051
1051
3.42049
1088
3.42046
1123
3.42044
998
3.42041
1054
3.42039
1054
3.42037
1045
3.42034
984
3.42032
1009
3.42029
1035
3.42027
1094
3.42025
1055
3.42022
994
3.4202
961
3.42018
1032
3.42015
1026
3.42013
1045
3.4201
1000
3.42008
1014
3.42006
1017
3.42003
1003
3.42001
1047
3.41998
993
3.41996
1068
3.41994
1024
3.41991
993
3.41989
1017
3.41986
1057
3.41984
977
3.41982
1041
3.41979
1028
3.41977
1021
3.41975
1039
3.41972
1006
3.4197
982
3.41967
1038
3.41965
1000
3.41963
977
3.4196
1018
3.41958
1048
3.41955
992
3.41953
987
3.41951
976
3.41948
1056
3.41946
1015
3.41944
1045
3.41941
1003
3.41939
963
3.41936
1006
3.41934
974
3.41932
1044
3.41929
1017
3.41927
1035
3.41924
1026
3.41922
1028
3.4192
1017
3.41917
1012
3.41915
957
3.41913
953
3.4191
994
3.41908
989
3.41905
987
3.41903
975
3.41901
943
3.41898
1008
3.41896
1024
3.41893
955
3.41891
961
3.41889
975
3.41886
982
3.41884
1009
3.41881
1014
3.41879
1019
3.41877
989
3.41874
1042
3.41872
1038
3.4187
1013
3.41867
1028
3.41865
1013
3.41862
1008
3.4186
921
3.41858
995
3.41855
1028
3.41853
978
3.4185
1062
3.41848
1032
3.41846
960
3.41843
1006
3.41841
982
3.41839
1000
3.41836
999
3.41834
1002
3.41831
1038
3.41829
966
3.41827
988
3.41824
976
3.41822
941
3.41819
957
3.41817
976
3.41815
1022
3.41812
1005
3.4181
978
3.41808
1020
3.41805
972
3.41803
982
3.418
1019
3.41798
1007
3.41796
1041
3.41793
1006
3.4179
996
3.41786
974
3.41781
1030
3.41777
971
3.41773
1013
3.41769
1020
3.41765
1007
3.41761
972
3.41757
983
3.41753
981
3.41748
995
3.41744
1002
3.4174
965
3.41736
967
3.41732
1021
3.41728
1007
3.41724
O 1s/6
Not Specified
2017
7
4
13
37
28
0
9
Casa Info Follows
1
Calib M = 282.722 A = 284.6 BE ADD
0
0
0
   XPS     Spectrum    Lens Mode:Hybrid   Resolution:Pass energy 40    Iris(Aper):slot(Slot)
   Acqn. Time(s): 162        Sweeps: 3        Anode:Mono(Al (Mono))(150 W)   Step(meV): 50.0
   Dwell Time(ms): 150        Charge Neutraliser :On   Acquired On :17/07/04 13:37:28
XPS
90
6
0
Mono(Al (Mono))
1486.69
150
1e+037
1e+037
6000
6000
1e+037
1e+037
FAT
40
1e+037
-4.45
0
1e+037
1e+037
1e+037
1e+037
O
1s
-1
Kinetic Energy
eV
946.69
0.05
2
Intensity
d
Transmission
d
pulse counting
0.15
3
0
1e+037
1e+037
1e+037
0
722
967
5389
3.32569
3.34183
1222
3.34183
1243
3.34178
1201
3.34174
1201
3.34169
1200
3.34165
1237
3.3416
1218
3.34156
1207
3.34151
1219
3.34147
1225
3.34142
1282
3.34138
1164
3.34133
1210
3.34129
1261
3.34124
1217
3.3412
1250
3.34115
1241
3.34111
1230
3.34107
1178
3.34102
1197
3.34098
1174
3.34093
1254
3.34089
1215
3.34084
1228
3.3408
1190
3.34075
1238
3.34071
1215
3.34066
1220
3.34062
1200
3.34057
1179
3.34053
1224
3.34048
1283
3.34044
1264
3.34039
1181
3.34035
1165
3.3403
1148
3.34026
1167
3.34021
1134
3.34017
1162
3.34012
1170
3.34008
1224
3.34003
1195
3.33999
1145
3.33994
1178
3.3399
1187
3.33985
1168
3.33981
1169
3.33976
1220
3.33972
1172
3.33968
1216
3.33963
1208
3.33959
1164
3.33954
1206
3.3395
1137
3.33945
1191
3.33941
1224
3.33936
1190
3.33932
1145
3.33927
1156
3.33923
1179
3.33918
1160
3.33914
1194
3.33909
1136
3.33905
1187
3.339
1240
3.33896
1166
3.33891
1180
3.33887
1176
3.33882
1138
3.33878
1197
3.33873
1173
3.33869
1131
3.33864
1259
3.3386
1206
3.33855
1203
3.33851
1121
3.33846
1186
3.33842
1204
3.33837
1184
3.33833
1180
3.33829
1204
3.33824
1209
3.3382
1156
3.33815
1190
3.33811
1220
3.33806
1164
3.33802
1118
3.33797
1163
3.33793
1154
3.33788
1164
3.33784
1230
3.33779
1150
3.33775
1251
3.3377
1230
3.33766
1170
3.33761
1138
3.33757
1182
3.33752
1197
3.33748
1188
3.33743
1199
3.33739
1222
3.33734
1172
3.3373
1269
3.33725
1211
3.33721
1178
3.33716
1183
3.33712
1195
3.33707
1219
3.33703
1236
3.33698
1202
3.33694
1213
3.3369
1234
3.33685
1273
3.33681
1273
3.33676
1261
3.33672
1272
3.33667
1299
3.33663
1300
3.33658
1266
3.33654
1273
3.33649
1243
3.33645
1279
3.3364
1261
3.33636
1304
3.33631
1328
3.33627
1357
3.33622
1340
3.33618
1391
3.33613
1374
3.33609
1402
3.33604
1391
3.336
1411
3.33595
1414
3.33591
1472
3.33586
1486
3.33582
1457
3.33577
1535
3.33573
1610
3.33568
1675
3.33564
1634
3.3356
1730
3.33555
1735
3.33551
1797
3.33546
1846
3.33542
1917
3.33537
1913
3.33533
2053
3.33528
2076
3.33524
2141
3.33519
2262
3.33515
2277
3.3351
2322
3.33506
2462
3.33501
2605
3.33497
2710
3.33492
2751
3.33488
3000
3.33483
3044
3.33479
3072
3.33474
3205
3.3347
3380
3.33465
3557
3.33461
3599
3.33456
3724
3.33452
3844
3.33447
4097
3.33443
4175
3.33438
4233
3.33434
4433
3.33429
4605
3.33425
4659
3.33421
4704
3.33416
4926
3.33412
4850
3.33407
5046
3.33403
5143
3.33398
5169
3.33394
5204
3.33389
5327
3.33385
5389
3.3338
5326
3.33376
5222
3.33371
5203
3.33367
5267
3.33362
5195
3.33358
5135
3.33353
5021
3.33349
5087
3.33344
5095
3.3334
4903
3.33335
4855
3.33331
4706
3.33326
4642
3.33322
4527
3.33317
4506
3.33313
4511
3.33308
4311
3.33304
4175
3.33299
4054
3.33295
3971
3.3329
3895
3.33286
3657
3.33282
3600
3.33277
3470
3.33273
3410
3.33268
3332
3.33264
3198
3.33259
3052
3.33255
3006
3.3325
2912
3.33246
2865
3.33241
2750
3.33237
2608
3.33232
2462
3.33228
2372
3.33223
2297
3.33219
2084
3.33214
2025
3.3321
1935
3.33205
2001
3.33201
1877
3.33196
1757
3.33192
1655
3.33187
1602
3.33183
1624
3.33178
1504
3.33174
1517
3.33169
1471
3.33165
1469
3.3316
1410
3.33156
1338
3.33151
1299
3.33147
1298
3.33143
1273
3.33138
1270
3.33134
1204
3.33129
1214
3.33125
1196
3.3312
1167
3.33116
1138
3.33111
1148
3.33107
1119
3.33102
1110
3.33098
1089
3.33093
1074
3.33089
1157
3.33084
1148
3.3308
1080
3.33075
1035
3.33071
1052
3.33066
1113
3.33062
1135
3.33057
1108
3.33053
1068
3.33048
1045
3.33044
1070
3.33039
1072
3.33035
1079
3.3303
1055
3.33026
1079
3.33021
1065
3.33017
1093
3.33012
1025
3.33008
1085
3.33004
1082
3.32999
1103
3.32995
1101
3.3299
1060
3.32986
1076
3.32981
1080
3.32977
1037
3.32972
988
3.32968
1048
3.32963
1070
3.32959
1042
3.32954
1027
3.3295
1048
3.32945
1083
3.32941
1032
3.32936
1006
3.32932
1024
3.32927
1053
3.32923
1117
3.32918
1074
3.32914
1025
3.32909
1034
3.32905
1066
3.329
1054
3.32896
1076
3.32891
1031
3.32887
1001
3.32882
1026
3.32878
1031
3.32873
1008
3.32869
1024
3.32865
1051
3.3286
987
3.32856
1008
3.32851
1080
3.32847
1106
3.32842
1054
3.32838
1033
3.32833
1063
3.32829
1050
3.32824
1040
3.3282
1100
3.32815
1066
3.32811
1063
3.32806
1064
3.32802
1083
3.32797
1077
3.32793
1013
3.32788
1103
3.32784
1080
3.32779
1038
3.32775
1020
3.3277
1030
3.32766
1043
3.32761
1034
3.32757
1036
3.32752
1042
3.32748
1042
3.32743
1039
3.32739
1024
3.32735
1035
3.3273
1080
3.32726
1080
3.32721
1054
3.32717
1076
3.32712
1050
3.32708
1087
3.32703
1069
3.32699
1077
3.32694
1036
3.3269
1056
3.32685
1072
3.32681
1064
3.32676
1036
3.32672
1042
3.32667
1042
3.32663
1063
3.32658
1128
3.32654
1052
3.32649
1069
3.32645
1015
3.3264
978
3.32636
1003
3.32631
1046
3.32627
990
3.32622
1027
3.32618
1041
3.32613
1026
3.32609
967
3.32604
1020
3.326
1023
3.32596
998
3.32591
1067
3.32587
1074
3.32582
1046
3.32578
1048
3.32573
1009
3.32569
C 1s/7
Not Specified
2017
7
4
13
37
28
0
9
Casa Info Follows
1
Calib M = 282.722 A = 284.6 BE ADD
0
0
0
   XPS     Spectrum    Lens Mode:Hybrid   Resolution:Pass energy 40    Iris(Aper):slot(Slot)
   Acqn. Time(s): 138        Sweeps: 2        Anode:Mono(Al (Mono))(150 W)   Step(meV): 50.0
   Dwell Time(ms): 150        Charge Neutraliser :On   Acquired On :17/07/04 13:37:28
XPS
90
6
0
Mono(Al (Mono))
1486.69
150
1e+037
1e+037
6000
6000
1e+037
1e+037
FAT
40
1e+037
-4.45
0
1e+037
1e+037
1e+037
1e+037
C
1s
-1
Kinetic Energy
eV
1190.19
0.05
2
Intensity
d
Transmission
d
pulse counting
0.15
2
0
1e+037
1e+037
1e+037
0
922
122
5277
3.16755
3.19198
495
3.16755
467
3.1676
512
3.16765
475
3.16771
482
3.16776
464
3.16781
479
3.16787
446
3.16792
450
3.16797
479
3.16802
463
3.16808
447
3.16813
448
3.16818
481
3.16824
449
3.16829
456
3.16834
447
3.1684
479
3.16845
414
3.1685
434
3.16856
437
3.16861
433
3.16866
429
3.16871
418
3.16877
453
3.16882
422
3.16887
383
3.16893
447
3.16898
428
3.16903
411
3.16909
401
3.16914
424
3.16919
410
3.16925
394
3.1693
378
3.16935
401
3.16941
404
3.16946
432
3.16951
437
3.16956
411
3.16962
405
3.16967
394
3.16972
393
3.16978
388
3.16983
371
3.16988
384
3.16994
446
3.16999
418
3.17004
370
3.1701
401
3.17015
391
3.1702
406
3.17025
374
3.17031
390
3.17036
388
3.17041
356
3.17047
371
3.17052
369
3.17057
360
3.17063
356
3.17068
357
3.17073
348
3.17079
381
3.17084
369
3.17089
354
3.17095
383
3.171
355
3.17105
355
3.1711
341
3.17116
350
3.17121
356
3.17126
341
3.17132
333
3.17137
350
3.17142
317
3.17148
327
3.17153
359
3.17158
340
3.17164
344
3.17169
356
3.17174
326
3.17179
370
3.17185
314
3.1719
352
3.17195
332
3.17201
340
3.17206
357
3.17211
357
3.17217
359
3.17222
326
3.17227
366
3.17233
399
3.17238
390
3.17243
341
3.17249
367
3.17254
370
3.17259
347
3.17264
370
3.1727
381
3.17275
382
3.1728
366
3.17286
401
3.17291
411
3.17296
430
3.17302
397
3.17307
409
3.17312
386
3.17318
413
3.17323
450
3.17328
399
3.17334
401
3.17339
456
3.17344
456
3.17349
482
3.17355
509
3.1736
501
3.17365
499
3.17371
515
3.17376
510
3.17381
536
3.17387
566
3.17392
638
3.17397
618
3.17403
639
3.17408
663
3.17413
696
3.17418
703
3.17424
741
3.17429
737
3.17434
790
3.1744
826
3.17445
849
3.1745
847
3.17456
894
3.17461
918
3.17466
930
3.17472
924
3.17477
967
3.17482
980
3.17488
978
3.17493
1039
3.17498
1041
3.17503
1045
3.17509
1094
3.17514
1184
3.17519
1215
3.17525
1219
3.1753
1296
3.17535
1364
3.17541
1422
3.17546
1552
3.17551
1683
3.17557
1741
3.17562
1980
3.17567
2059
3.17572
2248
3.17578
2326
3.17583
2494
3.17588
2694
3.17594
2990
3.17599
3096
3.17604
3340
3.1761
3593
3.17615
3817
3.1762
4075
3.17626
4295
3.17631
4420
3.17636
4711
3.17642
4803
3.17647
4942
3.17652
5102
3.17657
5193
3.17663
5194
3.17668
5277
3.17673
5220
3.17679
5016
3.17684
4866
3.17689
4780
3.17695
4581
3.177
4329
3.17705
4112
3.17711
3859
3.17716
3553
3.17721
3328
3.17726
3149
3.17732
2876
3.17737
2612
3.17742
2447
3.17748
2247
3.17753
2167
3.17758
1952
3.17764
1753
3.17769
1750
3.17774
1579
3.1778
1496
3.17785
1483
3.1779
1388
3.17796
1333
3.17801
1281
3.17806
1233
3.17811
1235
3.17817
1202
3.17822
1179
3.17827
1159
3.17833
1162
3.17838
1209
3.17843
1217
3.17849
1193
3.17854
1159
3.17859
1215
3.17865
1201
3.1787
1263
3.17875
1314
3.17881
1386
3.17886
1376
3.17891
1436
3.17896
1482
3.17902
1511
3.17907
1528
3.17912
1589
3.17918
1631
3.17923
1590
3.17928
1661
3.17934
1782
3.17939
1743
3.17944
1789
3.1795
1814
3.17955
1787
3.1796
1705
3.17965
1694
3.17971
1738
3.17976
1689
3.17981
1669
3.17987
1659
3.17992
1635
3.17997
1656
3.18003
1644
3.18008
1625
3.18013
1572
3.18019
1531
3.18024
1544
3.18029
1565
3.18035
1617
3.1804
1575
3.18045
1520
3.1805
1555
3.18056
1586
3.18061
1536
3.18066
1685
3.18072
1682
3.18077
1690
3.18082
1754
3.18088
1821
3.18093
1911
3.18098
1924
3.18104
1968
3.18109
2117
3.18114
2141
3.1812
2299
3.18125
2414
3.1813
2521
3.18135
2549
3.18141
2680
3.18146
2834
3.18151
2850
3.18157
3008
3.18162
3173
3.18167
3190
3.18173
3261
3.18178
3456
3.18183
3478
3.18189
3500
3.18194
3658
3.18199
3673
3.18204
3697
3.1821
3795
3.18215
3806
3.1822
3677
3.18226
3710
3.18231
3570
3.18236
3464
3.18242
3321
3.18247
3267
3.18252
3080
3.18258
2954
3.18263
2699
3.18268
2539
3.18274
2304
3.18279
2130
3.18284
1873
3.18289
1704
3.18295
1570
3.183
1349
3.18305
1281
3.18311
1143
3.18316
1026
3.18321
855
3.18327
741
3.18332
658
3.18337
585
3.18343
559
3.18348
501
3.18353
418
3.18358
371
3.18364
324
3.18369
347
3.18374
296
3.1838
286
3.18385
304
3.1839
266
3.18396
224
3.18401
226
3.18406
215
3.18412
218
3.18417
192
3.18422
177
3.18428
195
3.18433
189
3.18438
179
3.18443
175
3.18449
175
3.18454
172
3.18459
177
3.18465
159
3.1847
163
3.18475
158
3.18481
188
3.18486
165
3.18491
151
3.18497
147
3.18502
149
3.18507
150
3.18512
178
3.18518
147
3.18523
147
3.18528
171
3.18534
160
3.18539
145
3.18544
161
3.1855
155
3.18555
137
3.1856
139
3.18566
160
3.18571
152
3.18576
147
3.18582
152
3.18587
138
3.18592
150
3.18597
155
3.18603
134
3.18608
146
3.18613
164
3.18619
145
3.18624
158
3.18629
148
3.18635
145
3.1864
158
3.18645
158
3.18651
150
3.18656
155
3.18661
154
3.18667
171
3.18672
150
3.18677
129
3.18682
140
3.18688
130
3.18693
130
3.18698
153
3.18704
157
3.18709
142
3.18714
147
3.1872
142
3.18725
138
3.1873
159
3.18736
160
3.18741
134
3.18746
129
3.18751
132
3.18757
154
3.18762
155
3.18767
139
3.18773
127
3.18778
142
3.18783
164
3.18789
139
3.18794
145
3.18799
146
3.18805
151
3.1881
140
3.18815
142
3.18821
132
3.18826
141
3.18831
146
3.18836
140
3.18842
157
3.18847
152
3.18852
129
3.18858
141
3.18863
149
3.18868
134
3.18874
129
3.18879
140
3.18884
143
3.1889
150
3.18895
148
3.189
128
3.18905
131
3.18911
151
3.18916
125
3.18921
154
3.18927
146
3.18932
138
3.18937
145
3.18943
152
3.18948
129
3.18953
137
3.18959
158
3.18964
133
3.18969
140
3.18975
145
3.1898
151
3.18985
175
3.1899
151
3.18996
137
3.19001
140
3.19006
155
3.19012
126
3.19017
135
3.19022
137
3.19028
141
3.19033
162
3.19038
152
3.19044
131
3.19049
154
3.19054
144
3.19059
128
3.19065
135
3.1907
147
3.19075
146
3.19081
143
3.19086
137
3.19091
140
3.19097
137
3.19102
146
3.19107
149
3.19113
134
3.19118
141
3.19123
131
3.19129
154
3.19134
140
3.19139
137
3.19144
124
3.1915
132
3.19155
136
3.1916
131
3.19166
147
3.19171
143
3.19176
122
3.19182
136
3.19187
137
3.19192
140
3.19198
end of experiment