File: B3.vms
VAMAS Surface Chemical Analysis Standard Data Transfer Format 1988 May 4
Not Specified
Kratos Axis
Not Specified
/d=/data/20170705/2017006144/B3.dset
3
Casa Info Follows
0
SourceAnalyserAngle: Not Specified
MAP
REGULAR
4
2
32768
32768
1
Etch Time
s
0
0
0
0
4
wide/2
Not Specified
2017
7
4
11
2
29
0
27
Casa Info Follows
1
Calib M = 282.803 A = 284.6 BE ADD
9
annot text peak Data 1201.89 2013 RGB(0,0,0) Font(14,18,0,0,Times New Roman) Vertical
C 1s
annot text peak Data 1253.89 430 RGB(0,0,0) Font(14,18,0,0,Times New Roman) Vertical
S 2s
annot text peak Data 1317.89 568 RGB(0,0,0) Font(14,18,0,0,Times New Roman) Vertical
S 2p
annot text peak Data 507.893 2533 RGB(0,0,0) Font(14,18,0,0,Times New Roman) Vertical
O KLL
annot text peak Data 954.893 3425 RGB(0,0,0) Font(14,18,0,0,Times New Roman) Vertical
O 1s
annot text peak Data 642 1627 RGB(0,0,0) Font(14,18,0,0,Times New Roman) Vertical
F KLL
annot text peak Data 798.893 5329 RGB(0,0,0) Font(14,18,0,0,Times New Roman) Vertical
F 1s
annot text peak Data 1452.89 231 RGB(0,0,0) Font(14,18,0,0,Times New Roman) Vertical
F 2s
annot text peak Data 1085.89 861 RGB(0,0,0) Font(14,18,0,0,Times New Roman) Vertical
N 1s
0
0
   XPS     Spectrum    Lens Mode:Hybrid   Resolution:Pass energy 80    Iris(Aper):slot(Slot)
   Acqn. Time(s): 110        Sweeps: 1        Anode:Mono(Al (Mono))(150 W)   Step(meV): 1000.0
   Dwell Time(ms): 100        Charge Neutraliser :On   Acquired On :17/07/04 11:02:29
XPS
82
6
0
Mono(Al (Mono))
1486.69
150
1e+037
1e+037
6000
6000
1e+037
1e+037
FAT
80
1e+037
-4.45
0
1e+037
1e+037
1e+037
1e+037
Wide
None
-1
Kinetic Energy
eV
386.69
1
2
Intensity
d
Transmission
d
pulse counting
0.1
0
1e+037
0
4
8.48115
2165
2108
2145
2192
2171
2222
2201
2179
2148
2122
2160
2223
2210
2154
2164
2143
2238
2235
2203
2179
2110
2093
2106
2136
2135
2152
2141
2197
2145
2136
2138
2215
2145
2218
2231
2244
2247
2196
2242
2304
2209
2182
2245
2168
2159
2217
2174
2210
2255
2164
2254
2208
2259
2225
2171
2204
2251
2168
2215
2238
2259
2307
2274
2225
2304
2274
2241
2283
2222
2267
2308
2242
2282
2256
2297
2267
2256
2284
2265
2336
2332
2180
2242
2322
2362
2274
2265
2333
2322
2322
2264
2184
2338
2347
2304
2366
2350
2375
2440
2358
2372
2411
2433
2416
2396
2364
2361
2378
2406
2334
2257
2212
2216
2204
2220
2143
2256
2278
2254
2275
2307
2317
2412
2533
2430
2432
2476
2409
2374
2361
2329
2263
2139
2129
2032
1944
1909
1965
1931
1944
1948
1935
1947
1933
1896
1898
1983
1915
1904
1879
1878
1882
1844
1853
1876
1934
1928
1899
1925
1899
1888
1883
1821
1848
1953
1902
1912
1924
1913
1829
1935
1962
1879
1835
1894
1903
1916
1876
1909
1928
1914
1895
1859
1949
1902
1921
1890
1986
1965
1863
1909
1890
1887
1937
1901
1878
1878
1892
1900
1844
1826
1914
1913
1922
1936
1884
1950
1857
1956
1956
1926
1930
1914
1856
1919
1931
1897
1891
1891
1948
1957
1880
1919
1969
1925
1921
1904
1895
1925
1908
1896
1871
1870
1908
1896
1955
1940
1930
1917
1970
2028
2057
2071
2103
1979
1998
1973
1984
1956
1843
1830
1872
1831
1816
1778
1812
1707
1627
1663
1676
1676
1686
1693
1737
1885
2024
2144
2182
2271
2415
2384
2256
2053
1939
1904
1788
1722
1635
1543
1517
1498
1418
1455
1382
1454
1427
1371
1354
1376
1417
1366
1373
1353
1376
1369
1344
1347
1320
1343
1339
1328
1359
1393
1362
1399
1370
1323
1375
1297
1367
1353
1337
1362
1353
1372
1360
1344
1391
1382
1312
1341
1337
1326
1378
1393
1381
1372
1361
1373
1379
1358
1328
1398
1334
1349
1360
1340
1380
1340
1340
1325
1288
1388
1343
1384
1332
1370
1382
1368
1369
1382
1361
1297
1331
1347
1369
1370
1428
1341
1323
1363
1350
1302
1349
1352
1322
1313
1358
1299
1320
1260
1313
1254
1312
1313
1310
1333
1304
1394
1416
1387
1357
1380
1375
1359
1361
1401
1302
1321
1375
1322
1346
1353
1365
1310
1280
1260
1191
1128
1105
1068
1080
1051
1033
958
929
901
939
952
918
1010
1276
2235
4600
5329
2794
1207
902
862
862
788
827
828
853
841
808
816
857
864
871
835
827
794
813
768
805
811
825
811
848
827
824
854
856
887
862
820
879
877
790
885
853
853
852
863
834
853
850
837
867
894
914
901
902
937
880
876
911
893
888
869
880
864
878
875
887
908
901
864
851
907
897
900
876
939
901
909
878
899
873
899
883
929
925
901
910
924
918
839
911
892
892
946
898
895
963
945
917
911
949
937
952
962
954
914
894
922
980
988
948
913
934
965
960
989
983
977
1000
965
986
956
977
986
937
913
958
963
986
980
985
981
994
1033
1073
1082
1099
1066
1068
1053
1037
959
964
954
860
885
857
793
800
758
705
668
641
613
590
603
648
761
1152
2094
3154
3425
2175
929
588
543
507
519
517
524
536
550
508
538
524
479
533
543
549
547
522
545
506
544
533
519
538
540
565
516
538
533
536
508
518
541
580
536
507
488
530
541
528
540
542
526
526
529
537
572
541
550
545
551
527
544
514
553
545
520
573
567
568
546
532
557
567
565
557
558
549
560
552
581
581
562
563
577
564
561
571
551
552
549
582
553
544
553
576
530
568
556
556
551
577
581
571
546
554
565
588
581
551
596
574
598
564
575
595
560
600
583
593
586
552
570
590
565
567
561
546
542
504
532
539
559
560
508
528
582
701
854
861
744
582
573
526
536
509
526
582
554
547
526
543
526
544
539
545
547
555
502
538
550
550
533
547
555
511
512
540
535
535
557
543
530
578
568
581
533
566
552
592
555
568
561
575
553
593
580
558
570
558
577
581
594
557
569
566
600
546
572
568
606
586
568
601
609
577
586
572
622
616
603
567
558
580
611
617
629
597
622
640
660
641
635
630
635
623
671
665
628
643
632
627
606
606
578
566
558
523
492
522
472
399
411
374
335
316
342
380
519
835
1600
1739
982
1118
1613
2013
1614
513
205
179
161
175
183
170
167
179
177
177
171
160
187
188
175
174
187
206
189
170
168
182
181
209
181
183
187
191
207
192
183
167
205
175
151
161
172
182
157
165
140
147
166
179
171
167
188
240
372
430
421
261
189
178
186
162
159
147
149
157
148
129
177
160
147
157
143
131
149
154
154
151
152
161
159
143
139
151
158
164
145
164
146
171
172
159
156
141
153
187
173
158
183
176
135
164
166
156
128
123
135
98
105
104
107
114
109
112
108
110
134
230
487
568
434
184
106
110
89
100
102
97
98
105
104
93
104
100
98
85
89
97
100
102
93
100
104
96
103
105
110
96
95
101
94
94
100
105
107
97
105
106
100
102
91
98
92
100
98
113
99
90
106
100
107
86
103
74
87
113
105
103
110
93
100
102
103
102
104
101
109
100
105
103
103
104
103
121
95
98
103
125
101
103
104
101
110
101
119
92
99
87
94
99
93
114
99
114
104
114
105
105
100
86
122
101
94
107
106
114
115
89
120
107
100
115
133
127
111
117
92
107
111
84
100
95
98
84
93
88
88
96
89
81
94
97
146
217
231
206
149
111
116
123
103
103
114
106
94
74
74
76
74
66
83
71
73
85
97
85
84
101
115
84
63
36
40
29
20
4
5
8.94051
F 1s/5
Not Specified
2017
7
4
13
47
28
0
9
Casa Info Follows
1
Calib M = 282.803 A = 284.6 BE ADD
0
0
0
   XPS     Spectrum    Lens Mode:Hybrid   Resolution:Pass energy 40    Iris(Aper):slot(Slot)
   Acqn. Time(s): 121        Sweeps: 2        Anode:Mono(Al (Mono))(150 W)   Step(meV): 50.0
   Dwell Time(ms): 150        Charge Neutraliser :On   Acquired On :17/07/04 13:47:28
XPS
82
6
0
Mono(Al (Mono))
1486.69
150
1e+037
1e+037
6000
6000
1e+037
1e+037
FAT
40
1e+037
-4.45
0
1e+037
1e+037
1e+037
1e+037
F
1s
-1
Kinetic Energy
eV
790.64
0.05
2
Intensity
d
Transmission
d
pulse counting
0.15
2
0
1e+037
1e+037
1e+037
0
806
850
8692
3.41724
3.42712
1106
3.42712
1055
3.4271
1142
3.42707
1076
3.42705
1081
3.42702
1053
3.427
1077
3.42698
1064
3.42695
1100
3.42693
1080
3.4269
1094
3.42688
1067
3.42686
1088
3.42683
1064
3.42681
1063
3.42678
1049
3.42676
1039
3.42674
1048
3.42671
1034
3.42669
1022
3.42667
1024
3.42664
1017
3.42662
1003
3.42659
990
3.42657
1044
3.42655
1100
3.42652
1017
3.4265
1044
3.42647
1001
3.42645
1048
3.42643
1063
3.4264
1018
3.42638
960
3.42636
1007
3.42633
1017
3.42631
988
3.42628
1050
3.42626
1036
3.42624
1060
3.42621
983
3.42619
1025
3.42616
1050
3.42614
1022
3.42612
1063
3.42609
1021
3.42607
1030
3.42605
1012
3.42602
980
3.426
980
3.42597
1008
3.42595
988
3.42593
983
3.4259
1017
3.42588
1070
3.42585
1009
3.42583
1046
3.42581
1010
3.42578
996
3.42576
999
3.42573
1012
3.42571
1007
3.42569
967
3.42566
1021
3.42564
1034
3.42562
995
3.42559
1049
3.42557
983
3.42554
1030
3.42552
1063
3.4255
1060
3.42547
1023
3.42545
994
3.42542
985
3.4254
982
3.42538
1075
3.42535
1002
3.42533
1002
3.42531
1011
3.42528
993
3.42526
1021
3.42523
1009
3.42521
1027
3.42519
970
3.42516
987
3.42514
1039
3.42511
1017
3.42509
1020
3.42507
1052
3.42504
1007
3.42502
973
3.425
1008
3.42497
1007
3.42495
952
3.42492
1002
3.4249
1023
3.42488
1040
3.42485
1021
3.42483
1014
3.4248
1048
3.42478
1011
3.42476
1028
3.42473
1041
3.42471
997
3.42469
997
3.42466
1020
3.42464
1017
3.42461
1036
3.42459
991
3.42457
1013
3.42454
1040
3.42452
988
3.42449
1047
3.42447
1055
3.42445
994
3.42442
1079
3.4244
1048
3.42437
1064
3.42435
1084
3.42433
1042
3.4243
1089
3.42428
1033
3.42426
1081
3.42423
1049
3.42421
1077
3.42418
1042
3.42416
1070
3.42414
1102
3.42411
1136
3.42409
1095
3.42406
1108
3.42404
1104
3.42402
1140
3.42399
1114
3.42397
1122
3.42395
1114
3.42392
1163
3.4239
1219
3.42387
1209
3.42385
1204
3.42383
1189
3.4238
1268
3.42378
1287
3.42375
1263
3.42373
1320
3.42371
1325
3.42368
1354
3.42366
1419
3.42364
1446
3.42361
1503
3.42359
1589
3.42356
1601
3.42354
1585
3.42352
1706
3.42349
1841
3.42347
1828
3.42344
1946
3.42342
2094
3.4234
2174
3.42337
2255
3.42335
2327
3.42333
2439
3.4233
2638
3.42328
2797
3.42325
2988
3.42323
3137
3.42321
3309
3.42318
3500
3.42316
3765
3.42313
3885
3.42311
4066
3.42309
4286
3.42306
4593
3.42304
4878
3.42301
5146
3.42299
5508
3.42297
5820
3.42294
5986
3.42292
6285
3.4229
6607
3.42287
6923
3.42285
7064
3.42282
7268
3.4228
7440
3.42278
7769
3.42275
7928
3.42273
8205
3.4227
8128
3.42268
8461
3.42266
8544
3.42263
8675
3.42261
8692
3.42259
8638
3.42256
8659
3.42254
8593
3.42251
8478
3.42249
8257
3.42247
8181
3.42244
7872
3.42242
7728
3.42239
7398
3.42237
7059
3.42235
6873
3.42232
6507
3.4223
6241
3.42228
5896
3.42225
5435
3.42223
5165
3.4222
4856
3.42218
4649
3.42216
4242
3.42213
3975
3.42211
3616
3.42208
3396
3.42206
3132
3.42204
2948
3.42201
2726
3.42199
2607
3.42196
2438
3.42194
2221
3.42192
2123
3.42189
2003
3.42187
1912
3.42185
1807
3.42182
1668
3.4218
1598
3.42177
1574
3.42175
1518
3.42173
1437
3.4217
1425
3.42168
1353
3.42165
1297
3.42163
1290
3.42161
1267
3.42158
1215
3.42156
1180
3.42154
1182
3.42151
1200
3.42149
1127
3.42146
1108
3.42144
1090
3.42142
1130
3.42139
1136
3.42137
1063
3.42134
1057
3.42132
1048
3.4213
1043
3.42127
1052
3.42125
1075
3.42123
998
3.4212
1017
3.42118
1010
3.42115
1038
3.42113
1020
3.42111
1025
3.42108
978
3.42106
1027
3.42103
921
3.42101
939
3.42099
990
3.42096
1024
3.42094
1041
3.42091
1012
3.42089
958
3.42087
999
3.42084
957
3.42082
994
3.4208
1000
3.42077
931
3.42075
920
3.42072
989
3.4207
942
3.42068
946
3.42065
971
3.42063
944
3.4206
957
3.42058
941
3.42056
945
3.42053
939
3.42051
919
3.42049
963
3.42046
965
3.42044
932
3.42041
875
3.42039
913
3.42037
917
3.42034
923
3.42032
964
3.42029
927
3.42027
953
3.42025
929
3.42022
938
3.4202
955
3.42018
994
3.42015
960
3.42013
938
3.4201
989
3.42008
994
3.42006
928
3.42003
960
3.42001
934
3.41998
984
3.41996
955
3.41994
906
3.41991
888
3.41989
882
3.41986
955
3.41984
911
3.41982
953
3.41979
962
3.41977
967
3.41975
956
3.41972
941
3.4197
976
3.41967
953
3.41965
996
3.41963
938
3.4196
988
3.41958
929
3.41955
975
3.41953
945
3.41951
919
3.41948
935
3.41946
945
3.41944
955
3.41941
923
3.41939
940
3.41936
917
3.41934
950
3.41932
922
3.41929
933
3.41927
915
3.41924
923
3.41922
897
3.4192
967
3.41917
950
3.41915
945
3.41913
858
3.4191
922
3.41908
928
3.41905
942
3.41903
945
3.41901
913
3.41898
897
3.41896
996
3.41893
910
3.41891
933
3.41889
955
3.41886
973
3.41884
915
3.41881
955
3.41879
934
3.41877
963
3.41874
972
3.41872
936
3.4187
934
3.41867
970
3.41865
949
3.41862
954
3.4186
957
3.41858
916
3.41855
939
3.41853
967
3.4185
940
3.41848
951
3.41846
938
3.41843
921
3.41841
922
3.41839
966
3.41836
953
3.41834
916
3.41831
914
3.41829
941
3.41827
969
3.41824
932
3.41822
934
3.41819
937
3.41817
912
3.41815
939
3.41812
929
3.4181
978
3.41808
939
3.41805
935
3.41803
932
3.418
927
3.41798
959
3.41796
947
3.41793
942
3.4179
924
3.41786
943
3.41781
925
3.41777
940
3.41773
964
3.41769
962
3.41765
924
3.41761
917
3.41757
880
3.41753
850
3.41748
910
3.41744
958
3.4174
972
3.41736
954
3.41732
941
3.41728
895
3.41724
O 1s/6
Not Specified
2017
7
4
13
47
28
0
9
Casa Info Follows
1
Calib M = 282.803 A = 284.6 BE ADD
0
0
0
   XPS     Spectrum    Lens Mode:Hybrid   Resolution:Pass energy 40    Iris(Aper):slot(Slot)
   Acqn. Time(s): 162        Sweeps: 3        Anode:Mono(Al (Mono))(150 W)   Step(meV): 50.0
   Dwell Time(ms): 150        Charge Neutraliser :On   Acquired On :17/07/04 13:47:28
XPS
82
6
0
Mono(Al (Mono))
1486.69
150
1e+037
1e+037
6000
6000
1e+037
1e+037
FAT
40
1e+037
-4.45
0
1e+037
1e+037
1e+037
1e+037
O
1s
-1
Kinetic Energy
eV
946.69
0.05
2
Intensity
d
Transmission
d
pulse counting
0.15
3
0
1e+037
1e+037
1e+037
0
722
807
6992
3.32569
3.34183
1120
3.34183
1126
3.34178
1107
3.34174
1131
3.34169
1117
3.34165
1113
3.3416
1126
3.34156
1125
3.34151
1153
3.34147
1120
3.34142
1092
3.34138
1048
3.34133
1098
3.34129
1108
3.34124
1124
3.3412
1085
3.34115
1091
3.34111
1039
3.34107
1101
3.34102
1074
3.34098
1058
3.34093
1070
3.34089
1041
3.34084
1130
3.3408
1035
3.34075
1082
3.34071
1061
3.34066
1013
3.34062
1029
3.34057
1067
3.34053
1042
3.34048
1029
3.34044
1031
3.34039
1035
3.34035
1096
3.3403
993
3.34026
1017
3.34021
1086
3.34017
1036
3.34012
1032
3.34008
1024
3.34003
1002
3.33999
1006
3.33994
1020
3.3399
1029
3.33985
1062
3.33981
998
3.33976
1040
3.33972
1003
3.33968
1011
3.33963
992
3.33959
1013
3.33954
1024
3.3395
1031
3.33945
1022
3.33941
1016
3.33936
996
3.33932
970
3.33927
1061
3.33923
1055
3.33918
1020
3.33914
976
3.33909
974
3.33905
1004
3.339
1051
3.33896
994
3.33891
1000
3.33887
969
3.33882
990
3.33878
977
3.33873
992
3.33869
1012
3.33864
1051
3.3386
1015
3.33855
1014
3.33851
1017
3.33846
976
3.33842
1066
3.33837
1012
3.33833
994
3.33829
999
3.33824
1033
3.3382
1012
3.33815
1005
3.33811
960
3.33806
1030
3.33802
1037
3.33797
1003
3.33793
982
3.33788
1013
3.33784
1023
3.33779
989
3.33775
1015
3.3377
1011
3.33766
1047
3.33761
1080
3.33757
1023
3.33752
1040
3.33748
1048
3.33743
1094
3.33739
1042
3.33734
1022
3.3373
1024
3.33725
1102
3.33721
1083
3.33716
1011
3.33712
1086
3.33707
1040
3.33703
1040
3.33698
1071
3.33694
1087
3.3369
1096
3.33685
1132
3.33681
1152
3.33676
1161
3.33672
1149
3.33667
1207
3.33663
1158
3.33658
1133
3.33654
1184
3.33649
1145
3.33645
1152
3.3364
1194
3.33636
1201
3.33631
1261
3.33627
1227
3.33622
1285
3.33618
1324
3.33613
1391
3.33609
1342
3.33604
1398
3.336
1441
3.33595
1468
3.33591
1537
3.33586
1596
3.33582
1550
3.33577
1635
3.33573
1701
3.33568
1676
3.33564
1787
3.3356
1900
3.33555
1903
3.33551
2019
3.33546
2067
3.33542
2143
3.33537
2262
3.33533
2311
3.33528
2385
3.33524
2466
3.33519
2593
3.33515
2678
3.3351
2753
3.33506
2903
3.33501
3037
3.33497
3210
3.33492
3329
3.33488
3456
3.33483
3473
3.33479
3683
3.33474
3844
3.3347
3995
3.33465
4084
3.33461
4187
3.33456
4260
3.33452
4366
3.33447
4548
3.33443
4716
3.33438
4867
3.33434
4953
3.33429
5052
3.33425
5182
3.33421
5177
3.33416
5346
3.33412
5465
3.33407
5631
3.33403
5682
3.33398
5842
3.33394
5839
3.33389
5970
3.33385
6150
3.3338
6197
3.33376
6170
3.33371
6221
3.33367
6360
3.33362
6385
3.33358
6439
3.33353
6583
3.33349
6732
3.33344
6678
3.3334
6642
3.33335
6837
3.33331
6878
3.33326
6868
3.33322
6908
3.33317
6992
3.33313
6979
3.33308
6931
3.33304
6851
3.33299
6827
3.33295
6799
3.3329
6783
3.33286
6708
3.33282
6516
3.33277
6400
3.33273
6256
3.33268
6000
3.33264
5809
3.33259
5588
3.33255
5401
3.3325
5260
3.33246
5032
3.33241
4854
3.33237
4489
3.33232
4162
3.33228
3908
3.33223
3583
3.33219
3372
3.33214
3178
3.3321
2975
3.33205
2705
3.33201
2519
3.33196
2291
3.33192
2118
3.33187
1967
3.33183
1857
3.33178
1741
3.33174
1661
3.33169
1522
3.33165
1423
3.3316
1314
3.33156
1275
3.33151
1221
3.33147
1207
3.33143
1200
3.33138
1163
3.33134
1101
3.33129
1088
3.33125
1016
3.3312
1011
3.33116
1048
3.33111
1020
3.33107
1049
3.33102
997
3.33098
1002
3.33093
1001
3.33089
991
3.33084
968
3.3308
932
3.33075
945
3.33071
920
3.33066
903
3.33062
939
3.33057
927
3.33053
938
3.33048
951
3.33044
942
3.33039
885
3.33035
877
3.3303
920
3.33026
940
3.33021
924
3.33017
937
3.33012
925
3.33008
925
3.33004
894
3.32999
944
3.32995
875
3.3299
918
3.32986
863
3.32981
918
3.32977
893
3.32972
907
3.32968
917
3.32963
912
3.32959
946
3.32954
896
3.3295
935
3.32945
897
3.32941
923
3.32936
887
3.32932
833
3.32927
898
3.32923
949
3.32918
867
3.32914
883
3.32909
883
3.32905
878
3.329
894
3.32896
882
3.32891
892
3.32887
902
3.32882
915
3.32878
868
3.32873
866
3.32869
902
3.32865
884
3.3286
910
3.32856
930
3.32851
883
3.32847
875
3.32842
906
3.32838
878
3.32833
878
3.32829
913
3.32824
879
3.3282
902
3.32815
905
3.32811
887
3.32806
948
3.32802
925
3.32797
913
3.32793
863
3.32788
868
3.32784
871
3.32779
964
3.32775
886
3.3277
898
3.32766
895
3.32761
897
3.32757
840
3.32752
872
3.32748
881
3.32743
866
3.32739
905
3.32735
904
3.3273
860
3.32726
910
3.32721
917
3.32717
891
3.32712
851
3.32708
890
3.32703
878
3.32699
853
3.32694
881
3.3269
920
3.32685
934
3.32681
873
3.32676
845
3.32672
838
3.32667
875
3.32663
850
3.32658
843
3.32654
891
3.32649
828
3.32645
886
3.3264
853
3.32636
919
3.32631
845
3.32627
880
3.32622
872
3.32618
875
3.32613
888
3.32609
929
3.32604
887
3.326
807
3.32596
911
3.32591
894
3.32587
918
3.32582
880
3.32578
894
3.32573
900
3.32569
C 1s/7
Not Specified
2017
7
4
13
47
28
0
9
Casa Info Follows
1
Calib M = 282.803 A = 284.6 BE ADD
0
0
0
   XPS     Spectrum    Lens Mode:Hybrid   Resolution:Pass energy 40    Iris(Aper):slot(Slot)
   Acqn. Time(s): 138        Sweeps: 2        Anode:Mono(Al (Mono))(150 W)   Step(meV): 50.0
   Dwell Time(ms): 150        Charge Neutraliser :On   Acquired On :17/07/04 13:47:28
XPS
82
6
0
Mono(Al (Mono))
1486.69
150
1e+037
1e+037
6000
6000
1e+037
1e+037
FAT
40
1e+037
-4.45
0
1e+037
1e+037
1e+037
1e+037
C
1s
-1
Kinetic Energy
eV
1190.19
0.05
2
Intensity
d
Transmission
d
pulse counting
0.15
2
0
1e+037
1e+037
1e+037
0
922
160
2992
3.16755
3.19198
454
3.16755
418
3.1676
400
3.16765
430
3.16771
439
3.16776
373
3.16781
416
3.16787
425
3.16792
417
3.16797
425
3.16802
386
3.16808
389
3.16813
395
3.16818
374
3.16824
411
3.16829
393
3.16834
397
3.1684
390
3.16845
383
3.1685
404
3.16856
387
3.16861
397
3.16866
406
3.16871
365
3.16877
359
3.16882
353
3.16887
366
3.16893
385
3.16898
387
3.16903
344
3.16909
360
3.16914
364
3.16919
384
3.16925
403
3.1693
375
3.16935
352
3.16941
371
3.16946
372
3.16951
376
3.16956
381
3.16962
389
3.16967
388
3.16972
393
3.16978
352
3.16983
369
3.16988
393
3.16994
352
3.16999
357
3.17004
346
3.1701
371
3.17015
375
3.1702
334
3.17025
335
3.17031
343
3.17036
356
3.17041
377
3.17047
346
3.17052
343
3.17057
350
3.17063
347
3.17068
349
3.17073
353
3.17079
346
3.17084
362
3.17089
372
3.17095
342
3.171
324
3.17105
348
3.1711
340
3.17116
375
3.17121
359
3.17126
372
3.17132
306
3.17137
345
3.17142
339
3.17148
335
3.17153
352
3.17158
330
3.17164
330
3.17169
331
3.17174
343
3.17179
327
3.17185
333
3.1719
324
3.17195
324
3.17201
326
3.17206
292
3.17211
324
3.17217
298
3.17222
330
3.17227
327
3.17233
351
3.17238
319
3.17243
342
3.17249
302
3.17254
344
3.17259
334
3.17264
346
3.1727
339
3.17275
338
3.1728
312
3.17286
322
3.17291
357
3.17296
332
3.17302
338
3.17307
329
3.17312
319
3.17318
335
3.17323
343
3.17328
363
3.17334
359
3.17339
352
3.17344
389
3.17349
401
3.17355
389
3.1736
379
3.17365
380
3.17371
368
3.17376
394
3.17381
400
3.17387
411
3.17392
402
3.17397
422
3.17403
384
3.17408
435
3.17413
409
3.17418
516
3.17424
495
3.17429
517
3.17434
513
3.1744
508
3.17445
512
3.1745
564
3.17456
554
3.17461
585
3.17466
571
3.17472
643
3.17477
656
3.17482
638
3.17488
628
3.17493
680
3.17498
665
3.17503
689
3.17509
687
3.17514
712
3.17519
778
3.17525
768
3.1753
755
3.17535
819
3.17541
825
3.17546
894
3.17551
912
3.17557
948
3.17562
1019
3.17567
1055
3.17572
1146
3.17578
1180
3.17583
1257
3.17588
1402
3.17594
1493
3.17599
1519
3.17604
1530
3.1761
1647
3.17615
1807
3.1762
1876
3.17626
1975
3.17631
2121
3.17636
2260
3.17642
2331
3.17647
2424
3.17652
2569
3.17657
2662
3.17663
2772
3.17668
2820
3.17673
2910
3.17679
2895
3.17684
2887
3.17689
2958
3.17695
2945
3.177
2829
3.17705
2757
3.17711
2671
3.17716
2532
3.17721
2461
3.17726
2342
3.17732
2207
3.17737
2069
3.17742
1910
3.17748
1753
3.17753
1667
3.17758
1536
3.17764
1411
3.17769
1293
3.17774
1243
3.1778
1155
3.17785
1144
3.1779
1067
3.17796
944
3.17801
965
3.17806
910
3.17811
894
3.17817
844
3.17822
804
3.17827
801
3.17833
792
3.17838
817
3.17843
770
3.17849
735
3.17854
789
3.17859
758
3.17865
766
3.1787
794
3.17875
817
3.17881
790
3.17886
788
3.17891
769
3.17896
823
3.17902
849
3.17907
893
3.17912
921
3.17918
950
3.17923
1003
3.17928
985
3.17934
1005
3.17939
1077
3.17944
1056
3.1795
1150
3.17955
1163
3.1796
1280
3.17965
1282
3.17971
1325
3.17976
1321
3.17981
1364
3.17987
1429
3.17992
1432
3.17997
1513
3.18003
1564
3.18008
1493
3.18013
1638
3.18019
1686
3.18024
1782
3.18029
1690
3.18035
1799
3.1804
1853
3.18045
1912
3.1805
1915
3.18056
1918
3.18061
1936
3.18066
1941
3.18072
1982
3.18077
1972
3.18082
1959
3.18088
2020
3.18093
2094
3.18098
2116
3.18104
2118
3.18109
2201
3.18114
2168
3.1812
2225
3.18125
2265
3.1813
2343
3.18135
2373
3.18141
2457
3.18146
2518
3.18151
2529
3.18157
2599
3.18162
2698
3.18167
2785
3.18173
2707
3.18178
2800
3.18183
2845
3.18189
2828
3.18194
2937
3.18199
2923
3.18204
2992
3.1821
2918
3.18215
2926
3.1822
2833
3.18226
2722
3.18231
2698
3.18236
2588
3.18242
2601
3.18247
2413
3.18252
2259
3.18258
2192
3.18263
1995
3.18268
1862
3.18274
1710
3.18279
1594
3.18284
1470
3.18289
1314
3.18295
1196
3.183
1085
3.18305
960
3.18311
872
3.18316
772
3.18321
686
3.18327
595
3.18332
530
3.18337
496
3.18343
442
3.18348
423
3.18353
385
3.18358
331
3.18364
333
3.18369
277
3.18374
275
3.1838
273
3.18385
264
3.1839
245
3.18396
235
3.18401
221
3.18406
241
3.18412
224
3.18417
211
3.18422
210
3.18428
233
3.18433
213
3.18438
192
3.18443
196
3.18449
215
3.18454
216
3.18459
213
3.18465
206
3.1847
199
3.18475
202
3.18481
224
3.18486
211
3.18491
208
3.18497
203
3.18502
213
3.18507
208
3.18512
192
3.18518
189
3.18523
191
3.18528
180
3.18534
216
3.18539
189
3.18544
187
3.1855
194
3.18555
193
3.1856
202
3.18566
200
3.18571
204
3.18576
201
3.18582
186
3.18587
180
3.18592
193
3.18597
205
3.18603
193
3.18608
193
3.18613
214
3.18619
206
3.18624
184
3.18629
191
3.18635
217
3.1864
185
3.18645
201
3.18651
197
3.18656
165
3.18661
185
3.18667
203
3.18672
182
3.18677
181
3.18682
190
3.18688
193
3.18693
204
3.18698
210
3.18704
209
3.18709
169
3.18714
176
3.1872
174
3.18725
186
3.1873
197
3.18736
184
3.18741
175
3.18746
199
3.18751
199
3.18757
202
3.18762
196
3.18767
200
3.18773
211
3.18778
191
3.18783
187
3.18789
169
3.18794
189
3.18799
199
3.18805
196
3.1881
197
3.18815
176
3.18821
180
3.18826
199
3.18831
185
3.18836
180
3.18842
201
3.18847
183
3.18852
190
3.18858
202
3.18863
217
3.18868
190
3.18874
191
3.18879
209
3.18884
187
3.1889
192
3.18895
186
3.189
193
3.18905
166
3.18911
178
3.18916
218
3.18921
196
3.18927
220
3.18932
209
3.18937
184
3.18943
194
3.18948
182
3.18953
170
3.18959
183
3.18964
187
3.18969
199
3.18975
189
3.1898
196
3.18985
208
3.1899
164
3.18996
172
3.19001
185
3.19006
166
3.19012
189
3.19017
179
3.19022
179
3.19028
160
3.19033
190
3.19038
191
3.19044
171
3.19049
201
3.19054
189
3.19059
198
3.19065
202
3.1907
187
3.19075
202
3.19081
198
3.19086
185
3.19091
213
3.19097
188
3.19102
192
3.19107
195
3.19113
201
3.19118
204
3.19123
198
3.19129
199
3.19134
181
3.19139
204
3.19144
186
3.1915
163
3.19155
184
3.1916
191
3.19166
192
3.19171
184
3.19176
188
3.19182
188
3.19187
189
3.19192
192
3.19198
end of experiment