File: B4.vms
VAMAS Surface Chemical Analysis Standard Data Transfer Format 1988 May 4
Not Specified
Kratos Axis
Not Specified
/d=/data/20170705/2017006144/B4.dset
3
Casa Info Follows
0
SourceAnalyserAngle: Not Specified
MAP
REGULAR
4
2
32768
32768
1
Etch Time
s
0
0
0
0
4
wide/2
Not Specified
2017
7
4
11
5
2
0
21
Casa Info Follows
1
Calib M = 282.45 A = 284.6 BE ADD
6
annot text peak Data 1202.54 1946 RGB(0,0,0) Font(14,18,0,0,Times New Roman) Vertical
C 1s
annot text peak Data 510.54 3380 RGB(0,0,0) Font(14,18,0,0,Times New Roman) Vertical
O KLL
annot text peak Data 953.54 1864 RGB(0,0,0) Font(14,18,0,0,Times New Roman) Vertical
O 1s
annot text peak Data 642 2978 RGB(0,0,0) Font(14,18,0,0,Times New Roman) Vertical
F KLL
annot text peak Data 798.54 14257 RGB(0,0,0) Font(14,18,0,0,Times New Roman) Vertical
F 1s
annot text peak Data 1452.54 486 RGB(0,0,0) Font(14,18,0,0,Times New Roman) Vertical
F 2s
0
0
   XPS     Spectrum    Lens Mode:Hybrid   Resolution:Pass energy 80    Iris(Aper):slot(Slot)
   Acqn. Time(s): 110        Sweeps: 1        Anode:Mono(Al (Mono))(150 W)   Step(meV): 1000.0
   Dwell Time(ms): 100        Charge Neutraliser :On   Acquired On :17/07/04 11:05:02
XPS
72
6
0
Mono(Al (Mono))
1486.69
150
1e+037
1e+037
6000
6000
1e+037
1e+037
FAT
80
1e+037
-4.45
0
1e+037
1e+037
1e+037
1e+037
Wide
None
-1
Kinetic Energy
eV
386.69
1
2
Intensity
d
Transmission
d
pulse counting
0.1
0
1e+037
0
1
8.48115
2898
2948
2948
2892
2935
2851
2956
2933
2970
2897
2984
3013
2952
2858
2888
2981
2962
2986
2925
2979
2923
2937
2975
2908
2887
2971
3003
3008
2986
2940
2918
2999
2960
2919
3054
3025
2982
2922
2981
3044
2995
3120
3078
3023
2973
3064
3057
3043
2932
3028
3023
3008
3037
3040
2952
2929
3019
3066
3045
3043
3071
3094
3104
3147
3105
3161
3124
3117
3156
3105
3117
3096
3102
3122
3057
3129
3130
3180
3194
3156
3217
3202
3252
3182
3151
3113
3113
3193
3168
3176
3198
3308
3227
3187
3189
3236
3257
3225
3186
3290
3235
3232
3208
3130
3173
3233
3281
3259
3148
3219
3273
3279
3259
3194
3171
3298
3273
3251
3177
3190
3237
3205
3338
3294
3374
3387
3380
3254
3315
3273
3346
3292
3254
3254
3161
3147
3109
3100
3051
3074
3056
3128
3118
3076
3115
3124
3200
3027
3086
3072
3073
3035
3021
3183
3208
3180
3193
3042
3139
3126
3086
3215
3130
3105
3162
3203
3226
3162
3109
3134
3134
3078
3168
3221
3264
3184
3227
3158
3174
3235
3194
3336
3326
3183
3181
3262
3299
3254
3232
3282
3234
3245
3252
3242
3242
3259
3268
3223
3246
3251
3244
3209
3098
3231
3289
3325
3283
3330
3265
3291
3345
3320
3351
3293
3287
3382
3407
3362
3506
3456
3374
3501
3491
3501
3521
3445
3404
3406
3423
3373
3350
3283
3304
3344
3363
3321
3328
3496
3546
3719
3758
3797
3951
3877
3748
3620
3504
3412
3428
3403
3387
3346
3244
3137
3050
2972
2934
2978
2881
2862
2917
3023
3059
3165
3299
3578
3998
4420
4803
5066
4921
4598
4057
3664
3428
3197
3051
2841
2662
2534
2300
2209
2151
2126
2035
2078
2049
2034
2002
2032
1961
1978
1976
2035
2039
2014
2024
2079
1981
2041
2043
2074
2023
1954
2016
2104
2003
1942
1957
2027
1994
1936
1981
2010
1950
2022
2117
2072
2004
1992
2000
2000
1989
1965
2012
2023
2017
2049
2040
1963
1979
2027
2033
1949
2047
1934
1938
1913
1971
1968
1984
2042
2033
1976
1984
2018
2037
2007
2034
2023
2047
2006
2039
2022
2092
2049
2027
2025
2040
2043
2026
1997
2022
2040
1980
2008
1958
1972
2012
1930
1905
1991
1956
1979
1969
1983
2019
2018
2071
2147
2163
2136
2090
2160
2130
2085
2085
2078
2137
2128
2067
2039
2037
2021
2026
1893
1793
1752
1639
1488
1493
1441
1290
1227
1120
1049
990
933
911
942
1082
1427
3479
10099
14257
6820
1788
933
756
748
699
715
677
715
693
686
671
661
651
721
652
673
681
683
701
694
657
645
653
677
694
691
734
691
686
691
667
650
684
651
646
665
684
671
662
665
677
717
668
675
701
662
690
728
714
709
680
657
682
679
676
692
686
720
743
727
728
715
668
683
690
725
677
697
671
660
710
731
716
706
731
709
735
756
730
735
699
699
748
695
699
734
744
694
667
702
708
734
713
740
745
736
739
735
740
742
738
738
700
708
720
750
741
741
747
691
794
767
744
748
759
742
738
704
721
726
740
753
757
767
781
756
758
785
779
782
783
792
809
748
729
755
746
746
697
704
732
718
680
654
650
590
642
632
613
609
687
865
1288
1864
1812
1212
751
628
583
604
587
543
582
569
574
589
586
582
592
574
574
588
567
576
585
610
603
608
583
600
548
594
595
545
582
592
573
585
582
583
573
605
609
600
608
576
565
586
613
596
600
580
603
608
621
592
552
588
605
629
611
607
590
523
544
606
636
579
581
624
624
606
603
585
565
589
595
606
603
630
558
571
558
591
627
666
593
595
598
632
641
630
597
631
621
619
633
656
639
638
610
597
610
572
613
629
614
623
640
625
654
657
633
638
635
627
637
587
590
587
628
623
627
595
647
636
643
611
623
643
670
625
645
671
684
683
636
640
642
657
645
646
646
626
665
646
622
617
640
660
689
663
659
703
649
652
648
676
658
643
694
696
667
648
645
650
653
680
684
679
691
691
702
714
733
712
665
677
681
686
696
727
716
699
681
674
712
687
669
686
717
725
694
692
682
746
716
727
767
711
711
667
693
680
752
734
727
724
747
776
732
767
789
771
763
762
787
803
765
760
783
767
789
768
768
751
718
739
700
674
648
624
620
591
570
552
533
499
400
346
290
279
303
363
575
1133
3265
3646
1433
997
1093
1720
1946
684
191
134
118
126
113
119
114
126
126
128
129
120
132
117
128
124
117
119
128
127
136
132
115
112
121
113
114
108
120
116
129
110
129
119
123
117
127
123
128
117
112
113
108
108
127
119
129
122
128
143
143
152
124
120
129
121
130
134
129
131
121
136
124
111
120
123
111
132
125
132
131
103
111
108
121
140
104
112
132
123
133
145
129
122
121
124
128
115
135
115
121
142
130
109
114
117
128
120
120
148
117
115
113
131
123
127
117
147
132
117
143
133
145
177
160
141
134
135
146
139
126
135
130
128
122
110
121
127
146
171
165
144
130
129
120
122
136
130
138
135
128
128
132
116
113
121
155
129
140
125
128
117
125
145
135
117
125
127
133
128
117
132
124
137
138
155
136
129
130
141
145
139
151
125
138
150
121
138
134
126
171
163
144
145
136
138
131
144
143
133
123
147
132
137
141
137
124
120
136
136
138
148
124
126
129
133
135
138
142
136
147
138
140
146
148
168
139
152
153
153
141
150
141
131
154
152
152
134
150
159
152
139
129
135
131
107
98
136
130
92
112
113
113
112
136
171
272
397
486
462
309
171
119
118
85
77
77
77
80
81
88
112
95
86
79
85
98
115
119
117
122
146
161
104
63
50
37
28
10
5
1
8.94051
F 1s/5
Not Specified
2017
7
4
13
57
30
0
9
Casa Info Follows
1
Calib M = 282.45 A = 284.6 BE ADD
0
0
0
   XPS     Spectrum    Lens Mode:Hybrid   Resolution:Pass energy 40    Iris(Aper):slot(Slot)
   Acqn. Time(s): 121        Sweeps: 2        Anode:Mono(Al (Mono))(150 W)   Step(meV): 50.0
   Dwell Time(ms): 150        Charge Neutraliser :On   Acquired On :17/07/04 13:57:30
XPS
72
6
0
Mono(Al (Mono))
1486.69
150
1e+037
1e+037
6000
6000
1e+037
1e+037
FAT
40
1e+037
-4.45
0
1e+037
1e+037
1e+037
1e+037
F
1s
-1
Kinetic Energy
eV
790.64
0.05
2
Intensity
d
Transmission
d
pulse counting
0.15
2
0
1e+037
1e+037
1e+037
0
806
730
22732
3.41724
3.42712
1298
3.42712
1300
3.4271
1267
3.42707
1256
3.42705
1295
3.42702
1289
3.427
1235
3.42698
1214
3.42695
1203
3.42693
1191
3.4269
1147
3.42688
1200
3.42686
1171
3.42683
1144
3.42681
1161
3.42678
1159
3.42676
1181
3.42674
1172
3.42671
1181
3.42669
1148
3.42667
1134
3.42664
1052
3.42662
1080
3.42659
1046
3.42657
1146
3.42655
1061
3.42652
1047
3.4265
1091
3.42647
1075
3.42645
1057
3.42643
1078
3.4264
1084
3.42638
1073
3.42636
1003
3.42633
1069
3.42631
1016
3.42628
999
3.42626
1026
3.42624
993
3.42621
1040
3.42619
994
3.42616
1022
3.42614
978
3.42612
978
3.42609
1019
3.42607
1030
3.42605
1004
3.42602
1024
3.426
1013
3.42597
973
3.42595
944
3.42593
1021
3.4259
1028
3.42588
1020
3.42585
1004
3.42583
975
3.42581
981
3.42578
975
3.42576
1048
3.42573
981
3.42571
1053
3.42569
1037
3.42566
997
3.42564
1026
3.42562
1005
3.42559
1020
3.42557
982
3.42554
963
3.42552
981
3.4255
996
3.42547
1012
3.42545
1005
3.42542
1020
3.4254
1021
3.42538
975
3.42535
989
3.42533
1006
3.42531
1039
3.42528
1003
3.42526
996
3.42523
992
3.42521
1010
3.42519
1002
3.42516
1056
3.42514
1031
3.42511
982
3.42509
1015
3.42507
985
3.42504
988
3.42502
983
3.425
1007
3.42497
1051
3.42495
1019
3.42492
1012
3.4249
1045
3.42488
998
3.42485
1013
3.42483
1037
3.4248
996
3.42478
986
3.42476
1017
3.42473
1050
3.42471
1072
3.42469
1085
3.42466
1061
3.42464
1010
3.42461
1000
3.42459
1054
3.42457
1113
3.42454
1083
3.42452
1110
3.42449
1053
3.42447
1107
3.42445
1092
3.42442
1130
3.4244
1085
3.42437
1131
3.42435
1121
3.42433
1174
3.4243
1184
3.42428
1161
3.42426
1167
3.42423
1102
3.42421
1089
3.42418
1118
3.42416
1113
3.42414
1167
3.42411
1240
3.42409
1179
3.42406
1205
3.42404
1172
3.42402
1189
3.42399
1251
3.42397
1255
3.42395
1202
3.42392
1271
3.4239
1205
3.42387
1230
3.42385
1329
3.42383
1357
3.4238
1322
3.42378
1422
3.42375
1412
3.42373
1440
3.42371
1449
3.42368
1460
3.42366
1473
3.42364
1494
3.42361
1627
3.42359
1767
3.42356
1732
3.42354
1822
3.42352
2003
3.42349
2054
3.42347
2123
3.42344
2330
3.42342
2342
3.4234
2580
3.42337
2726
3.42335
3013
3.42333
3174
3.4233
3340
3.42328
3702
3.42325
4012
3.42323
4290
3.42321
4634
3.42318
5149
3.42316
5629
3.42313
6096
3.42311
6546
3.42309
7051
3.42306
7840
3.42304
8444
3.42301
9168
3.42299
9895
3.42297
10772
3.42294
11721
3.42292
12597
3.4229
13438
3.42287
14245
3.42285
15188
3.42282
15943
3.4228
17000
3.42278
17972
3.42275
18764
3.42273
19539
3.4227
20283
3.42268
20748
3.42266
21414
3.42263
22062
3.42261
22428
3.42259
22640
3.42256
22604
3.42254
22732
3.42251
22563
3.42249
22306
3.42247
21886
3.42244
21578
3.42242
21044
3.42239
20479
3.42237
19362
3.42235
18801
3.42232
17650
3.4223
16740
3.42228
15806
3.42225
14784
3.42223
13916
3.4222
12898
3.42218
11745
3.42216
10800
3.42213
9800
3.42211
9221
3.42208
8520
3.42206
7652
3.42204
6911
3.42201
6319
3.42199
5775
3.42196
5210
3.42194
4854
3.42192
4394
3.42189
4042
3.42187
3793
3.42185
3463
3.42182
3136
3.4218
2964
3.42177
2707
3.42175
2489
3.42173
2379
3.4217
2264
3.42168
2118
3.42165
1955
3.42163
1841
3.42161
1760
3.42158
1649
3.42156
1664
3.42154
1610
3.42151
1537
3.42149
1419
3.42146
1361
3.42144
1327
3.42142
1341
3.42139
1270
3.42137
1218
3.42134
1201
3.42132
1200
3.4213
1148
3.42127
1145
3.42125
1111
3.42123
1093
3.4212
1109
3.42118
1046
3.42115
1015
3.42113
1039
3.42111
1020
3.42108
1004
3.42106
978
3.42103
989
3.42101
1020
3.42099
984
3.42096
987
3.42094
929
3.42091
971
3.42089
923
3.42087
923
3.42084
977
3.42082
937
3.4208
934
3.42077
890
3.42075
905
3.42072
881
3.4207
886
3.42068
898
3.42065
887
3.42063
865
3.4206
876
3.42058
884
3.42056
861
3.42053
851
3.42051
859
3.42049
864
3.42046
887
3.42044
884
3.42041
833
3.42039
826
3.42037
826
3.42034
850
3.42032
875
3.42029
915
3.42027
877
3.42025
857
3.42022
893
3.4202
847
3.42018
824
3.42015
833
3.42013
868
3.4201
864
3.42008
847
3.42006
875
3.42003
832
3.42001
842
3.41998
810
3.41996
834
3.41994
831
3.41991
849
3.41989
844
3.41986
811
3.41984
796
3.41982
800
3.41979
828
3.41977
836
3.41975
869
3.41972
840
3.4197
833
3.41967
797
3.41965
827
3.41963
842
3.4196
876
3.41958
833
3.41955
823
3.41953
795
3.41951
783
3.41948
832
3.41946
787
3.41944
803
3.41941
855
3.41939
806
3.41936
822
3.41934
822
3.41932
821
3.41929
770
3.41927
878
3.41924
830
3.41922
792
3.4192
775
3.41917
818
3.41915
820
3.41913
796
3.4191
790
3.41908
825
3.41905
796
3.41903
747
3.41901
830
3.41898
794
3.41896
810
3.41893
810
3.41891
797
3.41889
788
3.41886
823
3.41884
861
3.41881
806
3.41879
764
3.41877
813
3.41874
793
3.41872
797
3.4187
831
3.41867
802
3.41865
833
3.41862
844
3.4186
788
3.41858
810
3.41855
837
3.41853
796
3.4185
774
3.41848
730
3.41846
775
3.41843
760
3.41841
796
3.41839
781
3.41836
845
3.41834
780
3.41831
758
3.41829
743
3.41827
785
3.41824
793
3.41822
787
3.41819
805
3.41817
815
3.41815
850
3.41812
800
3.4181
812
3.41808
796
3.41805
762
3.41803
789
3.418
820
3.41798
775
3.41796
778
3.41793
802
3.4179
782
3.41786
756
3.41781
763
3.41777
792
3.41773
792
3.41769
816
3.41765
793
3.41761
808
3.41757
809
3.41753
787
3.41748
798
3.41744
800
3.4174
793
3.41736
790
3.41732
807
3.41728
823
3.41724
O 1s/6
Not Specified
2017
7
4
13
57
30
0
9
Casa Info Follows
1
Calib M = 282.45 A = 284.6 BE ADD
0
0
0
   XPS     Spectrum    Lens Mode:Hybrid   Resolution:Pass energy 40    Iris(Aper):slot(Slot)
   Acqn. Time(s): 162        Sweeps: 3        Anode:Mono(Al (Mono))(150 W)   Step(meV): 50.0
   Dwell Time(ms): 150        Charge Neutraliser :On   Acquired On :17/07/04 13:57:30
XPS
72
6
0
Mono(Al (Mono))
1486.69
150
1e+037
1e+037
6000
6000
1e+037
1e+037
FAT
40
1e+037
-4.45
0
1e+037
1e+037
1e+037
1e+037
O
1s
-1
Kinetic Energy
eV
946.69
0.05
2
Intensity
d
Transmission
d
pulse counting
0.15
3
0
1e+037
1e+037
1e+037
0
722
920
3823
3.32569
3.34183
1063
3.34183
1106
3.34178
1123
3.34174
1043
3.34169
1096
3.34165
1105
3.3416
1138
3.34156
1071
3.34151
1059
3.34147
1095
3.34142
1173
3.34138
1097
3.34133
1073
3.34129
1053
3.34124
1052
3.3412
1117
3.34115
1092
3.34111
1069
3.34107
1093
3.34102
1096
3.34098
1101
3.34093
1088
3.34089
1088
3.34084
1072
3.3408
1063
3.34075
1058
3.34071
1067
3.34066
1029
3.34062
1078
3.34057
1047
3.34053
1066
3.34048
1046
3.34044
1089
3.34039
1057
3.34035
1133
3.3403
1067
3.34026
1075
3.34021
1070
3.34017
1051
3.34012
1061
3.34008
1059
3.34003
1075
3.33999
1068
3.33994
1086
3.3399
1090
3.33985
1080
3.33981
1095
3.33976
1074
3.33972
1105
3.33968
1060
3.33963
1050
3.33959
1056
3.33954
1101
3.3395
1103
3.33945
1096
3.33941
1100
3.33936
1044
3.33932
1021
3.33927
1055
3.33923
1067
3.33918
1092
3.33914
1032
3.33909
1064
3.33905
1056
3.339
1032
3.33896
1047
3.33891
1071
3.33887
1004
3.33882
1066
3.33878
1086
3.33873
1084
3.33869
1074
3.33864
1077
3.3386
1002
3.33855
1082
3.33851
1026
3.33846
1068
3.33842
1019
3.33837
1074
3.33833
1057
3.33829
1111
3.33824
1037
3.3382
1041
3.33815
1097
3.33811
1131
3.33806
1074
3.33802
1060
3.33797
1158
3.33793
1054
3.33788
1076
3.33784
1050
3.33779
1092
3.33775
1045
3.3377
1050
3.33766
1099
3.33761
1074
3.33757
1090
3.33752
1074
3.33748
1056
3.33743
1037
3.33739
1082
3.33734
1069
3.3373
1122
3.33725
1036
3.33721
1091
3.33716
1110
3.33712
1089
3.33707
1049
3.33703
1082
3.33698
1143
3.33694
1132
3.3369
1053
3.33685
1063
3.33681
1100
3.33676
1096
3.33672
1092
3.33667
1083
3.33663
1099
3.33658
1144
3.33654
1108
3.33649
1151
3.33645
1120
3.3364
1179
3.33636
1167
3.33631
1138
3.33627
1228
3.33622
1212
3.33618
1196
3.33613
1174
3.33609
1201
3.33604
1209
3.336
1221
3.33595
1210
3.33591
1256
3.33586
1254
3.33582
1355
3.33577
1342
3.33573
1308
3.33568
1301
3.33564
1348
3.3356
1403
3.33555
1399
3.33551
1459
3.33546
1508
3.33542
1513
3.33537
1533
3.33533
1621
3.33528
1643
3.33524
1692
3.33519
1658
3.33515
1749
3.3351
1801
3.33506
1882
3.33501
1940
3.33497
2001
3.33492
2098
3.33488
2176
3.33483
2233
3.33479
2405
3.33474
2446
3.3347
2482
3.33465
2645
3.33461
2770
3.33456
2860
3.33452
2909
3.33447
3018
3.33443
3139
3.33438
3230
3.33434
3202
3.33429
3414
3.33425
3374
3.33421
3452
3.33416
3676
3.33412
3620
3.33407
3666
3.33403
3692
3.33398
3640
3.33394
3720
3.33389
3823
3.33385
3817
3.3338
3750
3.33376
3711
3.33371
3770
3.33367
3796
3.33362
3700
3.33358
3729
3.33353
3637
3.33349
3629
3.33344
3596
3.3334
3619
3.33335
3566
3.33331
3495
3.33326
3441
3.33322
3418
3.33317
3275
3.33313
3314
3.33308
3194
3.33304
3289
3.33299
3127
3.33295
3056
3.3329
3029
3.33286
2886
3.33282
3011
3.33277
2970
3.33273
2809
3.33268
2804
3.33264
2755
3.33259
2642
3.33255
2616
3.3325
2453
3.33246
2443
3.33241
2301
3.33237
2228
3.33232
2210
3.33228
2114
3.33223
2077
3.33219
2030
3.33214
1940
3.3321
1787
3.33205
1777
3.33201
1656
3.33196
1574
3.33192
1466
3.33187
1420
3.33183
1441
3.33178
1401
3.33174
1371
3.33169
1325
3.33165
1255
3.3316
1210
3.33156
1183
3.33151
1181
3.33147
1167
3.33143
1128
3.33138
1149
3.33134
1174
3.33129
1097
3.33125
1116
3.3312
1064
3.33116
1049
3.33111
1038
3.33107
1039
3.33102
1008
3.33098
1010
3.33093
1024
3.33089
1033
3.33084
1004
3.3308
1020
3.33075
1001
3.33071
1043
3.33066
1067
3.33062
1029
3.33057
1037
3.33053
1029
3.33048
960
3.33044
1019
3.33039
965
3.33035
954
3.3303
948
3.33026
950
3.33021
965
3.33017
988
3.33012
990
3.33008
1002
3.33004
987
3.32999
975
3.32995
975
3.3299
969
3.32986
990
3.32981
1009
3.32977
1034
3.32972
1026
3.32968
955
3.32963
979
3.32959
999
3.32954
987
3.3295
978
3.32945
964
3.32941
973
3.32936
1013
3.32932
987
3.32927
1003
3.32923
1013
3.32918
968
3.32914
962
3.32909
984
3.32905
980
3.329
994
3.32896
996
3.32891
995
3.32887
981
3.32882
967
3.32878
1009
3.32873
1010
3.32869
1060
3.32865
1033
3.3286
960
3.32856
952
3.32851
985
3.32847
981
3.32842
994
3.32838
967
3.32833
1007
3.32829
1031
3.32824
1041
3.3282
946
3.32815
993
3.32811
956
3.32806
986
3.32802
998
3.32797
977
3.32793
978
3.32788
1008
3.32784
990
3.32779
1008
3.32775
957
3.3277
954
3.32766
955
3.32761
1030
3.32757
967
3.32752
953
3.32748
975
3.32743
988
3.32739
992
3.32735
965
3.3273
967
3.32726
1011
3.32721
982
3.32717
1000
3.32712
966
3.32708
1009
3.32703
973
3.32699
989
3.32694
990
3.3269
1036
3.32685
988
3.32681
998
3.32676
1038
3.32672
993
3.32667
985
3.32663
1035
3.32658
1017
3.32654
1008
3.32649
965
3.32645
949
3.3264
948
3.32636
989
3.32631
948
3.32627
941
3.32622
920
3.32618
1039
3.32613
1002
3.32609
966
3.32604
938
3.326
950
3.32596
971
3.32591
969
3.32587
980
3.32582
943
3.32578
1005
3.32573
959
3.32569
C 1s/7
Not Specified
2017
7
4
13
57
30
0
9
Casa Info Follows
1
Calib M = 282.45 A = 284.6 BE ADD
0
0
0
   XPS     Spectrum    Lens Mode:Hybrid   Resolution:Pass energy 40    Iris(Aper):slot(Slot)
   Acqn. Time(s): 138        Sweeps: 2        Anode:Mono(Al (Mono))(150 W)   Step(meV): 50.0
   Dwell Time(ms): 150        Charge Neutraliser :On   Acquired On :17/07/04 13:57:30
XPS
72
6
0
Mono(Al (Mono))
1486.69
150
1e+037
1e+037
6000
6000
1e+037
1e+037
FAT
40
1e+037
-4.45
0
1e+037
1e+037
1e+037
1e+037
C
1s
-1
Kinetic Energy
eV
1190.19
0.05
2
Intensity
d
Transmission
d
pulse counting
0.15
2
0
1e+037
1e+037
1e+037
0
922
103
6928
3.16755
3.19198
434
3.16755
416
3.1676
430
3.16765
433
3.16771
383
3.16776
417
3.16781
425
3.16787
421
3.16792
426
3.16797
411
3.16802
403
3.16808
393
3.16813
387
3.16818
398
3.16824
409
3.16829
381
3.16834
375
3.1684
413
3.16845
376
3.1685
382
3.16856
385
3.16861
387
3.16866
383
3.16871
404
3.16877
335
3.16882
371
3.16887
357
3.16893
384
3.16898
380
3.16903
379
3.16909
355
3.16914
373
3.16919
334
3.16925
364
3.1693
363
3.16935
365
3.16941
336
3.16946
328
3.16951
346
3.16956
348
3.16962
349
3.16967
358
3.16972
339
3.16978
334
3.16983
341
3.16988
331
3.16994
357
3.16999
358
3.17004
362
3.1701
370
3.17015
327
3.1702
341
3.17025
324
3.17031
333
3.17036
318
3.17041
362
3.17047
325
3.17052
329
3.17057
343
3.17063
334
3.17068
326
3.17073
304
3.17079
319
3.17084
344
3.17089
303
3.17095
322
3.171
319
3.17105
304
3.1711
290
3.17116
280
3.17121
300
3.17126
287
3.17132
317
3.17137
312
3.17142
315
3.17148
310
3.17153
328
3.17158
285
3.17164
324
3.17169
318
3.17174
288
3.17179
292
3.17185
284
3.1719
320
3.17195
271
3.17201
293
3.17206
282
3.17211
301
3.17217
281
3.17222
284
3.17227
282
3.17233
312
3.17238
312
3.17243
302
3.17249
330
3.17254
305
3.17259
285
3.17264
281
3.1727
311
3.17275
347
3.1728
331
3.17286
301
3.17291
293
3.17296
341
3.17302
336
3.17307
348
3.17312
321
3.17318
328
3.17323
321
3.17328
306
3.17334
320
3.17339
342
3.17344
361
3.17349
350
3.17355
330
3.1736
354
3.17365
378
3.17371
376
3.17376
392
3.17381
424
3.17387
416
3.17392
426
3.17397
453
3.17403
476
3.17408
511
3.17413
533
3.17418
548
3.17424
605
3.17429
613
3.17434
643
3.1744
666
3.17445
741
3.1745
771
3.17456
823
3.17461
816
3.17466
840
3.17472
873
3.17477
884
3.17482
890
3.17488
875
3.17493
860
3.17498
872
3.17503
868
3.17509
897
3.17514
866
3.17519
857
3.17525
863
3.1753
862
3.17535
834
3.17541
880
3.17546
913
3.17551
886
3.17557
991
3.17562
1081
3.17567
1142
3.17572
1251
3.17578
1282
3.17583
1448
3.17588
1556
3.17594
1812
3.17599
2023
3.17604
2310
3.1761
2538
3.17615
2852
3.1762
3171
3.17626
3587
3.17631
3937
3.17636
4275
3.17642
4642
3.17647
5006
3.17652
5412
3.17657
5770
3.17663
6100
3.17668
6390
3.17673
6651
3.17679
6878
3.17684
6890
3.17689
6928
3.17695
6796
3.177
6649
3.17705
6480
3.17711
6378
3.17716
6077
3.17721
5709
3.17726
5446
3.17732
5056
3.17737
4646
3.17742
4150
3.17748
3835
3.17753
3449
3.17758
3104
3.17764
2868
3.17769
2503
3.17774
2246
3.1778
2076
3.17785
1932
3.1779
1771
3.17796
1608
3.17801
1479
3.17806
1340
3.17811
1266
3.17817
1237
3.17822
1125
3.17827
1096
3.17833
1044
3.17838
1039
3.17843
964
3.17849
987
3.17854
908
3.17859
919
3.17865
984
3.1787
925
3.17875
993
3.17881
987
3.17886
1008
3.17891
1058
3.17896
1096
3.17902
1084
3.17907
1109
3.17912
1119
3.17918
1109
3.17923
1152
3.17928
1122
3.17934
1153
3.17939
1149
3.17944
1172
3.1795
1185
3.17955
1145
3.1796
1123
3.17965
1076
3.17971
1088
3.17976
1125
3.17981
1103
3.17987
1081
3.17992
1086
3.17997
1074
3.18003
1029
3.18008
1040
3.18013
1018
3.18019
1006
3.18024
1031
3.18029
1026
3.18035
1061
3.1804
1058
3.18045
1043
3.1805
1072
3.18056
1113
3.18061
1117
3.18066
1089
3.18072
1040
3.18077
1138
3.18082
1159
3.18088
1203
3.18093
1197
3.18098
1224
3.18104
1221
3.18109
1298
3.18114
1349
3.1812
1390
3.18125
1404
3.1813
1496
3.18135
1522
3.18141
1633
3.18146
1724
3.18151
1826
3.18157
1899
3.18162
2014
3.18167
2107
3.18173
2189
3.18178
2236
3.18183
2311
3.18189
2483
3.18194
2645
3.18199
2699
3.18204
2771
3.1821
2875
3.18215
2967
3.1822
3114
3.18226
3094
3.18231
3125
3.18236
3188
3.18242
3216
3.18247
3171
3.18252
3137
3.18258
3111
3.18263
2920
3.18268
2779
3.18274
2648
3.18279
2576
3.18284
2477
3.18289
2246
3.18295
2099
3.183
1934
3.18305
1779
3.18311
1596
3.18316
1408
3.18321
1222
3.18327
1066
3.18332
965
3.18337
778
3.18343
667
3.18348
610
3.18353
502
3.18358
471
3.18364
440
3.18369
398
3.18374
348
3.1838
314
3.18385
266
3.1839
274
3.18396
239
3.18401
224
3.18406
218
3.18412
214
3.18417
215
3.18422
208
3.18428
180
3.18433
162
3.18438
176
3.18443
169
3.18449
151
3.18454
162
3.18459
159
3.18465
146
3.1847
153
3.18475
162
3.18481
171
3.18486
167
3.18491
159
3.18497
160
3.18502
161
3.18507
179
3.18512
153
3.18518
145
3.18523
147
3.18528
141
3.18534
159
3.18539
145
3.18544
164
3.1855
154
3.18555
151
3.1856
152
3.18566
140
3.18571
139
3.18576
154
3.18582
155
3.18587
143
3.18592
144
3.18597
144
3.18603
145
3.18608
160
3.18613
161
3.18619
140
3.18624
152
3.18629
147
3.18635
143
3.1864
157
3.18645
148
3.18651
142
3.18656
142
3.18661
144
3.18667
145
3.18672
152
3.18677
151
3.18682
161
3.18688
146
3.18693
130
3.18698
148
3.18704
131
3.18709
155
3.18714
127
3.1872
115
3.18725
159
3.1873
144
3.18736
131
3.18741
126
3.18746
131
3.18751
147
3.18757
138
3.18762
130
3.18767
132
3.18773
142
3.18778
122
3.18783
133
3.18789
140
3.18794
128
3.18799
128
3.18805
146
3.1881
143
3.18815
121
3.18821
158
3.18826
133
3.18831
142
3.18836
145
3.18842
132
3.18847
135
3.18852
138
3.18858
142
3.18863
146
3.18868
135
3.18874
140
3.18879
143
3.18884
154
3.1889
127
3.18895
134
3.189
127
3.18905
117
3.18911
130
3.18916
133
3.18921
148
3.18927
115
3.18932
103
3.18937
143
3.18943
145
3.18948
132
3.18953
133
3.18959
131
3.18964
135
3.18969
128
3.18975
118
3.1898
136
3.18985
135
3.1899
128
3.18996
131
3.19001
150
3.19006
123
3.19012
135
3.19017
152
3.19022
139
3.19028
140
3.19033
133
3.19038
148
3.19044
126
3.19049
137
3.19054
119
3.19059
124
3.19065
135
3.1907
145
3.19075
156
3.19081
119
3.19086
129
3.19091
140
3.19097
132
3.19102
143
3.19107
149
3.19113
142
3.19118
139
3.19123
138
3.19129
113
3.19134
139
3.19139
122
3.19144
128
3.1915
121
3.19155
139
3.1916
146
3.19166
142
3.19171
157
3.19176
133
3.19182
125
3.19187
141
3.19192
152
3.19198
end of experiment