File: B5.vms
VAMAS Surface Chemical Analysis Standard Data Transfer Format 1988 May 4
Not Specified
Kratos Axis
Not Specified
/d=/data/20170705/2017006144/B5.dset
3
Casa Info Follows
0
SourceAnalyserAngle: Not Specified
MAP
REGULAR
4
2
32768
32768
1
Etch Time
s
0
0
0
0
4
wide/2
Not Specified
2017
7
4
11
7
33
0
21
Casa Info Follows
1
Calib M = 282.505 A = 284.6 BE ADD
6
annot text peak Data 1202.6 1994 RGB(0,0,0) Font(14,18,0,0,Times New Roman) Vertical
C 1s
annot text peak Data 642 3436 RGB(0,0,0) Font(14,18,0,0,Times New Roman) Vertical
F KLL
annot text peak Data 798.595 18103 RGB(0,0,0) Font(14,18,0,0,Times New Roman) Vertical
F 1s
annot text peak Data 1452.6 626 RGB(0,0,0) Font(14,18,0,0,Times New Roman) Vertical
F 2s
annot text peak Data 505 3725 RGB(0,0,0) Font(14,18,0,0,Times New Roman) Vertical
O KLL
annot text peak Data 953.595 1777 RGB(0,0,0) Font(14,18,0,0,Times New Roman) Vertical
O 1s
0
0
   XPS     Spectrum    Lens Mode:Hybrid   Resolution:Pass energy 80    Iris(Aper):slot(Slot)
   Acqn. Time(s): 110        Sweeps: 1        Anode:Mono(Al (Mono))(150 W)   Step(meV): 1000.0
   Dwell Time(ms): 100        Charge Neutraliser :On   Acquired On :17/07/04 11:07:33
XPS
63
7
0
Mono(Al (Mono))
1486.69
150
1e+037
1e+037
6000
6000
1e+037
1e+037
FAT
80
1e+037
-4.45
0
1e+037
1e+037
1e+037
1e+037
Wide
None
-1
Kinetic Energy
eV
386.69
1
2
Intensity
d
Transmission
d
pulse counting
0.1
0
1e+037
0
1
8.48115
3179
3272
3340
3259
3232
3307
3225
3258
3364
3318
3310
3329
3343
3358
3290
3405
3299
3299
3203
3239
3225
3236
3308
3360
3256
3253
3370
3351
3376
3414
3361
3376
3365
3392
3357
3369
3290
3381
3427
3382
3312
3331
3348
3357
3386
3383
3375
3375
3338
3359
3394
3305
3313
3376
3467
3562
3535
3431
3523
3464
3523
3549
3457
3432
3384
3390
3428
3439
3506
3599
3512
3411
3472
3471
3515
3453
3449
3493
3415
3525
3453
3459
3450
3527
3481
3569
3506
3466
3484
3533
3611
3624
3580
3575
3560
3547
3595
3551
3584
3676
3609
3571
3500
3560
3619
3599
3660
3602
3536
3654
3599
3449
3465
3571
3567
3633
3562
3695
3651
3647
3725
3669
3689
3700
3719
3723
3783
3721
3711
3699
3755
3619
3650
3502
3537
3553
3590
3499
3455
3492
3549
3470
3484
3592
3527
3490
3661
3569
3568
3640
3614
3558
3555
3623
3582
3608
3702
3573
3509
3523
3558
3528
3616
3617
3642
3597
3571
3657
3635
3601
3555
3569
3671
3665
3654
3663
3650
3651
3729
3686
3667
3729
3698
3659
3649
3678
3689
3686
3708
3789
3707
3701
3792
3685
3594
3626
3704
3663
3716
3701
3799
3810
3686
3776
3715
3790
3868
3858
3815
3764
3815
3799
3837
3866
3885
3796
3872
3999
4007
3936
3986
4075
4160
4133
3998
3940
3947
3953
3835
3871
3782
3837
3880
3895
3806
3942
3973
4103
4219
4274
4437
4521
4618
4572
4508
4423
4165
4186
4106
4093
4025
3829
3823
3708
3565
3567
3500
3436
3376
3385
3460
3636
3577
3663
3969
4427
4914
5548
5916
6122
5994
5435
4983
4555
4117
3834
3533
3299
3076
2919
2763
2641
2554
2409
2453
2466
2346
2402
2328
2254
2284
2332
2345
2308
2345
2295
2303
2294
2316
2325
2322
2275
2352
2285
2271
2298
2429
2320
2349
2352
2367
2372
2333
2341
2346
2384
2278
2287
2343
2312
2344
2318
2366
2387
2337
2347
2375
2326
2254
2304
2356
2338
2340
2393
2409
2397
2383
2364
2371
2325
2424
2454
2466
2377
2391
2474
2466
2511
2376
2404
2393
2392
2442
2473
2501
2409
2354
2399
2380
2394
2442
2425
2466
2395
2412
2388
2381
2291
2385
2411
2339
2350
2407
2447
2326
2310
2345
2335
2476
2512
2507
2550
2561
2565
2616
2568
2498
2554
2500
2579
2560
2589
2446
2448
2398
2293
2198
2061
1937
1846
1811
1700
1576
1465
1337
1177
1093
1053
1030
1108
1338
1995
5247
14425
18103
7999
2067
1052
849
792
783
801
789
750
757
788
735
750
745
756
743
726
732
714
776
815
770
766
731
726
770
741
770
790
807
762
689
731
773
764
771
798
766
786
791
737
764
710
754
790
766
784
804
798
758
770
776
760
821
770
726
769
781
785
755
792
774
774
752
764
720
759
785
810
786
785
774
808
799
775
790
840
801
729
816
808
769
757
748
769
791
782
774
745
797
792
808
799
789
791
793
788
782
790
801
784
802
805
798
838
836
783
788
848
818
832
807
795
811
817
817
797
815
819
840
830
789
812
836
792
818
813
818
841
833
878
852
893
844
852
796
799
812
796
795
787
767
772
790
753
703
682
699
711
725
724
783
943
1382
1777
1646
1138
809
693
697
675
693
655
672
655
698
692
660
689
683
676
708
683
678
666
681
667
686
705
654
681
693
651
709
688
694
690
681
694
678
691
690
658
692
675
674
693
701
714
686
688
681
713
708
711
699
659
690
685
675
692
698
692
720
682
696
750
717
672
696
731
682
685
704
730
718
709
690
710
716
730
714
682
663
722
743
708
717
714
704
690
694
745
732
697
684
689
745
711
707
730
711
730
738
747
766
744
752
714
733
705
735
779
724
746
698
738
728
735
760
704
739
734
743
747
745
771
765
756
773
766
748
763
770
797
800
776
785
796
797
722
711
745
752
752
738
760
763
798
751
765
763
793
787
805
784
788
793
782
764
797
795
791
806
850
811
773
777
814
751
767
815
786
792
800
806
791
788
805
813
827
784
808
829
851
820
840
889
853
818
894
873
854
786
812
834
845
846
819
852
807
823
860
849
833
801
830
904
866
901
854
896
900
947
868
917
962
974
925
877
892
933
873
899
884
870
862
868
843
834
776
783
754
744
718
647
614
558
485
480
415
371
352
338
452
827
1756
4347
4322
1596
1025
1177
1896
1994
739
243
165
138
130
131
132
147
132
142
148
145
150
155
158
125
126
133
132
147
138
132
145
137
145
140
118
146
134
149
133
151
143
144
145
145
151
140
134
150
128
148
146
159
148
126
140
149
145
151
141
156
157
145
145
131
146
150
140
120
149
136
143
154
133
110
151
140
140
162
141
154
146
153
155
141
151
165
142
144
146
146
162
149
156
138
147
148
156
145
140
143
154
162
125
129
158
168
138
149
144
148
147
146
151
148
159
143
149
134
155
144
150
170
172
170
159
149
162
148
132
141
149
156
142
123
148
140
152
156
184
156
161
159
143
140
145
137
142
142
160
151
144
145
138
162
170
157
151
162
147
151
162
168
151
153
159
164
166
175
155
142
146
146
150
149
171
164
159
160
152
155
146
144
170
146
145
154
157
150
168
178
184
186
157
144
185
163
168
162
159
149
178
173
169
146
157
168
147
148
146
153
159
176
155
144
158
171
160
172
158
170
163
171
172
173
181
165
180
174
182
172
189
186
159
165
184
168
163
147
178
161
168
151
167
144
130
156
147
119
126
131
122
134
142
161
213
332
506
626
541
323
215
160
131
120
93
103
82
78
88
116
129
130
132
120
114
143
144
173
148
136
161
181
132
82
56
44
30
20
8
1
8.94051
F 1s/5
Not Specified
2017
7
4
14
7
32
0
9
Casa Info Follows
1
Calib M = 282.505 A = 284.6 BE ADD
0
0
0
   XPS     Spectrum    Lens Mode:Hybrid   Resolution:Pass energy 40    Iris(Aper):slot(Slot)
   Acqn. Time(s): 121        Sweeps: 2        Anode:Mono(Al (Mono))(150 W)   Step(meV): 50.0
   Dwell Time(ms): 150        Charge Neutraliser :On   Acquired On :17/07/04 14:07:32
XPS
63
7
0
Mono(Al (Mono))
1486.69
150
1e+037
1e+037
6000
6000
1e+037
1e+037
FAT
40
1e+037
-4.45
0
1e+037
1e+037
1e+037
1e+037
F
1s
-1
Kinetic Energy
eV
790.64
0.05
2
Intensity
d
Transmission
d
pulse counting
0.15
2
0
1e+037
1e+037
1e+037
0
806
833
29838
3.41724
3.42712
1442
3.42712
1470
3.4271
1445
3.42707
1419
3.42705
1435
3.42702
1433
3.427
1413
3.42698
1331
3.42695
1403
3.42693
1416
3.4269
1352
3.42688
1341
3.42686
1376
3.42683
1384
3.42681
1372
3.42678
1344
3.42676
1394
3.42674
1310
3.42671
1333
3.42669
1324
3.42667
1317
3.42664
1264
3.42662
1210
3.42659
1273
3.42657
1283
3.42655
1284
3.42652
1203
3.4265
1229
3.42647
1164
3.42645
1171
3.42643
1192
3.4264
1201
3.42638
1215
3.42636
1161
3.42633
1203
3.42631
1182
3.42628
1190
3.42626
1178
3.42624
1200
3.42621
1168
3.42619
1147
3.42616
1127
3.42614
1181
3.42612
1172
3.42609
1185
3.42607
1186
3.42605
1186
3.42602
1218
3.426
1156
3.42597
1175
3.42595
1145
3.42593
1090
3.4259
1168
3.42588
1183
3.42585
1147
3.42583
1169
3.42581
1110
3.42578
1119
3.42576
1146
3.42573
1181
3.42571
1161
3.42569
1182
3.42566
1117
3.42564
1125
3.42562
1160
3.42559
1138
3.42557
1164
3.42554
1157
3.42552
1187
3.4255
1199
3.42547
1203
3.42545
1186
3.42542
1158
3.4254
1150
3.42538
1156
3.42535
1166
3.42533
1198
3.42531
1182
3.42528
1130
3.42526
1160
3.42523
1131
3.42521
1163
3.42519
1156
3.42516
1111
3.42514
1134
3.42511
1130
3.42509
1160
3.42507
1162
3.42504
1184
3.42502
1174
3.425
1158
3.42497
1199
3.42495
1217
3.42492
1209
3.4249
1175
3.42488
1219
3.42485
1235
3.42483
1215
3.4248
1194
3.42478
1269
3.42476
1244
3.42473
1225
3.42471
1167
3.42469
1185
3.42466
1218
3.42464
1248
3.42461
1268
3.42459
1269
3.42457
1270
3.42454
1248
3.42452
1281
3.42449
1309
3.42447
1241
3.42445
1224
3.42442
1268
3.4244
1331
3.42437
1322
3.42435
1323
3.42433
1337
3.4243
1364
3.42428
1357
3.42426
1392
3.42423
1401
3.42421
1341
3.42418
1369
3.42416
1381
3.42414
1408
3.42411
1425
3.42409
1432
3.42406
1395
3.42404
1525
3.42402
1500
3.42399
1547
3.42397
1520
3.42395
1547
3.42392
1537
3.4239
1589
3.42387
1575
3.42385
1655
3.42383
1680
3.4238
1746
3.42378
1797
3.42375
1881
3.42373
1904
3.42371
2049
3.42368
2085
3.42366
2188
3.42364
2204
3.42361
2380
3.42359
2485
3.42356
2688
3.42354
2744
3.42352
2976
3.42349
3087
3.42347
3369
3.42344
3584
3.42342
3997
3.4234
4223
3.42337
4480
3.42335
4846
3.42333
5332
3.4233
5863
3.42328
6167
3.42325
6751
3.42323
7374
3.42321
7983
3.42318
8656
3.42316
9563
3.42313
10255
3.42311
10948
3.42309
12004
3.42306
13110
3.42304
14077
3.42301
14976
3.42299
16271
3.42297
17220
3.42294
18304
3.42292
19325
3.4229
20713
3.42287
21846
3.42285
23007
3.42282
24039
3.4228
25046
3.42278
25912
3.42275
26802
3.42273
27686
3.4227
28443
3.42268
28869
3.42266
29104
3.42263
29579
3.42261
29838
3.42259
29776
3.42256
29766
3.42254
29018
3.42251
28465
3.42249
27958
3.42247
27099
3.42244
26273
3.42242
25034
3.42239
24308
3.42237
23103
3.42235
21744
3.42232
20405
3.4223
19049
3.42228
17730
3.42225
16497
3.42223
15344
3.4222
14238
3.42218
13095
3.42216
11920
3.42213
10966
3.42211
10014
3.42208
8994
3.42206
8408
3.42204
7619
3.42201
6931
3.42199
6362
3.42196
5911
3.42194
5409
3.42192
4800
3.42189
4349
3.42187
4183
3.42185
3822
3.42182
3525
3.4218
3252
3.42177
3026
3.42175
2800
3.42173
2637
3.4217
2454
3.42168
2255
3.42165
2208
3.42163
2083
3.42161
2000
3.42158
1954
3.42156
1876
3.42154
1751
3.42151
1653
3.42149
1588
3.42146
1573
3.42144
1516
3.42142
1517
3.42139
1496
3.42137
1372
3.42134
1320
3.42132
1387
3.4213
1315
3.42127
1272
3.42125
1284
3.42123
1226
3.4212
1222
3.42118
1258
3.42115
1216
3.42113
1129
3.42111
1150
3.42108
1178
3.42106
1096
3.42103
1097
3.42101
1096
3.42099
1097
3.42096
1101
3.42094
1094
3.42091
1061
3.42089
1046
3.42087
1046
3.42084
1108
3.42082
1071
3.4208
1037
3.42077
1067
3.42075
1029
3.42072
1048
3.4207
1032
3.42068
991
3.42065
984
3.42063
1027
3.4206
1024
3.42058
1033
3.42056
992
3.42053
990
3.42051
974
3.42049
1011
3.42046
956
3.42044
1018
3.42041
988
3.42039
973
3.42037
949
3.42034
935
3.42032
979
3.42029
924
3.42027
972
3.42025
975
3.42022
942
3.4202
963
3.42018
922
3.42015
928
3.42013
933
3.4201
930
3.42008
919
3.42006
910
3.42003
931
3.42001
888
3.41998
879
3.41996
904
3.41994
953
3.41991
943
3.41989
940
3.41986
913
3.41984
928
3.41982
915
3.41979
899
3.41977
908
3.41975
944
3.41972
930
3.4197
921
3.41967
882
3.41965
926
3.41963
886
3.4196
876
3.41958
924
3.41955
898
3.41953
913
3.41951
898
3.41948
901
3.41946
923
3.41944
876
3.41941
889
3.41939
899
3.41936
915
3.41934
927
3.41932
895
3.41929
885
3.41927
901
3.41924
886
3.41922
866
3.4192
852
3.41917
851
3.41915
901
3.41913
883
3.4191
908
3.41908
876
3.41905
896
3.41903
899
3.41901
915
3.41898
905
3.41896
833
3.41893
838
3.41891
835
3.41889
882
3.41886
854
3.41884
937
3.41881
898
3.41879
886
3.41877
893
3.41874
921
3.41872
914
3.4187
874
3.41867
875
3.41865
886
3.41862
857
3.4186
904
3.41858
867
3.41855
875
3.41853
877
3.4185
895
3.41848
887
3.41846
861
3.41843
891
3.41841
864
3.41839
862
3.41836
906
3.41834
886
3.41831
892
3.41829
879
3.41827
885
3.41824
911
3.41822
861
3.41819
865
3.41817
867
3.41815
836
3.41812
878
3.4181
917
3.41808
892
3.41805
863
3.41803
896
3.418
894
3.41798
844
3.41796
909
3.41793
900
3.4179
859
3.41786
896
3.41781
878
3.41777
876
3.41773
865
3.41769
865
3.41765
941
3.41761
916
3.41757
861
3.41753
873
3.41748
896
3.41744
875
3.4174
869
3.41736
879
3.41732
937
3.41728
861
3.41724
O 1s/6
Not Specified
2017
7
4
14
7
32
0
9
Casa Info Follows
1
Calib M = 282.505 A = 284.6 BE ADD
0
0
0
   XPS     Spectrum    Lens Mode:Hybrid   Resolution:Pass energy 40    Iris(Aper):slot(Slot)
   Acqn. Time(s): 162        Sweeps: 3        Anode:Mono(Al (Mono))(150 W)   Step(meV): 50.0
   Dwell Time(ms): 150        Charge Neutraliser :On   Acquired On :17/07/04 14:07:32
XPS
63
7
0
Mono(Al (Mono))
1486.69
150
1e+037
1e+037
6000
6000
1e+037
1e+037
FAT
40
1e+037
-4.45
0
1e+037
1e+037
1e+037
1e+037
O
1s
-1
Kinetic Energy
eV
946.69
0.05
2
Intensity
d
Transmission
d
pulse counting
0.15
3
0
1e+037
1e+037
1e+037
0
722
1080
3457
3.32569
3.34183
1263
3.34183
1255
3.34178
1243
3.34174
1213
3.34169
1212
3.34165
1253
3.3416
1233
3.34156
1231
3.34151
1189
3.34147
1227
3.34142
1249
3.34138
1285
3.34133
1235
3.34129
1231
3.34124
1195
3.3412
1205
3.34115
1250
3.34111
1217
3.34107
1227
3.34102
1212
3.34098
1260
3.34093
1236
3.34089
1222
3.34084
1220
3.3408
1202
3.34075
1209
3.34071
1239
3.34066
1280
3.34062
1252
3.34057
1216
3.34053
1227
3.34048
1199
3.34044
1215
3.34039
1198
3.34035
1233
3.3403
1201
3.34026
1256
3.34021
1215
3.34017
1214
3.34012
1230
3.34008
1225
3.34003
1233
3.33999
1240
3.33994
1240
3.3399
1201
3.33985
1178
3.33981
1163
3.33976
1240
3.33972
1236
3.33968
1229
3.33963
1210
3.33959
1229
3.33954
1183
3.3395
1222
3.33945
1181
3.33941
1199
3.33936
1229
3.33932
1180
3.33927
1197
3.33923
1206
3.33918
1218
3.33914
1237
3.33909
1263
3.33905
1228
3.339
1180
3.33896
1197
3.33891
1186
3.33887
1246
3.33882
1236
3.33878
1220
3.33873
1225
3.33869
1230
3.33864
1242
3.3386
1204
3.33855
1215
3.33851
1195
3.33846
1215
3.33842
1246
3.33837
1211
3.33833
1199
3.33829
1169
3.33824
1182
3.3382
1188
3.33815
1228
3.33811
1217
3.33806
1212
3.33802
1240
3.33797
1265
3.33793
1236
3.33788
1250
3.33784
1244
3.33779
1257
3.33775
1256
3.3377
1276
3.33766
1297
3.33761
1219
3.33757
1178
3.33752
1214
3.33748
1251
3.33743
1236
3.33739
1189
3.33734
1243
3.3373
1285
3.33725
1230
3.33721
1187
3.33716
1240
3.33712
1226
3.33707
1235
3.33703
1208
3.33698
1284
3.33694
1280
3.3369
1290
3.33685
1277
3.33681
1279
3.33676
1316
3.33672
1340
3.33667
1314
3.33663
1323
3.33658
1318
3.33654
1378
3.33649
1298
3.33645
1376
3.3364
1338
3.33636
1349
3.33631
1379
3.33627
1428
3.33622
1381
3.33618
1380
3.33613
1384
3.33609
1452
3.33604
1403
3.336
1456
3.33595
1502
3.33591
1450
3.33586
1477
3.33582
1522
3.33577
1565
3.33573
1589
3.33568
1581
3.33564
1596
3.3356
1578
3.33555
1685
3.33551
1720
3.33546
1834
3.33542
1712
3.33537
1835
3.33533
1938
3.33528
1930
3.33524
1993
3.33519
2047
3.33515
2099
3.3351
2158
3.33506
2247
3.33501
2227
3.33497
2316
3.33492
2328
3.33488
2466
3.33483
2495
3.33479
2609
3.33474
2670
3.3347
2712
3.33465
2742
3.33461
2857
3.33456
2892
3.33452
2930
3.33447
3012
3.33443
3039
3.33438
3080
3.33434
3116
3.33429
3187
3.33425
3226
3.33421
3375
3.33416
3426
3.33412
3399
3.33407
3428
3.33403
3391
3.33398
3366
3.33394
3426
3.33389
3430
3.33385
3395
3.3338
3308
3.33376
3457
3.33371
3328
3.33367
3402
3.33362
3436
3.33358
3293
3.33353
3329
3.33349
3307
3.33344
3230
3.3334
3126
3.33335
3052
3.33331
3123
3.33326
3105
3.33322
3026
3.33317
2985
3.33313
2914
3.33308
2842
3.33304
2765
3.33299
2768
3.33295
2729
3.3329
2656
3.33286
2596
3.33282
2605
3.33277
2497
3.33273
2546
3.33268
2437
3.33264
2293
3.33259
2258
3.33255
2283
3.3325
2200
3.33246
2078
3.33241
2100
3.33237
2048
3.33232
1926
3.33228
1950
3.33223
1839
3.33219
1744
3.33214
1773
3.3321
1703
3.33205
1662
3.33201
1621
3.33196
1579
3.33192
1511
3.33187
1501
3.33183
1499
3.33178
1442
3.33174
1374
3.33169
1399
3.33165
1371
3.3316
1349
3.33156
1324
3.33151
1337
3.33147
1273
3.33143
1303
3.33138
1193
3.33134
1192
3.33129
1244
3.33125
1253
3.3312
1209
3.33116
1168
3.33111
1195
3.33107
1174
3.33102
1157
3.33098
1202
3.33093
1235
3.33089
1208
3.33084
1206
3.3308
1167
3.33075
1199
3.33071
1177
3.33066
1152
3.33062
1147
3.33057
1152
3.33053
1162
3.33048
1163
3.33044
1225
3.33039
1221
3.33035
1146
3.3303
1211
3.33026
1160
3.33021
1138
3.33017
1183
3.33012
1192
3.33008
1146
3.33004
1135
3.32999
1164
3.32995
1151
3.3299
1159
3.32986
1119
3.32981
1158
3.32977
1088
3.32972
1136
3.32968
1145
3.32963
1228
3.32959
1214
3.32954
1179
3.3295
1197
3.32945
1171
3.32941
1180
3.32936
1162
3.32932
1181
3.32927
1169
3.32923
1162
3.32918
1137
3.32914
1156
3.32909
1171
3.32905
1190
3.329
1189
3.32896
1159
3.32891
1156
3.32887
1175
3.32882
1127
3.32878
1168
3.32873
1170
3.32869
1117
3.32865
1136
3.3286
1175
3.32856
1118
3.32851
1137
3.32847
1129
3.32842
1154
3.32838
1147
3.32833
1175
3.32829
1134
3.32824
1165
3.3282
1175
3.32815
1117
3.32811
1148
3.32806
1149
3.32802
1203
3.32797
1164
3.32793
1172
3.32788
1183
3.32784
1188
3.32779
1152
3.32775
1116
3.3277
1134
3.32766
1091
3.32761
1080
3.32757
1157
3.32752
1139
3.32748
1160
3.32743
1171
3.32739
1158
3.32735
1151
3.3273
1112
3.32726
1185
3.32721
1172
3.32717
1165
3.32712
1180
3.32708
1155
3.32703
1182
3.32699
1182
3.32694
1190
3.3269
1163
3.32685
1171
3.32681
1158
3.32676
1132
3.32672
1203
3.32667
1118
3.32663
1158
3.32658
1125
3.32654
1191
3.32649
1197
3.32645
1119
3.3264
1120
3.32636
1109
3.32631
1145
3.32627
1175
3.32622
1145
3.32618
1157
3.32613
1217
3.32609
1127
3.32604
1161
3.326
1103
3.32596
1159
3.32591
1132
3.32587
1113
3.32582
1192
3.32578
1148
3.32573
1189
3.32569
C 1s/7
Not Specified
2017
7
4
14
7
32
0
9
Casa Info Follows
1
Calib M = 282.505 A = 284.6 BE ADD
0
0
0
   XPS     Spectrum    Lens Mode:Hybrid   Resolution:Pass energy 40    Iris(Aper):slot(Slot)
   Acqn. Time(s): 138        Sweeps: 2        Anode:Mono(Al (Mono))(150 W)   Step(meV): 50.0
   Dwell Time(ms): 150        Charge Neutraliser :On   Acquired On :17/07/04 14:07:32
XPS
63
7
0
Mono(Al (Mono))
1486.69
150
1e+037
1e+037
6000
6000
1e+037
1e+037
FAT
40
1e+037
-4.45
0
1e+037
1e+037
1e+037
1e+037
C
1s
-1
Kinetic Energy
eV
1190.19
0.05
2
Intensity
d
Transmission
d
pulse counting
0.15
2
0
1e+037
1e+037
1e+037
0
922
136
8820
3.16755
3.19198
513
3.16755
474
3.1676
481
3.16765
488
3.16771
487
3.16776
451
3.16781
441
3.16787
455
3.16792
490
3.16797
453
3.16802
421
3.16808
425
3.16813
442
3.16818
469
3.16824
444
3.16829
447
3.16834
454
3.1684
477
3.16845
429
3.1685
424
3.16856
437
3.16861
457
3.16866
430
3.16871
449
3.16877
397
3.16882
467
3.16887
398
3.16893
429
3.16898
405
3.16903
428
3.16909
413
3.16914
421
3.16919
409
3.16925
405
3.1693
421
3.16935
400
3.16941
397
3.16946
394
3.16951
409
3.16956
410
3.16962
364
3.16967
368
3.16972
381
3.16978
353
3.16983
394
3.16988
411
3.16994
376
3.16999
373
3.17004
385
3.1701
388
3.17015
412
3.1702
377
3.17025
360
3.17031
385
3.17036
390
3.17041
381
3.17047
368
3.17052
363
3.17057
381
3.17063
367
3.17068
391
3.17073
376
3.17079
375
3.17084
394
3.17089
382
3.17095
341
3.171
338
3.17105
378
3.1711
402
3.17116
367
3.17121
351
3.17126
345
3.17132
368
3.17137
353
3.17142
346
3.17148
345
3.17153
332
3.17158
366
3.17164
359
3.17169
348
3.17174
330
3.17179
370
3.17185
337
3.1719
338
3.17195
364
3.17201
354
3.17206
371
3.17211
362
3.17217
363
3.17222
373
3.17227
365
3.17233
400
3.17238
403
3.17243
381
3.17249
367
3.17254
371
3.17259
354
3.17264
392
3.1727
358
3.17275
391
3.1728
394
3.17286
383
3.17291
393
3.17296
386
3.17302
410
3.17307
391
3.17312
399
3.17318
411
3.17323
392
3.17328
409
3.17334
420
3.17339
416
3.17344
460
3.17349
492
3.17355
495
3.1736
476
3.17365
468
3.17371
517
3.17376
534
3.17381
578
3.17387
584
3.17392
638
3.17397
652
3.17403
660
3.17408
686
3.17413
775
3.17418
786
3.17424
842
3.17429
914
3.17434
921
3.1744
930
3.17445
954
3.1745
1018
3.17456
1033
3.17461
1046
3.17466
1096
3.17472
1136
3.17477
1104
3.17482
1087
3.17488
1182
3.17493
1112
3.17498
1155
3.17503
1165
3.17509
1138
3.17514
1163
3.17519
1251
3.17525
1186
3.1753
1251
3.17535
1382
3.17541
1410
3.17546
1447
3.17551
1572
3.17557
1703
3.17562
1886
3.17567
2076
3.17572
2249
3.17578
2481
3.17583
2784
3.17588
3041
3.17594
3359
3.17599
3655
3.17604
3901
3.1761
4454
3.17615
4903
3.1762
5324
3.17626
5589
3.17631
6212
3.17636
6799
3.17642
7061
3.17647
7442
3.17652
7834
3.17657
8117
3.17663
8461
3.17668
8544
3.17673
8780
3.17679
8820
3.17684
8696
3.17689
8814
3.17695
8570
3.177
8056
3.17705
7747
3.17711
7259
3.17716
6791
3.17721
6386
3.17726
5930
3.17732
5475
3.17737
5002
3.17742
4469
3.17748
4030
3.17753
3655
3.17758
3245
3.17764
2981
3.17769
2666
3.17774
2394
3.1778
2201
3.17785
2022
3.1779
1860
3.17796
1744
3.17801
1579
3.17806
1523
3.17811
1366
3.17817
1286
3.17822
1232
3.17827
1226
3.17833
1169
3.17838
1163
3.17843
1055
3.17849
1054
3.17854
1077
3.17859
1085
3.17865
1059
3.1787
1043
3.17875
1016
3.17881
1042
3.17886
1042
3.17891
1028
3.17896
1032
3.17902
1045
3.17907
1050
3.17912
1091
3.17918
1067
3.17923
1061
3.17928
1115
3.17934
1099
3.17939
1099
3.17944
1101
3.1795
1097
3.17955
1076
3.1796
1098
3.17965
1062
3.17971
1099
3.17976
1101
3.17981
1132
3.17987
1086
3.17992
1126
3.17997
1115
3.18003
1113
3.18008
1075
3.18013
1143
3.18019
1112
3.18024
1178
3.18029
1178
3.18035
1156
3.1804
1162
3.18045
1179
3.1805
1223
3.18056
1240
3.18061
1232
3.18066
1253
3.18072
1305
3.18077
1306
3.18082
1299
3.18088
1346
3.18093
1361
3.18098
1405
3.18104
1445
3.18109
1573
3.18114
1566
3.1812
1618
3.18125
1733
3.1813
1739
3.18135
1850
3.18141
1925
3.18146
2025
3.18151
2072
3.18157
2078
3.18162
2235
3.18167
2418
3.18173
2523
3.18178
2654
3.18183
2719
3.18189
2713
3.18194
2956
3.18199
3066
3.18204
3170
3.1821
3202
3.18215
3346
3.1822
3299
3.18226
3371
3.18231
3373
3.18236
3322
3.18242
3400
3.18247
3273
3.18252
3261
3.18258
3163
3.18263
3018
3.18268
2897
3.18274
2784
3.18279
2590
3.18284
2413
3.18289
2254
3.18295
1964
3.183
1831
3.18305
1638
3.18311
1489
3.18316
1306
3.18321
1167
3.18327
987
3.18332
906
3.18337
777
3.18343
669
3.18348
541
3.18353
466
3.18358
462
3.18364
403
3.18369
362
3.18374
349
3.1838
307
3.18385
302
3.1839
269
3.18396
220
3.18401
254
3.18406
222
3.18412
220
3.18417
226
3.18422
198
3.18428
193
3.18433
185
3.18438
195
3.18443
203
3.18449
183
3.18454
209
3.18459
175
3.18465
180
3.1847
184
3.18475
186
3.18481
187
3.18486
171
3.18491
177
3.18497
192
3.18502
174
3.18507
171
3.18512
136
3.18518
174
3.18523
187
3.18528
161
3.18534
164
3.18539
170
3.18544
165
3.1855
162
3.18555
179
3.1856
174
3.18566
170
3.18571
158
3.18576
175
3.18582
181
3.18587
179
3.18592
168
3.18597
155
3.18603
146
3.18608
161
3.18613
155
3.18619
176
3.18624
198
3.18629
172
3.18635
165
3.1864
167
3.18645
151
3.18651
166
3.18656
150
3.18661
161
3.18667
162
3.18672
171
3.18677
152
3.18682
178
3.18688
184
3.18693
159
3.18698
148
3.18704
168
3.18709
167
3.18714
159
3.1872
162
3.18725
175
3.1873
172
3.18736
173
3.18741
148
3.18746
168
3.18751
147
3.18757
148
3.18762
138
3.18767
177
3.18773
151
3.18778
149
3.18783
162
3.18789
170
3.18794
178
3.18799
161
3.18805
143
3.1881
148
3.18815
157
3.18821
176
3.18826
164
3.18831
156
3.18836
145
3.18842
172
3.18847
156
3.18852
145
3.18858
173
3.18863
154
3.18868
150
3.18874
152
3.18879
148
3.18884
157
3.1889
140
3.18895
138
3.189
157
3.18905
167
3.18911
163
3.18916
155
3.18921
141
3.18927
167
3.18932
191
3.18937
137
3.18943
152
3.18948
149
3.18953
175
3.18959
169
3.18964
137
3.18969
173
3.18975
148
3.1898
151
3.18985
154
3.1899
142
3.18996
142
3.19001
173
3.19006
154
3.19012
158
3.19017
156
3.19022
160
3.19028
168
3.19033
151
3.19038
148
3.19044
153
3.19049
153
3.19054
146
3.19059
154
3.19065
168
3.1907
162
3.19075
150
3.19081
166
3.19086
160
3.19091
161
3.19097
152
3.19102
146
3.19107
151
3.19113
153
3.19118
164
3.19123
158
3.19129
157
3.19134
148
3.19139
150
3.19144
157
3.1915
172
3.19155
150
3.1916
178
3.19166
183
3.19171
160
3.19176
152
3.19182
154
3.19187
145
3.19192
149
3.19198
end of experiment