File: C.vms
VAMAS Surface Chemical Analysis Standard Data Transfer Format 1988 May 4
Not Specified
Kratos Axis
Not Specified
/d=/data/20170705/2017006144/C.dset
3
Casa Info Follows
0
SourceAnalyserAngle: Not Specified
MAP
REGULAR
4
2
32768
32768
1
Etch Time
s
0
0
0
0
4
wide/2
Not Specified
2017
7
4
11
10
6
0
21
Casa Info Follows
1
Calib M = 282.478 A = 284.6 BE ADD
6
annot text peak Data 1202.57 2242 RGB(0,0,0) Font(14,18,0,0,Times New Roman) Vertical
C 1s
annot text peak Data 505 3113 RGB(0,0,0) Font(14,18,0,0,Times New Roman) Vertical
O KLL
annot text peak Data 954.568 875 RGB(0,0,0) Font(14,18,0,0,Times New Roman) Vertical
O 1s
annot text peak Data 642 3053 RGB(0,0,0) Font(14,18,0,0,Times New Roman) Vertical
F KLL
annot text peak Data 798.568 15871 RGB(0,0,0) Font(14,18,0,0,Times New Roman) Vertical
F 1s
annot text peak Data 1452.57 576 RGB(0,0,0) Font(14,18,0,0,Times New Roman) Vertical
F 2s
0
0
   XPS     Spectrum    Lens Mode:Hybrid   Resolution:Pass energy 80    Iris(Aper):slot(Slot)
   Acqn. Time(s): 110        Sweeps: 1        Anode:Mono(Al (Mono))(150 W)   Step(meV): 1000.0
   Dwell Time(ms): 100        Charge Neutraliser :On   Acquired On :17/07/04 11:10:06
XPS
53
7
0
Mono(Al (Mono))
1486.69
150
1e+037
1e+037
6000
6000
1e+037
1e+037
FAT
80
1e+037
-4.45
0
1e+037
1e+037
1e+037
1e+037
Wide
None
-1
Kinetic Energy
eV
386.69
1
2
Intensity
d
Transmission
d
pulse counting
0.1
0
1e+037
0
0
8.48115
2857
2809
2808
2753
2751
2779
2788
2790
2763
2807
2838
2759
2773
2810
2768
2782
2816
2779
2855
2746
2758
2810
2752
2747
2852
2832
2828
2808
2793
2781
2762
2876
2896
2791
2844
2834
2835
2849
2852
2949
2879
2803
2897
2881
2843
2809
2827
2875
2910
2883
2893
2822
2771
2791
2893
2882
2875
2957
2954
2886
2912
2878
2885
2906
2910
2895
2919
2848
2813
2935
3026
2884
2890
2970
2971
2961
2980
3014
2903
2905
2976
2934
2971
2978
2949
2959
2964
3020
3027
2952
2992
3118
2941
3008
3043
3017
3063
3010
3029
3100
3094
3099
3051
3029
3020
3058
3023
3031
3070
2978
3045
3099
3058
3026
3095
3026
3012
3162
3062
2994
3113
3077
3109
3193
3152
3081
3120
3089
3142
3109
3093
3091
3148
3018
3094
3056
3026
3136
3188
3068
3113
3174
3151
3052
3124
3132
3247
3102
3111
3131
3093
3052
3085
3082
3117
3108
3115
3163
3152
3174
3147
3193
3141
3160
3195
3133
3176
3170
3168
3144
3203
3214
3197
3153
3212
3240
3235
3228
3175
3190
3240
3184
3287
3289
3191
3256
3310
3343
3311
3275
3345
3306
3253
3287
3299
3280
3260
3321
3370
3361
3376
3346
3322
3369
3370
3341
3368
3347
3313
3359
3385
3354
3446
3405
3463
3451
3454
3522
3458
3523
3525
3546
3561
3709
3606
3527
3528
3485
3452
3445
3508
3394
3461
3537
3384
3399
3644
3585
3677
3802
3996
4089
4080
4115
3930
3967
3771
3772
3662
3639
3576
3479
3436
3299
3204
3193
3068
3053
3061
3112
3131
3138
3203
3307
3632
4020
4498
4951
5347
5579
5436
4970
4619
4166
3805
3533
3196
2938
2817
2613
2434
2327
2142
2132
2158
2106
2001
2004
2068
2028
2019
1995
1949
1955
1979
1969
2006
1956
2003
1987
1970
1955
2008
2008
2011
2065
2001
1930
1959
1955
1976
2115
2020
1992
1971
1991
1953
2004
2028
2026
2018
1954
1975
1995
1981
1968
2053
2005
1932
2045
2052
2046
1955
1943
1994
2028
2073
1988
2066
2025
1985
2044
2007
2040
2047
2025
2037
2071
2102
2074
2081
2031
2057
2051
2032
2117
2054
2064
2046
2055
2088
2136
2118
2116
2026
2089
2059
2015
2006
1999
1988
1995
2008
2005
1974
2046
2120
2113
2162
2199
2226
2243
2232
2268
2289
2205
2236
2207
2222
2254
2143
2159
2175
2136
2058
1918
1835
1803
1686
1612
1511
1458
1356
1280
1132
1032
924
853
894
976
1110
1785
4763
12776
15871
7326
2110
1076
777
693
671
628
651
635
623
618
636
643
643
629
604
629
669
645
615
604
589
613
640
691
643
616
649
620
611
623
601
598
613
632
617
589
626
622
618
606
635
607
643
602
580
614
615
655
650
651
657
663
605
665
625
619
638
621
636
620
622
626
599
646
636
644
604
610
643
628
632
626
646
640
627
635
646
666
645
654
676
651
637
639
605
608
642
653
660
641
636
673
643
624
632
651
646
645
636
660
682
658
662
615
650
651
634
654
644
632
654
640
680
654
667
685
648
655
664
662
677
652
652
673
680
651
654
662
688
689
682
666
679
683
674
639
693
668
663
661
688
660
655
682
627
635
675
681
677
645
641
710
729
832
875
812
720
644
633
634
644
646
654
628
638
642
663
627
611
641
648
625
668
671
665
632
654
629
617
597
630
680
668
627
648
660
687
698
653
624
634
641
685
643
669
652
628
643
657
662
644
661
646
615
666
651
604
650
670
660
666
656
655
627
643
666
694
660
668
656
685
661
681
682
646
635
674
650
645
680
654
690
703
702
723
672
665
641
717
685
684
675
670
679
692
676
686
663
667
703
691
715
718
670
684
704
683
665
692
702
689
687
738
700
711
679
710
715
716
676
701
709
740
712
694
700
700
678
707
658
713
734
695
668
723
762
741
699
731
731
732
677
700
722
667
702
692
701
679
701
686
680
697
708
741
721
742
737
717
717
717
745
681
676
728
765
746
777
727
725
727
757
738
721
753
770
777
747
751
801
768
781
765
774
741
748
760
758
788
745
758
765
770
825
796
788
752
804
816
754
771
780
803
751
752
770
786
791
749
773
778
839
838
844
894
895
862
894
866
821
862
875
860
843
828
792
803
799
725
687
720
681
685
577
592
554
535
471
391
341
332
335
359
439
815
1580
3788
3685
1328
743
1007
1923
2242
825
195
113
132
116
124
111
82
106
109
101
104
101
119
107
96
106
86
103
110
100
128
120
108
101
119
96
107
103
107
115
101
107
94
96
100
105
103
114
98
112
102
110
112
100
117
101
123
110
123
129
116
114
117
105
103
133
110
116
93
92
123
102
98
111
102
115
120
114
102
95
115
117
115
117
110
102
131
119
119
123
124
112
113
124
121
107
120
117
125
109
113
117
109
127
121
134
114
101
115
107
100
111
125
134
103
144
112
131
131
119
131
130
140
109
127
115
116
102
116
120
133
133
143
123
124
118
109
138
152
160
163
129
122
122
110
119
123
117
123
104
117
107
110
135
126
123
140
131
111
106
115
105
120
139
109
124
119
149
136
120
132
136
138
117
119
135
121
133
130
108
116
107
135
130
140
112
126
135
145
145
170
149
137
133
122
147
135
140
146
137
147
159
128
126
105
129
129
148
130
131
147
146
143
137
147
128
142
143
151
145
144
154
153
140
139
159
129
151
144
155
144
161
139
130
140
143
159
152
149
136
144
150
133
130
134
116
118
132
122
111
101
110
113
129
161
200
312
457
576
488
291
193
136
100
72
62
59
65
68
73
93
108
123
105
86
101
120
135
133
143
113
129
163
127
75
61
33
24
7
2
0
8.94051
F 1s/5
Not Specified
2017
7
4
14
17
31
0
9
Casa Info Follows
1
Calib M = 282.478 A = 284.6 BE ADD
0
0
0
   XPS     Spectrum    Lens Mode:Hybrid   Resolution:Pass energy 40    Iris(Aper):slot(Slot)
   Acqn. Time(s): 121        Sweeps: 2        Anode:Mono(Al (Mono))(150 W)   Step(meV): 50.0
   Dwell Time(ms): 150        Charge Neutraliser :On   Acquired On :17/07/04 14:17:31
XPS
53
7
0
Mono(Al (Mono))
1486.69
150
1e+037
1e+037
6000
6000
1e+037
1e+037
FAT
40
1e+037
-4.45
0
1e+037
1e+037
1e+037
1e+037
F
1s
-1
Kinetic Energy
eV
790.64
0.05
2
Intensity
d
Transmission
d
pulse counting
0.15
2
0
1e+037
1e+037
1e+037
0
806
700
25446
3.41724
3.42712
1276
3.42712
1287
3.4271
1227
3.42707
1252
3.42705
1201
3.42702
1248
3.427
1232
3.42698
1177
3.42695
1235
3.42693
1202
3.4269
1213
3.42688
1172
3.42686
1187
3.42683
1191
3.42681
1215
3.42678
1127
3.42676
1153
3.42674
1112
3.42671
1109
3.42669
1116
3.42667
1107
3.42664
1141
3.42662
1082
3.42659
1111
3.42657
1063
3.42655
1050
3.42652
1038
3.4265
1082
3.42647
1059
3.42645
1042
3.42643
1067
3.4264
1024
3.42638
1008
3.42636
996
3.42633
1011
3.42631
1008
3.42628
973
3.42626
1020
3.42624
986
3.42621
975
3.42619
995
3.42616
969
3.42614
1035
3.42612
991
3.42609
974
3.42607
1027
3.42605
990
3.42602
1012
3.426
1037
3.42597
953
3.42595
1019
3.42593
1023
3.4259
1000
3.42588
1010
3.42585
963
3.42583
971
3.42581
973
3.42578
941
3.42576
991
3.42573
1001
3.42571
1013
3.42569
989
3.42566
972
3.42564
973
3.42562
1065
3.42559
1037
3.42557
1049
3.42554
979
3.42552
981
3.4255
1009
3.42547
1024
3.42545
1003
3.42542
978
3.4254
1003
3.42538
998
3.42535
1007
3.42533
1031
3.42531
1009
3.42528
964
3.42526
983
3.42523
1025
3.42521
1033
3.42519
1005
3.42516
1029
3.42514
1012
3.42511
996
3.42509
998
3.42507
1026
3.42504
1040
3.42502
1050
3.425
1061
3.42497
1014
3.42495
980
3.42492
1076
3.4249
998
3.42488
992
3.42485
1055
3.42483
1077
3.4248
1079
3.42478
1093
3.42476
1090
3.42473
1071
3.42471
1089
3.42469
1055
3.42466
1022
3.42464
1091
3.42461
1083
3.42459
1116
3.42457
1148
3.42454
1115
3.42452
1117
3.42449
1134
3.42447
1101
3.42445
1133
3.42442
1185
3.4244
1162
3.42437
1172
3.42435
1172
3.42433
1165
3.4243
1187
3.42428
1147
3.42426
1203
3.42423
1227
3.42421
1218
3.42418
1231
3.42416
1222
3.42414
1209
3.42411
1299
3.42409
1292
3.42406
1308
3.42404
1288
3.42402
1364
3.42399
1395
3.42397
1398
3.42395
1401
3.42392
1429
3.4239
1456
3.42387
1493
3.42385
1564
3.42383
1536
3.4238
1562
3.42378
1690
3.42375
1709
3.42373
1812
3.42371
1884
3.42368
1910
3.42366
1930
3.42364
2067
3.42361
2199
3.42359
2259
3.42356
2447
3.42354
2513
3.42352
2720
3.42349
2950
3.42347
3098
3.42344
3276
3.42342
3465
3.4234
3795
3.42337
4082
3.42335
4395
3.42333
4774
3.4233
4971
3.42328
5482
3.42325
6009
3.42323
6461
3.42321
7018
3.42318
7682
3.42316
8232
3.42313
8768
3.42311
9497
3.42309
10358
3.42306
11048
3.42304
11852
3.42301
12719
3.42299
13886
3.42297
14735
3.42294
15637
3.42292
16597
3.4229
17666
3.42287
18624
3.42285
19595
3.42282
20301
3.4228
21288
3.42278
21910
3.42275
22815
3.42273
23467
3.4227
24334
3.42268
24607
3.42266
25198
3.42263
25386
3.42261
25446
3.42259
25250
3.42256
25086
3.42254
25081
3.42251
24642
3.42249
24364
3.42247
23540
3.42244
22956
3.42242
21969
3.42239
21102
3.42237
20544
3.42235
19642
3.42232
18546
3.4223
17381
3.42228
16345
3.42225
15425
3.42223
14388
3.4222
13402
3.42218
12336
3.42216
11474
3.42213
10727
3.42211
9743
3.42208
8975
3.42206
8334
3.42204
7561
3.42201
6904
3.42199
6375
3.42196
5877
3.42194
5413
3.42192
5072
3.42189
4790
3.42187
4310
3.42185
4024
3.42182
3726
3.4218
3610
3.42177
3317
3.42175
3039
3.42173
2792
3.4217
2801
3.42168
2560
3.42165
2419
3.42163
2323
3.42161
2196
3.42158
2042
3.42156
1936
3.42154
1998
3.42151
1866
3.42149
1715
3.42146
1722
3.42144
1658
3.42142
1583
3.42139
1549
3.42137
1498
3.42134
1512
3.42132
1454
3.4213
1384
3.42127
1400
3.42125
1362
3.42123
1346
3.4212
1332
3.42118
1286
3.42115
1240
3.42113
1122
3.42111
1189
3.42108
1206
3.42106
1176
3.42103
1155
3.42101
1107
3.42099
1110
3.42096
1064
3.42094
1034
3.42091
1001
3.42089
1013
3.42087
1013
3.42084
1010
3.42082
977
3.4208
950
3.42077
885
3.42075
933
3.42072
924
3.4207
925
3.42068
906
3.42065
915
3.42063
884
3.4206
940
3.42058
902
3.42056
852
3.42053
918
3.42051
850
3.42049
822
3.42046
783
3.42044
826
3.42041
847
3.42039
808
3.42037
818
3.42034
830
3.42032
797
3.42029
808
3.42027
796
3.42025
844
3.42022
832
3.4202
802
3.42018
791
3.42015
852
3.42013
859
3.4201
833
3.42008
771
3.42006
746
3.42003
793
3.42001
828
3.41998
786
3.41996
790
3.41994
809
3.41991
765
3.41989
778
3.41986
768
3.41984
808
3.41982
755
3.41979
798
3.41977
781
3.41975
767
3.41972
776
3.4197
744
3.41967
756
3.41965
758
3.41963
741
3.4196
735
3.41958
791
3.41955
792
3.41953
778
3.41951
759
3.41948
769
3.41946
765
3.41944
771
3.41941
740
3.41939
767
3.41936
783
3.41934
774
3.41932
743
3.41929
766
3.41927
745
3.41924
765
3.41922
748
3.4192
726
3.41917
734
3.41915
779
3.41913
753
3.4191
755
3.41908
737
3.41905
721
3.41903
728
3.41901
724
3.41898
723
3.41896
747
3.41893
743
3.41891
771
3.41889
770
3.41886
727
3.41884
743
3.41881
788
3.41879
775
3.41877
734
3.41874
700
3.41872
761
3.4187
707
3.41867
732
3.41865
734
3.41862
710
3.4186
741
3.41858
748
3.41855
753
3.41853
756
3.4185
754
3.41848
734
3.41846
735
3.41843
708
3.41841
766
3.41839
736
3.41836
713
3.41834
752
3.41831
753
3.41829
724
3.41827
713
3.41824
746
3.41822
732
3.41819
731
3.41817
766
3.41815
734
3.41812
714
3.4181
720
3.41808
748
3.41805
722
3.41803
731
3.418
744
3.41798
731
3.41796
721
3.41793
737
3.4179
748
3.41786
744
3.41781
759
3.41777
744
3.41773
741
3.41769
767
3.41765
733
3.41761
702
3.41757
713
3.41753
709
3.41748
737
3.41744
760
3.4174
777
3.41736
738
3.41732
744
3.41728
757
3.41724
O 1s/6
Not Specified
2017
7
4
14
17
31
0
9
Casa Info Follows
1
Calib M = 282.478 A = 284.6 BE ADD
0
0
0
   XPS     Spectrum    Lens Mode:Hybrid   Resolution:Pass energy 40    Iris(Aper):slot(Slot)
   Acqn. Time(s): 162        Sweeps: 3        Anode:Mono(Al (Mono))(150 W)   Step(meV): 50.0
   Dwell Time(ms): 150        Charge Neutraliser :On   Acquired On :17/07/04 14:17:31
XPS
53
7
0
Mono(Al (Mono))
1486.69
150
1e+037
1e+037
6000
6000
1e+037
1e+037
FAT
40
1e+037
-4.45
0
1e+037
1e+037
1e+037
1e+037
O
1s
-1
Kinetic Energy
eV
946.69
0.05
2
Intensity
d
Transmission
d
pulse counting
0.15
3
0
1e+037
1e+037
1e+037
0
722
1041
1711
3.32569
3.34183
1100
3.34183
1093
3.34178
1139
3.34174
1076
3.34169
1141
3.34165
1137
3.3416
1152
3.34156
1116
3.34151
1128
3.34147
1152
3.34142
1096
3.34138
1111
3.34133
1138
3.34129
1145
3.34124
1105
3.3412
1107
3.34115
1132
3.34111
1050
3.34107
1152
3.34102
1138
3.34098
1094
3.34093
1094
3.34089
1115
3.34084
1093
3.3408
1098
3.34075
1130
3.34071
1089
3.34066
1110
3.34062
1105
3.34057
1094
3.34053
1126
3.34048
1114
3.34044
1119
3.34039
1117
3.34035
1141
3.3403
1111
3.34026
1114
3.34021
1123
3.34017
1102
3.34012
1116
3.34008
1129
3.34003
1122
3.33999
1107
3.33994
1118
3.3399
1113
3.33985
1115
3.33981
1166
3.33976
1105
3.33972
1157
3.33968
1173
3.33963
1171
3.33959
1129
3.33954
1168
3.3395
1113
3.33945
1071
3.33941
1103
3.33936
1060
3.33932
1135
3.33927
1155
3.33923
1120
3.33918
1125
3.33914
1086
3.33909
1053
3.33905
1110
3.339
1165
3.33896
1142
3.33891
1099
3.33887
1121
3.33882
1148
3.33878
1093
3.33873
1094
3.33869
1142
3.33864
1129
3.3386
1163
3.33855
1148
3.33851
1127
3.33846
1070
3.33842
1095
3.33837
1062
3.33833
1132
3.33829
1139
3.33824
1136
3.3382
1080
3.33815
1103
3.33811
1086
3.33806
1146
3.33802
1090
3.33797
1117
3.33793
1111
3.33788
1110
3.33784
1088
3.33779
1124
3.33775
1072
3.3377
1126
3.33766
1123
3.33761
1134
3.33757
1137
3.33752
1141
3.33748
1077
3.33743
1150
3.33739
1115
3.33734
1132
3.3373
1089
3.33725
1142
3.33721
1135
3.33716
1127
3.33712
1162
3.33707
1124
3.33703
1120
3.33698
1170
3.33694
1167
3.3369
1170
3.33685
1132
3.33681
1181
3.33676
1188
3.33672
1128
3.33667
1180
3.33663
1163
3.33658
1116
3.33654
1150
3.33649
1132
3.33645
1150
3.3364
1163
3.33636
1167
3.33631
1186
3.33627
1199
3.33622
1174
3.33618
1191
3.33613
1197
3.33609
1196
3.33604
1199
3.336
1188
3.33595
1235
3.33591
1239
3.33586
1220
3.33582
1229
3.33577
1242
3.33573
1210
3.33568
1269
3.33564
1246
3.3356
1198
3.33555
1224
3.33551
1314
3.33546
1232
3.33542
1223
3.33537
1296
3.33533
1254
3.33528
1204
3.33524
1289
3.33519
1270
3.33515
1292
3.3351
1235
3.33506
1259
3.33501
1253
3.33497
1353
3.33492
1310
3.33488
1351
3.33483
1343
3.33479
1351
3.33474
1351
3.3347
1341
3.33465
1348
3.33461
1379
3.33456
1424
3.33452
1378
3.33447
1377
3.33443
1425
3.33438
1441
3.33434
1435
3.33429
1423
3.33425
1437
3.33421
1441
3.33416
1462
3.33412
1471
3.33407
1523
3.33403
1441
3.33398
1475
3.33394
1462
3.33389
1506
3.33385
1473
3.3338
1514
3.33376
1577
3.33371
1587
3.33367
1536
3.33362
1583
3.33358
1512
3.33353
1561
3.33349
1527
3.33344
1606
3.3334
1597
3.33335
1575
3.33331
1569
3.33326
1501
3.33322
1599
3.33317
1602
3.33313
1711
3.33308
1684
3.33304
1600
3.33299
1610
3.33295
1626
3.3329
1585
3.33286
1605
3.33282
1614
3.33277
1611
3.33273
1662
3.33268
1582
3.33264
1534
3.33259
1490
3.33255
1549
3.3325
1498
3.33246
1482
3.33241
1418
3.33237
1469
3.33232
1469
3.33228
1393
3.33223
1359
3.33219
1379
3.33214
1366
3.3321
1342
3.33205
1338
3.33201
1244
3.33196
1248
3.33192
1225
3.33187
1217
3.33183
1186
3.33178
1184
3.33174
1236
3.33169
1223
3.33165
1151
3.3316
1140
3.33156
1157
3.33151
1117
3.33147
1183
3.33143
1113
3.33138
1159
3.33134
1169
3.33129
1185
3.33125
1143
3.3312
1134
3.33116
1129
3.33111
1121
3.33107
1112
3.33102
1141
3.33098
1093
3.33093
1160
3.33089
1120
3.33084
1155
3.3308
1076
3.33075
1079
3.33071
1118
3.33066
1087
3.33062
1122
3.33057
1084
3.33053
1069
3.33048
1115
3.33044
1105
3.33039
1101
3.33035
1131
3.3303
1111
3.33026
1123
3.33021
1063
3.33017
1095
3.33012
1124
3.33008
1127
3.33004
1120
3.32999
1127
3.32995
1115
3.3299
1084
3.32986
1099
3.32981
1167
3.32977
1070
3.32972
1092
3.32968
1098
3.32963
1149
3.32959
1102
3.32954
1129
3.3295
1104
3.32945
1160
3.32941
1128
3.32936
1161
3.32932
1132
3.32927
1185
3.32923
1105
3.32918
1090
3.32914
1114
3.32909
1162
3.32905
1125
3.329
1086
3.32896
1127
3.32891
1064
3.32887
1125
3.32882
1111
3.32878
1110
3.32873
1132
3.32869
1090
3.32865
1118
3.3286
1041
3.32856
1109
3.32851
1184
3.32847
1096
3.32842
1094
3.32838
1091
3.32833
1081
3.32829
1104
3.32824
1092
3.3282
1073
3.32815
1171
3.32811
1160
3.32806
1122
3.32802
1106
3.32797
1148
3.32793
1163
3.32788
1153
3.32784
1064
3.32779
1113
3.32775
1148
3.3277
1123
3.32766
1115
3.32761
1091
3.32757
1094
3.32752
1102
3.32748
1148
3.32743
1100
3.32739
1128
3.32735
1120
3.3273
1129
3.32726
1087
3.32721
1112
3.32717
1117
3.32712
1114
3.32708
1054
3.32703
1142
3.32699
1123
3.32694
1192
3.3269
1095
3.32685
1075
3.32681
1080
3.32676
1049
3.32672
1102
3.32667
1169
3.32663
1085
3.32658
1128
3.32654
1180
3.32649
1134
3.32645
1091
3.3264
1110
3.32636
1180
3.32631
1085
3.32627
1099
3.32622
1104
3.32618
1157
3.32613
1141
3.32609
1089
3.32604
1080
3.326
1138
3.32596
1097
3.32591
1125
3.32587
1120
3.32582
1133
3.32578
1119
3.32573
1100
3.32569
C 1s/7
Not Specified
2017
7
4
14
17
31
0
9
Casa Info Follows
1
Calib M = 282.478 A = 284.6 BE ADD
0
0
0
   XPS     Spectrum    Lens Mode:Hybrid   Resolution:Pass energy 40    Iris(Aper):slot(Slot)
   Acqn. Time(s): 138        Sweeps: 2        Anode:Mono(Al (Mono))(150 W)   Step(meV): 50.0
   Dwell Time(ms): 150        Charge Neutraliser :On   Acquired On :17/07/04 14:17:31
XPS
53
7
0
Mono(Al (Mono))
1486.69
150
1e+037
1e+037
6000
6000
1e+037
1e+037
FAT
40
1e+037
-4.45
0
1e+037
1e+037
1e+037
1e+037
C
1s
-1
Kinetic Energy
eV
1190.19
0.05
2
Intensity
d
Transmission
d
pulse counting
0.15
2
0
1e+037
1e+037
1e+037
0
922
95
7341
3.16755
3.19198
445
3.16755
473
3.1676
423
3.16765
436
3.16771
412
3.16776
431
3.16781
442
3.16787
425
3.16792
459
3.16797
425
3.16802
429
3.16808
428
3.16813
389
3.16818
419
3.16824
434
3.16829
391
3.16834
432
3.1684
422
3.16845
397
3.1685
398
3.16856
411
3.16861
387
3.16866
368
3.16871
396
3.16877
407
3.16882
392
3.16887
382
3.16893
384
3.16898
421
3.16903
379
3.16909
376
3.16914
398
3.16919
368
3.16925
378
3.1693
342
3.16935
368
3.16941
367
3.16946
388
3.16951
362
3.16956
367
3.16962
368
3.16967
335
3.16972
348
3.16978
371
3.16983
358
3.16988
380
3.16994
365
3.16999
315
3.17004
335
3.1701
357
3.17015
350
3.1702
361
3.17025
362
3.17031
382
3.17036
380
3.17041
362
3.17047
373
3.17052
338
3.17057
333
3.17063
375
3.17068
367
3.17073
325
3.17079
312
3.17084
348
3.17089
324
3.17095
330
3.171
347
3.17105
340
3.1711
338
3.17116
360
3.17121
351
3.17126
351
3.17132
342
3.17137
342
3.17142
332
3.17148
325
3.17153
335
3.17158
342
3.17164
378
3.17169
346
3.17174
317
3.17179
337
3.17185
367
3.1719
363
3.17195
363
3.17201
347
3.17206
356
3.17211
344
3.17217
377
3.17222
365
3.17227
363
3.17233
362
3.17238
348
3.17243
407
3.17249
386
3.17254
340
3.17259
382
3.17264
387
3.1727
383
3.17275
391
3.1728
368
3.17286
382
3.17291
389
3.17296
414
3.17302
421
3.17307
426
3.17312
425
3.17318
457
3.17323
460
3.17328
434
3.17334
469
3.17339
489
3.17344
445
3.17349
469
3.17355
474
3.1736
504
3.17365
523
3.17371
562
3.17376
564
3.17381
565
3.17387
616
3.17392
624
3.17397
647
3.17403
692
3.17408
727
3.17413
772
3.17418
804
3.17424
874
3.17429
842
3.17434
923
3.1744
1015
3.17445
1042
3.1745
1039
3.17456
1036
3.17461
1046
3.17466
1072
3.17472
1073
3.17477
1095
3.17482
1156
3.17488
1122
3.17493
1144
3.17498
1127
3.17503
1115
3.17509
1135
3.17514
1129
3.17519
1154
3.17525
1180
3.1753
1298
3.17535
1275
3.17541
1358
3.17546
1408
3.17551
1433
3.17557
1599
3.17562
1695
3.17567
1828
3.17572
1999
3.17578
2198
3.17583
2341
3.17588
2611
3.17594
2892
3.17599
3158
3.17604
3457
3.1761
3782
3.17615
4147
3.1762
4406
3.17626
4773
3.17631
5088
3.17636
5465
3.17642
5862
3.17647
6247
3.17652
6460
3.17657
6731
3.17663
6883
3.17668
6963
3.17673
7341
3.17679
7252
3.17684
7199
3.17689
7194
3.17695
6989
3.177
6694
3.17705
6502
3.17711
6246
3.17716
5914
3.17721
5503
3.17726
5202
3.17732
4864
3.17737
4517
3.17742
4120
3.17748
3735
3.17753
3394
3.17758
3210
3.17764
2875
3.17769
2600
3.17774
2424
3.1778
2266
3.17785
2053
3.1779
1866
3.17796
1708
3.17801
1515
3.17806
1418
3.17811
1358
3.17817
1281
3.17822
1183
3.17827
1096
3.17833
1045
3.17838
990
3.17843
934
3.17849
890
3.17854
863
3.17859
813
3.17865
800
3.1787
769
3.17875
768
3.17881
696
3.17886
750
3.17891
674
3.17896
665
3.17902
711
3.17907
707
3.17912
673
3.17918
671
3.17923
651
3.17928
648
3.17934
658
3.17939
671
3.17944
697
3.1795
686
3.17955
670
3.1796
689
3.17965
701
3.17971
771
3.17976
756
3.17981
712
3.17987
751
3.17992
789
3.17997
792
3.18003
804
3.18008
801
3.18013
849
3.18019
848
3.18024
879
3.18029
894
3.18035
921
3.1804
953
3.18045
962
3.1805
980
3.18056
1055
3.18061
1037
3.18066
1054
3.18072
1079
3.18077
1133
3.18082
1120
3.18088
1198
3.18093
1228
3.18098
1224
3.18104
1226
3.18109
1345
3.18114
1301
3.1812
1365
3.18125
1450
3.1813
1580
3.18135
1619
3.18141
1706
3.18146
1813
3.18151
1901
3.18157
2000
3.18162
2134
3.18167
2230
3.18173
2335
3.18178
2564
3.18183
2659
3.18189
2748
3.18194
2940
3.18199
3008
3.18204
3165
3.1821
3386
3.18215
3421
3.1822
3666
3.18226
3726
3.18231
3836
3.18236
3821
3.18242
3962
3.18247
3919
3.18252
3838
3.18258
3697
3.18263
3661
3.18268
3370
3.18274
3143
3.18279
2992
3.18284
2808
3.18289
2488
3.18295
2321
3.183
2165
3.18305
1946
3.18311
1701
3.18316
1426
3.18321
1335
3.18327
1154
3.18332
1027
3.18337
912
3.18343
754
3.18348
694
3.18353
632
3.18358
547
3.18364
512
3.18369
469
3.18374
442
3.1838
388
3.18385
351
3.1839
318
3.18396
296
3.18401
277
3.18406
259
3.18412
230
3.18417
218
3.18422
216
3.18428
225
3.18433
196
3.18438
174
3.18443
189
3.18449
186
3.18454
168
3.18459
160
3.18465
154
3.1847
151
3.18475
184
3.18481
182
3.18486
139
3.18491
149
3.18497
154
3.18502
163
3.18507
140
3.18512
144
3.18518
130
3.18523
159
3.18528
141
3.18534
140
3.18539
147
3.18544
135
3.1855
130
3.18555
136
3.1856
146
3.18566
123
3.18571
138
3.18576
124
3.18582
141
3.18587
133
3.18592
142
3.18597
127
3.18603
125
3.18608
129
3.18613
128
3.18619
138
3.18624
118
3.18629
128
3.18635
117
3.1864
125
3.18645
117
3.18651
144
3.18656
134
3.18661
148
3.18667
127
3.18672
138
3.18677
141
3.18682
134
3.18688
125
3.18693
132
3.18698
125
3.18704
122
3.18709
134
3.18714
126
3.1872
135
3.18725
140
3.1873
108
3.18736
121
3.18741
128
3.18746
146
3.18751
138
3.18757
151
3.18762
147
3.18767
110
3.18773
120
3.18778
108
3.18783
118
3.18789
119
3.18794
118
3.18799
127
3.18805
119
3.1881
131
3.18815
122
3.18821
117
3.18826
122
3.18831
118
3.18836
125
3.18842
134
3.18847
125
3.18852
110
3.18858
112
3.18863
119
3.18868
117
3.18874
119
3.18879
124
3.18884
110
3.1889
125
3.18895
122
3.189
111
3.18905
123
3.18911
112
3.18916
115
3.18921
132
3.18927
107
3.18932
116
3.18937
126
3.18943
135
3.18948
117
3.18953
124
3.18959
109
3.18964
122
3.18969
101
3.18975
126
3.1898
125
3.18985
144
3.1899
111
3.18996
126
3.19001
120
3.19006
109
3.19012
126
3.19017
130
3.19022
136
3.19028
126
3.19033
118
3.19038
121
3.19044
123
3.19049
104
3.19054
121
3.19059
135
3.19065
95
3.1907
117
3.19075
112
3.19081
129
3.19086
119
3.19091
122
3.19097
123
3.19102
138
3.19107
141
3.19113
108
3.19118
120
3.19123
136
3.19129
127
3.19134
112
3.19139
106
3.19144
124
3.1915
133
3.19155
125
3.1916
133
3.19166
113
3.19171
126
3.19176
131
3.19182
131
3.19187
129
3.19192
126
3.19198
end of experiment