File: D.vms
VAMAS Surface Chemical Analysis Standard Data Transfer Format 1988 May 4
Not Specified
Kratos Axis
Not Specified
/d=/data/20170705/2017006144/D.dset
3
Casa Info Follows
0
SourceAnalyserAngle: Not Specified
MAP
REGULAR
3
2
32768
32768
1
Etch Time
s
0
0
0
0
3
wide/2
Not Specified
2017
7
4
11
12
40
0
21
Casa Info Follows
1
Calib M = 283.4 A = 284.6 BE ADD
6
annot text peak Data 1202.49 2174 RGB(0,0,0) Font(14,18,0,0,Times New Roman) Vertical
C 1s
annot text peak Data 1084.49 655 RGB(0,0,0) Font(14,18,0,0,Times New Roman) Vertical
N 1s
annot text peak Data 511.49 1642 RGB(0,0,0) Font(14,18,0,0,Times New Roman) Vertical
O KLL
annot text peak Data 954.49 3746 RGB(0,0,0) Font(14,18,0,0,Times New Roman) Vertical
O 1s
annot text peak Data 1254.49 258 RGB(0,0,0) Font(14,18,0,0,Times New Roman) Vertical
S 2s
annot text peak Data 1318.49 324 RGB(0,0,0) Font(14,18,0,0,Times New Roman) Vertical
S 2p
0
0
   XPS     Spectrum    Lens Mode:Hybrid   Resolution:Pass energy 80    Iris(Aper):slot(Slot)
   Acqn. Time(s): 110        Sweeps: 1        Anode:Mono(Al (Mono))(150 W)   Step(meV): 1000.0
   Dwell Time(ms): 100        Charge Neutraliser :On   Acquired On :17/07/04 11:12:40
XPS
42
7
0
Mono(Al (Mono))
1486.69
150
1e+037
1e+037
6000
6000
1e+037
1e+037
FAT
80
1e+037
-4.45
0
1e+037
1e+037
1e+037
1e+037
Wide
None
-1
Kinetic Energy
eV
386.69
1
2
Intensity
d
Transmission
d
pulse counting
0.1
0
1e+037
0
1
8.48115
1342
1302
1328
1344
1292
1304
1368
1312
1302
1302
1347
1409
1388
1314
1348
1317
1331
1382
1382
1347
1378
1394
1350
1373
1392
1336
1379
1358
1375
1360
1313
1340
1354
1386
1403
1421
1385
1375
1335
1393
1422
1363
1406
1343
1374
1425
1381
1426
1422
1437
1424
1352
1372
1410
1421
1380
1373
1423
1478
1392
1428
1409
1394
1435
1427
1448
1423
1442
1386
1431
1418
1390
1397
1464
1436
1449
1448
1445
1459
1508
1521
1518
1434
1435
1484
1463
1416
1491
1452
1427
1450
1461
1509
1480
1418
1424
1490
1495
1505
1542
1565
1595
1587
1564
1527
1495
1463
1410
1422
1455
1423
1383
1400
1372
1273
1280
1332
1354
1371
1462
1516
1503
1536
1574
1646
1619
1642
1581
1571
1480
1384
1368
1284
1208
1125
1079
1026
995
999
922
942
954
957
961
968
937
927
934
949
940
961
954
907
935
946
964
930
906
910
956
916
937
954
985
882
920
971
965
932
927
927
920
961
929
927
964
905
941
954
979
945
967
980
983
971
954
936
934
922
946
983
934
960
954
945
1006
909
954
968
943
960
922
946
952
994
952
983
980
978
951
949
946
930
975
985
989
1007
968
953
959
1033
978
946
993
1000
967
935
947
958
976
1004
970
967
998
993
988
953
951
950
979
931
969
923
960
975
987
948
914
961
960
988
991
980
973
1002
956
978
972
969
926
983
971
970
968
991
985
936
975
967
1037
994
970
1020
985
966
966
959
960
987
990
1030
999
965
958
946
1020
1006
1003
969
1012
1008
948
945
997
980
954
984
987
988
1001
986
1001
960
993
998
1014
945
951
1004
956
996
947
950
996
1029
1026
1003
973
963
957
1034
1048
1002
1000
1039
1017
1046
1011
990
1046
1041
1000
1018
1039
1013
943
978
1001
1038
1006
1002
1061
1000
1000
1006
1003
1013
1014
1019
990
1022
987
997
994
1041
1078
996
985
1008
1008
1014
967
989
1022
1056
1002
1036
1008
970
1033
1042
987
1014
997
1007
1019
1087
1055
1005
968
994
1016
993
1048
1059
1037
1061
1025
1007
1027
1028
1014
1003
1036
1048
1018
1040
942
977
989
1010
1001
1021
1028
1050
1033
1021
1011
1064
1082
1025
1014
1063
1012
1027
1069
1023
1056
1045
1027
993
982
1005
1020
1027
1038
1021
997
1007
1064
1077
1010
1035
1010
983
1018
1024
1008
1036
1012
1061
1051
1052
975
1022
1022
1021
974
1006
1032
1032
1040
979
1035
1033
1016
1043
1061
1056
995
1030
1027
997
1015
1033
1008
1018
1037
1071
1029
1051
1055
1046
1045
1044
1054
1054
1070
1032
999
982
993
983
1040
1069
1062
1009
1009
1049
1036
996
1035
1041
1016
1060
1028
1026
1012
1048
1032
1030
1028
1024
1048
1003
1014
1033
1028
1048
991
1030
1019
1002
973
994
1020
1046
1006
1054
1034
1027
1005
1043
1038
1045
1035
957
995
1029
959
1016
992
974
974
1051
1009
982
1035
963
993
1004
1035
1031
1072
1068
1139
1061
1061
1062
1019
951
964
896
904
855
851
819
763
740
711
642
640
636
634
598
640
807
1466
2843
3746
2950
1397
634
520
461
424
460
485
494
467
452
471
453
455
424
451
486
446
470
468
422
434
492
450
444
463
466
440
438
447
451
458
471
449
476
497
511
437
459
441
454
443
447
439
469
452
451
452
452
449
466
438
449
434
471
443
475
453
494
433
450
446
467
440
464
456
463
466
465
485
470
449
460
439
484
479
465
443
426
460
507
478
453
449
493
514
479
464
478
476
463
488
495
516
482
480
494
472
484
471
537
481
467
495
493
516
497
520
488
503
485
457
460
462
450
490
501
460
496
490
483
437
474
489
483
451
437
496
552
655
649
560
500
458
458
467
502
481
462
452
508
493
457
505
481
471
469
500
488
458
492
488
481
484
491
469
524
484
474
476
475
476
477
514
466
493
503
468
505
475
501
483
476
502
505
496
509
506
505
497
471
488
513
492
521
510
517
504
469
508
539
541
484
512
468
492
493
495
491
492
484
522
544
523
510
454
499
500
490
514
517
494
540
516
530
552
550
534
521
497
543
549
554
522
564
561
526
495
477
465
409
371
356
349
333
289
269
265
235
247
285
356
536
795
1194
1656
2116
2174
926
212
129
110
110
99
98
98
98
95
99
115
134
135
117
98
114
114
111
101
97
105
93
91
101
102
117
106
109
114
118
106
101
97
95
95
108
99
115
108
97
109
94
93
93
99
97
98
112
164
226
258
189
125
111
104
80
92
82
93
102
105
82
95
90
90
80
90
84
74
78
85
96
78
72
96
90
92
101
87
99
93
102
104
106
95
91
87
88
83
91
94
106
104
99
76
87
82
91
78
72
75
70
86
85
63
63
64
64
74
78
65
98
191
304
324
168
79
67
52
49
51
49
47
60
54
53
60
55
64
71
68
63
52
55
49
46
53
49
41
45
52
58
62
41
50
55
59
62
53
60
53
43
47
50
57
50
51
52
52
44
54
51
62
54
41
48
62
57
59
61
59
51
53
65
50
66
59
55
54
54
62
60
56
52
56
62
56
53
67
52
57
53
55
62
70
56
54
50
42
59
44
53
63
63
58
61
63
60
56
61
50
51
51
70
50
51
61
62
67
40
65
52
57
69
62
58
65
56
49
50
66
71
57
56
61
61
76
53
55
56
57
58
63
49
50
40
47
50
47
48
49
47
83
91
87
105
119
128
114
64
63
46
39
47
47
50
50
57
47
65
61
54
63
48
51
36
33
27
32
12
5
1
8.94051
O 1s/5
Not Specified
2017
7
4
14
27
29
0
9
Casa Info Follows
1
Calib M = 283.4 A = 284.6 BE ADD
0
0
0
   XPS     Spectrum    Lens Mode:Hybrid   Resolution:Pass energy 40    Iris(Aper):slot(Slot)
   Acqn. Time(s): 108        Sweeps: 2        Anode:Mono(Al (Mono))(150 W)   Step(meV): 50.0
   Dwell Time(ms): 150        Charge Neutraliser :On   Acquired On :17/07/04 14:27:29
XPS
42
7
0
Mono(Al (Mono))
1486.69
150
1e+037
1e+037
6000
6000
1e+037
1e+037
FAT
40
1e+037
-4.45
0
1e+037
1e+037
1e+037
1e+037
O
1s
-1
Kinetic Energy
eV
946.69
0.05
2
Intensity
d
Transmission
d
pulse counting
0.15
2
0
1e+037
1e+037
1e+037
0
722
470
4914
3.32569
3.34183
693
3.34183
712
3.34178
729
3.34174
726
3.34169
696
3.34165
729
3.3416
715
3.34156
690
3.34151
698
3.34147
702
3.34142
648
3.34138
711
3.34133
721
3.34129
695
3.34124
676
3.3412
709
3.34115
712
3.34111
651
3.34107
637
3.34102
666
3.34098
693
3.34093
743
3.34089
683
3.34084
689
3.3408
708
3.34075
689
3.34071
645
3.34066
647
3.34062
684
3.34057
664
3.34053
630
3.34048
670
3.34044
682
3.34039
653
3.34035
652
3.3403
683
3.34026
652
3.34021
637
3.34017
660
3.34012
666
3.34008
649
3.34003
652
3.33999
628
3.33994
635
3.3399
659
3.33985
636
3.33981
663
3.33976
672
3.33972
675
3.33968
661
3.33963
643
3.33959
676
3.33954
648
3.3395
687
3.33945
727
3.33941
712
3.33936
651
3.33932
658
3.33927
670
3.33923
679
3.33918
680
3.33914
668
3.33909
675
3.33905
644
3.339
647
3.33896
685
3.33891
677
3.33887
677
3.33882
683
3.33878
694
3.33873
684
3.33869
672
3.33864
662
3.3386
651
3.33855
642
3.33851
658
3.33846
698
3.33842
641
3.33837
680
3.33833
678
3.33829
668
3.33824
648
3.3382
666
3.33815
688
3.33811
708
3.33806
642
3.33802
707
3.33797
688
3.33793
712
3.33788
705
3.33784
695
3.33779
678
3.33775
725
3.3377
674
3.33766
651
3.33761
678
3.33757
668
3.33752
727
3.33748
711
3.33743
691
3.33739
697
3.33734
714
3.3373
707
3.33725
722
3.33721
751
3.33716
700
3.33712
687
3.33707
756
3.33703
762
3.33698
704
3.33694
705
3.3369
781
3.33685
789
3.33681
792
3.33676
781
3.33672
776
3.33667
789
3.33663
830
3.33658
834
3.33654
859
3.33649
845
3.33645
850
3.3364
891
3.33636
934
3.33631
961
3.33627
963
3.33622
1026
3.33618
1000
3.33613
1056
3.33609
1123
3.33604
1165
3.336
1169
3.33595
1216
3.33591
1263
3.33586
1356
3.33582
1381
3.33577
1425
3.33573
1463
3.33568
1586
3.33564
1591
3.3356
1727
3.33555
1834
3.33551
1856
3.33546
1974
3.33542
2077
3.33537
2143
3.33533
2242
3.33528
2392
3.33524
2456
3.33519
2512
3.33515
2703
3.3351
2805
3.33506
2959
3.33501
2975
3.33497
3173
3.33492
3322
3.33488
3350
3.33483
3546
3.33479
3631
3.33474
3767
3.3347
3971
3.33465
4054
3.33461
4106
3.33456
4271
3.33452
4306
3.33447
4436
3.33443
4567
3.33438
4598
3.33434
4664
3.33429
4776
3.33425
4757
3.33421
4687
3.33416
4817
3.33412
4825
3.33407
4779
3.33403
4850
3.33398
4914
3.33394
4784
3.33389
4875
3.33385
4889
3.3338
4704
3.33376
4728
3.33371
4568
3.33367
4496
3.33362
4575
3.33358
4498
3.33353
4434
3.33349
4269
3.33344
4214
3.3334
4166
3.33335
4077
3.33331
3986
3.33326
3951
3.33322
3814
3.33317
3691
3.33313
3543
3.33308
3457
3.33304
3378
3.33299
3192
3.33295
3069
3.3329
2972
3.33286
2802
3.33282
2754
3.33277
2559
3.33273
2584
3.33268
2426
3.33264
2231
3.33259
2142
3.33255
1916
3.3325
1804
3.33246
1774
3.33241
1610
3.33237
1495
3.33232
1424
3.33228
1259
3.33223
1158
3.33219
1107
3.33214
1024
3.3321
993
3.33205
956
3.33201
894
3.33196
822
3.33192
786
3.33187
736
3.33183
719
3.33178
703
3.33174
676
3.33169
679
3.33165
633
3.3316
602
3.33156
604
3.33151
588
3.33147
644
3.33143
612
3.33138
601
3.33134
570
3.33129
585
3.33125
514
3.3312
544
3.33116
581
3.33111
534
3.33107
559
3.33102
560
3.33098
533
3.33093
559
3.33089
559
3.33084
542
3.3308
545
3.33075
581
3.33071
558
3.33066
532
3.33062
578
3.33057
551
3.33053
522
3.33048
548
3.33044
540
3.33039
552
3.33035
523
3.3303
546
3.33026
515
3.33021
543
3.33017
567
3.33012
523
3.33008
521
3.33004
539
3.32999
547
3.32995
521
3.3299
496
3.32986
555
3.32981
528
3.32977
521
3.32972
573
3.32968
514
3.32963
506
3.32959
495
3.32954
498
3.3295
536
3.32945
537
3.32941
511
3.32936
534
3.32932
531
3.32927
531
3.32923
553
3.32918
554
3.32914
539
3.32909
558
3.32905
497
3.329
514
3.32896
508
3.32891
495
3.32887
531
3.32882
555
3.32878
532
3.32873
518
3.32869
505
3.32865
509
3.3286
525
3.32856
537
3.32851
531
3.32847
539
3.32842
523
3.32838
495
3.32833
470
3.32829
479
3.32824
517
3.3282
528
3.32815
531
3.32811
538
3.32806
555
3.32802
550
3.32797
514
3.32793
540
3.32788
522
3.32784
547
3.32779
538
3.32775
512
3.3277
536
3.32766
563
3.32761
532
3.32757
580
3.32752
529
3.32748
514
3.32743
515
3.32739
533
3.32735
521
3.3273
536
3.32726
553
3.32721
519
3.32717
524
3.32712
531
3.32708
503
3.32703
515
3.32699
495
3.32694
523
3.3269
543
3.32685
559
3.32681
549
3.32676
511
3.32672
512
3.32667
500
3.32663
569
3.32658
555
3.32654
495
3.32649
507
3.32645
541
3.3264
562
3.32636
532
3.32631
520
3.32627
513
3.32622
514
3.32618
526
3.32613
542
3.32609
542
3.32604
515
3.326
524
3.32596
541
3.32591
527
3.32587
528
3.32582
518
3.32578
545
3.32573
503
3.32569
C 1s/6
Not Specified
2017
7
4
14
27
29
0
9
Casa Info Follows
1
Calib M = 283.4 A = 284.6 BE ADD
0
0
0
   XPS     Spectrum    Lens Mode:Hybrid   Resolution:Pass energy 40    Iris(Aper):slot(Slot)
   Acqn. Time(s): 138        Sweeps: 2        Anode:Mono(Al (Mono))(150 W)   Step(meV): 50.0
   Dwell Time(ms): 150        Charge Neutraliser :On   Acquired On :17/07/04 14:27:29
XPS
42
7
0
Mono(Al (Mono))
1486.69
150
1e+037
1e+037
6000
6000
1e+037
1e+037
FAT
40
1e+037
-4.45
0
1e+037
1e+037
1e+037
1e+037
C
1s
-1
Kinetic Energy
eV
1190.19
0.05
2
Intensity
d
Transmission
d
pulse counting
0.15
2
0
1e+037
1e+037
1e+037
0
922
93
3270
3.16755
3.19198
318
3.16755
371
3.1676
378
3.16765
399
3.16771
388
3.16776
368
3.16781
355
3.16787
384
3.16792
338
3.16797
355
3.16802
347
3.16808
367
3.16813
358
3.16818
360
3.16824
336
3.16829
349
3.16834
349
3.1684
347
3.16845
350
3.1685
346
3.16856
324
3.16861
335
3.16866
320
3.16871
352
3.16877
345
3.16882
360
3.16887
368
3.16893
350
3.16898
318
3.16903
319
3.16909
329
3.16914
324
3.16919
312
3.16925
329
3.1693
332
3.16935
348
3.16941
308
3.16946
292
3.16951
312
3.16956
304
3.16962
305
3.16967
332
3.16972
302
3.16978
279
3.16983
286
3.16988
287
3.16994
313
3.16999
290
3.17004
274
3.1701
324
3.17015
301
3.1702
288
3.17025
275
3.17031
257
3.17036
285
3.17041
303
3.17047
281
3.17052
281
3.17057
275
3.17063
281
3.17068
286
3.17073
279
3.17079
299
3.17084
285
3.17089
295
3.17095
281
3.171
291
3.17105
289
3.1711
291
3.17116
287
3.17121
298
3.17126
262
3.17132
253
3.17137
260
3.17142
251
3.17148
278
3.17153
286
3.17158
279
3.17164
283
3.17169
258
3.17174
263
3.17179
258
3.17185
289
3.1719
278
3.17195
249
3.17201
244
3.17206
250
3.17211
262
3.17217
259
3.17222
273
3.17227
284
3.17233
267
3.17238
251
3.17243
245
3.17249
260
3.17254
271
3.17259
274
3.17264
279
3.1727
268
3.17275
281
3.1728
279
3.17286
281
3.17291
261
3.17296
241
3.17302
285
3.17307
257
3.17312
272
3.17318
288
3.17323
302
3.17328
283
3.17334
261
3.17339
267
3.17344
284
3.17349
268
3.17355
270
3.1736
236
3.17365
262
3.17371
262
3.17376
278
3.17381
277
3.17387
284
3.17392
274
3.17397
265
3.17403
247
3.17408
276
3.17413
283
3.17418
262
3.17424
280
3.17429
275
3.17434
271
3.1744
291
3.17445
276
3.1745
285
3.17456
307
3.17461
303
3.17466
284
3.17472
292
3.17477
277
3.17482
308
3.17488
314
3.17493
313
3.17498
303
3.17503
321
3.17509
334
3.17514
318
3.17519
322
3.17525
349
3.1753
338
3.17535
340
3.17541
353
3.17546
378
3.17551
414
3.17557
376
3.17562
424
3.17567
427
3.17572
440
3.17578
456
3.17583
455
3.17588
490
3.17594
461
3.17599
502
3.17604
514
3.1761
545
3.17615
514
3.1762
559
3.17626
591
3.17631
657
3.17636
627
3.17642
674
3.17647
691
3.17652
673
3.17657
738
3.17663
761
3.17668
733
3.17673
718
3.17679
771
3.17684
806
3.17689
779
3.17695
841
3.177
824
3.17705
810
3.17711
831
3.17716
873
3.17721
820
3.17726
865
3.17732
857
3.17737
870
3.17742
907
3.17748
872
3.17753
894
3.17758
881
3.17764
898
3.17769
941
3.17774
951
3.1778
952
3.17785
953
3.1779
1009
3.17796
1084
3.17801
1089
3.17806
1123
3.17811
1123
3.17817
1190
3.17822
1196
3.17827
1293
3.17833
1357
3.17838
1458
3.17843
1495
3.17849
1490
3.17854
1560
3.17859
1671
3.17865
1673
3.1787
1712
3.17875
1784
3.17881
1899
3.17886
1929
3.17891
1911
3.17896
1945
3.17902
1990
3.17907
2065
3.17912
1987
3.17918
2003
3.17923
1979
3.17928
2026
3.17934
1975
3.17939
1964
3.17944
1985
3.1795
1903
3.17955
1981
3.1796
1846
3.17965
1908
3.17971
1865
3.17976
1917
3.17981
1905
3.17987
1932
3.17992
1914
3.17997
1921
3.18003
1958
3.18008
2037
3.18013
2079
3.18019
2091
3.18024
2153
3.18029
2172
3.18035
2171
3.1804
2249
3.18045
2314
3.1805
2354
3.18056
2385
3.18061
2517
3.18066
2592
3.18072
2689
3.18077
2672
3.18082
2794
3.18088
2843
3.18093
2933
3.18098
2990
3.18104
2962
3.18109
3023
3.18114
3054
3.1812
3138
3.18125
3166
3.1813
3140
3.18135
3270
3.18141
3243
3.18146
3188
3.18151
3197
3.18157
3097
3.18162
3006
3.18167
2963
3.18173
2851
3.18178
2715
3.18183
2567
3.18189
2439
3.18194
2279
3.18199
2162
3.18204
1988
3.1821
1805
3.18215
1657
3.1822
1509
3.18226
1425
3.18231
1196
3.18236
1122
3.18242
1013
3.18247
966
3.18252
840
3.18258
737
3.18263
646
3.18268
593
3.18274
519
3.18279
442
3.18284
393
3.18289
388
3.18295
328
3.183
316
3.18305
270
3.18311
247
3.18316
227
3.18321
206
3.18327
188
3.18332
206
3.18337
197
3.18343
181
3.18348
176
3.18353
149
3.18358
143
3.18364
144
3.18369
149
3.18374
140
3.1838
151
3.18385
149
3.1839
158
3.18396
148
3.18401
129
3.18406
138
3.18412
140
3.18417
137
3.18422
135
3.18428
123
3.18433
115
3.18438
125
3.18443
131
3.18449
136
3.18454
128
3.18459
135
3.18465
137
3.1847
132
3.18475
129
3.18481
128
3.18486
112
3.18491
130
3.18497
131
3.18502
134
3.18507
120
3.18512
115
3.18518
133
3.18523
130
3.18528
130
3.18534
114
3.18539
121
3.18544
120
3.1855
129
3.18555
124
3.1856
128
3.18566
119
3.18571
141
3.18576
126
3.18582
106
3.18587
120
3.18592
119
3.18597
112
3.18603
117
3.18608
120
3.18613
124
3.18619
136
3.18624
123
3.18629
129
3.18635
111
3.1864
133
3.18645
141
3.18651
133
3.18656
123
3.18661
123
3.18667
130
3.18672
119
3.18677
97
3.18682
125
3.18688
103
3.18693
110
3.18698
109
3.18704
120
3.18709
116
3.18714
126
3.1872
130
3.18725
106
3.1873
123
3.18736
117
3.18741
122
3.18746
112
3.18751
118
3.18757
110
3.18762
108
3.18767
123
3.18773
133
3.18778
115
3.18783
116
3.18789
108
3.18794
129
3.18799
119
3.18805
107
3.1881
112
3.18815
121
3.18821
112
3.18826
107
3.18831
113
3.18836
117
3.18842
118
3.18847
127
3.18852
121
3.18858
138
3.18863
124
3.18868
109
3.18874
120
3.18879
134
3.18884
142
3.1889
122
3.18895
132
3.189
115
3.18905
139
3.18911
123
3.18916
113
3.18921
106
3.18927
107
3.18932
103
3.18937
103
3.18943
110
3.18948
97
3.18953
111
3.18959
119
3.18964
109
3.18969
110
3.18975
110
3.1898
114
3.18985
113
3.1899
108
3.18996
105
3.19001
95
3.19006
109
3.19012
124
3.19017
126
3.19022
117
3.19028
111
3.19033
122
3.19038
107
3.19044
112
3.19049
112
3.19054
130
3.19059
115
3.19065
119
3.1907
103
3.19075
113
3.19081
115
3.19086
123
3.19091
108
3.19097
108
3.19102
121
3.19107
122
3.19113
112
3.19118
128
3.19123
97
3.19129
121
3.19134
119
3.19139
107
3.19144
139
3.1915
111
3.19155
119
3.1916
120
3.19166
111
3.19171
93
3.19176
109
3.19182
114
3.19187
139
3.19192
118
3.19198
end of experiment