File: 2017007296/7296-b4#.csv
[Measurement conditions]
Sample identification,
Comment - 1,"Configuration=Stage for flat samples/holders, Owner=User-1, Creation date=3/27/2015 11:56:23 AM"
Comment - 2,"Goniometer=Theta/Theta; Minimum step size 2Theta:0.0001; Minimum step size Omega:0.0001"
Comment - 3,"Sample stage=Stage for flat samples/holders"
Comment - 4,"Diffractometer system=EMPYREAN"
Comment - 5,"Measurement program=C:\PANalytical\Data Collector\Programs\Powder - Copy.xrdmp, Identifier={BEEA10DD-8FD6-4721-8940-4FBC5A4262A1}"
Comment - 6,"Fine Calibration Offset for 2Theta = -0.0130 deg"
Comment - 7,"Fine Calibration Offset for Omega = -0.0070 deg"
Anode material,Cu
K-Alpha1 wavelength,1.5405980
K-Alpha2 wavelength,1.5444260
Ratio K-Alpha2/K-Alpha1,0.500
Divergence slit,Fixed,0.38mm
Monochromator used,NO
Generator voltage, 40
Tube current, 35
File date and time,24/Jul/2017 16:46
Unit cell,
h k l, 0 0 0
Scan axis,Gonio
Scan range,5.020799997,89.999988363
Scan step size,0.0262606
No. of points, 3236
Scan type,CONTINUOUS
Time per step,18.615
[Scan points]
Angle,Intensity
5.033930280,3306.0
5.112711975,3257.0
5.191493670,3222.0
5.270275365,3163.0
5.349057060,3034.0
5.427838755,3065.0
5.506620450,3037.0
5.585402145,3023.0
5.664183840,3016.0
5.742965535,3057.0
5.821747230,2942.0
5.900528925,3008.0
5.979310620,2832.0
6.058092315,2824.0
6.136874010,2793.0
6.215655705,2752.0
6.294437400,2649.0
6.373219095,2619.0
6.452000790,2705.0
6.530782485,2710.0
6.609564180,2762.0
6.688345875,2535.0
6.767127571,2486.0
6.845909266,2577.0
6.924690961,2542.0
7.003472656,2416.0
7.082254351,2479.0
7.161036046,2409.0
7.239817741,2470.0
7.318599436,2380.0
7.397381131,2452.0
7.476162826,2434.0
7.554944521,2407.0
7.633726216,2241.0
7.712507911,2256.0
7.791289606,2323.0
7.870071301,2207.0
7.948852996,2277.0
8.027634691,2314.0
8.106416386,2241.0
8.185198081,2178.0
8.263979776,2274.0
8.342761471,2135.0
8.421543166,2257.0
8.500324861,2170.0
8.579106556,2143.0
8.657888251,2173.0
8.736669946,2127.0
8.815451641,2192.0
8.894233336,2167.0
8.973015031,2069.0
9.051796726,2078.0
9.130578421,2100.0
9.209360116,2096.0
9.288141811,2071.0
9.366923506,2015.0
9.445705201,2038.0
9.524486896,2091.0
9.603268591,2056.0
9.682050286,1993.0
9.760831981,2091.0
9.839613676,2067.0
9.918395371,1964.0
9.997177066,2066.0
10.075958761,2093.0
10.154740457,2075.0
10.233522152,2080.0
10.312303847,2059.0
10.391085542,1991.0
10.469867237,2018.0
10.548648932,1953.0
10.627430627,2030.0
10.706212322,2077.0
10.784994017,2120.0
10.863775712,1999.0
10.942557407,2012.0
11.021339102,2071.0
11.100120797,2039.0
11.178902492,2044.0
11.257684187,2095.0
11.336465882,2028.0
11.415247577,1990.0
11.494029272,2049.0
11.572810967,2023.0
11.651592662,1931.0
11.730374357,2051.0
11.809156052,2060.0
11.887937747,1941.0
11.966719442,2085.0
12.045501137,2017.0
12.124282832,2048.0
12.203064527,1979.0
12.281846222,2096.0
12.360627917,2077.0
12.439409612,2004.0
12.518191307,2093.0
12.596973002,2036.0
12.675754697,2130.0
12.754536392,2098.0
12.833318087,2086.0
12.912099782,2132.0
12.990881477,2141.0
13.069663172,2080.0
13.148444867,2102.0
13.227226562,2023.0
13.306008257,2042.0
13.384789952,2207.0
13.463571647,2155.0
13.542353343,2097.0
13.621135038,2184.0
13.699916733,2080.0
13.778698428,2193.0
13.857480123,2145.0
13.936261818,2180.0
14.015043513,2167.0
14.093825208,2153.0
14.172606903,2133.0
14.251388598,2115.0
14.330170293,2203.0
14.408951988,2162.0
14.487733683,2192.0
14.566515378,2185.0
14.645297073,2126.0
14.724078768,2172.0
14.802860463,2211.0
14.881642158,2076.0
14.960423853,2172.0
15.039205548,2184.0
15.117987243,2024.0
15.196768938,2052.0
15.275550633,1989.0
15.354332328,1889.0
15.433114023,1822.0
15.511895718,1722.0
15.590677413,1636.0
15.669459108,1534.0
15.748240803,1509.0
15.827022498,1404.0
15.905804193,1384.0
15.984585888,1285.0
16.063367583,1286.0
16.142149278,1236.0
16.220930973,1194.0
16.299712668,1130.0
16.378494363,1109.0
16.457276058,1140.0
16.536057753,1022.0
16.614839448,1022.0
16.693621143,1090.0
16.772402838,1061.0
16.851184533,943.0
16.929966229,972.0
17.008747924,973.0
17.087529619,909.0
17.166311314,915.0
17.245093009,899.0
17.323874704,920.0
17.402656399,895.0
17.481438094,860.0
17.560219789,902.0
17.639001484,824.0
17.717783179,848.0
17.796564874,858.0
17.875346569,881.0
17.954128264,887.0
18.032909959,838.0
18.111691654,803.0
18.190473349,783.0
18.269255044,780.0
18.348036739,791.0
18.426818434,841.0
18.505600129,793.0
18.584381824,747.0
18.663163519,772.0
18.741945214,831.0
18.820726909,801.0
18.899508604,797.0
18.978290299,769.0
19.057071994,775.0
19.135853689,844.0
19.214635384,849.0
19.293417079,782.0
19.372198774,774.0
19.450980469,790.0
19.529762164,751.0
19.608543859,741.0
19.687325554,810.0
19.766107249,749.0
19.844888944,721.0
19.923670639,791.0
20.002452334,786.0
20.081234029,770.0
20.160015724,754.0
20.238797419,741.0
20.317579114,812.0
20.396360810,756.0
20.475142505,793.0
20.553924200,744.0
20.632705895,787.0
20.711487590,757.0
20.790269285,787.0
20.869050980,751.0
20.947832675,761.0
21.026614370,759.0
21.105396065,779.0
21.184177760,751.0
21.262959455,759.0
21.341741150,770.0
21.420522845,773.0
21.499304540,679.0
21.578086235,782.0
21.656867930,736.0
21.735649625,773.0
21.814431320,722.0
21.893213015,752.0
21.971994710,757.0
22.050776405,740.0
22.129558100,759.0
22.208339795,777.0
22.287121490,788.0
22.365903185,780.0
22.444684880,745.0
22.523466575,724.0
22.602248270,763.0
22.681029965,780.0
22.759811660,772.0
22.838593355,737.0
22.917375050,742.0
22.996156745,746.0
23.074938440,752.0
23.153720135,768.0
23.232501830,752.0
23.311283525,742.0
23.390065220,756.0
23.468846915,792.0
23.547628610,713.0
23.626410305,736.0
23.705192000,739.0
23.783973696,732.0
23.862755391,690.0
23.941537086,797.0
24.020318781,752.0
24.099100476,765.0
24.177882171,770.0
24.256663866,724.0
24.335445561,753.0
24.414227256,744.0
24.493008951,773.0
24.571790646,777.0
24.650572341,758.0
24.729354036,699.0
24.808135731,769.0
24.886917426,750.0
24.965699121,691.0
25.044480816,673.0
25.123262511,746.0
25.202044206,803.0
25.280825901,781.0
25.359607596,746.0
25.438389291,756.0
25.517170986,727.0
25.595952681,704.0
25.674734376,725.0
25.753516071,704.0
25.832297766,718.0
25.911079461,740.0
25.989861156,729.0
26.068642851,758.0
26.147424546,713.0
26.226206241,769.0
26.304987936,776.0
26.383769631,710.0
26.462551326,694.0
26.541333021,731.0
26.620114716,731.0
26.698896411,716.0
26.777678106,756.0
26.856459801,735.0
26.935241496,706.0
27.014023191,728.0
27.092804886,707.0
27.171586582,682.0
27.250368277,715.0
27.329149972,721.0
27.407931667,733.0
27.486713362,773.0
27.565495057,671.0
27.644276752,692.0
27.723058447,751.0
27.801840142,706.0
27.880621837,707.0
27.959403532,733.0
28.038185227,736.0
28.116966922,712.0
28.195748617,778.0
28.274530312,689.0
28.353312007,695.0
28.432093702,719.0
28.510875397,720.0
28.589657092,742.0
28.668438787,755.0
28.747220482,691.0
28.826002177,697.0
28.904783872,719.0
28.983565567,711.0
29.062347262,740.0
29.141128957,687.0
29.219910652,671.0
29.298692347,721.0
29.377474042,707.0
29.456255737,658.0
29.535037432,697.0
29.613819127,736.0
29.692600822,691.0
29.771382517,680.0
29.850164212,650.0
29.928945907,736.0
30.007727602,691.0
30.086509297,735.0
30.165290992,726.0
30.244072687,657.0
30.322854382,688.0
30.401636077,722.0
30.480417772,691.0
30.559199468,654.0
30.637981163,659.0
30.716762858,672.0
30.795544553,719.0
30.874326248,647.0
30.953107943,627.0
31.031889638,662.0
31.110671333,670.0
31.189453028,590.0
31.268234723,676.0
31.347016418,619.0
31.425798113,629.0
31.504579808,637.0
31.583361503,633.0
31.662143198,695.0
31.740924893,609.0
31.819706588,594.0
31.898488283,602.0
31.977269978,646.0
32.056051673,607.0
32.134833368,636.0
32.213615063,633.0
32.292396758,597.0
32.371178453,577.0
32.449960148,620.0
32.528741843,572.0
32.607523538,570.0
32.686305233,558.0
32.765086928,613.0
32.843868623,580.0
32.922650318,581.0
33.001432013,568.0
33.080213708,560.0
33.158995403,577.0
33.237777098,594.0
33.316558793,546.0
33.395340488,533.0
33.474122183,547.0
33.552903878,567.0
33.631685573,567.0
33.710467268,598.0
33.789248963,523.0
33.868030658,549.0
33.946812354,532.0
34.025594049,524.0
34.104375744,537.0
34.183157439,533.0
34.261939134,569.0
34.340720829,561.0
34.419502524,542.0
34.498284219,576.0
34.577065914,524.0
34.655847609,502.0
34.734629304,541.0
34.813410999,542.0
34.892192694,537.0
34.970974389,502.0
35.049756084,540.0
35.128537779,576.0
35.207319474,512.0
35.286101169,482.0
35.364882864,491.0
35.443664559,581.0
35.522446254,519.0
35.601227949,537.0
35.680009644,519.0
35.758791339,497.0
35.837573034,532.0
35.916354729,522.0
35.995136424,536.0
36.073918119,514.0
36.152699814,512.0
36.231481509,525.0
36.310263204,548.0
36.389044899,560.0
36.467826594,534.0
36.546608289,568.0
36.625389984,574.0
36.704171679,520.0
36.782953374,522.0
36.861735069,547.0
36.940516764,545.0
37.019298459,493.0
37.098080154,494.0
37.176861849,516.0
37.255643544,533.0
37.334425240,552.0
37.413206935,510.0
37.491988630,524.0
37.570770325,530.0
37.649552020,545.0
37.728333715,549.0
37.807115410,550.0
37.885897105,566.0
37.964678800,579.0
38.043460495,610.0
38.122242190,574.0
38.201023885,598.0
38.279805580,536.0
38.358587275,555.0
38.437368970,564.0
38.516150665,516.0
38.594932360,619.0
38.673714055,633.0
38.752495750,577.0
38.831277445,586.0
38.910059140,616.0
38.988840835,638.0
39.067622530,605.0
39.146404225,667.0
39.225185920,683.0
39.303967615,652.0
39.382749310,636.0
39.461531005,688.0
39.540312700,718.0
39.619094395,792.0
39.697876090,775.0
39.776657785,817.0
39.855439480,865.0
39.934221175,868.0
40.013002870,954.0
40.091784565,982.0
40.170566260,1039.0
40.249347955,1090.0
40.328129650,1193.0
40.406911345,1246.0
40.485693040,1273.0
40.564474735,1352.0
40.643256430,1347.0
40.722038126,1357.0
40.800819821,1353.0
40.879601516,1388.0
40.958383211,1352.0
41.037164906,1320.0
41.115946601,1334.0
41.194728296,1339.0
41.273509991,1354.0
41.352291686,1320.0
41.431073381,1263.0
41.509855076,1298.0
41.588636771,1292.0
41.667418466,1293.0
41.746200161,1187.0
41.824981856,1270.0
41.903763551,1242.0
41.982545246,1249.0
42.061326941,1218.0
42.140108636,1220.0
42.218890331,1204.0
42.297672026,1203.0
42.376453721,1143.0
42.455235416,1093.0
42.534017111,1117.0
42.612798806,1164.0
42.691580501,1125.0
42.770362196,1085.0
42.849143891,1048.0
42.927925586,1013.0
43.006707281,1060.0
43.085488976,1044.0
43.164270671,1011.0
43.243052366,1040.0
43.321834061,914.0
43.400615756,1007.0
43.479397451,926.0
43.558179146,870.0
43.636960841,908.0
43.715742536,883.0
43.794524231,912.0
43.873305926,851.0
43.952087621,878.0
44.030869316,823.0
44.109651011,797.0
44.188432707,827.0
44.267214402,852.0
44.345996097,782.0
44.424777792,808.0
44.503559487,781.0
44.582341182,808.0
44.661122877,730.0
44.739904572,741.0
44.818686267,667.0
44.897467962,634.0
44.976249657,752.0
45.055031352,684.0
45.133813047,737.0
45.212594742,678.0
45.291376437,651.0
45.370158132,639.0
45.448939827,676.0
45.527721522,659.0
45.606503217,617.0
45.685284912,626.0
45.764066607,608.0
45.842848302,596.0
45.921629997,653.0
46.000411692,598.0
46.079193387,588.0
46.157975082,603.0
46.236756777,538.0
46.315538472,602.0
46.394320167,581.0
46.473101862,544.0
46.551883557,581.0
46.630665252,575.0
46.709446947,515.0
46.788228642,526.0
46.867010337,566.0
46.945792032,550.0
47.024573727,499.0
47.103355422,550.0
47.182137117,546.0
47.260918812,524.0
47.339700507,492.0
47.418482202,513.0
47.497263897,489.0
47.576045593,482.0
47.654827288,510.0
47.733608983,508.0
47.812390678,462.0
47.891172373,472.0
47.969954068,432.0
48.048735763,483.0
48.127517458,482.0
48.206299153,470.0
48.285080848,450.0
48.363862543,453.0
48.442644238,466.0
48.521425933,439.0
48.600207628,450.0
48.678989323,438.0
48.757771018,436.0
48.836552713,420.0
48.915334408,398.0
48.994116103,431.0
49.072897798,426.0
49.151679493,478.0
49.230461188,415.0
49.309242883,406.0
49.388024578,383.0
49.466806273,377.0
49.545587968,415.0
49.624369663,429.0
49.703151358,385.0
49.781933053,403.0
49.860714748,372.0
49.939496443,350.0
50.018278138,367.0
50.097059833,393.0
50.175841528,375.0
50.254623223,370.0
50.333404918,370.0
50.412186613,390.0
50.490968308,389.0
50.569750003,361.0
50.648531698,407.0
50.727313393,381.0
50.806095088,427.0
50.884876783,351.0
50.963658479,389.0
51.042440174,372.0
51.121221869,360.0
51.200003564,380.0
51.278785259,345.0
51.357566954,348.0
51.436348649,341.0
51.515130344,352.0
51.593912039,343.0
51.672693734,333.0
51.751475429,382.0
51.830257124,370.0
51.909038819,325.0
51.987820514,345.0
52.066602209,356.0
52.145383904,347.0
52.224165599,334.0
52.302947294,341.0
52.381728989,368.0
52.460510684,350.0
52.539292379,340.0
52.618074074,355.0
52.696855769,369.0
52.775637464,318.0
52.854419159,345.0
52.933200854,337.0
53.011982549,299.0
53.090764244,369.0
53.169545939,336.0
53.248327634,379.0
53.327109329,338.0
53.405891024,363.0
53.484672719,328.0
53.563454414,317.0
53.642236109,343.0
53.721017804,323.0
53.799799499,317.0
53.878581194,323.0
53.957362889,376.0
54.036144584,355.0
54.114926279,346.0
54.193707974,307.0
54.272489669,340.0
54.351271365,328.0
54.430053060,321.0
54.508834755,313.0
54.587616450,371.0
54.666398145,336.0
54.745179840,354.0
54.823961535,314.0
54.902743230,363.0
54.981524925,331.0
55.060306620,310.0
55.139088315,315.0
55.217870010,321.0
55.296651705,299.0
55.375433400,336.0
55.454215095,295.0
55.532996790,309.0
55.611778485,310.0
55.690560180,337.0
55.769341875,312.0
55.848123570,315.0
55.926905265,375.0
56.005686960,324.0
56.084468655,295.0
56.163250350,352.0
56.242032045,310.0
56.320813740,340.0
56.399595435,320.0
56.478377130,321.0
56.557158825,330.0
56.635940520,332.0
56.714722215,315.0
56.793503910,345.0
56.872285605,324.0
56.951067300,324.0
57.029848995,301.0
57.108630690,303.0
57.187412385,312.0
57.266194080,353.0
57.344975775,358.0
57.423757470,330.0
57.502539165,347.0
57.581320860,278.0
57.660102555,333.0
57.738884251,328.0
57.817665946,310.0
57.896447641,296.0
57.975229336,311.0
58.054011031,319.0
58.132792726,275.0
58.211574421,322.0
58.290356116,346.0
58.369137811,315.0
58.447919506,332.0
58.526701201,374.0
58.605482896,281.0
58.684264591,309.0
58.763046286,320.0
58.841827981,316.0
58.920609676,304.0
58.999391371,316.0
59.078173066,301.0
59.156954761,293.0
59.235736456,293.0
59.314518151,300.0
59.393299846,302.0
59.472081541,324.0
59.550863236,296.0
59.629644931,294.0
59.708426626,303.0
59.787208321,314.0
59.865990016,316.0
59.944771711,350.0
60.023553406,326.0
60.102335101,305.0
60.181116796,302.0
60.259898491,300.0
60.338680186,320.0
60.417461881,291.0
60.496243576,322.0
60.575025271,321.0
60.653806966,310.0
60.732588661,293.0
60.811370356,313.0
60.890152051,292.0
60.968933746,311.0
61.047715441,279.0
61.126497137,309.0
61.205278832,309.0
61.284060527,317.0
61.362842222,325.0
61.441623917,293.0
61.520405612,297.0
61.599187307,326.0
61.677969002,292.0
61.756750697,302.0
61.835532392,324.0
61.914314087,335.0
61.993095782,317.0
62.071877477,326.0
62.150659172,312.0
62.229440867,350.0
62.308222562,303.0
62.387004257,283.0
62.465785952,322.0
62.544567647,295.0
62.623349342,300.0
62.702131037,297.0
62.780912732,349.0
62.859694427,371.0
62.938476122,292.0
63.017257817,319.0
63.096039512,301.0
63.174821207,300.0
63.253602902,296.0
63.332384597,312.0
63.411166292,295.0
63.489947987,284.0
63.568729682,262.0
63.647511377,313.0
63.726293072,338.0
63.805074767,317.0
63.883856462,311.0
63.962638157,304.0
64.041419852,313.0
64.120201547,279.0
64.198983242,281.0
64.277764937,297.0
64.356546632,317.0
64.435328327,313.0
64.514110023,273.0
64.592891718,301.0
64.671673413,289.0
64.750455108,261.0
64.829236803,312.0
64.908018498,293.0
64.986800193,304.0
65.065581888,291.0
65.144363583,279.0
65.223145278,279.0
65.301926973,315.0
65.380708668,276.0
65.459490363,255.0
65.538272058,288.0
65.617053753,282.0
65.695835448,256.0
65.774617143,261.0
65.853398838,290.0
65.932180533,268.0
66.010962228,251.0
66.089743923,275.0
66.168525618,288.0
66.247307313,292.0
66.326089008,216.0
66.404870703,254.0
66.483652398,291.0
66.562434093,259.0
66.641215788,278.0
66.719997483,282.0
66.798779178,288.0
66.877560873,302.0
66.956342568,262.0
67.035124263,276.0
67.113905958,293.0
67.192687653,267.0
67.271469348,262.0
67.350251043,249.0
67.429032738,276.0
67.507814433,313.0
67.586596128,267.0
67.665377823,277.0
67.744159518,291.0
67.822941213,236.0
67.901722909,272.0
67.980504604,270.0
68.059286299,248.0
68.138067994,270.0
68.216849689,267.0
68.295631384,263.0
68.374413079,262.0
68.453194774,254.0
68.531976469,209.0
68.610758164,255.0
68.689539859,260.0
68.768321554,261.0
68.847103249,252.0
68.925884944,269.0
69.004666639,267.0
69.083448334,295.0
69.162230029,277.0
69.241011724,239.0
69.319793419,243.0
69.398575114,272.0
69.477356809,254.0
69.556138504,264.0
69.634920199,281.0
69.713701894,250.0
69.792483589,234.0
69.871265284,293.0
69.950046979,249.0
70.028828674,277.0
70.107610369,269.0
70.186392064,247.0
70.265173759,272.0
70.343955454,241.0
70.422737149,241.0
70.501518844,298.0
70.580300539,247.0
70.659082234,271.0
70.737863929,266.0
70.816645624,251.0
70.895427319,259.0
70.974209014,230.0
71.052990709,255.0
71.131772404,271.0
71.210554099,255.0
71.289335794,298.0
71.368117490,243.0
71.446899185,246.0
71.525680880,263.0
71.604462575,260.0
71.683244270,255.0
71.762025965,240.0
71.840807660,247.0
71.919589355,272.0
71.998371050,244.0
72.077152745,251.0
72.155934440,268.0
72.234716135,293.0
72.313497830,309.0
72.392279525,255.0
72.471061220,280.0
72.549842915,269.0
72.628624610,291.0
72.707406305,307.0
72.786188000,290.0
72.864969695,319.0
72.943751390,323.0
73.022533085,326.0
73.101314780,366.0
73.180096475,353.0
73.258878170,306.0
73.337659865,319.0
73.416441560,362.0
73.495223255,414.0
73.574004950,360.0
73.652786645,346.0
73.731568340,315.0
73.810350035,305.0
73.889131730,327.0
73.967913425,349.0
74.046695120,340.0
74.125476815,328.0
74.204258510,315.0
74.283040205,332.0
74.361821900,294.0
74.440603595,298.0
74.519385290,295.0
74.598166985,286.0
74.676948680,275.0
74.755730376,262.0
74.834512071,253.0
74.913293766,292.0
74.992075461,278.0
75.070857156,296.0
75.149638851,277.0
75.228420546,277.0
75.307202241,271.0
75.385983936,285.0
75.464765631,293.0
75.543547326,293.0
75.622329021,245.0
75.701110716,270.0
75.779892411,264.0
75.858674106,254.0
75.937455801,272.0
76.016237496,254.0
76.095019191,246.0
76.173800886,266.0
76.252582581,197.0
76.331364276,244.0
76.410145971,264.0
76.488927666,250.0
76.567709361,258.0
76.646491056,220.0
76.725272751,241.0
76.804054446,264.0
76.882836141,233.0
76.961617836,219.0
77.040399531,229.0
77.119181226,228.0
77.197962921,266.0
77.276744616,234.0
77.355526311,217.0
77.434308006,262.0
77.513089701,257.0
77.591871396,222.0
77.670653091,236.0
77.749434786,258.0
77.828216481,241.0
77.906998176,249.0
77.985779871,241.0
78.064561566,269.0
78.143343262,216.0
78.222124957,276.0
78.300906652,220.0
78.379688347,251.0
78.458470042,208.0
78.537251737,228.0
78.616033432,239.0
78.694815127,224.0
78.773596822,232.0
78.852378517,265.0
78.931160212,236.0
79.009941907,224.0
79.088723602,231.0
79.167505297,248.0
79.246286992,244.0
79.325068687,227.0
79.403850382,225.0
79.482632077,217.0
79.561413772,230.0
79.640195467,238.0
79.718977162,244.0
79.797758857,222.0
79.876540552,227.0
79.955322247,245.0
80.034103942,228.0
80.112885637,243.0
80.191667332,244.0
80.270449027,205.0
80.349230722,224.0
80.428012417,244.0
80.506794112,225.0
80.585575807,247.0
80.664357502,229.0
80.743139197,233.0
80.821920892,217.0
80.900702587,236.0
80.979484282,230.0
81.058265977,222.0
81.137047672,237.0
81.215829367,200.0
81.294611062,198.0
81.373392757,203.0
81.452174452,212.0
81.530956148,235.0
81.609737843,218.0
81.688519538,210.0
81.767301233,220.0
81.846082928,240.0
81.924864623,210.0
82.003646318,207.0
82.082428013,224.0
82.161209708,214.0
82.239991403,225.0
82.318773098,212.0
82.397554793,243.0
82.476336488,220.0
82.555118183,220.0
82.633899878,239.0
82.712681573,206.0
82.791463268,214.0
82.870244963,227.0
82.949026658,208.0
83.027808353,211.0
83.106590048,225.0
83.185371743,228.0
83.264153438,221.0
83.342935133,211.0
83.421716828,190.0
83.500498523,213.0
83.579280218,221.0
83.658061913,200.0
83.736843608,184.0
83.815625303,203.0
83.894406998,206.0
83.973188693,207.0
84.051970388,212.0
84.130752083,229.0
84.209533778,194.0
84.288315473,217.0
84.367097168,218.0
84.445878863,212.0
84.524660558,223.0
84.603442253,226.0
84.682223948,219.0
84.761005643,208.0
84.839787338,221.0
84.918569034,217.0
84.997350729,195.0
85.076132424,218.0
85.154914119,206.0
85.233695814,201.0
85.312477509,191.0
85.391259204,209.0
85.470040899,204.0
85.548822594,210.0
85.627604289,217.0
85.706385984,192.0
85.785167679,234.0
85.863949374,214.0
85.942731069,213.0
86.021512764,216.0
86.100294459,186.0
86.179076154,188.0
86.257857849,215.0
86.336639544,216.0
86.415421239,208.0
86.494202934,237.0
86.572984629,194.0
86.651766324,230.0
86.730548019,192.0
86.809329714,234.0
86.888111409,199.0
86.966893104,206.0
87.045674799,248.0
87.124456494,218.0
87.203238189,245.0
87.282019884,212.0
87.360801579,248.0
87.439583274,222.0
87.518364969,210.0
87.597146664,229.0
87.675928359,233.0
87.754710054,213.0
87.833491749,212.0
87.912273444,218.0
87.991055139,223.0
88.069836834,232.0
88.148618529,207.0
88.227400224,201.0
88.306181920,223.0
88.384963615,216.0
88.463745310,212.0
88.542527005,175.0
88.621308700,209.0
88.700090395,228.0
88.778872090,230.0
88.857653785,212.0
88.936435480,234.0
89.015217175,211.0
89.093998870,206.0
89.172780565,231.0
89.251562260,181.0
89.330343955,218.0
89.409125650,221.0
89.487907345,240.0
89.566689040,206.0
89.645470735,207.0
89.724252430,209.0
89.803034125,198.0
89.881815820,227.0
89.960597515,209.0
89.986858080,198.0