File: 2017007296/7296-a4#.csv
[Measurement conditions]
Sample identification,
Comment - 1,"Configuration=Stage for flat samples/holders, Owner=User-1, Creation date=3/27/2015 11:56:23 AM"
Comment - 2,"Goniometer=Theta/Theta; Minimum step size 2Theta:0.0001; Minimum step size Omega:0.0001"
Comment - 3,"Sample stage=Stage for flat samples/holders"
Comment - 4,"Diffractometer system=EMPYREAN"
Comment - 5,"Measurement program=C:\PANalytical\Data Collector\Programs\Powder - Copy.xrdmp, Identifier={BEEA10DD-8FD6-4721-8940-4FBC5A4262A1}"
Comment - 6,"Fine Calibration Offset for 2Theta = -0.0130 deg"
Comment - 7,"Fine Calibration Offset for Omega = -0.0070 deg"
Anode material,Cu
K-Alpha1 wavelength,1.5405980
K-Alpha2 wavelength,1.5444260
Ratio K-Alpha2/K-Alpha1,0.500
Divergence slit,Fixed,0.38mm
Monochromator used,NO
Generator voltage, 40
Tube current, 35
File date and time,24/Jul/2017 16:14
Unit cell,
h k l, 0 0 0
Scan axis,Gonio
Scan range,5.020799997,89.999988363
Scan step size,0.0262606
No. of points, 3236
Scan type,CONTINUOUS
Time per step,18.615
[Scan points]
Angle,Intensity
5.033930280,1352.0
5.112711975,1410.0
5.191493670,1315.0
5.270275365,1405.0
5.349057060,1342.0
5.427838755,1370.0
5.506620450,1359.0
5.585402145,1397.0
5.664183840,1390.0
5.742965535,1361.0
5.821747230,1315.0
5.900528925,1329.0
5.979310620,1341.0
6.058092315,1370.0
6.136874010,1342.0
6.215655705,1304.0
6.294437400,1341.0
6.373219095,1372.0
6.452000790,1284.0
6.530782485,1366.0
6.609564180,1358.0
6.688345875,1311.0
6.767127571,1346.0
6.845909266,1354.0
6.924690961,1282.0
7.003472656,1276.0
7.082254351,1285.0
7.161036046,1221.0
7.239817741,1267.0
7.318599436,1237.0
7.397381131,1276.0
7.476162826,1269.0
7.554944521,1322.0
7.633726216,1230.0
7.712507911,1274.0
7.791289606,1311.0
7.870071301,1309.0
7.948852996,1285.0
8.027634691,1267.0
8.106416386,1252.0
8.185198081,1299.0
8.263979776,1286.0
8.342761471,1201.0
8.421543166,1282.0
8.500324861,1200.0
8.579106556,1212.0
8.657888251,1236.0
8.736669946,1290.0
8.815451641,1217.0
8.894233336,1145.0
8.973015031,1206.0
9.051796726,1180.0
9.130578421,1138.0
9.209360116,1187.0
9.288141811,1172.0
9.366923506,1133.0
9.445705201,1194.0
9.524486896,1188.0
9.603268591,1176.0
9.682050286,1160.0
9.760831981,1187.0
9.839613676,1211.0
9.918395371,1143.0
9.997177066,1207.0
10.075958761,1210.0
10.154740457,1212.0
10.233522152,1133.0
10.312303847,1175.0
10.391085542,1174.0
10.469867237,1162.0
10.548648932,1162.0
10.627430627,1190.0
10.706212322,1116.0
10.784994017,1183.0
10.863775712,1253.0
10.942557407,1162.0
11.021339102,1141.0
11.100120797,1166.0
11.178902492,1184.0
11.257684187,1085.0
11.336465882,1209.0
11.415247577,1177.0
11.494029272,1257.0
11.572810967,1216.0
11.651592662,1192.0
11.730374357,1208.0
11.809156052,1250.0
11.887937747,1180.0
11.966719442,1156.0
12.045501137,1163.0
12.124282832,1189.0
12.203064527,1174.0
12.281846222,1189.0
12.360627917,1199.0
12.439409612,1190.0
12.518191307,1208.0
12.596973002,1221.0
12.675754697,1187.0
12.754536392,1227.0
12.833318087,1170.0
12.912099782,1177.0
12.990881477,1248.0
13.069663172,1214.0
13.148444867,1252.0
13.227226562,1246.0
13.306008257,1232.0
13.384789952,1226.0
13.463571647,1261.0
13.542353343,1220.0
13.621135038,1221.0
13.699916733,1242.0
13.778698428,1221.0
13.857480123,1261.0
13.936261818,1209.0
14.015043513,1277.0
14.093825208,1258.0
14.172606903,1261.0
14.251388598,1256.0
14.330170293,1244.0
14.408951988,1243.0
14.487733683,1330.0
14.566515378,1242.0
14.645297073,1225.0
14.724078768,1175.0
14.802860463,1287.0
14.881642158,1282.0
14.960423853,1268.0
15.039205548,1200.0
15.117987243,1277.0
15.196768938,1198.0
15.275550633,1131.0
15.354332328,1204.0
15.433114023,1175.0
15.511895718,1058.0
15.590677413,1054.0
15.669459108,1068.0
15.748240803,1012.0
15.827022498,1009.0
15.905804193,980.0
15.984585888,958.0
16.063367583,948.0
16.142149278,967.0
16.220930973,924.0
16.299712668,983.0
16.378494363,958.0
16.457276058,913.0
16.536057753,970.0
16.614839448,908.0
16.693621143,947.0
16.772402838,956.0
16.851184533,868.0
16.929966229,847.0
17.008747924,929.0
17.087529619,952.0
17.166311314,959.0
17.245093009,848.0
17.323874704,875.0
17.402656399,921.0
17.481438094,891.0
17.560219789,915.0
17.639001484,908.0
17.717783179,944.0
17.796564874,877.0
17.875346569,866.0
17.954128264,822.0
18.032909959,861.0
18.111691654,830.0
18.190473349,869.0
18.269255044,832.0
18.348036739,837.0
18.426818434,868.0
18.505600129,824.0
18.584381824,839.0
18.663163519,834.0
18.741945214,880.0
18.820726909,911.0
18.899508604,909.0
18.978290299,867.0
19.057071994,857.0
19.135853689,828.0
19.214635384,913.0
19.293417079,888.0
19.372198774,856.0
19.450980469,834.0
19.529762164,800.0
19.608543859,860.0
19.687325554,854.0
19.766107249,839.0
19.844888944,883.0
19.923670639,810.0
20.002452334,812.0
20.081234029,856.0
20.160015724,832.0
20.238797419,811.0
20.317579114,881.0
20.396360810,879.0
20.475142505,895.0
20.553924200,848.0
20.632705895,830.0
20.711487590,856.0
20.790269285,894.0
20.869050980,910.0
20.947832675,818.0
21.026614370,920.0
21.105396065,876.0
21.184177760,870.0
21.262959455,841.0
21.341741150,888.0
21.420522845,877.0
21.499304540,860.0
21.578086235,814.0
21.656867930,865.0
21.735649625,875.0
21.814431320,860.0
21.893213015,955.0
21.971994710,868.0
22.050776405,843.0
22.129558100,945.0
22.208339795,891.0
22.287121490,868.0
22.365903185,878.0
22.444684880,864.0
22.523466575,882.0
22.602248270,899.0
22.681029965,876.0
22.759811660,842.0
22.838593355,893.0
22.917375050,882.0
22.996156745,831.0
23.074938440,904.0
23.153720135,879.0
23.232501830,865.0
23.311283525,871.0
23.390065220,921.0
23.468846915,938.0
23.547628610,900.0
23.626410305,858.0
23.705192000,918.0
23.783973696,914.0
23.862755391,919.0
23.941537086,896.0
24.020318781,932.0
24.099100476,955.0
24.177882171,944.0
24.256663866,873.0
24.335445561,905.0
24.414227256,868.0
24.493008951,909.0
24.571790646,932.0
24.650572341,884.0
24.729354036,955.0
24.808135731,933.0
24.886917426,911.0
24.965699121,867.0
25.044480816,899.0
25.123262511,890.0
25.202044206,942.0
25.280825901,866.0
25.359607596,836.0
25.438389291,968.0
25.517170986,867.0
25.595952681,858.0
25.674734376,910.0
25.753516071,912.0
25.832297766,849.0
25.911079461,869.0
25.989861156,903.0
26.068642851,885.0
26.147424546,892.0
26.226206241,897.0
26.304987936,952.0
26.383769631,925.0
26.462551326,934.0
26.541333021,894.0
26.620114716,902.0
26.698896411,901.0
26.777678106,880.0
26.856459801,914.0
26.935241496,947.0
27.014023191,881.0
27.092804886,867.0
27.171586582,925.0
27.250368277,963.0
27.329149972,926.0
27.407931667,901.0
27.486713362,908.0
27.565495057,914.0
27.644276752,879.0
27.723058447,934.0
27.801840142,941.0
27.880621837,920.0
27.959403532,878.0
28.038185227,860.0
28.116966922,836.0
28.195748617,938.0
28.274530312,898.0
28.353312007,933.0
28.432093702,941.0
28.510875397,948.0
28.589657092,917.0
28.668438787,926.0
28.747220482,921.0
28.826002177,912.0
28.904783872,937.0
28.983565567,891.0
29.062347262,940.0
29.141128957,899.0
29.219910652,881.0
29.298692347,843.0
29.377474042,916.0
29.456255737,884.0
29.535037432,806.0
29.613819127,947.0
29.692600822,868.0
29.771382517,862.0
29.850164212,862.0
29.928945907,876.0
30.007727602,938.0
30.086509297,852.0
30.165290992,875.0
30.244072687,869.0
30.322854382,849.0
30.401636077,801.0
30.480417772,857.0
30.559199468,869.0
30.637981163,862.0
30.716762858,879.0
30.795544553,774.0
30.874326248,849.0
30.953107943,829.0
31.031889638,858.0
31.110671333,873.0
31.189453028,881.0
31.268234723,848.0
31.347016418,856.0
31.425798113,816.0
31.504579808,828.0
31.583361503,807.0
31.662143198,832.0
31.740924893,834.0
31.819706588,813.0
31.898488283,752.0
31.977269978,844.0
32.056051673,818.0
32.134833368,741.0
32.213615063,793.0
32.292396758,857.0
32.371178453,825.0
32.449960148,791.0
32.528741843,795.0
32.607523538,789.0
32.686305233,783.0
32.765086928,755.0
32.843868623,770.0
32.922650318,815.0
33.001432013,838.0
33.080213708,748.0
33.158995403,749.0
33.237777098,802.0
33.316558793,782.0
33.395340488,750.0
33.474122183,819.0
33.552903878,728.0
33.631685573,719.0
33.710467268,779.0
33.789248963,757.0
33.868030658,735.0
33.946812354,760.0
34.025594049,770.0
34.104375744,758.0
34.183157439,719.0
34.261939134,728.0
34.340720829,742.0
34.419502524,777.0
34.498284219,735.0
34.577065914,713.0
34.655847609,701.0
34.734629304,692.0
34.813410999,750.0
34.892192694,805.0
34.970974389,721.0
35.049756084,717.0
35.128537779,788.0
35.207319474,788.0
35.286101169,758.0
35.364882864,684.0
35.443664559,763.0
35.522446254,719.0
35.601227949,720.0
35.680009644,743.0
35.758791339,711.0
35.837573034,734.0
35.916354729,734.0
35.995136424,744.0
36.073918119,757.0
36.152699814,733.0
36.231481509,708.0
36.310263204,698.0
36.389044899,710.0
36.467826594,657.0
36.546608289,738.0
36.625389984,748.0
36.704171679,677.0
36.782953374,733.0
36.861735069,660.0
36.940516764,759.0
37.019298459,695.0
37.098080154,751.0
37.176861849,745.0
37.255643544,762.0
37.334425240,709.0
37.413206935,750.0
37.491988630,705.0
37.570770325,729.0
37.649552020,712.0
37.728333715,707.0
37.807115410,676.0
37.885897105,724.0
37.964678800,726.0
38.043460495,728.0
38.122242190,708.0
38.201023885,775.0
38.279805580,693.0
38.358587275,783.0
38.437368970,741.0
38.516150665,749.0
38.594932360,737.0
38.673714055,790.0
38.752495750,775.0
38.831277445,828.0
38.910059140,798.0
38.988840835,778.0
39.067622530,821.0
39.146404225,804.0
39.225185920,800.0
39.303967615,884.0
39.382749310,808.0
39.461531005,851.0
39.540312700,833.0
39.619094395,878.0
39.697876090,942.0
39.776657785,932.0
39.855439480,982.0
39.934221175,1076.0
40.013002870,993.0
40.091784565,1025.0
40.170566260,1155.0
40.249347955,1202.0
40.328129650,1209.0
40.406911345,1235.0
40.485693040,1296.0
40.564474735,1251.0
40.643256430,1266.0
40.722038126,1312.0
40.800819821,1293.0
40.879601516,1284.0
40.958383211,1274.0
41.037164906,1304.0
41.115946601,1238.0
41.194728296,1305.0
41.273509991,1280.0
41.352291686,1248.0
41.431073381,1209.0
41.509855076,1202.0
41.588636771,1217.0
41.667418466,1199.0
41.746200161,1200.0
41.824981856,1215.0
41.903763551,1130.0
41.982545246,1188.0
42.061326941,1169.0
42.140108636,1209.0
42.218890331,1137.0
42.297672026,1130.0
42.376453721,1134.0
42.455235416,1073.0
42.534017111,1151.0
42.612798806,1129.0
42.691580501,1101.0
42.770362196,968.0
42.849143891,1064.0
42.927925586,1051.0
43.006707281,1019.0
43.085488976,986.0
43.164270671,1013.0
43.243052366,929.0
43.321834061,1012.0
43.400615756,994.0
43.479397451,977.0
43.558179146,970.0
43.636960841,969.0
43.715742536,972.0
43.794524231,946.0
43.873305926,891.0
43.952087621,896.0
44.030869316,966.0
44.109651011,896.0
44.188432707,912.0
44.267214402,930.0
44.345996097,885.0
44.424777792,903.0
44.503559487,834.0
44.582341182,811.0
44.661122877,884.0
44.739904572,846.0
44.818686267,873.0
44.897467962,793.0
44.976249657,798.0
45.055031352,809.0
45.133813047,835.0
45.212594742,815.0
45.291376437,751.0
45.370158132,727.0
45.448939827,799.0
45.527721522,783.0
45.606503217,774.0
45.685284912,773.0
45.764066607,772.0
45.842848302,769.0
45.921629997,767.0
46.000411692,760.0
46.079193387,759.0
46.157975082,732.0
46.236756777,759.0
46.315538472,700.0
46.394320167,658.0
46.473101862,688.0
46.551883557,684.0
46.630665252,737.0
46.709446947,717.0
46.788228642,661.0
46.867010337,656.0
46.945792032,742.0
47.024573727,697.0
47.103355422,729.0
47.182137117,671.0
47.260918812,673.0
47.339700507,689.0
47.418482202,741.0
47.497263897,640.0
47.576045593,700.0
47.654827288,675.0
47.733608983,662.0
47.812390678,629.0
47.891172373,642.0
47.969954068,624.0
48.048735763,657.0
48.127517458,619.0
48.206299153,664.0
48.285080848,620.0
48.363862543,606.0
48.442644238,594.0
48.521425933,606.0
48.600207628,601.0
48.678989323,621.0
48.757771018,674.0
48.836552713,612.0
48.915334408,578.0
48.994116103,629.0
49.072897798,594.0
49.151679493,600.0
49.230461188,592.0
49.309242883,619.0
49.388024578,614.0
49.466806273,613.0
49.545587968,594.0
49.624369663,617.0
49.703151358,575.0
49.781933053,578.0
49.860714748,609.0
49.939496443,554.0
50.018278138,599.0
50.097059833,586.0
50.175841528,567.0
50.254623223,592.0
50.333404918,574.0
50.412186613,544.0
50.490968308,568.0
50.569750003,549.0
50.648531698,567.0
50.727313393,551.0
50.806095088,564.0
50.884876783,601.0
50.963658479,622.0
51.042440174,582.0
51.121221869,523.0
51.200003564,580.0
51.278785259,563.0
51.357566954,561.0
51.436348649,613.0
51.515130344,563.0
51.593912039,564.0
51.672693734,594.0
51.751475429,523.0
51.830257124,544.0
51.909038819,592.0
51.987820514,528.0
52.066602209,587.0
52.145383904,566.0
52.224165599,550.0
52.302947294,534.0
52.381728989,611.0
52.460510684,593.0
52.539292379,572.0
52.618074074,517.0
52.696855769,556.0
52.775637464,562.0
52.854419159,514.0
52.933200854,589.0
53.011982549,566.0
53.090764244,543.0
53.169545939,604.0
53.248327634,541.0
53.327109329,591.0
53.405891024,532.0
53.484672719,544.0
53.563454414,531.0
53.642236109,532.0
53.721017804,560.0
53.799799499,562.0
53.878581194,566.0
53.957362889,521.0
54.036144584,599.0
54.114926279,547.0
54.193707974,547.0
54.272489669,546.0
54.351271365,551.0
54.430053060,571.0
54.508834755,556.0
54.587616450,538.0
54.666398145,577.0
54.745179840,578.0
54.823961535,581.0
54.902743230,533.0
54.981524925,543.0
55.060306620,518.0
55.139088315,601.0
55.217870010,563.0
55.296651705,532.0
55.375433400,563.0
55.454215095,560.0
55.532996790,527.0
55.611778485,549.0
55.690560180,527.0
55.769341875,522.0
55.848123570,533.0
55.926905265,572.0
56.005686960,526.0
56.084468655,488.0
56.163250350,536.0
56.242032045,499.0
56.320813740,509.0
56.399595435,508.0
56.478377130,525.0
56.557158825,524.0
56.635940520,527.0
56.714722215,557.0
56.793503910,505.0
56.872285605,530.0
56.951067300,505.0
57.029848995,549.0
57.108630690,491.0
57.187412385,502.0
57.266194080,512.0
57.344975775,514.0
57.423757470,552.0
57.502539165,504.0
57.581320860,522.0
57.660102555,499.0
57.738884251,490.0
57.817665946,527.0
57.896447641,526.0
57.975229336,545.0
58.054011031,555.0
58.132792726,496.0
58.211574421,551.0
58.290356116,516.0
58.369137811,513.0
58.447919506,512.0
58.526701201,566.0
58.605482896,528.0
58.684264591,484.0
58.763046286,527.0
58.841827981,543.0
58.920609676,532.0
58.999391371,492.0
59.078173066,510.0
59.156954761,503.0
59.235736456,488.0
59.314518151,483.0
59.393299846,501.0
59.472081541,504.0
59.550863236,503.0
59.629644931,534.0
59.708426626,559.0
59.787208321,501.0
59.865990016,504.0
59.944771711,533.0
60.023553406,482.0
60.102335101,511.0
60.181116796,488.0
60.259898491,509.0
60.338680186,487.0
60.417461881,504.0
60.496243576,497.0
60.575025271,511.0
60.653806966,562.0
60.732588661,478.0
60.811370356,516.0
60.890152051,461.0
60.968933746,481.0
61.047715441,470.0
61.126497137,516.0
61.205278832,460.0
61.284060527,477.0
61.362842222,499.0
61.441623917,464.0
61.520405612,491.0
61.599187307,483.0
61.677969002,474.0
61.756750697,512.0
61.835532392,520.0
61.914314087,531.0
61.993095782,479.0
62.071877477,508.0
62.150659172,538.0
62.229440867,484.0
62.308222562,553.0
62.387004257,511.0
62.465785952,532.0
62.544567647,499.0
62.623349342,491.0
62.702131037,485.0
62.780912732,495.0
62.859694427,522.0
62.938476122,477.0
63.017257817,517.0
63.096039512,487.0
63.174821207,507.0
63.253602902,479.0
63.332384597,510.0
63.411166292,483.0
63.489947987,503.0
63.568729682,486.0
63.647511377,490.0
63.726293072,502.0
63.805074767,463.0
63.883856462,475.0
63.962638157,437.0
64.041419852,505.0
64.120201547,516.0
64.198983242,515.0
64.277764937,468.0
64.356546632,479.0
64.435328327,464.0
64.514110023,515.0
64.592891718,459.0
64.671673413,494.0
64.750455108,486.0
64.829236803,517.0
64.908018498,486.0
64.986800193,463.0
65.065581888,497.0
65.144363583,479.0
65.223145278,485.0
65.301926973,478.0
65.380708668,487.0
65.459490363,490.0
65.538272058,493.0
65.617053753,479.0
65.695835448,510.0
65.774617143,480.0
65.853398838,473.0
65.932180533,453.0
66.010962228,504.0
66.089743923,435.0
66.168525618,477.0
66.247307313,467.0
66.326089008,489.0
66.404870703,451.0
66.483652398,478.0
66.562434093,465.0
66.641215788,466.0
66.719997483,491.0
66.798779178,453.0
66.877560873,477.0
66.956342568,471.0
67.035124263,467.0
67.113905958,490.0
67.192687653,479.0
67.271469348,504.0
67.350251043,480.0
67.429032738,464.0
67.507814433,471.0
67.586596128,466.0
67.665377823,480.0
67.744159518,447.0
67.822941213,468.0
67.901722909,444.0
67.980504604,465.0
68.059286299,441.0
68.138067994,436.0
68.216849689,458.0
68.295631384,463.0
68.374413079,452.0
68.453194774,460.0
68.531976469,473.0
68.610758164,448.0
68.689539859,444.0
68.768321554,474.0
68.847103249,466.0
68.925884944,475.0
69.004666639,465.0
69.083448334,430.0
69.162230029,468.0
69.241011724,445.0
69.319793419,452.0
69.398575114,466.0
69.477356809,475.0
69.556138504,430.0
69.634920199,503.0
69.713701894,473.0
69.792483589,493.0
69.871265284,454.0
69.950046979,430.0
70.028828674,440.0
70.107610369,512.0
70.186392064,466.0
70.265173759,444.0
70.343955454,436.0
70.422737149,455.0
70.501518844,481.0
70.580300539,423.0
70.659082234,468.0
70.737863929,433.0
70.816645624,475.0
70.895427319,406.0
70.974209014,452.0
71.052990709,453.0
71.131772404,446.0
71.210554099,480.0
71.289335794,476.0
71.368117490,470.0
71.446899185,473.0
71.525680880,460.0
71.604462575,475.0
71.683244270,438.0
71.762025965,448.0
71.840807660,445.0
71.919589355,447.0
71.998371050,475.0
72.077152745,477.0
72.155934440,497.0
72.234716135,501.0
72.313497830,473.0
72.392279525,487.0
72.471061220,449.0
72.549842915,455.0
72.628624610,511.0
72.707406305,483.0
72.786188000,435.0
72.864969695,528.0
72.943751390,512.0
73.022533085,497.0
73.101314780,485.0
73.180096475,562.0
73.258878170,512.0
73.337659865,516.0
73.416441560,541.0
73.495223255,536.0
73.574004950,544.0
73.652786645,558.0
73.731568340,534.0
73.810350035,519.0
73.889131730,474.0
73.967913425,512.0
74.046695120,506.0
74.125476815,473.0
74.204258510,526.0
74.283040205,534.0
74.361821900,487.0
74.440603595,487.0
74.519385290,482.0
74.598166985,514.0
74.676948680,493.0
74.755730376,471.0
74.834512071,504.0
74.913293766,449.0
74.992075461,449.0
75.070857156,446.0
75.149638851,461.0
75.228420546,502.0
75.307202241,459.0
75.385983936,458.0
75.464765631,503.0
75.543547326,474.0
75.622329021,457.0
75.701110716,468.0
75.779892411,450.0
75.858674106,457.0
75.937455801,465.0
76.016237496,441.0
76.095019191,482.0
76.173800886,453.0
76.252582581,446.0
76.331364276,434.0
76.410145971,495.0
76.488927666,417.0
76.567709361,397.0
76.646491056,461.0
76.725272751,428.0
76.804054446,460.0
76.882836141,440.0
76.961617836,449.0
77.040399531,431.0
77.119181226,476.0
77.197962921,478.0
77.276744616,469.0
77.355526311,470.0
77.434308006,483.0
77.513089701,455.0
77.591871396,430.0
77.670653091,448.0
77.749434786,424.0
77.828216481,465.0
77.906998176,476.0
77.985779871,446.0
78.064561566,442.0
78.143343262,429.0
78.222124957,452.0
78.300906652,413.0
78.379688347,430.0
78.458470042,452.0
78.537251737,471.0
78.616033432,407.0
78.694815127,443.0
78.773596822,411.0
78.852378517,423.0
78.931160212,456.0
79.009941907,434.0
79.088723602,466.0
79.167505297,448.0
79.246286992,456.0
79.325068687,422.0
79.403850382,398.0
79.482632077,434.0
79.561413772,446.0
79.640195467,428.0
79.718977162,421.0
79.797758857,463.0
79.876540552,435.0
79.955322247,438.0
80.034103942,428.0
80.112885637,454.0
80.191667332,459.0
80.270449027,413.0
80.349230722,420.0
80.428012417,444.0
80.506794112,398.0
80.585575807,432.0
80.664357502,422.0
80.743139197,462.0
80.821920892,430.0
80.900702587,435.0
80.979484282,448.0
81.058265977,404.0
81.137047672,430.0
81.215829367,439.0
81.294611062,447.0
81.373392757,451.0
81.452174452,447.0
81.530956148,449.0
81.609737843,441.0
81.688519538,427.0
81.767301233,421.0
81.846082928,425.0
81.924864623,408.0
82.003646318,398.0
82.082428013,412.0
82.161209708,422.0
82.239991403,428.0
82.318773098,424.0
82.397554793,442.0
82.476336488,399.0
82.555118183,425.0
82.633899878,457.0
82.712681573,431.0
82.791463268,411.0
82.870244963,417.0
82.949026658,423.0
83.027808353,434.0
83.106590048,442.0
83.185371743,433.0
83.264153438,410.0
83.342935133,414.0
83.421716828,431.0
83.500498523,451.0
83.579280218,387.0
83.658061913,423.0
83.736843608,426.0
83.815625303,437.0
83.894406998,431.0
83.973188693,397.0
84.051970388,429.0
84.130752083,383.0
84.209533778,426.0
84.288315473,386.0
84.367097168,399.0
84.445878863,397.0
84.524660558,384.0
84.603442253,417.0
84.682223948,401.0
84.761005643,418.0
84.839787338,407.0
84.918569034,437.0
84.997350729,363.0
85.076132424,406.0
85.154914119,399.0
85.233695814,427.0
85.312477509,394.0
85.391259204,430.0
85.470040899,434.0
85.548822594,429.0
85.627604289,386.0
85.706385984,394.0
85.785167679,421.0
85.863949374,401.0
85.942731069,392.0
86.021512764,385.0
86.100294459,425.0
86.179076154,428.0
86.257857849,443.0
86.336639544,400.0
86.415421239,406.0
86.494202934,423.0
86.572984629,421.0
86.651766324,403.0
86.730548019,434.0
86.809329714,391.0
86.888111409,409.0
86.966893104,418.0
87.045674799,431.0
87.124456494,439.0
87.203238189,401.0
87.282019884,458.0
87.360801579,431.0
87.439583274,403.0
87.518364969,448.0
87.597146664,425.0
87.675928359,459.0
87.754710054,419.0
87.833491749,432.0
87.912273444,451.0
87.991055139,413.0
88.069836834,446.0
88.148618529,468.0
88.227400224,434.0
88.306181920,407.0
88.384963615,440.0
88.463745310,445.0
88.542527005,455.0
88.621308700,425.0
88.700090395,426.0
88.778872090,417.0
88.857653785,405.0
88.936435480,414.0
89.015217175,443.0
89.093998870,437.0
89.172780565,413.0
89.251562260,421.0
89.330343955,418.0
89.409125650,442.0
89.487907345,415.0
89.566689040,413.0
89.645470735,419.0
89.724252430,441.0
89.803034125,401.0
89.881815820,468.0
89.960597515,382.0
89.986858080,466.0