File: 2017007296/7296-a1.csv
[Measurement conditions]
Sample identification,
Comment - 1,"Configuration=Stage for flat samples/holders, Owner=User-1, Creation date=3/27/2015 11:56:23 AM"
Comment - 2,"Goniometer=Theta/Theta; Minimum step size 2Theta:0.0001; Minimum step size Omega:0.0001"
Comment - 3,"Sample stage=Stage for flat samples/holders"
Comment - 4,"Diffractometer system=EMPYREAN"
Comment - 5,"Measurement program=C:\PANalytical\Data Collector\Programs\Powder - Copy.xrdmp, Identifier={BEEA10DD-8FD6-4721-8940-4FBC5A4262A1}"
Comment - 6,"Fine Calibration Offset for 2Theta = -0.0130 deg"
Comment - 7,"Fine Calibration Offset for Omega = -0.0070 deg"
Anode material,Cu
K-Alpha1 wavelength,1.5405980
K-Alpha2 wavelength,1.5444260
Ratio K-Alpha2/K-Alpha1,0.500
Divergence slit,Fixed,0.38mm
Monochromator used,NO
Generator voltage, 40
Tube current, 35
File date and time,24/Jul/2017 15:55
Unit cell,
h k l, 0 0 0
Scan axis,Gonio
Scan range,5.020799997,89.999988363
Scan step size,0.0262606
No. of points, 3236
Scan type,CONTINUOUS
Time per step,18.615
[Scan points]
Angle,Intensity
5.033930280,1863.0
5.112711975,1927.0
5.191493670,2045.0
5.270275365,1882.0
5.349057060,2027.0
5.427838755,2044.0
5.506620450,1942.0
5.585402145,1943.0
5.664183840,1975.0
5.742965535,1939.0
5.821747230,1901.0
5.900528925,1981.0
5.979310620,1930.0
6.058092315,1949.0
6.136874010,1889.0
6.215655705,1906.0
6.294437400,1948.0
6.373219095,2047.0
6.452000790,2018.0
6.530782485,2004.0
6.609564180,1952.0
6.688345875,1856.0
6.767127571,2003.0
6.845909266,2019.0
6.924690961,1934.0
7.003472656,1955.0
7.082254351,1972.0
7.161036046,1916.0
7.239817741,2041.0
7.318599436,1967.0
7.397381131,2096.0
7.476162826,1950.0
7.554944521,2068.0
7.633726216,2050.0
7.712507911,2038.0
7.791289606,2105.0
7.870071301,2136.0
7.948852996,2100.0
8.027634691,2120.0
8.106416386,2164.0
8.185198081,2133.0
8.263979776,2216.0
8.342761471,2251.0
8.421543166,2231.0
8.500324861,2340.0
8.579106556,2363.0
8.657888251,2457.0
8.736669946,2458.0
8.815451641,2438.0
8.894233336,2736.0
8.973015031,2603.0
9.051796726,2752.0
9.130578421,2901.0
9.209360116,3049.0
9.288141811,3256.0
9.366923506,3305.0
9.445705201,3371.0
9.524486896,3312.0
9.603268591,3246.0
9.682050286,3253.0
9.760831981,3063.0
9.839613676,2963.0
9.918395371,2788.0
9.997177066,2731.0
10.075958761,2594.0
10.154740457,2432.0
10.233522152,2366.0
10.312303847,2289.0
10.391085542,2274.0
10.469867237,2252.0
10.548648932,2075.0
10.627430627,2008.0
10.706212322,2054.0
10.784994017,1902.0
10.863775712,1909.0
10.942557407,1840.0
11.021339102,1862.0
11.100120797,1837.0
11.178902492,1808.0
11.257684187,1749.0
11.336465882,1813.0
11.415247577,1705.0
11.494029272,1725.0
11.572810967,1713.0
11.651592662,1601.0
11.730374357,1638.0
11.809156052,1566.0
11.887937747,1754.0
11.966719442,1547.0
12.045501137,1554.0
12.124282832,1647.0
12.203064527,1559.0
12.281846222,1526.0
12.360627917,1542.0
12.439409612,1459.0
12.518191307,1497.0
12.596973002,1537.0
12.675754697,1471.0
12.754536392,1453.0
12.833318087,1507.0
12.912099782,1522.0
12.990881477,1540.0
13.069663172,1458.0
13.148444867,1456.0
13.227226562,1382.0
13.306008257,1378.0
13.384789952,1406.0
13.463571647,1391.0
13.542353343,1457.0
13.621135038,1387.0
13.699916733,1390.0
13.778698428,1502.0
13.857480123,1388.0
13.936261818,1407.0
14.015043513,1382.0
14.093825208,1372.0
14.172606903,1390.0
14.251388598,1381.0
14.330170293,1343.0
14.408951988,1422.0
14.487733683,1367.0
14.566515378,1371.0
14.645297073,1291.0
14.724078768,1350.0
14.802860463,1339.0
14.881642158,1322.0
14.960423853,1372.0
15.039205548,1300.0
15.117987243,1330.0
15.196768938,1242.0
15.275550633,1274.0
15.354332328,1249.0
15.433114023,1313.0
15.511895718,1207.0
15.590677413,1250.0
15.669459108,1226.0
15.748240803,1280.0
15.827022498,1255.0
15.905804193,1192.0
15.984585888,1173.0
16.063367583,1213.0
16.142149278,1252.0
16.220930973,1251.0
16.299712668,1266.0
16.378494363,1204.0
16.457276058,1146.0
16.536057753,1171.0
16.614839448,1141.0
16.693621143,1157.0
16.772402838,1116.0
16.851184533,1205.0
16.929966229,1130.0
17.008747924,1125.0
17.087529619,1123.0
17.166311314,1125.0
17.245093009,1181.0
17.323874704,1103.0
17.402656399,1140.0
17.481438094,1131.0
17.560219789,1158.0
17.639001484,1112.0
17.717783179,1199.0
17.796564874,1161.0
17.875346569,1166.0
17.954128264,1080.0
18.032909959,1073.0
18.111691654,1141.0
18.190473349,1202.0
18.269255044,1121.0
18.348036739,1125.0
18.426818434,1116.0
18.505600129,1087.0
18.584381824,1124.0
18.663163519,1121.0
18.741945214,1109.0
18.820726909,1102.0
18.899508604,1145.0
18.978290299,1129.0
19.057071994,1058.0
19.135853689,1171.0
19.214635384,1090.0
19.293417079,1143.0
19.372198774,1082.0
19.450980469,1113.0
19.529762164,1084.0
19.608543859,1079.0
19.687325554,1119.0
19.766107249,1111.0
19.844888944,1109.0
19.923670639,1100.0
20.002452334,1098.0
20.081234029,1131.0
20.160015724,1186.0
20.238797419,1119.0
20.317579114,1055.0
20.396360810,1051.0
20.475142505,1021.0
20.553924200,1151.0
20.632705895,1145.0
20.711487590,1089.0
20.790269285,1142.0
20.869050980,1144.0
20.947832675,1087.0
21.026614370,1047.0
21.105396065,1118.0
21.184177760,1083.0
21.262959455,1065.0
21.341741150,1072.0
21.420522845,1117.0
21.499304540,1069.0
21.578086235,1088.0
21.656867930,1002.0
21.735649625,1090.0
21.814431320,1063.0
21.893213015,1022.0
21.971994710,1119.0
22.050776405,1085.0
22.129558100,1087.0
22.208339795,1096.0
22.287121490,1088.0
22.365903185,1097.0
22.444684880,1073.0
22.523466575,1058.0
22.602248270,1043.0
22.681029965,1096.0
22.759811660,1054.0
22.838593355,1065.0
22.917375050,1089.0
22.996156745,1092.0
23.074938440,1030.0
23.153720135,1045.0
23.232501830,1097.0
23.311283525,1069.0
23.390065220,1105.0
23.468846915,1074.0
23.547628610,1057.0
23.626410305,1024.0
23.705192000,1045.0
23.783973696,1043.0
23.862755391,1102.0
23.941537086,1170.0
24.020318781,1112.0
24.099100476,1052.0
24.177882171,1036.0
24.256663866,1036.0
24.335445561,1154.0
24.414227256,1142.0
24.493008951,1032.0
24.571790646,1057.0
24.650572341,1035.0
24.729354036,1071.0
24.808135731,1078.0
24.886917426,1054.0
24.965699121,1072.0
25.044480816,1021.0
25.123262511,1156.0
25.202044206,1053.0
25.280825901,1022.0
25.359607596,1077.0
25.438389291,1059.0
25.517170986,1082.0
25.595952681,1039.0
25.674734376,1001.0
25.753516071,1022.0
25.832297766,1043.0
25.911079461,1050.0
25.989861156,998.0
26.068642851,1043.0
26.147424546,1077.0
26.226206241,1037.0
26.304987936,1042.0
26.383769631,1060.0
26.462551326,1072.0
26.541333021,1040.0
26.620114716,1046.0
26.698896411,1008.0
26.777678106,1030.0
26.856459801,1026.0
26.935241496,1028.0
27.014023191,1014.0
27.092804886,1072.0
27.171586582,1016.0
27.250368277,1068.0
27.329149972,985.0
27.407931667,971.0
27.486713362,1021.0
27.565495057,1009.0
27.644276752,992.0
27.723058447,1002.0
27.801840142,984.0
27.880621837,1001.0
27.959403532,1058.0
28.038185227,956.0
28.116966922,1012.0
28.195748617,1020.0
28.274530312,987.0
28.353312007,977.0
28.432093702,1049.0
28.510875397,1002.0
28.589657092,1028.0
28.668438787,959.0
28.747220482,1039.0
28.826002177,938.0
28.904783872,989.0
28.983565567,1023.0
29.062347262,1005.0
29.141128957,1011.0
29.219910652,930.0
29.298692347,1020.0
29.377474042,1018.0
29.456255737,993.0
29.535037432,981.0
29.613819127,991.0
29.692600822,984.0
29.771382517,1001.0
29.850164212,978.0
29.928945907,962.0
30.007727602,930.0
30.086509297,962.0
30.165290992,912.0
30.244072687,943.0
30.322854382,1003.0
30.401636077,998.0
30.480417772,934.0
30.559199468,1007.0
30.637981163,1016.0
30.716762858,996.0
30.795544553,938.0
30.874326248,968.0
30.953107943,1024.0
31.031889638,922.0
31.110671333,954.0
31.189453028,959.0
31.268234723,927.0
31.347016418,919.0
31.425798113,916.0
31.504579808,905.0
31.583361503,887.0
31.662143198,892.0
31.740924893,953.0
31.819706588,960.0
31.898488283,905.0
31.977269978,976.0
32.056051673,956.0
32.134833368,899.0
32.213615063,869.0
32.292396758,892.0
32.371178453,878.0
32.449960148,870.0
32.528741843,926.0
32.607523538,894.0
32.686305233,915.0
32.765086928,875.0
32.843868623,872.0
32.922650318,851.0
33.001432013,879.0
33.080213708,833.0
33.158995403,865.0
33.237777098,850.0
33.316558793,761.0
33.395340488,877.0
33.474122183,870.0
33.552903878,833.0
33.631685573,831.0
33.710467268,784.0
33.789248963,892.0
33.868030658,845.0
33.946812354,823.0
34.025594049,831.0
34.104375744,855.0
34.183157439,823.0
34.261939134,899.0
34.340720829,841.0
34.419502524,812.0
34.498284219,812.0
34.577065914,867.0
34.655847609,801.0
34.734629304,853.0
34.813410999,818.0
34.892192694,837.0
34.970974389,801.0
35.049756084,781.0
35.128537779,726.0
35.207319474,833.0
35.286101169,797.0
35.364882864,803.0
35.443664559,797.0
35.522446254,744.0
35.601227949,788.0
35.680009644,820.0
35.758791339,765.0
35.837573034,793.0
35.916354729,796.0
35.995136424,820.0
36.073918119,817.0
36.152699814,731.0
36.231481509,773.0
36.310263204,730.0
36.389044899,757.0
36.467826594,741.0
36.546608289,750.0
36.625389984,770.0
36.704171679,760.0
36.782953374,707.0
36.861735069,699.0
36.940516764,755.0
37.019298459,739.0
37.098080154,729.0
37.176861849,726.0
37.255643544,739.0
37.334425240,711.0
37.413206935,722.0
37.491988630,698.0
37.570770325,764.0
37.649552020,706.0
37.728333715,761.0
37.807115410,708.0
37.885897105,749.0
37.964678800,716.0
38.043460495,694.0
38.122242190,676.0
38.201023885,682.0
38.279805580,719.0
38.358587275,707.0
38.437368970,654.0
38.516150665,623.0
38.594932360,692.0
38.673714055,714.0
38.752495750,671.0
38.831277445,715.0
38.910059140,687.0
38.988840835,683.0
39.067622530,664.0
39.146404225,734.0
39.225185920,716.0
39.303967615,644.0
39.382749310,698.0
39.461531005,701.0
39.540312700,679.0
39.619094395,703.0
39.697876090,725.0
39.776657785,703.0
39.855439480,648.0
39.934221175,749.0
40.013002870,757.0
40.091784565,705.0
40.170566260,744.0
40.249347955,757.0
40.328129650,742.0
40.406911345,682.0
40.485693040,716.0
40.564474735,740.0
40.643256430,737.0
40.722038126,708.0
40.800819821,761.0
40.879601516,706.0
40.958383211,751.0
41.037164906,726.0
41.115946601,757.0
41.194728296,747.0
41.273509991,755.0
41.352291686,720.0
41.431073381,708.0
41.509855076,724.0
41.588636771,792.0
41.667418466,770.0
41.746200161,733.0
41.824981856,766.0
41.903763551,711.0
41.982545246,690.0
42.061326941,760.0
42.140108636,725.0
42.218890331,726.0
42.297672026,710.0
42.376453721,759.0
42.455235416,770.0
42.534017111,775.0
42.612798806,686.0
42.691580501,753.0
42.770362196,668.0
42.849143891,700.0
42.927925586,731.0
43.006707281,730.0
43.085488976,754.0
43.164270671,723.0
43.243052366,662.0
43.321834061,678.0
43.400615756,664.0
43.479397451,636.0
43.558179146,673.0
43.636960841,648.0
43.715742536,653.0
43.794524231,609.0
43.873305926,657.0
43.952087621,632.0
44.030869316,558.0
44.109651011,638.0
44.188432707,587.0
44.267214402,604.0
44.345996097,583.0
44.424777792,566.0
44.503559487,598.0
44.582341182,532.0
44.661122877,554.0
44.739904572,569.0
44.818686267,548.0
44.897467962,592.0
44.976249657,525.0
45.055031352,618.0
45.133813047,536.0
45.212594742,566.0
45.291376437,521.0
45.370158132,584.0
45.448939827,571.0
45.527721522,536.0
45.606503217,522.0
45.685284912,518.0
45.764066607,559.0
45.842848302,548.0
45.921629997,517.0
46.000411692,505.0
46.079193387,522.0
46.157975082,510.0
46.236756777,536.0
46.315538472,534.0
46.394320167,538.0
46.473101862,536.0
46.551883557,495.0
46.630665252,467.0
46.709446947,503.0
46.788228642,477.0
46.867010337,501.0
46.945792032,472.0
47.024573727,485.0
47.103355422,483.0
47.182137117,483.0
47.260918812,477.0
47.339700507,441.0
47.418482202,475.0
47.497263897,487.0
47.576045593,462.0
47.654827288,470.0
47.733608983,452.0
47.812390678,459.0
47.891172373,515.0
47.969954068,454.0
48.048735763,467.0
48.127517458,497.0
48.206299153,474.0
48.285080848,427.0
48.363862543,411.0
48.442644238,480.0
48.521425933,437.0
48.600207628,452.0
48.678989323,438.0
48.757771018,455.0
48.836552713,450.0
48.915334408,461.0
48.994116103,456.0
49.072897798,436.0
49.151679493,466.0
49.230461188,432.0
49.309242883,446.0
49.388024578,420.0
49.466806273,425.0
49.545587968,453.0
49.624369663,449.0
49.703151358,414.0
49.781933053,425.0
49.860714748,395.0
49.939496443,451.0
50.018278138,441.0
50.097059833,452.0
50.175841528,442.0
50.254623223,441.0
50.333404918,442.0
50.412186613,429.0
50.490968308,396.0
50.569750003,416.0
50.648531698,391.0
50.727313393,429.0
50.806095088,389.0
50.884876783,436.0
50.963658479,410.0
51.042440174,428.0
51.121221869,406.0
51.200003564,389.0
51.278785259,448.0
51.357566954,433.0
51.436348649,420.0
51.515130344,426.0
51.593912039,402.0
51.672693734,400.0
51.751475429,391.0
51.830257124,378.0
51.909038819,397.0
51.987820514,378.0
52.066602209,349.0
52.145383904,436.0
52.224165599,392.0
52.302947294,368.0
52.381728989,420.0
52.460510684,370.0
52.539292379,384.0
52.618074074,393.0
52.696855769,405.0
52.775637464,400.0
52.854419159,384.0
52.933200854,427.0
53.011982549,388.0
53.090764244,362.0
53.169545939,394.0
53.248327634,391.0
53.327109329,388.0
53.405891024,386.0
53.484672719,432.0
53.563454414,396.0
53.642236109,399.0
53.721017804,397.0
53.799799499,345.0
53.878581194,389.0
53.957362889,363.0
54.036144584,380.0
54.114926279,375.0
54.193707974,406.0
54.272489669,371.0
54.351271365,368.0
54.430053060,410.0
54.508834755,380.0
54.587616450,412.0
54.666398145,358.0
54.745179840,386.0
54.823961535,391.0
54.902743230,382.0
54.981524925,372.0
55.060306620,431.0
55.139088315,368.0
55.217870010,364.0
55.296651705,368.0
55.375433400,428.0
55.454215095,379.0
55.532996790,375.0
55.611778485,364.0
55.690560180,356.0
55.769341875,359.0
55.848123570,384.0
55.926905265,355.0
56.005686960,342.0
56.084468655,394.0
56.163250350,363.0
56.242032045,368.0
56.320813740,335.0
56.399595435,341.0
56.478377130,380.0
56.557158825,379.0
56.635940520,348.0
56.714722215,367.0
56.793503910,387.0
56.872285605,385.0
56.951067300,369.0
57.029848995,355.0
57.108630690,363.0
57.187412385,359.0
57.266194080,317.0
57.344975775,363.0
57.423757470,335.0
57.502539165,374.0
57.581320860,384.0
57.660102555,359.0
57.738884251,335.0
57.817665946,342.0
57.896447641,307.0
57.975229336,387.0
58.054011031,350.0
58.132792726,358.0
58.211574421,371.0
58.290356116,360.0
58.369137811,357.0
58.447919506,341.0
58.526701201,353.0
58.605482896,347.0
58.684264591,335.0
58.763046286,339.0
58.841827981,335.0
58.920609676,347.0
58.999391371,330.0
59.078173066,357.0
59.156954761,341.0
59.235736456,317.0
59.314518151,329.0
59.393299846,310.0
59.472081541,344.0
59.550863236,341.0
59.629644931,346.0
59.708426626,337.0
59.787208321,357.0
59.865990016,382.0
59.944771711,321.0
60.023553406,341.0
60.102335101,338.0
60.181116796,341.0
60.259898491,309.0
60.338680186,328.0
60.417461881,330.0
60.496243576,343.0
60.575025271,323.0
60.653806966,336.0
60.732588661,351.0
60.811370356,334.0
60.890152051,355.0
60.968933746,381.0
61.047715441,355.0
61.126497137,376.0
61.205278832,322.0
61.284060527,346.0
61.362842222,362.0
61.441623917,368.0
61.520405612,320.0
61.599187307,375.0
61.677969002,341.0
61.756750697,321.0
61.835532392,294.0
61.914314087,329.0
61.993095782,352.0
62.071877477,367.0
62.150659172,350.0
62.229440867,348.0
62.308222562,311.0
62.387004257,348.0
62.465785952,349.0
62.544567647,346.0
62.623349342,368.0
62.702131037,337.0
62.780912732,333.0
62.859694427,320.0
62.938476122,357.0
63.017257817,299.0
63.096039512,303.0
63.174821207,348.0
63.253602902,331.0
63.332384597,315.0
63.411166292,328.0
63.489947987,334.0
63.568729682,315.0
63.647511377,318.0
63.726293072,330.0
63.805074767,357.0
63.883856462,341.0
63.962638157,343.0
64.041419852,336.0
64.120201547,355.0
64.198983242,287.0
64.277764937,321.0
64.356546632,296.0
64.435328327,362.0
64.514110023,294.0
64.592891718,323.0
64.671673413,337.0
64.750455108,308.0
64.829236803,335.0
64.908018498,315.0
64.986800193,299.0
65.065581888,329.0
65.144363583,302.0
65.223145278,312.0
65.301926973,285.0
65.380708668,320.0
65.459490363,342.0
65.538272058,262.0
65.617053753,328.0
65.695835448,287.0
65.774617143,300.0
65.853398838,321.0
65.932180533,319.0
66.010962228,311.0
66.089743923,290.0
66.168525618,263.0
66.247307313,324.0
66.326089008,338.0
66.404870703,324.0
66.483652398,272.0
66.562434093,308.0
66.641215788,300.0
66.719997483,286.0
66.798779178,311.0
66.877560873,304.0
66.956342568,301.0
67.035124263,299.0
67.113905958,287.0
67.192687653,323.0
67.271469348,290.0
67.350251043,287.0
67.429032738,318.0
67.507814433,290.0
67.586596128,307.0
67.665377823,307.0
67.744159518,291.0
67.822941213,302.0
67.901722909,299.0
67.980504604,309.0
68.059286299,266.0
68.138067994,304.0
68.216849689,310.0
68.295631384,290.0
68.374413079,277.0
68.453194774,288.0
68.531976469,305.0
68.610758164,275.0
68.689539859,313.0
68.768321554,313.0
68.847103249,296.0
68.925884944,283.0
69.004666639,295.0
69.083448334,289.0
69.162230029,297.0
69.241011724,296.0
69.319793419,315.0
69.398575114,283.0
69.477356809,318.0
69.556138504,290.0
69.634920199,292.0
69.713701894,278.0
69.792483589,275.0
69.871265284,285.0
69.950046979,275.0
70.028828674,298.0
70.107610369,286.0
70.186392064,273.0
70.265173759,266.0
70.343955454,267.0
70.422737149,303.0
70.501518844,289.0
70.580300539,305.0
70.659082234,289.0
70.737863929,289.0
70.816645624,255.0
70.895427319,271.0
70.974209014,283.0
71.052990709,299.0
71.131772404,270.0
71.210554099,289.0
71.289335794,314.0
71.368117490,260.0
71.446899185,266.0
71.525680880,288.0
71.604462575,267.0
71.683244270,258.0
71.762025965,253.0
71.840807660,325.0
71.919589355,278.0
71.998371050,315.0
72.077152745,280.0
72.155934440,288.0
72.234716135,276.0
72.313497830,266.0
72.392279525,272.0
72.471061220,271.0
72.549842915,292.0
72.628624610,246.0
72.707406305,277.0
72.786188000,306.0
72.864969695,304.0
72.943751390,272.0
73.022533085,258.0
73.101314780,279.0
73.180096475,317.0
73.258878170,283.0
73.337659865,270.0
73.416441560,274.0
73.495223255,281.0
73.574004950,294.0
73.652786645,281.0
73.731568340,284.0
73.810350035,285.0
73.889131730,306.0
73.967913425,274.0
74.046695120,259.0
74.125476815,268.0
74.204258510,290.0
74.283040205,273.0
74.361821900,277.0
74.440603595,282.0
74.519385290,272.0
74.598166985,256.0
74.676948680,308.0
74.755730376,298.0
74.834512071,272.0
74.913293766,274.0
74.992075461,273.0
75.070857156,262.0
75.149638851,267.0
75.228420546,292.0
75.307202241,282.0
75.385983936,284.0
75.464765631,271.0
75.543547326,263.0
75.622329021,262.0
75.701110716,271.0
75.779892411,274.0
75.858674106,287.0
75.937455801,293.0
76.016237496,253.0
76.095019191,243.0
76.173800886,282.0
76.252582581,220.0
76.331364276,250.0
76.410145971,290.0
76.488927666,238.0
76.567709361,267.0
76.646491056,255.0
76.725272751,257.0
76.804054446,272.0
76.882836141,250.0
76.961617836,271.0
77.040399531,266.0
77.119181226,289.0
77.197962921,261.0
77.276744616,246.0
77.355526311,269.0
77.434308006,260.0
77.513089701,288.0
77.591871396,290.0
77.670653091,256.0
77.749434786,288.0
77.828216481,270.0
77.906998176,236.0
77.985779871,291.0
78.064561566,276.0
78.143343262,282.0
78.222124957,274.0
78.300906652,271.0
78.379688347,238.0
78.458470042,264.0
78.537251737,230.0
78.616033432,260.0
78.694815127,261.0
78.773596822,273.0
78.852378517,294.0
78.931160212,266.0
79.009941907,271.0
79.088723602,260.0
79.167505297,242.0
79.246286992,253.0
79.325068687,230.0
79.403850382,242.0
79.482632077,267.0
79.561413772,256.0
79.640195467,265.0
79.718977162,297.0
79.797758857,224.0
79.876540552,259.0
79.955322247,249.0
80.034103942,274.0
80.112885637,213.0
80.191667332,253.0
80.270449027,227.0
80.349230722,250.0
80.428012417,266.0
80.506794112,254.0
80.585575807,229.0
80.664357502,219.0
80.743139197,252.0
80.821920892,228.0
80.900702587,246.0
80.979484282,253.0
81.058265977,252.0
81.137047672,232.0
81.215829367,251.0
81.294611062,253.0
81.373392757,280.0
81.452174452,246.0
81.530956148,223.0
81.609737843,245.0
81.688519538,240.0
81.767301233,245.0
81.846082928,222.0
81.924864623,231.0
82.003646318,212.0
82.082428013,227.0
82.161209708,235.0
82.239991403,228.0
82.318773098,234.0
82.397554793,252.0
82.476336488,243.0
82.555118183,222.0
82.633899878,255.0
82.712681573,258.0
82.791463268,223.0
82.870244963,233.0
82.949026658,230.0
83.027808353,263.0
83.106590048,232.0
83.185371743,225.0
83.264153438,245.0
83.342935133,246.0
83.421716828,212.0
83.500498523,234.0
83.579280218,221.0
83.658061913,204.0
83.736843608,220.0
83.815625303,231.0
83.894406998,267.0
83.973188693,250.0
84.051970388,228.0
84.130752083,216.0
84.209533778,229.0
84.288315473,202.0
84.367097168,221.0
84.445878863,229.0
84.524660558,219.0
84.603442253,217.0
84.682223948,229.0
84.761005643,202.0
84.839787338,198.0
84.918569034,208.0
84.997350729,249.0
85.076132424,239.0
85.154914119,239.0
85.233695814,223.0
85.312477509,231.0
85.391259204,232.0
85.470040899,210.0
85.548822594,214.0
85.627604289,196.0
85.706385984,246.0
85.785167679,230.0
85.863949374,219.0
85.942731069,226.0
86.021512764,229.0
86.100294459,237.0
86.179076154,224.0
86.257857849,226.0
86.336639544,230.0
86.415421239,206.0
86.494202934,177.0
86.572984629,240.0
86.651766324,242.0
86.730548019,233.0
86.809329714,197.0
86.888111409,205.0
86.966893104,237.0
87.045674799,222.0
87.124456494,188.0
87.203238189,245.0
87.282019884,228.0
87.360801579,220.0
87.439583274,198.0
87.518364969,252.0
87.597146664,198.0
87.675928359,223.0
87.754710054,212.0
87.833491749,225.0
87.912273444,196.0
87.991055139,228.0
88.069836834,216.0
88.148618529,194.0
88.227400224,219.0
88.306181920,229.0
88.384963615,220.0
88.463745310,223.0
88.542527005,220.0
88.621308700,228.0
88.700090395,240.0
88.778872090,252.0
88.857653785,202.0
88.936435480,200.0
89.015217175,187.0
89.093998870,206.0
89.172780565,206.0
89.251562260,217.0
89.330343955,222.0
89.409125650,199.0
89.487907345,201.0
89.566689040,213.0
89.645470735,218.0
89.724252430,207.0
89.803034125,192.0
89.881815820,212.0
89.960597515,204.0
89.986858080,214.0