File: 2017007296/7296-c#.csv
[Measurement conditions]
Sample identification,
Comment - 1,"Configuration=Stage for flat samples/holders, Owner=User-1, Creation date=3/27/2015 11:56:23 AM"
Comment - 2,"Goniometer=Theta/Theta; Minimum step size 2Theta:0.0001; Minimum step size Omega:0.0001"
Comment - 3,"Sample stage=Stage for flat samples/holders"
Comment - 4,"Diffractometer system=EMPYREAN"
Comment - 5,"Measurement program=C:\PANalytical\Data Collector\Programs\Powder - Copy.xrdmp, Identifier={BEEA10DD-8FD6-4721-8940-4FBC5A4262A1}"
Comment - 6,"Fine Calibration Offset for 2Theta = -0.0130 deg"
Comment - 7,"Fine Calibration Offset for Omega = -0.0070 deg"
Anode material,Cu
K-Alpha1 wavelength,1.5405980
K-Alpha2 wavelength,1.5444260
Ratio K-Alpha2/K-Alpha1,0.500
Divergence slit,Fixed,0.38mm
Monochromator used,NO
Generator voltage, 40
Tube current, 35
File date and time,24/Jul/2017 16:59
Unit cell,
h k l, 0 0 0
Scan axis,Gonio
Scan range,5.020799997,89.999988363
Scan step size,0.0262606
No. of points, 3236
Scan type,CONTINUOUS
Time per step,18.615
[Scan points]
Angle,Intensity
5.033930280,2598.0
5.112711975,2513.0
5.191493670,2496.0
5.270275365,2510.0
5.349057060,2422.0
5.427838755,2379.0
5.506620450,2424.0
5.585402145,2374.0
5.664183840,2411.0
5.742965535,2418.0
5.821747230,2316.0
5.900528925,2310.0
5.979310620,2334.0
6.058092315,2314.0
6.136874010,2357.0
6.215655705,2255.0
6.294437400,2253.0
6.373219095,2255.0
6.452000790,2205.0
6.530782485,2223.0
6.609564180,2147.0
6.688345875,2113.0
6.767127571,2142.0
6.845909266,2052.0
6.924690961,2082.0
7.003472656,2159.0
7.082254351,2048.0
7.161036046,2120.0
7.239817741,2111.0
7.318599436,2013.0
7.397381131,2100.0
7.476162826,2002.0
7.554944521,1955.0
7.633726216,1973.0
7.712507911,1989.0
7.791289606,2029.0
7.870071301,1957.0
7.948852996,2049.0
8.027634691,2061.0
8.106416386,1970.0
8.185198081,1918.0
8.263979776,1992.0
8.342761471,1911.0
8.421543166,1922.0
8.500324861,1902.0
8.579106556,1899.0
8.657888251,1846.0
8.736669946,1955.0
8.815451641,1959.0
8.894233336,1878.0
8.973015031,1918.0
9.051796726,1913.0
9.130578421,1836.0
9.209360116,1773.0
9.288141811,1861.0
9.366923506,1832.0
9.445705201,1833.0
9.524486896,1899.0
9.603268591,1879.0
9.682050286,1789.0
9.760831981,1900.0
9.839613676,1864.0
9.918395371,1857.0
9.997177066,1866.0
10.075958761,1910.0
10.154740457,1957.0
10.233522152,1906.0
10.312303847,1802.0
10.391085542,1882.0
10.469867237,1884.0
10.548648932,1838.0
10.627430627,1845.0
10.706212322,1959.0
10.784994017,1880.0
10.863775712,1962.0
10.942557407,1913.0
11.021339102,1896.0
11.100120797,1950.0
11.178902492,1836.0
11.257684187,1964.0
11.336465882,1872.0
11.415247577,2009.0
11.494029272,1940.0
11.572810967,1959.0
11.651592662,1930.0
11.730374357,1998.0
11.809156052,1915.0
11.887937747,2043.0
11.966719442,2010.0
12.045501137,2029.0
12.124282832,2072.0
12.203064527,2086.0
12.281846222,2074.0
12.360627917,2062.0
12.439409612,2119.0
12.518191307,2153.0
12.596973002,2127.0
12.675754697,2137.0
12.754536392,2092.0
12.833318087,2197.0
12.912099782,2162.0
12.990881477,2124.0
13.069663172,2146.0
13.148444867,2206.0
13.227226562,2221.0
13.306008257,2282.0
13.384789952,2314.0
13.463571647,2219.0
13.542353343,2229.0
13.621135038,2219.0
13.699916733,2261.0
13.778698428,2153.0
13.857480123,2108.0
13.936261818,2216.0
14.015043513,2289.0
14.093825208,2369.0
14.172606903,2358.0
14.251388598,2296.0
14.330170293,2308.0
14.408951988,2308.0
14.487733683,2251.0
14.566515378,2246.0
14.645297073,2313.0
14.724078768,2280.0
14.802860463,2218.0
14.881642158,2307.0
14.960423853,2262.0
15.039205548,2234.0
15.117987243,2173.0
15.196768938,2120.0
15.275550633,1979.0
15.354332328,1896.0
15.433114023,1955.0
15.511895718,1815.0
15.590677413,1769.0
15.669459108,1655.0
15.748240803,1574.0
15.827022498,1601.0
15.905804193,1438.0
15.984585888,1450.0
16.063367583,1347.0
16.142149278,1335.0
16.220930973,1297.0
16.299712668,1274.0
16.378494363,1188.0
16.457276058,1231.0
16.536057753,1185.0
16.614839448,1195.0
16.693621143,1055.0
16.772402838,1131.0
16.851184533,1108.0
16.929966229,1023.0
17.008747924,1059.0
17.087529619,1081.0
17.166311314,993.0
17.245093009,1036.0
17.323874704,1068.0
17.402656399,978.0
17.481438094,957.0
17.560219789,972.0
17.639001484,900.0
17.717783179,936.0
17.796564874,944.0
17.875346569,941.0
17.954128264,974.0
18.032909959,927.0
18.111691654,873.0
18.190473349,893.0
18.269255044,901.0
18.348036739,967.0
18.426818434,866.0
18.505600129,922.0
18.584381824,813.0
18.663163519,849.0
18.741945214,819.0
18.820726909,859.0
18.899508604,886.0
18.978290299,894.0
19.057071994,884.0
19.135853689,869.0
19.214635384,840.0
19.293417079,813.0
19.372198774,834.0
19.450980469,820.0
19.529762164,880.0
19.608543859,894.0
19.687325554,839.0
19.766107249,832.0
19.844888944,785.0
19.923670639,892.0
20.002452334,891.0
20.081234029,829.0
20.160015724,885.0
20.238797419,791.0
20.317579114,776.0
20.396360810,783.0
20.475142505,798.0
20.553924200,869.0
20.632705895,892.0
20.711487590,849.0
20.790269285,841.0
20.869050980,804.0
20.947832675,830.0
21.026614370,843.0
21.105396065,856.0
21.184177760,829.0
21.262959455,771.0
21.341741150,808.0
21.420522845,827.0
21.499304540,800.0
21.578086235,836.0
21.656867930,803.0
21.735649625,816.0
21.814431320,858.0
21.893213015,901.0
21.971994710,781.0
22.050776405,819.0
22.129558100,787.0
22.208339795,789.0
22.287121490,820.0
22.365903185,766.0
22.444684880,807.0
22.523466575,857.0
22.602248270,860.0
22.681029965,833.0
22.759811660,872.0
22.838593355,855.0
22.917375050,824.0
22.996156745,795.0
23.074938440,880.0
23.153720135,823.0
23.232501830,874.0
23.311283525,879.0
23.390065220,842.0
23.468846915,843.0
23.547628610,901.0
23.626410305,899.0
23.705192000,920.0
23.783973696,857.0
23.862755391,859.0
23.941537086,885.0
24.020318781,854.0
24.099100476,839.0
24.177882171,898.0
24.256663866,871.0
24.335445561,868.0
24.414227256,906.0
24.493008951,868.0
24.571790646,823.0
24.650572341,849.0
24.729354036,915.0
24.808135731,865.0
24.886917426,889.0
24.965699121,882.0
25.044480816,906.0
25.123262511,855.0
25.202044206,938.0
25.280825901,884.0
25.359607596,997.0
25.438389291,941.0
25.517170986,1024.0
25.595952681,1075.0
25.674734376,1120.0
25.753516071,1138.0
25.832297766,1123.0
25.911079461,1274.0
25.989861156,1416.0
26.068642851,1795.0
26.147424546,2530.0
26.226206241,3771.0
26.304987936,5425.0
26.383769631,6678.0
26.462551326,7808.0
26.541333021,6245.0
26.620114716,3165.0
26.698896411,1940.0
26.777678106,1490.0
26.856459801,1315.0
26.935241496,1227.0
27.014023191,1160.0
27.092804886,1072.0
27.171586582,1011.0
27.250368277,959.0
27.329149972,1023.0
27.407931667,991.0
27.486713362,885.0
27.565495057,880.0
27.644276752,896.0
27.723058447,914.0
27.801840142,844.0
27.880621837,898.0
27.959403532,864.0
28.038185227,860.0
28.116966922,872.0
28.195748617,827.0
28.274530312,823.0
28.353312007,803.0
28.432093702,784.0
28.510875397,847.0
28.589657092,798.0
28.668438787,811.0
28.747220482,809.0
28.826002177,732.0
28.904783872,748.0
28.983565567,772.0
29.062347262,707.0
29.141128957,776.0
29.219910652,740.0
29.298692347,746.0
29.377474042,757.0
29.456255737,816.0
29.535037432,731.0
29.613819127,758.0
29.692600822,692.0
29.771382517,735.0
29.850164212,767.0
29.928945907,740.0
30.007727602,667.0
30.086509297,671.0
30.165290992,691.0
30.244072687,717.0
30.322854382,689.0
30.401636077,744.0
30.480417772,672.0
30.559199468,669.0
30.637981163,669.0
30.716762858,650.0
30.795544553,649.0
30.874326248,620.0
30.953107943,613.0
31.031889638,633.0
31.110671333,641.0
31.189453028,645.0
31.268234723,606.0
31.347016418,607.0
31.425798113,629.0
31.504579808,586.0
31.583361503,603.0
31.662143198,584.0
31.740924893,578.0
31.819706588,621.0
31.898488283,590.0
31.977269978,565.0
32.056051673,596.0
32.134833368,613.0
32.213615063,588.0
32.292396758,627.0
32.371178453,567.0
32.449960148,604.0
32.528741843,601.0
32.607523538,556.0
32.686305233,586.0
32.765086928,623.0
32.843868623,596.0
32.922650318,549.0
33.001432013,579.0
33.080213708,573.0
33.158995403,576.0
33.237777098,538.0
33.316558793,551.0
33.395340488,556.0
33.474122183,529.0
33.552903878,504.0
33.631685573,505.0
33.710467268,519.0
33.789248963,502.0
33.868030658,547.0
33.946812354,504.0
34.025594049,517.0
34.104375744,545.0
34.183157439,547.0
34.261939134,508.0
34.340720829,519.0
34.419502524,534.0
34.498284219,516.0
34.577065914,527.0
34.655847609,550.0
34.734629304,526.0
34.813410999,547.0
34.892192694,542.0
34.970974389,559.0
35.049756084,503.0
35.128537779,504.0
35.207319474,576.0
35.286101169,497.0
35.364882864,542.0
35.443664559,595.0
35.522446254,527.0
35.601227949,572.0
35.680009644,539.0
35.758791339,552.0
35.837573034,574.0
35.916354729,565.0
35.995136424,552.0
36.073918119,573.0
36.152699814,530.0
36.231481509,563.0
36.310263204,586.0
36.389044899,545.0
36.467826594,538.0
36.546608289,572.0
36.625389984,519.0
36.704171679,586.0
36.782953374,563.0
36.861735069,625.0
36.940516764,575.0
37.019298459,604.0
37.098080154,590.0
37.176861849,604.0
37.255643544,636.0
37.334425240,620.0
37.413206935,602.0
37.491988630,565.0
37.570770325,594.0
37.649552020,591.0
37.728333715,610.0
37.807115410,567.0
37.885897105,607.0
37.964678800,639.0
38.043460495,631.0
38.122242190,645.0
38.201023885,643.0
38.279805580,616.0
38.358587275,650.0
38.437368970,689.0
38.516150665,668.0
38.594932360,685.0
38.673714055,717.0
38.752495750,743.0
38.831277445,727.0
38.910059140,770.0
38.988840835,784.0
39.067622530,785.0
39.146404225,783.0
39.225185920,799.0
39.303967615,856.0
39.382749310,909.0
39.461531005,858.0
39.540312700,947.0
39.619094395,987.0
39.697876090,1045.0
39.776657785,1063.0
39.855439480,1187.0
39.934221175,1275.0
40.013002870,1290.0
40.091784565,1481.0
40.170566260,1588.0
40.249347955,1610.0
40.328129650,1701.0
40.406911345,1719.0
40.485693040,1858.0
40.564474735,1855.0
40.643256430,1823.0
40.722038126,1810.0
40.800819821,1896.0
40.879601516,1884.0
40.958383211,1873.0
41.037164906,1841.0
41.115946601,1933.0
41.194728296,1820.0
41.273509991,1794.0
41.352291686,1808.0
41.431073381,1799.0
41.509855076,1690.0
41.588636771,1714.0
41.667418466,1762.0
41.746200161,1740.0
41.824981856,1713.0
41.903763551,1703.0
41.982545246,1630.0
42.061326941,1688.0
42.140108636,1787.0
42.218890331,1661.0
42.297672026,1777.0
42.376453721,1700.0
42.455235416,1638.0
42.534017111,1614.0
42.612798806,1529.0
42.691580501,1523.0
42.770362196,1488.0
42.849143891,1516.0
42.927925586,1434.0
43.006707281,1378.0
43.085488976,1481.0
43.164270671,1510.0
43.243052366,1522.0
43.321834061,1482.0
43.400615756,1369.0
43.479397451,1403.0
43.558179146,1275.0
43.636960841,1255.0
43.715742536,1275.0
43.794524231,1235.0
43.873305926,1193.0
43.952087621,1245.0
44.030869316,1152.0
44.109651011,1241.0
44.188432707,1174.0
44.267214402,1181.0
44.345996097,1285.0
44.424777792,1265.0
44.503559487,1333.0
44.582341182,1272.0
44.661122877,1069.0
44.739904572,1073.0
44.818686267,1058.0
44.897467962,985.0
44.976249657,948.0
45.055031352,966.0
45.133813047,946.0
45.212594742,860.0
45.291376437,894.0
45.370158132,831.0
45.448939827,858.0
45.527721522,874.0
45.606503217,876.0
45.685284912,847.0
45.764066607,768.0
45.842848302,871.0
45.921629997,835.0
46.000411692,833.0
46.079193387,880.0
46.157975082,820.0
46.236756777,743.0
46.315538472,740.0
46.394320167,718.0
46.473101862,746.0
46.551883557,718.0
46.630665252,712.0
46.709446947,686.0
46.788228642,638.0
46.867010337,679.0
46.945792032,633.0
47.024573727,659.0
47.103355422,615.0
47.182137117,617.0
47.260918812,631.0
47.339700507,627.0
47.418482202,554.0
47.497263897,574.0
47.576045593,568.0
47.654827288,585.0
47.733608983,563.0
47.812390678,580.0
47.891172373,541.0
47.969954068,546.0
48.048735763,539.0
48.127517458,575.0
48.206299153,533.0
48.285080848,532.0
48.363862543,531.0
48.442644238,504.0
48.521425933,546.0
48.600207628,478.0
48.678989323,504.0
48.757771018,526.0
48.836552713,548.0
48.915334408,496.0
48.994116103,505.0
49.072897798,474.0
49.151679493,488.0
49.230461188,475.0
49.309242883,401.0
49.388024578,508.0
49.466806273,500.0
49.545587968,441.0
49.624369663,426.0
49.703151358,475.0
49.781933053,463.0
49.860714748,462.0
49.939496443,471.0
50.018278138,452.0
50.097059833,428.0
50.175841528,440.0
50.254623223,418.0
50.333404918,442.0
50.412186613,438.0
50.490968308,450.0
50.569750003,446.0
50.648531698,429.0
50.727313393,468.0
50.806095088,473.0
50.884876783,417.0
50.963658479,453.0
51.042440174,438.0
51.121221869,458.0
51.200003564,378.0
51.278785259,392.0
51.357566954,370.0
51.436348649,385.0
51.515130344,369.0
51.593912039,370.0
51.672693734,412.0
51.751475429,418.0
51.830257124,403.0
51.909038819,385.0
51.987820514,407.0
52.066602209,354.0
52.145383904,368.0
52.224165599,377.0
52.302947294,333.0
52.381728989,383.0
52.460510684,389.0
52.539292379,360.0
52.618074074,384.0
52.696855769,417.0
52.775637464,353.0
52.854419159,370.0
52.933200854,378.0
53.011982549,366.0
53.090764244,380.0
53.169545939,406.0
53.248327634,365.0
53.327109329,398.0
53.405891024,382.0
53.484672719,362.0
53.563454414,364.0
53.642236109,411.0
53.721017804,399.0
53.799799499,378.0
53.878581194,382.0
53.957362889,398.0
54.036144584,389.0
54.114926279,388.0
54.193707974,402.0
54.272489669,431.0
54.351271365,474.0
54.430053060,565.0
54.508834755,597.0
54.587616450,603.0
54.666398145,587.0
54.745179840,517.0
54.823961535,501.0
54.902743230,429.0
54.981524925,386.0
55.060306620,397.0
55.139088315,374.0
55.217870010,390.0
55.296651705,379.0
55.375433400,357.0
55.454215095,366.0
55.532996790,411.0
55.611778485,394.0
55.690560180,405.0
55.769341875,385.0
55.848123570,368.0
55.926905265,340.0
56.005686960,335.0
56.084468655,401.0
56.163250350,378.0
56.242032045,364.0
56.320813740,405.0
56.399595435,390.0
56.478377130,421.0
56.557158825,341.0
56.635940520,391.0
56.714722215,338.0
56.793503910,345.0
56.872285605,346.0
56.951067300,356.0
57.029848995,332.0
57.108630690,347.0
57.187412385,364.0
57.266194080,355.0
57.344975775,360.0
57.423757470,360.0
57.502539165,346.0
57.581320860,370.0
57.660102555,371.0
57.738884251,391.0
57.817665946,356.0
57.896447641,344.0
57.975229336,358.0
58.054011031,339.0
58.132792726,383.0
58.211574421,360.0
58.290356116,370.0
58.369137811,377.0
58.447919506,368.0
58.526701201,395.0
58.605482896,361.0
58.684264591,361.0
58.763046286,341.0
58.841827981,372.0
58.920609676,330.0
58.999391371,333.0
59.078173066,363.0
59.156954761,352.0
59.235736456,405.0
59.314518151,378.0
59.393299846,354.0
59.472081541,369.0
59.550863236,341.0
59.629644931,383.0
59.708426626,373.0
59.787208321,358.0
59.865990016,414.0
59.944771711,402.0
60.023553406,366.0
60.102335101,340.0
60.181116796,364.0
60.259898491,365.0
60.338680186,352.0
60.417461881,343.0
60.496243576,339.0
60.575025271,327.0
60.653806966,323.0
60.732588661,332.0
60.811370356,333.0
60.890152051,346.0
60.968933746,321.0
61.047715441,316.0
61.126497137,330.0
61.205278832,351.0
61.284060527,340.0
61.362842222,332.0
61.441623917,337.0
61.520405612,295.0
61.599187307,330.0
61.677969002,332.0
61.756750697,318.0
61.835532392,326.0
61.914314087,346.0
61.993095782,350.0
62.071877477,314.0
62.150659172,316.0
62.229440867,329.0
62.308222562,375.0
62.387004257,345.0
62.465785952,318.0
62.544567647,323.0
62.623349342,342.0
62.702131037,337.0
62.780912732,332.0
62.859694427,314.0
62.938476122,290.0
63.017257817,339.0
63.096039512,307.0
63.174821207,315.0
63.253602902,329.0
63.332384597,293.0
63.411166292,344.0
63.489947987,333.0
63.568729682,347.0
63.647511377,305.0
63.726293072,306.0
63.805074767,283.0
63.883856462,293.0
63.962638157,328.0
64.041419852,282.0
64.120201547,306.0
64.198983242,307.0
64.277764937,281.0
64.356546632,313.0
64.435328327,311.0
64.514110023,274.0
64.592891718,289.0
64.671673413,274.0
64.750455108,325.0
64.829236803,342.0
64.908018498,265.0
64.986800193,249.0
65.065581888,292.0
65.144363583,283.0
65.223145278,260.0
65.301926973,286.0
65.380708668,331.0
65.459490363,298.0
65.538272058,279.0
65.617053753,293.0
65.695835448,280.0
65.774617143,276.0
65.853398838,274.0
65.932180533,281.0
66.010962228,286.0
66.089743923,289.0
66.168525618,294.0
66.247307313,282.0
66.326089008,300.0
66.404870703,296.0
66.483652398,270.0
66.562434093,268.0
66.641215788,287.0
66.719997483,293.0
66.798779178,286.0
66.877560873,272.0
66.956342568,304.0
67.035124263,260.0
67.113905958,300.0
67.192687653,305.0
67.271469348,270.0
67.350251043,294.0
67.429032738,250.0
67.507814433,279.0
67.586596128,268.0
67.665377823,282.0
67.744159518,280.0
67.822941213,238.0
67.901722909,287.0
67.980504604,286.0
68.059286299,285.0
68.138067994,275.0
68.216849689,288.0
68.295631384,278.0
68.374413079,266.0
68.453194774,296.0
68.531976469,259.0
68.610758164,259.0
68.689539859,262.0
68.768321554,266.0
68.847103249,275.0
68.925884944,254.0
69.004666639,259.0
69.083448334,281.0
69.162230029,266.0
69.241011724,267.0
69.319793419,251.0
69.398575114,247.0
69.477356809,281.0
69.556138504,250.0
69.634920199,253.0
69.713701894,258.0
69.792483589,281.0
69.871265284,255.0
69.950046979,265.0
70.028828674,277.0
70.107610369,261.0
70.186392064,298.0
70.265173759,287.0
70.343955454,310.0
70.422737149,260.0
70.501518844,307.0
70.580300539,251.0
70.659082234,307.0
70.737863929,291.0
70.816645624,277.0
70.895427319,266.0
70.974209014,264.0
71.052990709,268.0
71.131772404,298.0
71.210554099,300.0
71.289335794,285.0
71.368117490,313.0
71.446899185,259.0
71.525680880,265.0
71.604462575,296.0
71.683244270,308.0
71.762025965,273.0
71.840807660,283.0
71.919589355,285.0
71.998371050,305.0
72.077152745,272.0
72.155934440,312.0
72.234716135,316.0
72.313497830,301.0
72.392279525,314.0
72.471061220,336.0
72.549842915,305.0
72.628624610,332.0
72.707406305,307.0
72.786188000,344.0
72.864969695,352.0
72.943751390,387.0
73.022533085,421.0
73.101314780,418.0
73.180096475,426.0
73.258878170,395.0
73.337659865,418.0
73.416441560,413.0
73.495223255,422.0
73.574004950,357.0
73.652786645,423.0
73.731568340,420.0
73.810350035,408.0
73.889131730,358.0
73.967913425,389.0
74.046695120,362.0
74.125476815,351.0
74.204258510,361.0
74.283040205,331.0
74.361821900,348.0
74.440603595,308.0
74.519385290,345.0
74.598166985,319.0
74.676948680,329.0
74.755730376,358.0
74.834512071,321.0
74.913293766,332.0
74.992075461,312.0
75.070857156,321.0
75.149638851,310.0
75.228420546,314.0
75.307202241,306.0
75.385983936,277.0
75.464765631,283.0
75.543547326,304.0
75.622329021,290.0
75.701110716,284.0
75.779892411,288.0
75.858674106,289.0
75.937455801,305.0
76.016237496,260.0
76.095019191,264.0
76.173800886,258.0
76.252582581,283.0
76.331364276,249.0
76.410145971,275.0
76.488927666,267.0
76.567709361,255.0
76.646491056,253.0
76.725272751,280.0
76.804054446,281.0
76.882836141,246.0
76.961617836,306.0
77.040399531,273.0
77.119181226,307.0
77.197962921,337.0
77.276744616,419.0
77.355526311,430.0
77.434308006,499.0
77.513089701,448.0
77.591871396,376.0
77.670653091,365.0
77.749434786,339.0
77.828216481,280.0
77.906998176,296.0
77.985779871,309.0
78.064561566,249.0
78.143343262,294.0
78.222124957,261.0
78.300906652,284.0
78.379688347,286.0
78.458470042,264.0
78.537251737,272.0
78.616033432,257.0
78.694815127,290.0
78.773596822,265.0
78.852378517,259.0
78.931160212,278.0
79.009941907,281.0
79.088723602,250.0
79.167505297,269.0
79.246286992,267.0
79.325068687,271.0
79.403850382,256.0
79.482632077,284.0
79.561413772,252.0
79.640195467,278.0
79.718977162,247.0
79.797758857,239.0
79.876540552,255.0
79.955322247,265.0
80.034103942,264.0
80.112885637,287.0
80.191667332,251.0
80.270449027,247.0
80.349230722,242.0
80.428012417,272.0
80.506794112,239.0
80.585575807,267.0
80.664357502,281.0
80.743139197,263.0
80.821920892,255.0
80.900702587,234.0
80.979484282,262.0
81.058265977,249.0
81.137047672,228.0
81.215829367,241.0
81.294611062,269.0
81.373392757,228.0
81.452174452,245.0
81.530956148,222.0
81.609737843,250.0
81.688519538,266.0
81.767301233,234.0
81.846082928,263.0
81.924864623,248.0
82.003646318,249.0
82.082428013,262.0
82.161209708,266.0
82.239991403,250.0
82.318773098,249.0
82.397554793,225.0
82.476336488,255.0
82.555118183,232.0
82.633899878,270.0
82.712681573,229.0
82.791463268,226.0
82.870244963,252.0
82.949026658,242.0
83.027808353,265.0
83.106590048,286.0
83.185371743,279.0
83.264153438,292.0
83.342935133,349.0
83.421716828,371.0
83.500498523,373.0
83.579280218,427.0
83.658061913,345.0
83.736843608,324.0
83.815625303,313.0
83.894406998,310.0
83.973188693,300.0
84.051970388,239.0
84.130752083,256.0
84.209533778,253.0
84.288315473,246.0
84.367097168,244.0
84.445878863,255.0
84.524660558,277.0
84.603442253,270.0
84.682223948,253.0
84.761005643,254.0
84.839787338,258.0
84.918569034,230.0
84.997350729,239.0
85.076132424,234.0
85.154914119,243.0
85.233695814,209.0
85.312477509,247.0
85.391259204,245.0
85.470040899,230.0
85.548822594,226.0
85.627604289,238.0
85.706385984,226.0
85.785167679,235.0
85.863949374,263.0
85.942731069,254.0
86.021512764,265.0
86.100294459,246.0
86.179076154,271.0
86.257857849,248.0
86.336639544,232.0
86.415421239,272.0
86.494202934,236.0
86.572984629,228.0
86.651766324,244.0
86.730548019,283.0
86.809329714,245.0
86.888111409,297.0
86.966893104,290.0
87.045674799,262.0
87.124456494,280.0
87.203238189,256.0
87.282019884,279.0
87.360801579,235.0
87.439583274,273.0
87.518364969,260.0
87.597146664,268.0
87.675928359,249.0
87.754710054,275.0
87.833491749,251.0
87.912273444,278.0
87.991055139,255.0
88.069836834,243.0
88.148618529,239.0
88.227400224,258.0
88.306181920,264.0
88.384963615,256.0
88.463745310,263.0
88.542527005,237.0
88.621308700,252.0
88.700090395,253.0
88.778872090,251.0
88.857653785,243.0
88.936435480,251.0
89.015217175,237.0
89.093998870,284.0
89.172780565,223.0
89.251562260,274.0
89.330343955,209.0
89.409125650,273.0
89.487907345,251.0
89.566689040,216.0
89.645470735,254.0
89.724252430,234.0
89.803034125,206.0
89.881815820,246.0
89.960597515,215.0
89.986858080,230.0