File: 2017007296/7296-a2.csv
[Measurement conditions]
Sample identification,
Comment - 1,"Configuration=Stage for flat samples/holders, Owner=User-1, Creation date=3/27/2015 11:56:23 AM"
Comment - 2,"Goniometer=Theta/Theta; Minimum step size 2Theta:0.0001; Minimum step size Omega:0.0001"
Comment - 3,"Sample stage=Stage for flat samples/holders"
Comment - 4,"Diffractometer system=EMPYREAN"
Comment - 5,"Measurement program=C:\PANalytical\Data Collector\Programs\Powder - Copy.xrdmp, Identifier={BEEA10DD-8FD6-4721-8940-4FBC5A4262A1}"
Comment - 6,"Fine Calibration Offset for 2Theta = -0.0130 deg"
Comment - 7,"Fine Calibration Offset for Omega = -0.0070 deg"
Anode material,Cu
K-Alpha1 wavelength,1.5405980
K-Alpha2 wavelength,1.5444260
Ratio K-Alpha2/K-Alpha1,0.500
Divergence slit,Fixed,0.38mm
Monochromator used,NO
Generator voltage, 40
Tube current, 35
File date and time,24/Jul/2017 16:01
Unit cell,
h k l, 0 0 0
Scan axis,Gonio
Scan range,5.020799997,89.999988363
Scan step size,0.0262606
No. of points, 3236
Scan type,CONTINUOUS
Time per step,18.615
[Scan points]
Angle,Intensity
5.033930280,1689.0
5.112711975,1796.0
5.191493670,1817.0
5.270275365,1809.0
5.349057060,1765.0
5.427838755,1785.0
5.506620450,1703.0
5.585402145,1820.0
5.664183840,1758.0
5.742965535,1695.0
5.821747230,1891.0
5.900528925,1864.0
5.979310620,1765.0
6.058092315,1811.0
6.136874010,1815.0
6.215655705,1845.0
6.294437400,1790.0
6.373219095,1828.0
6.452000790,1694.0
6.530782485,1829.0
6.609564180,1785.0
6.688345875,1813.0
6.767127571,1755.0
6.845909266,1789.0
6.924690961,1862.0
7.003472656,1830.0
7.082254351,1825.0
7.161036046,1810.0
7.239817741,1850.0
7.318599436,1928.0
7.397381131,1963.0
7.476162826,1949.0
7.554944521,1945.0
7.633726216,1959.0
7.712507911,1912.0
7.791289606,1988.0
7.870071301,2018.0
7.948852996,1904.0
8.027634691,2084.0
8.106416386,1988.0
8.185198081,2059.0
8.263979776,2007.0
8.342761471,2020.0
8.421543166,2091.0
8.500324861,2147.0
8.579106556,2081.0
8.657888251,2154.0
8.736669946,2240.0
8.815451641,2239.0
8.894233336,2278.0
8.973015031,2306.0
9.051796726,2348.0
9.130578421,2447.0
9.209360116,2552.0
9.288141811,2549.0
9.366923506,2594.0
9.445705201,2506.0
9.524486896,2359.0
9.603268591,2463.0
9.682050286,2421.0
9.760831981,2400.0
9.839613676,2382.0
9.918395371,2271.0
9.997177066,2112.0
10.075958761,2190.0
10.154740457,2077.0
10.233522152,2026.0
10.312303847,2036.0
10.391085542,1952.0
10.469867237,1890.0
10.548648932,1877.0
10.627430627,1799.0
10.706212322,1815.0
10.784994017,1704.0
10.863775712,1651.0
10.942557407,1676.0
11.021339102,1510.0
11.100120797,1578.0
11.178902492,1550.0
11.257684187,1473.0
11.336465882,1522.0
11.415247577,1574.0
11.494029272,1551.0
11.572810967,1451.0
11.651592662,1505.0
11.730374357,1522.0
11.809156052,1379.0
11.887937747,1423.0
11.966719442,1442.0
12.045501137,1373.0
12.124282832,1401.0
12.203064527,1331.0
12.281846222,1315.0
12.360627917,1334.0
12.439409612,1309.0
12.518191307,1348.0
12.596973002,1273.0
12.675754697,1389.0
12.754536392,1415.0
12.833318087,1303.0
12.912099782,1276.0
12.990881477,1335.0
13.069663172,1312.0
13.148444867,1221.0
13.227226562,1330.0
13.306008257,1185.0
13.384789952,1331.0
13.463571647,1288.0
13.542353343,1252.0
13.621135038,1218.0
13.699916733,1224.0
13.778698428,1247.0
13.857480123,1250.0
13.936261818,1275.0
14.015043513,1203.0
14.093825208,1247.0
14.172606903,1228.0
14.251388598,1233.0
14.330170293,1208.0
14.408951988,1246.0
14.487733683,1265.0
14.566515378,1217.0
14.645297073,1235.0
14.724078768,1196.0
14.802860463,1203.0
14.881642158,1157.0
14.960423853,1129.0
15.039205548,1161.0
15.117987243,1171.0
15.196768938,1236.0
15.275550633,1194.0
15.354332328,1166.0
15.433114023,1172.0
15.511895718,1119.0
15.590677413,1097.0
15.669459108,1122.0
15.748240803,1184.0
15.827022498,1124.0
15.905804193,1032.0
15.984585888,1062.0
16.063367583,1015.0
16.142149278,1065.0
16.220930973,1064.0
16.299712668,1008.0
16.378494363,1058.0
16.457276058,1126.0
16.536057753,1051.0
16.614839448,975.0
16.693621143,1092.0
16.772402838,1050.0
16.851184533,1041.0
16.929966229,1032.0
17.008747924,1039.0
17.087529619,1033.0
17.166311314,1006.0
17.245093009,999.0
17.323874704,1058.0
17.402656399,971.0
17.481438094,1043.0
17.560219789,1053.0
17.639001484,1049.0
17.717783179,1030.0
17.796564874,1029.0
17.875346569,1041.0
17.954128264,1025.0
18.032909959,1041.0
18.111691654,1048.0
18.190473349,1113.0
18.269255044,1059.0
18.348036739,971.0
18.426818434,1062.0
18.505600129,1019.0
18.584381824,1024.0
18.663163519,1004.0
18.741945214,1018.0
18.820726909,1016.0
18.899508604,1051.0
18.978290299,1031.0
19.057071994,1045.0
19.135853689,1062.0
19.214635384,1052.0
19.293417079,1071.0
19.372198774,1069.0
19.450980469,1056.0
19.529762164,1043.0
19.608543859,1090.0
19.687325554,1048.0
19.766107249,1053.0
19.844888944,1019.0
19.923670639,1015.0
20.002452334,1079.0
20.081234029,1079.0
20.160015724,961.0
20.238797419,1076.0
20.317579114,992.0
20.396360810,1050.0
20.475142505,1105.0
20.553924200,1053.0
20.632705895,1103.0
20.711487590,1064.0
20.790269285,1110.0
20.869050980,1122.0
20.947832675,1097.0
21.026614370,1072.0
21.105396065,1096.0
21.184177760,1052.0
21.262959455,1137.0
21.341741150,1071.0
21.420522845,1049.0
21.499304540,1046.0
21.578086235,1113.0
21.656867930,1158.0
21.735649625,1075.0
21.814431320,1120.0
21.893213015,1121.0
21.971994710,1092.0
22.050776405,1107.0
22.129558100,1180.0
22.208339795,1032.0
22.287121490,1122.0
22.365903185,1068.0
22.444684880,1173.0
22.523466575,1174.0
22.602248270,1131.0
22.681029965,1139.0
22.759811660,1115.0
22.838593355,1055.0
22.917375050,1084.0
22.996156745,1162.0
23.074938440,1146.0
23.153720135,1140.0
23.232501830,1154.0
23.311283525,1086.0
23.390065220,1140.0
23.468846915,1100.0
23.547628610,1136.0
23.626410305,1134.0
23.705192000,1119.0
23.783973696,1124.0
23.862755391,1135.0
23.941537086,1123.0
24.020318781,1124.0
24.099100476,1158.0
24.177882171,1118.0
24.256663866,1130.0
24.335445561,1156.0
24.414227256,1174.0
24.493008951,1110.0
24.571790646,1160.0
24.650572341,1188.0
24.729354036,1108.0
24.808135731,1127.0
24.886917426,1071.0
24.965699121,1112.0
25.044480816,1094.0
25.123262511,1127.0
25.202044206,1102.0
25.280825901,1107.0
25.359607596,1120.0
25.438389291,1110.0
25.517170986,1104.0
25.595952681,1121.0
25.674734376,1206.0
25.753516071,1136.0
25.832297766,1122.0
25.911079461,1127.0
25.989861156,1105.0
26.068642851,1127.0
26.147424546,1081.0
26.226206241,1123.0
26.304987936,1157.0
26.383769631,1133.0
26.462551326,1236.0
26.541333021,1267.0
26.620114716,1313.0
26.698896411,1142.0
26.777678106,1113.0
26.856459801,1111.0
26.935241496,1123.0
27.014023191,1218.0
27.092804886,1163.0
27.171586582,1157.0
27.250368277,1111.0
27.329149972,1133.0
27.407931667,1094.0
27.486713362,1086.0
27.565495057,1190.0
27.644276752,1115.0
27.723058447,1155.0
27.801840142,1087.0
27.880621837,1103.0
27.959403532,1130.0
28.038185227,1094.0
28.116966922,1084.0
28.195748617,1108.0
28.274530312,1093.0
28.353312007,1140.0
28.432093702,1067.0
28.510875397,1085.0
28.589657092,1105.0
28.668438787,1119.0
28.747220482,1040.0
28.826002177,1070.0
28.904783872,1042.0
28.983565567,1062.0
29.062347262,1115.0
29.141128957,1064.0
29.219910652,1100.0
29.298692347,1052.0
29.377474042,1085.0
29.456255737,1135.0
29.535037432,1057.0
29.613819127,1100.0
29.692600822,1080.0
29.771382517,1044.0
29.850164212,1122.0
29.928945907,1079.0
30.007727602,1081.0
30.086509297,1087.0
30.165290992,1126.0
30.244072687,1075.0
30.322854382,984.0
30.401636077,1054.0
30.480417772,995.0
30.559199468,1109.0
30.637981163,1043.0
30.716762858,1063.0
30.795544553,1071.0
30.874326248,1064.0
30.953107943,1082.0
31.031889638,1079.0
31.110671333,1055.0
31.189453028,1052.0
31.268234723,1062.0
31.347016418,1034.0
31.425798113,1070.0
31.504579808,974.0
31.583361503,1026.0
31.662143198,1052.0
31.740924893,1012.0
31.819706588,974.0
31.898488283,979.0
31.977269978,1031.0
32.056051673,1019.0
32.134833368,1043.0
32.213615063,981.0
32.292396758,990.0
32.371178453,986.0
32.449960148,967.0
32.528741843,970.0
32.607523538,937.0
32.686305233,1036.0
32.765086928,956.0
32.843868623,980.0
32.922650318,996.0
33.001432013,975.0
33.080213708,1023.0
33.158995403,937.0
33.237777098,957.0
33.316558793,959.0
33.395340488,952.0
33.474122183,999.0
33.552903878,957.0
33.631685573,927.0
33.710467268,903.0
33.789248963,960.0
33.868030658,998.0
33.946812354,960.0
34.025594049,924.0
34.104375744,955.0
34.183157439,891.0
34.261939134,937.0
34.340720829,899.0
34.419502524,854.0
34.498284219,971.0
34.577065914,924.0
34.655847609,965.0
34.734629304,938.0
34.813410999,892.0
34.892192694,916.0
34.970974389,871.0
35.049756084,894.0
35.128537779,917.0
35.207319474,937.0
35.286101169,859.0
35.364882864,957.0
35.443664559,866.0
35.522446254,907.0
35.601227949,846.0
35.680009644,897.0
35.758791339,910.0
35.837573034,858.0
35.916354729,920.0
35.995136424,901.0
36.073918119,835.0
36.152699814,857.0
36.231481509,835.0
36.310263204,772.0
36.389044899,881.0
36.467826594,808.0
36.546608289,835.0
36.625389984,811.0
36.704171679,827.0
36.782953374,825.0
36.861735069,827.0
36.940516764,832.0
37.019298459,826.0
37.098080154,835.0
37.176861849,866.0
37.255643544,817.0
37.334425240,803.0
37.413206935,773.0
37.491988630,788.0
37.570770325,799.0
37.649552020,854.0
37.728333715,791.0
37.807115410,800.0
37.885897105,830.0
37.964678800,789.0
38.043460495,802.0
38.122242190,795.0
38.201023885,746.0
38.279805580,808.0
38.358587275,790.0
38.437368970,808.0
38.516150665,761.0
38.594932360,764.0
38.673714055,747.0
38.752495750,750.0
38.831277445,757.0
38.910059140,785.0
38.988840835,822.0
39.067622530,794.0
39.146404225,771.0
39.225185920,870.0
39.303967615,795.0
39.382749310,777.0
39.461531005,763.0
39.540312700,783.0
39.619094395,781.0
39.697876090,758.0
39.776657785,729.0
39.855439480,811.0
39.934221175,830.0
40.013002870,754.0
40.091784565,845.0
40.170566260,828.0
40.249347955,876.0
40.328129650,863.0
40.406911345,899.0
40.485693040,825.0
40.564474735,840.0
40.643256430,864.0
40.722038126,860.0
40.800819821,865.0
40.879601516,869.0
40.958383211,905.0
41.037164906,812.0
41.115946601,873.0
41.194728296,865.0
41.273509991,860.0
41.352291686,890.0
41.431073381,982.0
41.509855076,879.0
41.588636771,896.0
41.667418466,845.0
41.746200161,843.0
41.824981856,876.0
41.903763551,834.0
41.982545246,865.0
42.061326941,840.0
42.140108636,826.0
42.218890331,888.0
42.297672026,852.0
42.376453721,859.0
42.455235416,837.0
42.534017111,873.0
42.612798806,863.0
42.691580501,835.0
42.770362196,797.0
42.849143891,826.0
42.927925586,807.0
43.006707281,798.0
43.085488976,703.0
43.164270671,779.0
43.243052366,732.0
43.321834061,760.0
43.400615756,743.0
43.479397451,690.0
43.558179146,677.0
43.636960841,710.0
43.715742536,739.0
43.794524231,687.0
43.873305926,730.0
43.952087621,699.0
44.030869316,707.0
44.109651011,667.0
44.188432707,683.0
44.267214402,749.0
44.345996097,680.0
44.424777792,645.0
44.503559487,653.0
44.582341182,645.0
44.661122877,619.0
44.739904572,631.0
44.818686267,622.0
44.897467962,598.0
44.976249657,641.0
45.055031352,624.0
45.133813047,685.0
45.212594742,612.0
45.291376437,621.0
45.370158132,561.0
45.448939827,562.0
45.527721522,597.0
45.606503217,600.0
45.685284912,591.0
45.764066607,629.0
45.842848302,558.0
45.921629997,598.0
46.000411692,537.0
46.079193387,570.0
46.157975082,590.0
46.236756777,588.0
46.315538472,577.0
46.394320167,542.0
46.473101862,549.0
46.551883557,565.0
46.630665252,513.0
46.709446947,514.0
46.788228642,528.0
46.867010337,513.0
46.945792032,566.0
47.024573727,495.0
47.103355422,553.0
47.182137117,494.0
47.260918812,518.0
47.339700507,515.0
47.418482202,488.0
47.497263897,542.0
47.576045593,477.0
47.654827288,478.0
47.733608983,480.0
47.812390678,512.0
47.891172373,493.0
47.969954068,524.0
48.048735763,548.0
48.127517458,477.0
48.206299153,459.0
48.285080848,494.0
48.363862543,497.0
48.442644238,431.0
48.521425933,498.0
48.600207628,469.0
48.678989323,483.0
48.757771018,503.0
48.836552713,462.0
48.915334408,467.0
48.994116103,457.0
49.072897798,462.0
49.151679493,500.0
49.230461188,466.0
49.309242883,479.0
49.388024578,456.0
49.466806273,461.0
49.545587968,453.0
49.624369663,466.0
49.703151358,435.0
49.781933053,447.0
49.860714748,459.0
49.939496443,438.0
50.018278138,432.0
50.097059833,488.0
50.175841528,436.0
50.254623223,475.0
50.333404918,446.0
50.412186613,425.0
50.490968308,442.0
50.569750003,429.0
50.648531698,464.0
50.727313393,431.0
50.806095088,412.0
50.884876783,434.0
50.963658479,408.0
51.042440174,439.0
51.121221869,391.0
51.200003564,388.0
51.278785259,429.0
51.357566954,422.0
51.436348649,421.0
51.515130344,411.0
51.593912039,459.0
51.672693734,406.0
51.751475429,427.0
51.830257124,440.0
51.909038819,433.0
51.987820514,446.0
52.066602209,414.0
52.145383904,416.0
52.224165599,406.0
52.302947294,400.0
52.381728989,454.0
52.460510684,411.0
52.539292379,393.0
52.618074074,410.0
52.696855769,401.0
52.775637464,439.0
52.854419159,397.0
52.933200854,432.0
53.011982549,405.0
53.090764244,391.0
53.169545939,435.0
53.248327634,338.0
53.327109329,390.0
53.405891024,380.0
53.484672719,372.0
53.563454414,391.0
53.642236109,390.0
53.721017804,387.0
53.799799499,396.0
53.878581194,411.0
53.957362889,414.0
54.036144584,372.0
54.114926279,378.0
54.193707974,411.0
54.272489669,350.0
54.351271365,349.0
54.430053060,398.0
54.508834755,382.0
54.587616450,363.0
54.666398145,411.0
54.745179840,408.0
54.823961535,412.0
54.902743230,350.0
54.981524925,363.0
55.060306620,401.0
55.139088315,409.0
55.217870010,367.0
55.296651705,390.0
55.375433400,384.0
55.454215095,387.0
55.532996790,371.0
55.611778485,351.0
55.690560180,382.0
55.769341875,386.0
55.848123570,361.0
55.926905265,388.0
56.005686960,371.0
56.084468655,395.0
56.163250350,389.0
56.242032045,326.0
56.320813740,330.0
56.399595435,402.0
56.478377130,367.0
56.557158825,342.0
56.635940520,366.0
56.714722215,399.0
56.793503910,368.0
56.872285605,388.0
56.951067300,346.0
57.029848995,382.0
57.108630690,366.0
57.187412385,358.0
57.266194080,339.0
57.344975775,380.0
57.423757470,359.0
57.502539165,342.0
57.581320860,406.0
57.660102555,354.0
57.738884251,332.0
57.817665946,340.0
57.896447641,355.0
57.975229336,355.0
58.054011031,394.0
58.132792726,311.0
58.211574421,359.0
58.290356116,357.0
58.369137811,378.0
58.447919506,359.0
58.526701201,379.0
58.605482896,386.0
58.684264591,334.0
58.763046286,332.0
58.841827981,346.0
58.920609676,382.0
58.999391371,362.0
59.078173066,356.0
59.156954761,353.0
59.235736456,354.0
59.314518151,348.0
59.393299846,366.0
59.472081541,352.0
59.550863236,369.0
59.629644931,367.0
59.708426626,366.0
59.787208321,337.0
59.865990016,346.0
59.944771711,354.0
60.023553406,373.0
60.102335101,355.0
60.181116796,333.0
60.259898491,360.0
60.338680186,357.0
60.417461881,335.0
60.496243576,309.0
60.575025271,358.0
60.653806966,352.0
60.732588661,345.0
60.811370356,358.0
60.890152051,335.0
60.968933746,350.0
61.047715441,352.0
61.126497137,363.0
61.205278832,342.0
61.284060527,328.0
61.362842222,367.0
61.441623917,318.0
61.520405612,344.0
61.599187307,336.0
61.677969002,321.0
61.756750697,292.0
61.835532392,335.0
61.914314087,340.0
61.993095782,316.0
62.071877477,347.0
62.150659172,365.0
62.229440867,333.0
62.308222562,338.0
62.387004257,326.0
62.465785952,320.0
62.544567647,343.0
62.623349342,335.0
62.702131037,319.0
62.780912732,343.0
62.859694427,343.0
62.938476122,324.0
63.017257817,311.0
63.096039512,333.0
63.174821207,345.0
63.253602902,379.0
63.332384597,299.0
63.411166292,370.0
63.489947987,345.0
63.568729682,300.0
63.647511377,328.0
63.726293072,332.0
63.805074767,323.0
63.883856462,353.0
63.962638157,340.0
64.041419852,360.0
64.120201547,379.0
64.198983242,334.0
64.277764937,342.0
64.356546632,311.0
64.435328327,325.0
64.514110023,329.0
64.592891718,312.0
64.671673413,288.0
64.750455108,331.0
64.829236803,337.0
64.908018498,286.0
64.986800193,312.0
65.065581888,315.0
65.144363583,315.0
65.223145278,291.0
65.301926973,309.0
65.380708668,311.0
65.459490363,317.0
65.538272058,334.0
65.617053753,303.0
65.695835448,294.0
65.774617143,317.0
65.853398838,319.0
65.932180533,296.0
66.010962228,304.0
66.089743923,316.0
66.168525618,309.0
66.247307313,304.0
66.326089008,310.0
66.404870703,314.0
66.483652398,306.0
66.562434093,294.0
66.641215788,338.0
66.719997483,325.0
66.798779178,297.0
66.877560873,317.0
66.956342568,310.0
67.035124263,311.0
67.113905958,304.0
67.192687653,280.0
67.271469348,325.0
67.350251043,296.0
67.429032738,288.0
67.507814433,292.0
67.586596128,317.0
67.665377823,300.0
67.744159518,295.0
67.822941213,332.0
67.901722909,320.0
67.980504604,292.0
68.059286299,290.0
68.138067994,298.0
68.216849689,309.0
68.295631384,310.0
68.374413079,299.0
68.453194774,299.0
68.531976469,265.0
68.610758164,287.0
68.689539859,314.0
68.768321554,276.0
68.847103249,304.0
68.925884944,297.0
69.004666639,285.0
69.083448334,318.0
69.162230029,291.0
69.241011724,286.0
69.319793419,317.0
69.398575114,292.0
69.477356809,272.0
69.556138504,330.0
69.634920199,274.0
69.713701894,279.0
69.792483589,293.0
69.871265284,302.0
69.950046979,310.0
70.028828674,255.0
70.107610369,312.0
70.186392064,289.0
70.265173759,274.0
70.343955454,264.0
70.422737149,274.0
70.501518844,312.0
70.580300539,282.0
70.659082234,268.0
70.737863929,288.0
70.816645624,285.0
70.895427319,303.0
70.974209014,266.0
71.052990709,284.0
71.131772404,279.0
71.210554099,292.0
71.289335794,280.0
71.368117490,303.0
71.446899185,265.0
71.525680880,236.0
71.604462575,288.0
71.683244270,299.0
71.762025965,309.0
71.840807660,305.0
71.919589355,271.0
71.998371050,246.0
72.077152745,273.0
72.155934440,265.0
72.234716135,243.0
72.313497830,313.0
72.392279525,291.0
72.471061220,282.0
72.549842915,255.0
72.628624610,269.0
72.707406305,304.0
72.786188000,330.0
72.864969695,279.0
72.943751390,266.0
73.022533085,282.0
73.101314780,269.0
73.180096475,261.0
73.258878170,316.0
73.337659865,314.0
73.416441560,305.0
73.495223255,272.0
73.574004950,288.0
73.652786645,266.0
73.731568340,250.0
73.810350035,267.0
73.889131730,276.0
73.967913425,294.0
74.046695120,299.0
74.125476815,259.0
74.204258510,266.0
74.283040205,272.0
74.361821900,264.0
74.440603595,304.0
74.519385290,260.0
74.598166985,266.0
74.676948680,236.0
74.755730376,286.0
74.834512071,277.0
74.913293766,279.0
74.992075461,264.0
75.070857156,288.0
75.149638851,236.0
75.228420546,272.0
75.307202241,272.0
75.385983936,244.0
75.464765631,266.0
75.543547326,275.0
75.622329021,280.0
75.701110716,258.0
75.779892411,272.0
75.858674106,288.0
75.937455801,244.0
76.016237496,274.0
76.095019191,291.0
76.173800886,266.0
76.252582581,306.0
76.331364276,252.0
76.410145971,249.0
76.488927666,246.0
76.567709361,276.0
76.646491056,271.0
76.725272751,235.0
76.804054446,245.0
76.882836141,258.0
76.961617836,269.0
77.040399531,263.0
77.119181226,258.0
77.197962921,270.0
77.276744616,278.0
77.355526311,231.0
77.434308006,258.0
77.513089701,237.0
77.591871396,248.0
77.670653091,281.0
77.749434786,248.0
77.828216481,262.0
77.906998176,243.0
77.985779871,224.0
78.064561566,236.0
78.143343262,262.0
78.222124957,245.0
78.300906652,281.0
78.379688347,249.0
78.458470042,306.0
78.537251737,250.0
78.616033432,245.0
78.694815127,277.0
78.773596822,254.0
78.852378517,239.0
78.931160212,222.0
79.009941907,275.0
79.088723602,250.0
79.167505297,246.0
79.246286992,233.0
79.325068687,267.0
79.403850382,273.0
79.482632077,267.0
79.561413772,266.0
79.640195467,264.0
79.718977162,225.0
79.797758857,245.0
79.876540552,253.0
79.955322247,249.0
80.034103942,258.0
80.112885637,255.0
80.191667332,264.0
80.270449027,219.0
80.349230722,243.0
80.428012417,233.0
80.506794112,223.0
80.585575807,255.0
80.664357502,271.0
80.743139197,259.0
80.821920892,251.0
80.900702587,220.0
80.979484282,241.0
81.058265977,223.0
81.137047672,253.0
81.215829367,230.0
81.294611062,228.0
81.373392757,262.0
81.452174452,243.0
81.530956148,244.0
81.609737843,243.0
81.688519538,253.0
81.767301233,248.0
81.846082928,224.0
81.924864623,210.0
82.003646318,209.0
82.082428013,262.0
82.161209708,221.0
82.239991403,227.0
82.318773098,233.0
82.397554793,222.0
82.476336488,226.0
82.555118183,239.0
82.633899878,237.0
82.712681573,231.0
82.791463268,257.0
82.870244963,231.0
82.949026658,212.0
83.027808353,253.0
83.106590048,234.0
83.185371743,230.0
83.264153438,235.0
83.342935133,252.0
83.421716828,214.0
83.500498523,238.0
83.579280218,236.0
83.658061913,223.0
83.736843608,214.0
83.815625303,209.0
83.894406998,220.0
83.973188693,234.0
84.051970388,220.0
84.130752083,235.0
84.209533778,249.0
84.288315473,227.0
84.367097168,227.0
84.445878863,221.0
84.524660558,214.0
84.603442253,237.0
84.682223948,241.0
84.761005643,241.0
84.839787338,213.0
84.918569034,226.0
84.997350729,193.0
85.076132424,225.0
85.154914119,227.0
85.233695814,215.0
85.312477509,205.0
85.391259204,207.0
85.470040899,212.0
85.548822594,228.0
85.627604289,210.0
85.706385984,205.0
85.785167679,192.0
85.863949374,229.0
85.942731069,202.0
86.021512764,229.0
86.100294459,213.0
86.179076154,219.0
86.257857849,224.0
86.336639544,212.0
86.415421239,216.0
86.494202934,218.0
86.572984629,224.0
86.651766324,209.0
86.730548019,213.0
86.809329714,228.0
86.888111409,215.0
86.966893104,230.0
87.045674799,219.0
87.124456494,230.0
87.203238189,224.0
87.282019884,208.0
87.360801579,254.0
87.439583274,238.0
87.518364969,214.0
87.597146664,214.0
87.675928359,204.0
87.754710054,216.0
87.833491749,217.0
87.912273444,201.0
87.991055139,234.0
88.069836834,206.0
88.148618529,228.0
88.227400224,200.0
88.306181920,204.0
88.384963615,224.0
88.463745310,191.0
88.542527005,224.0
88.621308700,205.0
88.700090395,229.0
88.778872090,212.0
88.857653785,224.0
88.936435480,192.0
89.015217175,218.0
89.093998870,205.0
89.172780565,205.0
89.251562260,230.0
89.330343955,201.0
89.409125650,192.0
89.487907345,221.0
89.566689040,207.0
89.645470735,208.0
89.724252430,204.0
89.803034125,219.0
89.881815820,214.0
89.960597515,242.0
89.986858080,230.0