File: 2017007296/7296-b2#.csv
[Measurement conditions]
Sample identification,
Comment - 1,"Configuration=Stage for flat samples/holders, Owner=User-1, Creation date=3/27/2015 11:56:23 AM"
Comment - 2,"Goniometer=Theta/Theta; Minimum step size 2Theta:0.0001; Minimum step size Omega:0.0001"
Comment - 3,"Sample stage=Stage for flat samples/holders"
Comment - 4,"Diffractometer system=EMPYREAN"
Comment - 5,"Measurement program=C:\PANalytical\Data Collector\Programs\Powder - Copy.xrdmp, Identifier={BEEA10DD-8FD6-4721-8940-4FBC5A4262A1}"
Comment - 6,"Fine Calibration Offset for 2Theta = -0.0130 deg"
Comment - 7,"Fine Calibration Offset for Omega = -0.0070 deg"
Anode material,Cu
K-Alpha1 wavelength,1.5405980
K-Alpha2 wavelength,1.5444260
Ratio K-Alpha2/K-Alpha1,0.500
Divergence slit,Fixed,0.38mm
Monochromator used,NO
Generator voltage, 40
Tube current, 35
File date and time,24/Jul/2017 16:34
Unit cell,
h k l, 0 0 0
Scan axis,Gonio
Scan range,5.020799997,89.999988363
Scan step size,0.0262606
No. of points, 3236
Scan type,CONTINUOUS
Time per step,18.615
[Scan points]
Angle,Intensity
5.033930280,1190.0
5.112711975,1147.0
5.191493670,1179.0
5.270275365,1159.0
5.349057060,1148.0
5.427838755,1110.0
5.506620450,1194.0
5.585402145,1133.0
5.664183840,1143.0
5.742965535,1170.0
5.821747230,1184.0
5.900528925,1199.0
5.979310620,1169.0
6.058092315,1159.0
6.136874010,1175.0
6.215655705,1104.0
6.294437400,1209.0
6.373219095,1152.0
6.452000790,1225.0
6.530782485,1204.0
6.609564180,1180.0
6.688345875,1168.0
6.767127571,1117.0
6.845909266,1145.0
6.924690961,1183.0
7.003472656,1182.0
7.082254351,1212.0
7.161036046,1155.0
7.239817741,1142.0
7.318599436,1205.0
7.397381131,1135.0
7.476162826,1162.0
7.554944521,1222.0
7.633726216,1164.0
7.712507911,1161.0
7.791289606,1118.0
7.870071301,1195.0
7.948852996,1189.0
8.027634691,1162.0
8.106416386,1116.0
8.185198081,1181.0
8.263979776,1144.0
8.342761471,1149.0
8.421543166,1092.0
8.500324861,1183.0
8.579106556,1215.0
8.657888251,1186.0
8.736669946,1183.0
8.815451641,1261.0
8.894233336,1148.0
8.973015031,1170.0
9.051796726,1169.0
9.130578421,1227.0
9.209360116,1254.0
9.288141811,1191.0
9.366923506,1218.0
9.445705201,1190.0
9.524486896,1213.0
9.603268591,1173.0
9.682050286,1281.0
9.760831981,1216.0
9.839613676,1248.0
9.918395371,1210.0
9.997177066,1256.0
10.075958761,1285.0
10.154740457,1241.0
10.233522152,1127.0
10.312303847,1194.0
10.391085542,1128.0
10.469867237,1153.0
10.548648932,1207.0
10.627430627,1188.0
10.706212322,1164.0
10.784994017,1179.0
10.863775712,1200.0
10.942557407,1157.0
11.021339102,1194.0
11.100120797,1201.0
11.178902492,1060.0
11.257684187,1149.0
11.336465882,1102.0
11.415247577,1159.0
11.494029272,1085.0
11.572810967,1070.0
11.651592662,1138.0
11.730374357,1105.0
11.809156052,1138.0
11.887937747,1130.0
11.966719442,1137.0
12.045501137,1157.0
12.124282832,1197.0
12.203064527,1115.0
12.281846222,1159.0
12.360627917,1122.0
12.439409612,1146.0
12.518191307,1148.0
12.596973002,1119.0
12.675754697,1205.0
12.754536392,1124.0
12.833318087,1151.0
12.912099782,1170.0
12.990881477,1224.0
13.069663172,1189.0
13.148444867,1181.0
13.227226562,1162.0
13.306008257,1195.0
13.384789952,1184.0
13.463571647,1165.0
13.542353343,1249.0
13.621135038,1205.0
13.699916733,1202.0
13.778698428,1156.0
13.857480123,1265.0
13.936261818,1286.0
14.015043513,1237.0
14.093825208,1261.0
14.172606903,1209.0
14.251388598,1235.0
14.330170293,1238.0
14.408951988,1282.0
14.487733683,1160.0
14.566515378,1314.0
14.645297073,1180.0
14.724078768,1201.0
14.802860463,1201.0
14.881642158,1226.0
14.960423853,1187.0
15.039205548,1091.0
15.117987243,1133.0
15.196768938,1124.0
15.275550633,1112.0
15.354332328,1043.0
15.433114023,1072.0
15.511895718,1017.0
15.590677413,1068.0
15.669459108,937.0
15.748240803,955.0
15.827022498,941.0
15.905804193,895.0
15.984585888,854.0
16.063367583,876.0
16.142149278,844.0
16.220930973,800.0
16.299712668,781.0
16.378494363,798.0
16.457276058,769.0
16.536057753,793.0
16.614839448,767.0
16.693621143,804.0
16.772402838,870.0
16.851184533,730.0
16.929966229,760.0
17.008747924,770.0
17.087529619,782.0
17.166311314,686.0
17.245093009,786.0
17.323874704,743.0
17.402656399,714.0
17.481438094,733.0
17.560219789,733.0
17.639001484,735.0
17.717783179,811.0
17.796564874,730.0
17.875346569,783.0
17.954128264,726.0
18.032909959,723.0
18.111691654,727.0
18.190473349,667.0
18.269255044,753.0
18.348036739,722.0
18.426818434,704.0
18.505600129,736.0
18.584381824,649.0
18.663163519,702.0
18.741945214,675.0
18.820726909,769.0
18.899508604,704.0
18.978290299,764.0
19.057071994,731.0
19.135853689,676.0
19.214635384,680.0
19.293417079,678.0
19.372198774,706.0
19.450980469,764.0
19.529762164,648.0
19.608543859,712.0
19.687325554,702.0
19.766107249,721.0
19.844888944,673.0
19.923670639,712.0
20.002452334,707.0
20.081234029,702.0
20.160015724,778.0
20.238797419,793.0
20.317579114,668.0
20.396360810,725.0
20.475142505,708.0
20.553924200,754.0
20.632705895,710.0
20.711487590,717.0
20.790269285,702.0
20.869050980,737.0
20.947832675,749.0
21.026614370,704.0
21.105396065,762.0
21.184177760,697.0
21.262959455,823.0
21.341741150,780.0
21.420522845,734.0
21.499304540,742.0
21.578086235,700.0
21.656867930,739.0
21.735649625,834.0
21.814431320,758.0
21.893213015,771.0
21.971994710,742.0
22.050776405,733.0
22.129558100,768.0
22.208339795,764.0
22.287121490,770.0
22.365903185,764.0
22.444684880,764.0
22.523466575,773.0
22.602248270,825.0
22.681029965,755.0
22.759811660,794.0
22.838593355,789.0
22.917375050,755.0
22.996156745,773.0
23.074938440,808.0
23.153720135,760.0
23.232501830,764.0
23.311283525,812.0
23.390065220,788.0
23.468846915,791.0
23.547628610,791.0
23.626410305,778.0
23.705192000,869.0
23.783973696,801.0
23.862755391,779.0
23.941537086,786.0
24.020318781,836.0
24.099100476,808.0
24.177882171,814.0
24.256663866,792.0
24.335445561,818.0
24.414227256,778.0
24.493008951,834.0
24.571790646,805.0
24.650572341,819.0
24.729354036,787.0
24.808135731,803.0
24.886917426,815.0
24.965699121,819.0
25.044480816,756.0
25.123262511,840.0
25.202044206,838.0
25.280825901,736.0
25.359607596,808.0
25.438389291,813.0
25.517170986,756.0
25.595952681,835.0
25.674734376,834.0
25.753516071,811.0
25.832297766,775.0
25.911079461,797.0
25.989861156,836.0
26.068642851,793.0
26.147424546,819.0
26.226206241,814.0
26.304987936,845.0
26.383769631,902.0
26.462551326,854.0
26.541333021,810.0
26.620114716,778.0
26.698896411,811.0
26.777678106,854.0
26.856459801,807.0
26.935241496,861.0
27.014023191,804.0
27.092804886,794.0
27.171586582,840.0
27.250368277,841.0
27.329149972,851.0
27.407931667,827.0
27.486713362,814.0
27.565495057,839.0
27.644276752,837.0
27.723058447,842.0
27.801840142,864.0
27.880621837,828.0
27.959403532,813.0
28.038185227,789.0
28.116966922,820.0
28.195748617,750.0
28.274530312,802.0
28.353312007,848.0
28.432093702,854.0
28.510875397,831.0
28.589657092,846.0
28.668438787,887.0
28.747220482,819.0
28.826002177,825.0
28.904783872,874.0
28.983565567,807.0
29.062347262,824.0
29.141128957,794.0
29.219910652,813.0
29.298692347,800.0
29.377474042,818.0
29.456255737,804.0
29.535037432,783.0
29.613819127,865.0
29.692600822,795.0
29.771382517,787.0
29.850164212,824.0
29.928945907,807.0
30.007727602,822.0
30.086509297,895.0
30.165290992,781.0
30.244072687,768.0
30.322854382,795.0
30.401636077,804.0
30.480417772,830.0
30.559199468,782.0
30.637981163,816.0
30.716762858,757.0
30.795544553,780.0
30.874326248,768.0
30.953107943,723.0
31.031889638,744.0
31.110671333,676.0
31.189453028,770.0
31.268234723,696.0
31.347016418,769.0
31.425798113,715.0
31.504579808,778.0
31.583361503,706.0
31.662143198,743.0
31.740924893,695.0
31.819706588,713.0
31.898488283,726.0
31.977269978,731.0
32.056051673,693.0
32.134833368,716.0
32.213615063,725.0
32.292396758,745.0
32.371178453,717.0
32.449960148,693.0
32.528741843,661.0
32.607523538,742.0
32.686305233,725.0
32.765086928,679.0
32.843868623,660.0
32.922650318,695.0
33.001432013,674.0
33.080213708,686.0
33.158995403,645.0
33.237777098,641.0
33.316558793,648.0
33.395340488,628.0
33.474122183,691.0
33.552903878,666.0
33.631685573,687.0
33.710467268,674.0
33.789248963,617.0
33.868030658,650.0
33.946812354,643.0
34.025594049,590.0
34.104375744,640.0
34.183157439,631.0
34.261939134,643.0
34.340720829,705.0
34.419502524,587.0
34.498284219,642.0
34.577065914,620.0
34.655847609,646.0
34.734629304,599.0
34.813410999,614.0
34.892192694,622.0
34.970974389,625.0
35.049756084,559.0
35.128537779,572.0
35.207319474,611.0
35.286101169,615.0
35.364882864,640.0
35.443664559,626.0
35.522446254,580.0
35.601227949,621.0
35.680009644,612.0
35.758791339,650.0
35.837573034,654.0
35.916354729,579.0
35.995136424,592.0
36.073918119,567.0
36.152699814,644.0
36.231481509,617.0
36.310263204,569.0
36.389044899,614.0
36.467826594,635.0
36.546608289,610.0
36.625389984,599.0
36.704171679,615.0
36.782953374,574.0
36.861735069,630.0
36.940516764,623.0
37.019298459,652.0
37.098080154,588.0
37.176861849,636.0
37.255643544,628.0
37.334425240,628.0
37.413206935,616.0
37.491988630,568.0
37.570770325,630.0
37.649552020,558.0
37.728333715,638.0
37.807115410,627.0
37.885897105,631.0
37.964678800,623.0
38.043460495,653.0
38.122242190,626.0
38.201023885,660.0
38.279805580,616.0
38.358587275,587.0
38.437368970,611.0
38.516150665,651.0
38.594932360,661.0
38.673714055,631.0
38.752495750,661.0
38.831277445,686.0
38.910059140,658.0
38.988840835,672.0
39.067622530,683.0
39.146404225,673.0
39.225185920,735.0
39.303967615,751.0
39.382749310,717.0
39.461531005,760.0
39.540312700,763.0
39.619094395,820.0
39.697876090,848.0
39.776657785,889.0
39.855439480,886.0
39.934221175,938.0
40.013002870,939.0
40.091784565,970.0
40.170566260,1049.0
40.249347955,1127.0
40.328129650,1122.0
40.406911345,1141.0
40.485693040,1207.0
40.564474735,1212.0
40.643256430,1225.0
40.722038126,1160.0
40.800819821,1184.0
40.879601516,1214.0
40.958383211,1191.0
41.037164906,1153.0
41.115946601,1205.0
41.194728296,1089.0
41.273509991,1123.0
41.352291686,1150.0
41.431073381,1114.0
41.509855076,1072.0
41.588636771,1077.0
41.667418466,1087.0
41.746200161,1131.0
41.824981856,1076.0
41.903763551,1043.0
41.982545246,1099.0
42.061326941,1087.0
42.140108636,1003.0
42.218890331,1016.0
42.297672026,995.0
42.376453721,971.0
42.455235416,972.0
42.534017111,975.0
42.612798806,1009.0
42.691580501,968.0
42.770362196,975.0
42.849143891,950.0
42.927925586,912.0
43.006707281,910.0
43.085488976,830.0
43.164270671,874.0
43.243052366,795.0
43.321834061,858.0
43.400615756,804.0
43.479397451,785.0
43.558179146,783.0
43.636960841,766.0
43.715742536,747.0
43.794524231,768.0
43.873305926,725.0
43.952087621,770.0
44.030869316,720.0
44.109651011,674.0
44.188432707,651.0
44.267214402,721.0
44.345996097,734.0
44.424777792,736.0
44.503559487,678.0
44.582341182,644.0
44.661122877,690.0
44.739904572,596.0
44.818686267,654.0
44.897467962,630.0
44.976249657,657.0
45.055031352,612.0
45.133813047,625.0
45.212594742,578.0
45.291376437,562.0
45.370158132,581.0
45.448939827,588.0
45.527721522,595.0
45.606503217,535.0
45.685284912,533.0
45.764066607,566.0
45.842848302,575.0
45.921629997,558.0
46.000411692,549.0
46.079193387,529.0
46.157975082,525.0
46.236756777,524.0
46.315538472,534.0
46.394320167,512.0
46.473101862,482.0
46.551883557,505.0
46.630665252,479.0
46.709446947,517.0
46.788228642,551.0
46.867010337,509.0
46.945792032,525.0
47.024573727,507.0
47.103355422,526.0
47.182137117,457.0
47.260918812,507.0
47.339700507,509.0
47.418482202,490.0
47.497263897,484.0
47.576045593,493.0
47.654827288,459.0
47.733608983,457.0
47.812390678,475.0
47.891172373,482.0
47.969954068,450.0
48.048735763,465.0
48.127517458,446.0
48.206299153,430.0
48.285080848,421.0
48.363862543,430.0
48.442644238,431.0
48.521425933,440.0
48.600207628,416.0
48.678989323,384.0
48.757771018,418.0
48.836552713,414.0
48.915334408,430.0
48.994116103,365.0
49.072897798,395.0
49.151679493,384.0
49.230461188,424.0
49.309242883,432.0
49.388024578,372.0
49.466806273,404.0
49.545587968,390.0
49.624369663,373.0
49.703151358,392.0
49.781933053,376.0
49.860714748,380.0
49.939496443,402.0
50.018278138,386.0
50.097059833,374.0
50.175841528,352.0
50.254623223,403.0
50.333404918,376.0
50.412186613,391.0
50.490968308,384.0
50.569750003,344.0
50.648531698,358.0
50.727313393,381.0
50.806095088,347.0
50.884876783,369.0
50.963658479,329.0
51.042440174,350.0
51.121221869,381.0
51.200003564,349.0
51.278785259,360.0
51.357566954,364.0
51.436348649,355.0
51.515130344,350.0
51.593912039,370.0
51.672693734,358.0
51.751475429,339.0
51.830257124,357.0
51.909038819,386.0
51.987820514,296.0
52.066602209,353.0
52.145383904,314.0
52.224165599,337.0
52.302947294,349.0
52.381728989,358.0
52.460510684,305.0
52.539292379,340.0
52.618074074,330.0
52.696855769,343.0
52.775637464,334.0
52.854419159,340.0
52.933200854,355.0
53.011982549,358.0
53.090764244,336.0
53.169545939,311.0
53.248327634,352.0
53.327109329,346.0
53.405891024,333.0
53.484672719,342.0
53.563454414,341.0
53.642236109,331.0
53.721017804,361.0
53.799799499,336.0
53.878581194,331.0
53.957362889,320.0
54.036144584,347.0
54.114926279,330.0
54.193707974,325.0
54.272489669,322.0
54.351271365,322.0
54.430053060,343.0
54.508834755,351.0
54.587616450,332.0
54.666398145,336.0
54.745179840,315.0
54.823961535,336.0
54.902743230,312.0
54.981524925,307.0
55.060306620,349.0
55.139088315,351.0
55.217870010,280.0
55.296651705,330.0
55.375433400,315.0
55.454215095,321.0
55.532996790,321.0
55.611778485,284.0
55.690560180,321.0
55.769341875,329.0
55.848123570,332.0
55.926905265,354.0
56.005686960,301.0
56.084468655,322.0
56.163250350,333.0
56.242032045,290.0
56.320813740,338.0
56.399595435,334.0
56.478377130,340.0
56.557158825,339.0
56.635940520,335.0
56.714722215,325.0
56.793503910,317.0
56.872285605,304.0
56.951067300,304.0
57.029848995,298.0
57.108630690,311.0
57.187412385,290.0
57.266194080,344.0
57.344975775,333.0
57.423757470,326.0
57.502539165,353.0
57.581320860,302.0
57.660102555,298.0
57.738884251,314.0
57.817665946,328.0
57.896447641,317.0
57.975229336,348.0
58.054011031,316.0
58.132792726,342.0
58.211574421,310.0
58.290356116,303.0
58.369137811,328.0
58.447919506,331.0
58.526701201,301.0
58.605482896,315.0
58.684264591,305.0
58.763046286,287.0
58.841827981,300.0
58.920609676,307.0
58.999391371,306.0
59.078173066,332.0
59.156954761,316.0
59.235736456,288.0
59.314518151,291.0
59.393299846,304.0
59.472081541,304.0
59.550863236,323.0
59.629644931,318.0
59.708426626,332.0
59.787208321,302.0
59.865990016,297.0
59.944771711,314.0
60.023553406,282.0
60.102335101,303.0
60.181116796,302.0
60.259898491,299.0
60.338680186,315.0
60.417461881,303.0
60.496243576,301.0
60.575025271,296.0
60.653806966,327.0
60.732588661,313.0
60.811370356,292.0
60.890152051,330.0
60.968933746,327.0
61.047715441,284.0
61.126497137,314.0
61.205278832,323.0
61.284060527,313.0
61.362842222,353.0
61.441623917,306.0
61.520405612,292.0
61.599187307,348.0
61.677969002,310.0
61.756750697,333.0
61.835532392,319.0
61.914314087,306.0
61.993095782,328.0
62.071877477,310.0
62.150659172,303.0
62.229440867,297.0
62.308222562,302.0
62.387004257,309.0
62.465785952,274.0
62.544567647,282.0
62.623349342,307.0
62.702131037,273.0
62.780912732,270.0
62.859694427,270.0
62.938476122,286.0
63.017257817,274.0
63.096039512,269.0
63.174821207,306.0
63.253602902,290.0
63.332384597,283.0
63.411166292,272.0
63.489947987,297.0
63.568729682,300.0
63.647511377,246.0
63.726293072,283.0
63.805074767,289.0
63.883856462,319.0
63.962638157,297.0
64.041419852,269.0
64.120201547,299.0
64.198983242,296.0
64.277764937,295.0
64.356546632,301.0
64.435328327,296.0
64.514110023,305.0
64.592891718,301.0
64.671673413,298.0
64.750455108,274.0
64.829236803,298.0
64.908018498,317.0
64.986800193,310.0
65.065581888,286.0
65.144363583,261.0
65.223145278,297.0
65.301926973,264.0
65.380708668,266.0
65.459490363,272.0
65.538272058,273.0
65.617053753,268.0
65.695835448,253.0
65.774617143,278.0
65.853398838,273.0
65.932180533,271.0
66.010962228,278.0
66.089743923,261.0
66.168525618,250.0
66.247307313,306.0
66.326089008,266.0
66.404870703,300.0
66.483652398,279.0
66.562434093,290.0
66.641215788,234.0
66.719997483,263.0
66.798779178,287.0
66.877560873,268.0
66.956342568,246.0
67.035124263,300.0
67.113905958,241.0
67.192687653,294.0
67.271469348,244.0
67.350251043,270.0
67.429032738,247.0
67.507814433,242.0
67.586596128,292.0
67.665377823,308.0
67.744159518,205.0
67.822941213,240.0
67.901722909,255.0
67.980504604,259.0
68.059286299,260.0
68.138067994,289.0
68.216849689,265.0
68.295631384,264.0
68.374413079,230.0
68.453194774,244.0
68.531976469,254.0
68.610758164,257.0
68.689539859,269.0
68.768321554,297.0
68.847103249,297.0
68.925884944,254.0
69.004666639,268.0
69.083448334,249.0
69.162230029,291.0
69.241011724,272.0
69.319793419,262.0
69.398575114,263.0
69.477356809,264.0
69.556138504,248.0
69.634920199,270.0
69.713701894,257.0
69.792483589,251.0
69.871265284,250.0
69.950046979,250.0
70.028828674,218.0
70.107610369,246.0
70.186392064,266.0
70.265173759,262.0
70.343955454,269.0
70.422737149,274.0
70.501518844,225.0
70.580300539,255.0
70.659082234,260.0
70.737863929,273.0
70.816645624,270.0
70.895427319,283.0
70.974209014,256.0
71.052990709,247.0
71.131772404,236.0
71.210554099,232.0
71.289335794,253.0
71.368117490,234.0
71.446899185,251.0
71.525680880,237.0
71.604462575,238.0
71.683244270,263.0
71.762025965,251.0
71.840807660,245.0
71.919589355,277.0
71.998371050,274.0
72.077152745,276.0
72.155934440,259.0
72.234716135,311.0
72.313497830,265.0
72.392279525,292.0
72.471061220,274.0
72.549842915,274.0
72.628624610,299.0
72.707406305,257.0
72.786188000,293.0
72.864969695,245.0
72.943751390,278.0
73.022533085,290.0
73.101314780,304.0
73.180096475,300.0
73.258878170,310.0
73.337659865,323.0
73.416441560,301.0
73.495223255,293.0
73.574004950,296.0
73.652786645,309.0
73.731568340,284.0
73.810350035,307.0
73.889131730,288.0
73.967913425,269.0
74.046695120,298.0
74.125476815,297.0
74.204258510,278.0
74.283040205,266.0
74.361821900,286.0
74.440603595,264.0
74.519385290,262.0
74.598166985,245.0
74.676948680,292.0
74.755730376,255.0
74.834512071,292.0
74.913293766,262.0
74.992075461,259.0
75.070857156,284.0
75.149638851,273.0
75.228420546,242.0
75.307202241,259.0
75.385983936,266.0
75.464765631,226.0
75.543547326,232.0
75.622329021,246.0
75.701110716,244.0
75.779892411,262.0
75.858674106,268.0
75.937455801,221.0
76.016237496,224.0
76.095019191,220.0
76.173800886,251.0
76.252582581,245.0
76.331364276,226.0
76.410145971,220.0
76.488927666,242.0
76.567709361,253.0
76.646491056,226.0
76.725272751,238.0
76.804054446,209.0
76.882836141,261.0
76.961617836,218.0
77.040399531,233.0
77.119181226,227.0
77.197962921,220.0
77.276744616,257.0
77.355526311,250.0
77.434308006,238.0
77.513089701,232.0
77.591871396,235.0
77.670653091,278.0
77.749434786,241.0
77.828216481,226.0
77.906998176,246.0
77.985779871,243.0
78.064561566,236.0
78.143343262,238.0
78.222124957,238.0
78.300906652,255.0
78.379688347,199.0
78.458470042,219.0
78.537251737,223.0
78.616033432,249.0
78.694815127,238.0
78.773596822,221.0
78.852378517,219.0
78.931160212,242.0
79.009941907,216.0
79.088723602,237.0
79.167505297,234.0
79.246286992,256.0
79.325068687,245.0
79.403850382,220.0
79.482632077,255.0
79.561413772,255.0
79.640195467,234.0
79.718977162,216.0
79.797758857,219.0
79.876540552,256.0
79.955322247,219.0
80.034103942,232.0
80.112885637,219.0
80.191667332,247.0
80.270449027,228.0
80.349230722,237.0
80.428012417,234.0
80.506794112,232.0
80.585575807,211.0
80.664357502,228.0
80.743139197,207.0
80.821920892,232.0
80.900702587,214.0
80.979484282,237.0
81.058265977,220.0
81.137047672,221.0
81.215829367,212.0
81.294611062,183.0
81.373392757,216.0
81.452174452,226.0
81.530956148,229.0
81.609737843,223.0
81.688519538,198.0
81.767301233,228.0
81.846082928,231.0
81.924864623,217.0
82.003646318,234.0
82.082428013,196.0
82.161209708,214.0
82.239991403,205.0
82.318773098,233.0
82.397554793,229.0
82.476336488,214.0
82.555118183,232.0
82.633899878,242.0
82.712681573,195.0
82.791463268,204.0
82.870244963,239.0
82.949026658,214.0
83.027808353,220.0
83.106590048,239.0
83.185371743,226.0
83.264153438,221.0
83.342935133,196.0
83.421716828,225.0
83.500498523,193.0
83.579280218,250.0
83.658061913,217.0
83.736843608,188.0
83.815625303,194.0
83.894406998,184.0
83.973188693,205.0
84.051970388,179.0
84.130752083,202.0
84.209533778,200.0
84.288315473,228.0
84.367097168,196.0
84.445878863,235.0
84.524660558,204.0
84.603442253,209.0
84.682223948,176.0
84.761005643,213.0
84.839787338,215.0
84.918569034,204.0
84.997350729,237.0
85.076132424,224.0
85.154914119,168.0
85.233695814,206.0
85.312477509,208.0
85.391259204,215.0
85.470040899,217.0
85.548822594,206.0
85.627604289,209.0
85.706385984,211.0
85.785167679,197.0
85.863949374,178.0
85.942731069,215.0
86.021512764,188.0
86.100294459,211.0
86.179076154,177.0
86.257857849,210.0
86.336639544,202.0
86.415421239,212.0
86.494202934,191.0
86.572984629,216.0
86.651766324,202.0
86.730548019,210.0
86.809329714,193.0
86.888111409,222.0
86.966893104,211.0
87.045674799,212.0
87.124456494,223.0
87.203238189,218.0
87.282019884,211.0
87.360801579,215.0
87.439583274,223.0
87.518364969,231.0
87.597146664,201.0
87.675928359,194.0
87.754710054,206.0
87.833491749,207.0
87.912273444,196.0
87.991055139,188.0
88.069836834,219.0
88.148618529,183.0
88.227400224,203.0
88.306181920,177.0
88.384963615,205.0
88.463745310,211.0
88.542527005,241.0
88.621308700,218.0
88.700090395,202.0
88.778872090,200.0
88.857653785,198.0
88.936435480,203.0
89.015217175,193.0
89.093998870,208.0
89.172780565,211.0
89.251562260,194.0
89.330343955,216.0
89.409125650,196.0
89.487907345,212.0
89.566689040,194.0
89.645470735,213.0
89.724252430,217.0
89.803034125,185.0
89.881815820,210.0
89.960597515,196.0
89.986858080,199.0