File: 2017007296/7296-b5#.csv
[Measurement conditions]
Sample identification,
Comment - 1,"Configuration=Stage for flat samples/holders, Owner=User-1, Creation date=3/27/2015 11:56:23 AM"
Comment - 2,"Goniometer=Theta/Theta; Minimum step size 2Theta:0.0001; Minimum step size Omega:0.0001"
Comment - 3,"Sample stage=Stage for flat samples/holders"
Comment - 4,"Diffractometer system=EMPYREAN"
Comment - 5,"Measurement program=C:\PANalytical\Data Collector\Programs\Powder - Copy.xrdmp, Identifier={BEEA10DD-8FD6-4721-8940-4FBC5A4262A1}"
Comment - 6,"Fine Calibration Offset for 2Theta = -0.0130 deg"
Comment - 7,"Fine Calibration Offset for Omega = -0.0070 deg"
Anode material,Cu
K-Alpha1 wavelength,1.5405980
K-Alpha2 wavelength,1.5444260
Ratio K-Alpha2/K-Alpha1,0.500
Divergence slit,Fixed,0.38mm
Monochromator used,NO
Generator voltage, 40
Tube current, 35
File date and time,24/Jul/2017 16:52
Unit cell,
h k l, 0 0 0
Scan axis,Gonio
Scan range,5.020799997,89.999988363
Scan step size,0.0262606
No. of points, 3236
Scan type,CONTINUOUS
Time per step,18.615
[Scan points]
Angle,Intensity
5.033930280,1818.0
5.112711975,1779.0
5.191493670,1753.0
5.270275365,1842.0
5.349057060,1801.0
5.427838755,1740.0
5.506620450,1718.0
5.585402145,1770.0
5.664183840,1881.0
5.742965535,1783.0
5.821747230,1803.0
5.900528925,1700.0
5.979310620,1711.0
6.058092315,1669.0
6.136874010,1689.0
6.215655705,1652.0
6.294437400,1708.0
6.373219095,1664.0
6.452000790,1550.0
6.530782485,1605.0
6.609564180,1607.0
6.688345875,1626.0
6.767127571,1622.0
6.845909266,1603.0
6.924690961,1584.0
7.003472656,1683.0
7.082254351,1562.0
7.161036046,1601.0
7.239817741,1508.0
7.318599436,1505.0
7.397381131,1568.0
7.476162826,1446.0
7.554944521,1530.0
7.633726216,1422.0
7.712507911,1453.0
7.791289606,1370.0
7.870071301,1400.0
7.948852996,1455.0
8.027634691,1357.0
8.106416386,1452.0
8.185198081,1415.0
8.263979776,1362.0
8.342761471,1400.0
8.421543166,1305.0
8.500324861,1361.0
8.579106556,1429.0
8.657888251,1388.0
8.736669946,1227.0
8.815451641,1376.0
8.894233336,1339.0
8.973015031,1356.0
9.051796726,1363.0
9.130578421,1300.0
9.209360116,1318.0
9.288141811,1366.0
9.366923506,1376.0
9.445705201,1316.0
9.524486896,1255.0
9.603268591,1352.0
9.682050286,1336.0
9.760831981,1232.0
9.839613676,1245.0
9.918395371,1269.0
9.997177066,1268.0
10.075958761,1260.0
10.154740457,1261.0
10.233522152,1193.0
10.312303847,1274.0
10.391085542,1295.0
10.469867237,1305.0
10.548648932,1265.0
10.627430627,1290.0
10.706212322,1178.0
10.784994017,1180.0
10.863775712,1246.0
10.942557407,1223.0
11.021339102,1212.0
11.100120797,1190.0
11.178902492,1168.0
11.257684187,1226.0
11.336465882,1200.0
11.415247577,1200.0
11.494029272,1196.0
11.572810967,1207.0
11.651592662,1254.0
11.730374357,1126.0
11.809156052,1175.0
11.887937747,1191.0
11.966719442,1207.0
12.045501137,1251.0
12.124282832,1204.0
12.203064527,1186.0
12.281846222,1161.0
12.360627917,1222.0
12.439409612,1231.0
12.518191307,1182.0
12.596973002,1236.0
12.675754697,1241.0
12.754536392,1247.0
12.833318087,1174.0
12.912099782,1269.0
12.990881477,1250.0
13.069663172,1265.0
13.148444867,1316.0
13.227226562,1255.0
13.306008257,1224.0
13.384789952,1326.0
13.463571647,1255.0
13.542353343,1338.0
13.621135038,1272.0
13.699916733,1309.0
13.778698428,1251.0
13.857480123,1326.0
13.936261818,1261.0
14.015043513,1294.0
14.093825208,1352.0
14.172606903,1311.0
14.251388598,1338.0
14.330170293,1271.0
14.408951988,1300.0
14.487733683,1334.0
14.566515378,1375.0
14.645297073,1345.0
14.724078768,1367.0
14.802860463,1318.0
14.881642158,1305.0
14.960423853,1248.0
15.039205548,1247.0
15.117987243,1280.0
15.196768938,1184.0
15.275550633,1101.0
15.354332328,1186.0
15.433114023,1080.0
15.511895718,986.0
15.590677413,1003.0
15.669459108,978.0
15.748240803,905.0
15.827022498,906.0
15.905804193,822.0
15.984585888,786.0
16.063367583,801.0
16.142149278,753.0
16.220930973,742.0
16.299712668,714.0
16.378494363,706.0
16.457276058,650.0
16.536057753,712.0
16.614839448,604.0
16.693621143,670.0
16.772402838,598.0
16.851184533,645.0
16.929966229,625.0
17.008747924,641.0
17.087529619,568.0
17.166311314,591.0
17.245093009,571.0
17.323874704,543.0
17.402656399,516.0
17.481438094,535.0
17.560219789,545.0
17.639001484,578.0
17.717783179,560.0
17.796564874,537.0
17.875346569,561.0
17.954128264,494.0
18.032909959,528.0
18.111691654,488.0
18.190473349,518.0
18.269255044,548.0
18.348036739,520.0
18.426818434,504.0
18.505600129,513.0
18.584381824,496.0
18.663163519,495.0
18.741945214,519.0
18.820726909,496.0
18.899508604,468.0
18.978290299,440.0
19.057071994,453.0
19.135853689,466.0
19.214635384,487.0
19.293417079,473.0
19.372198774,473.0
19.450980469,456.0
19.529762164,481.0
19.608543859,412.0
19.687325554,467.0
19.766107249,454.0
19.844888944,425.0
19.923670639,434.0
20.002452334,464.0
20.081234029,464.0
20.160015724,454.0
20.238797419,436.0
20.317579114,448.0
20.396360810,447.0
20.475142505,446.0
20.553924200,453.0
20.632705895,423.0
20.711487590,433.0
20.790269285,393.0
20.869050980,401.0
20.947832675,464.0
21.026614370,426.0
21.105396065,424.0
21.184177760,457.0
21.262959455,415.0
21.341741150,431.0
21.420522845,438.0
21.499304540,431.0
21.578086235,411.0
21.656867930,389.0
21.735649625,451.0
21.814431320,425.0
21.893213015,429.0
21.971994710,441.0
22.050776405,431.0
22.129558100,447.0
22.208339795,420.0
22.287121490,417.0
22.365903185,432.0
22.444684880,417.0
22.523466575,431.0
22.602248270,416.0
22.681029965,469.0
22.759811660,423.0
22.838593355,391.0
22.917375050,475.0
22.996156745,441.0
23.074938440,444.0
23.153720135,487.0
23.232501830,505.0
23.311283525,475.0
23.390065220,423.0
23.468846915,421.0
23.547628610,453.0
23.626410305,444.0
23.705192000,459.0
23.783973696,437.0
23.862755391,414.0
23.941537086,432.0
24.020318781,460.0
24.099100476,476.0
24.177882171,442.0
24.256663866,478.0
24.335445561,455.0
24.414227256,481.0
24.493008951,392.0
24.571790646,444.0
24.650572341,469.0
24.729354036,492.0
24.808135731,442.0
24.886917426,477.0
24.965699121,474.0
25.044480816,462.0
25.123262511,471.0
25.202044206,450.0
25.280825901,458.0
25.359607596,477.0
25.438389291,458.0
25.517170986,420.0
25.595952681,439.0
25.674734376,506.0
25.753516071,464.0
25.832297766,454.0
25.911079461,462.0
25.989861156,464.0
26.068642851,448.0
26.147424546,517.0
26.226206241,473.0
26.304987936,468.0
26.383769631,447.0
26.462551326,484.0
26.541333021,526.0
26.620114716,457.0
26.698896411,468.0
26.777678106,476.0
26.856459801,451.0
26.935241496,473.0
27.014023191,478.0
27.092804886,506.0
27.171586582,480.0
27.250368277,476.0
27.329149972,483.0
27.407931667,487.0
27.486713362,468.0
27.565495057,521.0
27.644276752,501.0
27.723058447,510.0
27.801840142,497.0
27.880621837,516.0
27.959403532,525.0
28.038185227,535.0
28.116966922,518.0
28.195748617,507.0
28.274530312,513.0
28.353312007,524.0
28.432093702,529.0
28.510875397,490.0
28.589657092,487.0
28.668438787,467.0
28.747220482,538.0
28.826002177,524.0
28.904783872,544.0
28.983565567,486.0
29.062347262,531.0
29.141128957,539.0
29.219910652,480.0
29.298692347,551.0
29.377474042,499.0
29.456255737,559.0
29.535037432,542.0
29.613819127,561.0
29.692600822,528.0
29.771382517,523.0
29.850164212,496.0
29.928945907,480.0
30.007727602,455.0
30.086509297,529.0
30.165290992,532.0
30.244072687,501.0
30.322854382,544.0
30.401636077,485.0
30.480417772,503.0
30.559199468,517.0
30.637981163,499.0
30.716762858,544.0
30.795544553,476.0
30.874326248,464.0
30.953107943,552.0
31.031889638,501.0
31.110671333,544.0
31.189453028,538.0
31.268234723,476.0
31.347016418,485.0
31.425798113,478.0
31.504579808,470.0
31.583361503,444.0
31.662143198,475.0
31.740924893,486.0
31.819706588,465.0
31.898488283,452.0
31.977269978,461.0
32.056051673,476.0
32.134833368,476.0
32.213615063,457.0
32.292396758,472.0
32.371178453,507.0
32.449960148,444.0
32.528741843,447.0
32.607523538,459.0
32.686305233,503.0
32.765086928,463.0
32.843868623,491.0
32.922650318,447.0
33.001432013,465.0
33.080213708,448.0
33.158995403,482.0
33.237777098,480.0
33.316558793,455.0
33.395340488,448.0
33.474122183,420.0
33.552903878,444.0
33.631685573,434.0
33.710467268,437.0
33.789248963,471.0
33.868030658,446.0
33.946812354,436.0
34.025594049,434.0
34.104375744,511.0
34.183157439,446.0
34.261939134,426.0
34.340720829,458.0
34.419502524,475.0
34.498284219,474.0
34.577065914,478.0
34.655847609,477.0
34.734629304,441.0
34.813410999,463.0
34.892192694,500.0
34.970974389,489.0
35.049756084,468.0
35.128537779,467.0
35.207319474,429.0
35.286101169,462.0
35.364882864,466.0
35.443664559,518.0
35.522446254,447.0
35.601227949,487.0
35.680009644,486.0
35.758791339,452.0
35.837573034,463.0
35.916354729,495.0
35.995136424,536.0
36.073918119,466.0
36.152699814,491.0
36.231481509,483.0
36.310263204,468.0
36.389044899,494.0
36.467826594,469.0
36.546608289,462.0
36.625389984,530.0
36.704171679,475.0
36.782953374,496.0
36.861735069,483.0
36.940516764,480.0
37.019298459,494.0
37.098080154,510.0
37.176861849,502.0
37.255643544,483.0
37.334425240,530.0
37.413206935,555.0
37.491988630,558.0
37.570770325,515.0
37.649552020,531.0
37.728333715,556.0
37.807115410,511.0
37.885897105,515.0
37.964678800,560.0
38.043460495,502.0
38.122242190,504.0
38.201023885,537.0
38.279805580,547.0
38.358587275,534.0
38.437368970,596.0
38.516150665,547.0
38.594932360,607.0
38.673714055,590.0
38.752495750,662.0
38.831277445,632.0
38.910059140,714.0
38.988840835,680.0
39.067622530,648.0
39.146404225,670.0
39.225185920,649.0
39.303967615,724.0
39.382749310,711.0
39.461531005,708.0
39.540312700,752.0
39.619094395,846.0
39.697876090,821.0
39.776657785,897.0
39.855439480,928.0
39.934221175,1026.0
40.013002870,1088.0
40.091784565,1111.0
40.170566260,1287.0
40.249347955,1312.0
40.328129650,1346.0
40.406911345,1426.0
40.485693040,1458.0
40.564474735,1422.0
40.643256430,1464.0
40.722038126,1519.0
40.800819821,1456.0
40.879601516,1507.0
40.958383211,1479.0
41.037164906,1508.0
41.115946601,1448.0
41.194728296,1434.0
41.273509991,1463.0
41.352291686,1423.0
41.431073381,1444.0
41.509855076,1408.0
41.588636771,1380.0
41.667418466,1418.0
41.746200161,1377.0
41.824981856,1383.0
41.903763551,1359.0
41.982545246,1228.0
42.061326941,1322.0
42.140108636,1278.0
42.218890331,1330.0
42.297672026,1237.0
42.376453721,1181.0
42.455235416,1145.0
42.534017111,1198.0
42.612798806,1130.0
42.691580501,1152.0
42.770362196,1152.0
42.849143891,1101.0
42.927925586,1159.0
43.006707281,1041.0
43.085488976,1062.0
43.164270671,1032.0
43.243052366,1006.0
43.321834061,1030.0
43.400615756,1037.0
43.479397451,981.0
43.558179146,931.0
43.636960841,992.0
43.715742536,833.0
43.794524231,917.0
43.873305926,860.0
43.952087621,921.0
44.030869316,909.0
44.109651011,881.0
44.188432707,858.0
44.267214402,829.0
44.345996097,820.0
44.424777792,757.0
44.503559487,815.0
44.582341182,777.0
44.661122877,784.0
44.739904572,744.0
44.818686267,716.0
44.897467962,741.0
44.976249657,745.0
45.055031352,738.0
45.133813047,692.0
45.212594742,643.0
45.291376437,694.0
45.370158132,710.0
45.448939827,721.0
45.527721522,713.0
45.606503217,700.0
45.685284912,683.0
45.764066607,641.0
45.842848302,685.0
45.921629997,663.0
46.000411692,577.0
46.079193387,587.0
46.157975082,607.0
46.236756777,646.0
46.315538472,650.0
46.394320167,602.0
46.473101862,627.0
46.551883557,664.0
46.630665252,609.0
46.709446947,603.0
46.788228642,602.0
46.867010337,551.0
46.945792032,483.0
47.024573727,513.0
47.103355422,531.0
47.182137117,507.0
47.260918812,510.0
47.339700507,522.0
47.418482202,537.0
47.497263897,502.0
47.576045593,511.0
47.654827288,501.0
47.733608983,485.0
47.812390678,527.0
47.891172373,490.0
47.969954068,446.0
48.048735763,479.0
48.127517458,518.0
48.206299153,438.0
48.285080848,486.0
48.363862543,509.0
48.442644238,430.0
48.521425933,417.0
48.600207628,476.0
48.678989323,424.0
48.757771018,441.0
48.836552713,448.0
48.915334408,424.0
48.994116103,386.0
49.072897798,408.0
49.151679493,440.0
49.230461188,396.0
49.309242883,414.0
49.388024578,360.0
49.466806273,380.0
49.545587968,413.0
49.624369663,416.0
49.703151358,367.0
49.781933053,426.0
49.860714748,378.0
49.939496443,365.0
50.018278138,377.0
50.097059833,411.0
50.175841528,365.0
50.254623223,387.0
50.333404918,369.0
50.412186613,369.0
50.490968308,398.0
50.569750003,421.0
50.648531698,398.0
50.727313393,396.0
50.806095088,409.0
50.884876783,363.0
50.963658479,356.0
51.042440174,382.0
51.121221869,351.0
51.200003564,368.0
51.278785259,380.0
51.357566954,389.0
51.436348649,343.0
51.515130344,355.0
51.593912039,368.0
51.672693734,345.0
51.751475429,349.0
51.830257124,367.0
51.909038819,339.0
51.987820514,381.0
52.066602209,365.0
52.145383904,372.0
52.224165599,346.0
52.302947294,331.0
52.381728989,351.0
52.460510684,366.0
52.539292379,392.0
52.618074074,319.0
52.696855769,379.0
52.775637464,350.0
52.854419159,364.0
52.933200854,355.0
53.011982549,304.0
53.090764244,372.0
53.169545939,374.0
53.248327634,394.0
53.327109329,351.0
53.405891024,372.0
53.484672719,347.0
53.563454414,312.0
53.642236109,378.0
53.721017804,353.0
53.799799499,334.0
53.878581194,368.0
53.957362889,347.0
54.036144584,351.0
54.114926279,357.0
54.193707974,344.0
54.272489669,348.0
54.351271365,331.0
54.430053060,326.0
54.508834755,334.0
54.587616450,335.0
54.666398145,318.0
54.745179840,317.0
54.823961535,348.0
54.902743230,346.0
54.981524925,324.0
55.060306620,353.0
55.139088315,333.0
55.217870010,338.0
55.296651705,315.0
55.375433400,358.0
55.454215095,339.0
55.532996790,345.0
55.611778485,342.0
55.690560180,308.0
55.769341875,326.0
55.848123570,316.0
55.926905265,319.0
56.005686960,327.0
56.084468655,342.0
56.163250350,335.0
56.242032045,335.0
56.320813740,315.0
56.399595435,322.0
56.478377130,316.0
56.557158825,295.0
56.635940520,313.0
56.714722215,340.0
56.793503910,342.0
56.872285605,295.0
56.951067300,336.0
57.029848995,337.0
57.108630690,308.0
57.187412385,311.0
57.266194080,314.0
57.344975775,292.0
57.423757470,319.0
57.502539165,310.0
57.581320860,335.0
57.660102555,314.0
57.738884251,279.0
57.817665946,315.0
57.896447641,347.0
57.975229336,304.0
58.054011031,335.0
58.132792726,329.0
58.211574421,327.0
58.290356116,311.0
58.369137811,319.0
58.447919506,322.0
58.526701201,338.0
58.605482896,317.0
58.684264591,328.0
58.763046286,314.0
58.841827981,348.0
58.920609676,349.0
58.999391371,358.0
59.078173066,311.0
59.156954761,344.0
59.235736456,284.0
59.314518151,329.0
59.393299846,314.0
59.472081541,283.0
59.550863236,356.0
59.629644931,285.0
59.708426626,321.0
59.787208321,353.0
59.865990016,301.0
59.944771711,319.0
60.023553406,297.0
60.102335101,281.0
60.181116796,328.0
60.259898491,314.0
60.338680186,319.0
60.417461881,331.0
60.496243576,317.0
60.575025271,320.0
60.653806966,323.0
60.732588661,290.0
60.811370356,291.0
60.890152051,294.0
60.968933746,299.0
61.047715441,301.0
61.126497137,300.0
61.205278832,307.0
61.284060527,323.0
61.362842222,292.0
61.441623917,320.0
61.520405612,300.0
61.599187307,291.0
61.677969002,299.0
61.756750697,326.0
61.835532392,330.0
61.914314087,312.0
61.993095782,292.0
62.071877477,306.0
62.150659172,337.0
62.229440867,287.0
62.308222562,303.0
62.387004257,300.0
62.465785952,317.0
62.544567647,289.0
62.623349342,294.0
62.702131037,311.0
62.780912732,295.0
62.859694427,281.0
62.938476122,279.0
63.017257817,306.0
63.096039512,328.0
63.174821207,300.0
63.253602902,315.0
63.332384597,280.0
63.411166292,341.0
63.489947987,292.0
63.568729682,314.0
63.647511377,311.0
63.726293072,342.0
63.805074767,308.0
63.883856462,318.0
63.962638157,307.0
64.041419852,281.0
64.120201547,317.0
64.198983242,268.0
64.277764937,287.0
64.356546632,323.0
64.435328327,285.0
64.514110023,300.0
64.592891718,301.0
64.671673413,271.0
64.750455108,304.0
64.829236803,296.0
64.908018498,289.0
64.986800193,296.0
65.065581888,256.0
65.144363583,280.0
65.223145278,267.0
65.301926973,296.0
65.380708668,279.0
65.459490363,268.0
65.538272058,298.0
65.617053753,296.0
65.695835448,287.0
65.774617143,282.0
65.853398838,274.0
65.932180533,295.0
66.010962228,298.0
66.089743923,295.0
66.168525618,294.0
66.247307313,263.0
66.326089008,286.0
66.404870703,284.0
66.483652398,281.0
66.562434093,263.0
66.641215788,286.0
66.719997483,289.0
66.798779178,261.0
66.877560873,263.0
66.956342568,246.0
67.035124263,292.0
67.113905958,262.0
67.192687653,281.0
67.271469348,272.0
67.350251043,292.0
67.429032738,294.0
67.507814433,256.0
67.586596128,247.0
67.665377823,286.0
67.744159518,275.0
67.822941213,266.0
67.901722909,271.0
67.980504604,271.0
68.059286299,259.0
68.138067994,281.0
68.216849689,256.0
68.295631384,279.0
68.374413079,277.0
68.453194774,290.0
68.531976469,238.0
68.610758164,269.0
68.689539859,244.0
68.768321554,243.0
68.847103249,287.0
68.925884944,248.0
69.004666639,253.0
69.083448334,270.0
69.162230029,249.0
69.241011724,230.0
69.319793419,268.0
69.398575114,249.0
69.477356809,248.0
69.556138504,248.0
69.634920199,254.0
69.713701894,250.0
69.792483589,280.0
69.871265284,292.0
69.950046979,253.0
70.028828674,286.0
70.107610369,247.0
70.186392064,254.0
70.265173759,268.0
70.343955454,256.0
70.422737149,278.0
70.501518844,237.0
70.580300539,274.0
70.659082234,248.0
70.737863929,254.0
70.816645624,251.0
70.895427319,269.0
70.974209014,225.0
71.052990709,291.0
71.131772404,292.0
71.210554099,251.0
71.289335794,307.0
71.368117490,277.0
71.446899185,289.0
71.525680880,254.0
71.604462575,244.0
71.683244270,253.0
71.762025965,291.0
71.840807660,280.0
71.919589355,278.0
71.998371050,300.0
72.077152745,277.0
72.155934440,259.0
72.234716135,306.0
72.313497830,291.0
72.392279525,276.0
72.471061220,302.0
72.549842915,312.0
72.628624610,328.0
72.707406305,306.0
72.786188000,327.0
72.864969695,348.0
72.943751390,343.0
73.022533085,359.0
73.101314780,380.0
73.180096475,421.0
73.258878170,377.0
73.337659865,349.0
73.416441560,355.0
73.495223255,341.0
73.574004950,375.0
73.652786645,353.0
73.731568340,355.0
73.810350035,340.0
73.889131730,348.0
73.967913425,334.0
74.046695120,333.0
74.125476815,302.0
74.204258510,314.0
74.283040205,292.0
74.361821900,298.0
74.440603595,317.0
74.519385290,313.0
74.598166985,334.0
74.676948680,305.0
74.755730376,287.0
74.834512071,284.0
74.913293766,325.0
74.992075461,269.0
75.070857156,292.0
75.149638851,261.0
75.228420546,260.0
75.307202241,293.0
75.385983936,315.0
75.464765631,268.0
75.543547326,272.0
75.622329021,263.0
75.701110716,273.0
75.779892411,259.0
75.858674106,255.0
75.937455801,259.0
76.016237496,247.0
76.095019191,223.0
76.173800886,260.0
76.252582581,259.0
76.331364276,264.0
76.410145971,271.0
76.488927666,269.0
76.567709361,257.0
76.646491056,238.0
76.725272751,288.0
76.804054446,250.0
76.882836141,260.0
76.961617836,246.0
77.040399531,250.0
77.119181226,230.0
77.197962921,260.0
77.276744616,232.0
77.355526311,239.0
77.434308006,236.0
77.513089701,246.0
77.591871396,255.0
77.670653091,260.0
77.749434786,197.0
77.828216481,215.0
77.906998176,252.0
77.985779871,226.0
78.064561566,231.0
78.143343262,241.0
78.222124957,230.0
78.300906652,226.0
78.379688347,234.0
78.458470042,235.0
78.537251737,208.0
78.616033432,243.0
78.694815127,235.0
78.773596822,248.0
78.852378517,259.0
78.931160212,256.0
79.009941907,236.0
79.088723602,258.0
79.167505297,213.0
79.246286992,254.0
79.325068687,240.0
79.403850382,255.0
79.482632077,199.0
79.561413772,250.0
79.640195467,206.0
79.718977162,252.0
79.797758857,224.0
79.876540552,236.0
79.955322247,252.0
80.034103942,227.0
80.112885637,248.0
80.191667332,228.0
80.270449027,237.0
80.349230722,217.0
80.428012417,215.0
80.506794112,262.0
80.585575807,231.0
80.664357502,271.0
80.743139197,228.0
80.821920892,241.0
80.900702587,238.0
80.979484282,228.0
81.058265977,227.0
81.137047672,244.0
81.215829367,217.0
81.294611062,216.0
81.373392757,226.0
81.452174452,223.0
81.530956148,227.0
81.609737843,210.0
81.688519538,213.0
81.767301233,236.0
81.846082928,242.0
81.924864623,239.0
82.003646318,218.0
82.082428013,201.0
82.161209708,212.0
82.239991403,233.0
82.318773098,226.0
82.397554793,228.0
82.476336488,215.0
82.555118183,222.0
82.633899878,205.0
82.712681573,225.0
82.791463268,207.0
82.870244963,203.0
82.949026658,223.0
83.027808353,215.0
83.106590048,197.0
83.185371743,205.0
83.264153438,250.0
83.342935133,200.0
83.421716828,206.0
83.500498523,237.0
83.579280218,226.0
83.658061913,210.0
83.736843608,204.0
83.815625303,220.0
83.894406998,219.0
83.973188693,205.0
84.051970388,245.0
84.130752083,236.0
84.209533778,232.0
84.288315473,202.0
84.367097168,247.0
84.445878863,251.0
84.524660558,231.0
84.603442253,210.0
84.682223948,200.0
84.761005643,235.0
84.839787338,203.0
84.918569034,207.0
84.997350729,210.0
85.076132424,223.0
85.154914119,210.0
85.233695814,209.0
85.312477509,200.0
85.391259204,196.0
85.470040899,216.0
85.548822594,203.0
85.627604289,222.0
85.706385984,192.0
85.785167679,211.0
85.863949374,220.0
85.942731069,208.0
86.021512764,227.0
86.100294459,189.0
86.179076154,212.0
86.257857849,205.0
86.336639544,233.0
86.415421239,193.0
86.494202934,185.0
86.572984629,232.0
86.651766324,213.0
86.730548019,220.0
86.809329714,234.0
86.888111409,209.0
86.966893104,214.0
87.045674799,230.0
87.124456494,218.0
87.203238189,241.0
87.282019884,240.0
87.360801579,235.0
87.439583274,246.0
87.518364969,238.0
87.597146664,232.0
87.675928359,224.0
87.754710054,230.0
87.833491749,245.0
87.912273444,233.0
87.991055139,211.0
88.069836834,230.0
88.148618529,201.0
88.227400224,261.0
88.306181920,222.0
88.384963615,221.0
88.463745310,208.0
88.542527005,230.0
88.621308700,233.0
88.700090395,254.0
88.778872090,245.0
88.857653785,212.0
88.936435480,238.0
89.015217175,202.0
89.093998870,223.0
89.172780565,231.0
89.251562260,232.0
89.330343955,205.0
89.409125650,233.0
89.487907345,243.0
89.566689040,231.0
89.645470735,229.0
89.724252430,206.0
89.803034125,207.0
89.881815820,197.0
89.960597515,238.0
89.986858080,242.0