File: 2017007296/7296-d#.csv
[Measurement conditions]
Sample identification,
Comment - 1,"Configuration=Stage for flat samples/holders, Owner=User-1, Creation date=3/27/2015 11:56:23 AM"
Comment - 2,"Goniometer=Theta/Theta; Minimum step size 2Theta:0.0001; Minimum step size Omega:0.0001"
Comment - 3,"Sample stage=Stage for flat samples/holders"
Comment - 4,"Diffractometer system=EMPYREAN"
Comment - 5,"Measurement program=C:\PANalytical\Data Collector\Programs\Powder - Copy.xrdmp, Identifier={BEEA10DD-8FD6-4721-8940-4FBC5A4262A1}"
Comment - 6,"Fine Calibration Offset for 2Theta = -0.0130 deg"
Comment - 7,"Fine Calibration Offset for Omega = -0.0070 deg"
Anode material,Cu
K-Alpha1 wavelength,1.5405980
K-Alpha2 wavelength,1.5444260
Ratio K-Alpha2/K-Alpha1,0.500
Divergence slit,Fixed,0.38mm
Monochromator used,NO
Generator voltage, 40
Tube current, 35
File date and time,24/Jul/2017 17:05
Unit cell,
h k l, 0 0 0
Scan axis,Gonio
Scan range,5.020799997,89.999988363
Scan step size,0.0262606
No. of points, 3236
Scan type,CONTINUOUS
Time per step,18.615
[Scan points]
Angle,Intensity
5.033930280,1447.0
5.112711975,1409.0
5.191493670,1387.0
5.270275365,1389.0
5.349057060,1412.0
5.427838755,1387.0
5.506620450,1414.0
5.585402145,1409.0
5.664183840,1393.0
5.742965535,1395.0
5.821747230,1421.0
5.900528925,1440.0
5.979310620,1439.0
6.058092315,1359.0
6.136874010,1384.0
6.215655705,1376.0
6.294437400,1419.0
6.373219095,1442.0
6.452000790,1454.0
6.530782485,1375.0
6.609564180,1441.0
6.688345875,1419.0
6.767127571,1385.0
6.845909266,1428.0
6.924690961,1393.0
7.003472656,1388.0
7.082254351,1429.0
7.161036046,1406.0
7.239817741,1437.0
7.318599436,1443.0
7.397381131,1478.0
7.476162826,1431.0
7.554944521,1448.0
7.633726216,1466.0
7.712507911,1408.0
7.791289606,1457.0
7.870071301,1408.0
7.948852996,1440.0
8.027634691,1503.0
8.106416386,1502.0
8.185198081,1589.0
8.263979776,1577.0
8.342761471,1497.0
8.421543166,1560.0
8.500324861,1565.0
8.579106556,1628.0
8.657888251,1605.0
8.736669946,1653.0
8.815451641,1695.0
8.894233336,1688.0
8.973015031,1621.0
9.051796726,1694.0
9.130578421,1687.0
9.209360116,1671.0
9.288141811,1746.0
9.366923506,1694.0
9.445705201,1593.0
9.524486896,1650.0
9.603268591,1610.0
9.682050286,1570.0
9.760831981,1513.0
9.839613676,1431.0
9.918395371,1436.0
9.997177066,1372.0
10.075958761,1313.0
10.154740457,1283.0
10.233522152,1240.0
10.312303847,1296.0
10.391085542,1249.0
10.469867237,1178.0
10.548648932,1220.0
10.627430627,1172.0
10.706212322,1171.0
10.784994017,1130.0
10.863775712,1188.0
10.942557407,1173.0
11.021339102,1112.0
11.100120797,1081.0
11.178902492,1139.0
11.257684187,1061.0
11.336465882,1088.0
11.415247577,1049.0
11.494029272,1066.0
11.572810967,1049.0
11.651592662,1017.0
11.730374357,1039.0
11.809156052,1068.0
11.887937747,990.0
11.966719442,1042.0
12.045501137,993.0
12.124282832,1006.0
12.203064527,973.0
12.281846222,1015.0
12.360627917,946.0
12.439409612,870.0
12.518191307,938.0
12.596973002,959.0
12.675754697,860.0
12.754536392,891.0
12.833318087,945.0
12.912099782,899.0
12.990881477,984.0
13.069663172,882.0
13.148444867,919.0
13.227226562,939.0
13.306008257,900.0
13.384789952,873.0
13.463571647,887.0
13.542353343,905.0
13.621135038,855.0
13.699916733,929.0
13.778698428,874.0
13.857480123,874.0
13.936261818,910.0
14.015043513,847.0
14.093825208,880.0
14.172606903,822.0
14.251388598,839.0
14.330170293,877.0
14.408951988,795.0
14.487733683,774.0
14.566515378,826.0
14.645297073,810.0
14.724078768,821.0
14.802860463,812.0
14.881642158,844.0
14.960423853,842.0
15.039205548,833.0
15.117987243,867.0
15.196768938,815.0
15.275550633,802.0
15.354332328,806.0
15.433114023,858.0
15.511895718,783.0
15.590677413,824.0
15.669459108,786.0
15.748240803,878.0
15.827022498,849.0
15.905804193,828.0
15.984585888,864.0
16.063367583,749.0
16.142149278,807.0
16.220930973,832.0
16.299712668,813.0
16.378494363,778.0
16.457276058,765.0
16.536057753,835.0
16.614839448,774.0
16.693621143,818.0
16.772402838,775.0
16.851184533,824.0
16.929966229,838.0
17.008747924,806.0
17.087529619,826.0
17.166311314,810.0
17.245093009,837.0
17.323874704,775.0
17.402656399,797.0
17.481438094,804.0
17.560219789,802.0
17.639001484,872.0
17.717783179,784.0
17.796564874,802.0
17.875346569,807.0
17.954128264,825.0
18.032909959,859.0
18.111691654,790.0
18.190473349,860.0
18.269255044,839.0
18.348036739,790.0
18.426818434,738.0
18.505600129,850.0
18.584381824,859.0
18.663163519,841.0
18.741945214,859.0
18.820726909,918.0
18.899508604,872.0
18.978290299,766.0
19.057071994,819.0
19.135853689,803.0
19.214635384,799.0
19.293417079,750.0
19.372198774,802.0
19.450980469,789.0
19.529762164,766.0
19.608543859,883.0
19.687325554,794.0
19.766107249,811.0
19.844888944,832.0
19.923670639,855.0
20.002452334,831.0
20.081234029,830.0
20.160015724,842.0
20.238797419,894.0
20.317579114,810.0
20.396360810,875.0
20.475142505,817.0
20.553924200,854.0
20.632705895,861.0
20.711487590,829.0
20.790269285,865.0
20.869050980,875.0
20.947832675,923.0
21.026614370,900.0
21.105396065,842.0
21.184177760,917.0
21.262959455,939.0
21.341741150,845.0
21.420522845,895.0
21.499304540,845.0
21.578086235,838.0
21.656867930,940.0
21.735649625,878.0
21.814431320,870.0
21.893213015,867.0
21.971994710,856.0
22.050776405,870.0
22.129558100,881.0
22.208339795,937.0
22.287121490,881.0
22.365903185,900.0
22.444684880,861.0
22.523466575,862.0
22.602248270,907.0
22.681029965,900.0
22.759811660,861.0
22.838593355,851.0
22.917375050,891.0
22.996156745,900.0
23.074938440,941.0
23.153720135,908.0
23.232501830,899.0
23.311283525,969.0
23.390065220,948.0
23.468846915,956.0
23.547628610,926.0
23.626410305,935.0
23.705192000,926.0
23.783973696,942.0
23.862755391,942.0
23.941537086,994.0
24.020318781,955.0
24.099100476,943.0
24.177882171,969.0
24.256663866,941.0
24.335445561,974.0
24.414227256,946.0
24.493008951,947.0
24.571790646,913.0
24.650572341,963.0
24.729354036,928.0
24.808135731,980.0
24.886917426,972.0
24.965699121,970.0
25.044480816,949.0
25.123262511,913.0
25.202044206,934.0
25.280825901,954.0
25.359607596,1020.0
25.438389291,979.0
25.517170986,977.0
25.595952681,1007.0
25.674734376,932.0
25.753516071,957.0
25.832297766,1018.0
25.911079461,954.0
25.989861156,968.0
26.068642851,944.0
26.147424546,1030.0
26.226206241,1003.0
26.304987936,918.0
26.383769631,963.0
26.462551326,958.0
26.541333021,987.0
26.620114716,964.0
26.698896411,1044.0
26.777678106,996.0
26.856459801,1024.0
26.935241496,985.0
27.014023191,990.0
27.092804886,999.0
27.171586582,967.0
27.250368277,954.0
27.329149972,958.0
27.407931667,998.0
27.486713362,992.0
27.565495057,971.0
27.644276752,963.0
27.723058447,1015.0
27.801840142,992.0
27.880621837,954.0
27.959403532,951.0
28.038185227,1005.0
28.116966922,1043.0
28.195748617,987.0
28.274530312,882.0
28.353312007,858.0
28.432093702,1037.0
28.510875397,953.0
28.589657092,957.0
28.668438787,984.0
28.747220482,979.0
28.826002177,1022.0
28.904783872,957.0
28.983565567,995.0
29.062347262,990.0
29.141128957,985.0
29.219910652,923.0
29.298692347,969.0
29.377474042,985.0
29.456255737,1021.0
29.535037432,934.0
29.613819127,985.0
29.692600822,969.0
29.771382517,1025.0
29.850164212,1037.0
29.928945907,959.0
30.007727602,928.0
30.086509297,987.0
30.165290992,955.0
30.244072687,1000.0
30.322854382,960.0
30.401636077,873.0
30.480417772,926.0
30.559199468,990.0
30.637981163,864.0
30.716762858,947.0
30.795544553,920.0
30.874326248,902.0
30.953107943,911.0
31.031889638,982.0
31.110671333,994.0
31.189453028,946.0
31.268234723,940.0
31.347016418,919.0
31.425798113,917.0
31.504579808,935.0
31.583361503,870.0
31.662143198,954.0
31.740924893,903.0
31.819706588,961.0
31.898488283,973.0
31.977269978,875.0
32.056051673,899.0
32.134833368,917.0
32.213615063,917.0
32.292396758,927.0
32.371178453,920.0
32.449960148,950.0
32.528741843,940.0
32.607523538,859.0
32.686305233,908.0
32.765086928,861.0
32.843868623,833.0
32.922650318,948.0
33.001432013,880.0
33.080213708,905.0
33.158995403,831.0
33.237777098,875.0
33.316558793,864.0
33.395340488,897.0
33.474122183,833.0
33.552903878,836.0
33.631685573,902.0
33.710467268,886.0
33.789248963,813.0
33.868030658,904.0
33.946812354,874.0
34.025594049,862.0
34.104375744,869.0
34.183157439,844.0
34.261939134,796.0
34.340720829,840.0
34.419502524,842.0
34.498284219,847.0
34.577065914,792.0
34.655847609,797.0
34.734629304,850.0
34.813410999,821.0
34.892192694,797.0
34.970974389,810.0
35.049756084,823.0
35.128537779,771.0
35.207319474,819.0
35.286101169,846.0
35.364882864,743.0
35.443664559,775.0
35.522446254,801.0
35.601227949,862.0
35.680009644,795.0
35.758791339,820.0
35.837573034,795.0
35.916354729,815.0
35.995136424,779.0
36.073918119,788.0
36.152699814,805.0
36.231481509,764.0
36.310263204,752.0
36.389044899,749.0
36.467826594,807.0
36.546608289,705.0
36.625389984,763.0
36.704171679,746.0
36.782953374,865.0
36.861735069,737.0
36.940516764,720.0
37.019298459,772.0
37.098080154,742.0
37.176861849,704.0
37.255643544,703.0
37.334425240,754.0
37.413206935,689.0
37.491988630,725.0
37.570770325,751.0
37.649552020,694.0
37.728333715,739.0
37.807115410,710.0
37.885897105,700.0
37.964678800,672.0
38.043460495,731.0
38.122242190,717.0
38.201023885,718.0
38.279805580,681.0
38.358587275,689.0
38.437368970,716.0
38.516150665,673.0
38.594932360,666.0
38.673714055,671.0
38.752495750,669.0
38.831277445,666.0
38.910059140,675.0
38.988840835,727.0
39.067622530,654.0
39.146404225,678.0
39.225185920,667.0
39.303967615,713.0
39.382749310,690.0
39.461531005,717.0
39.540312700,721.0
39.619094395,706.0
39.697876090,641.0
39.776657785,735.0
39.855439480,658.0
39.934221175,644.0
40.013002870,688.0
40.091784565,672.0
40.170566260,655.0
40.249347955,712.0
40.328129650,685.0
40.406911345,629.0
40.485693040,712.0
40.564474735,679.0
40.643256430,669.0
40.722038126,645.0
40.800819821,632.0
40.879601516,670.0
40.958383211,659.0
41.037164906,662.0
41.115946601,660.0
41.194728296,646.0
41.273509991,632.0
41.352291686,698.0
41.431073381,701.0
41.509855076,698.0
41.588636771,663.0
41.667418466,617.0
41.746200161,703.0
41.824981856,679.0
41.903763551,681.0
41.982545246,687.0
42.061326941,635.0
42.140108636,676.0
42.218890331,671.0
42.297672026,728.0
42.376453721,753.0
42.455235416,680.0
42.534017111,705.0
42.612798806,693.0
42.691580501,718.0
42.770362196,685.0
42.849143891,676.0
42.927925586,633.0
43.006707281,629.0
43.085488976,667.0
43.164270671,664.0
43.243052366,655.0
43.321834061,674.0
43.400615756,679.0
43.479397451,622.0
43.558179146,651.0
43.636960841,592.0
43.715742536,610.0
43.794524231,607.0
43.873305926,568.0
43.952087621,557.0
44.030869316,572.0
44.109651011,567.0
44.188432707,579.0
44.267214402,507.0
44.345996097,560.0
44.424777792,580.0
44.503559487,550.0
44.582341182,545.0
44.661122877,565.0
44.739904572,522.0
44.818686267,601.0
44.897467962,556.0
44.976249657,531.0
45.055031352,563.0
45.133813047,519.0
45.212594742,568.0
45.291376437,558.0
45.370158132,524.0
45.448939827,470.0
45.527721522,565.0
45.606503217,493.0
45.685284912,569.0
45.764066607,527.0
45.842848302,512.0
45.921629997,527.0
46.000411692,541.0
46.079193387,471.0
46.157975082,495.0
46.236756777,478.0
46.315538472,506.0
46.394320167,476.0
46.473101862,497.0
46.551883557,500.0
46.630665252,436.0
46.709446947,485.0
46.788228642,489.0
46.867010337,473.0
46.945792032,496.0
47.024573727,479.0
47.103355422,499.0
47.182137117,438.0
47.260918812,456.0
47.339700507,463.0
47.418482202,502.0
47.497263897,456.0
47.576045593,482.0
47.654827288,498.0
47.733608983,524.0
47.812390678,438.0
47.891172373,492.0
47.969954068,440.0
48.048735763,474.0
48.127517458,471.0
48.206299153,431.0
48.285080848,429.0
48.363862543,465.0
48.442644238,434.0
48.521425933,422.0
48.600207628,427.0
48.678989323,468.0
48.757771018,394.0
48.836552713,423.0
48.915334408,440.0
48.994116103,444.0
49.072897798,437.0
49.151679493,439.0
49.230461188,485.0
49.309242883,387.0
49.388024578,442.0
49.466806273,431.0
49.545587968,417.0
49.624369663,411.0
49.703151358,420.0
49.781933053,440.0
49.860714748,439.0
49.939496443,435.0
50.018278138,423.0
50.097059833,427.0
50.175841528,411.0
50.254623223,407.0
50.333404918,437.0
50.412186613,434.0
50.490968308,408.0
50.569750003,408.0
50.648531698,401.0
50.727313393,430.0
50.806095088,407.0
50.884876783,432.0
50.963658479,371.0
51.042440174,418.0
51.121221869,434.0
51.200003564,375.0
51.278785259,433.0
51.357566954,403.0
51.436348649,406.0
51.515130344,373.0
51.593912039,393.0
51.672693734,401.0
51.751475429,401.0
51.830257124,401.0
51.909038819,422.0
51.987820514,391.0
52.066602209,419.0
52.145383904,373.0
52.224165599,411.0
52.302947294,398.0
52.381728989,392.0
52.460510684,402.0
52.539292379,384.0
52.618074074,398.0
52.696855769,365.0
52.775637464,414.0
52.854419159,377.0
52.933200854,383.0
53.011982549,381.0
53.090764244,357.0
53.169545939,351.0
53.248327634,386.0
53.327109329,406.0
53.405891024,378.0
53.484672719,387.0
53.563454414,389.0
53.642236109,392.0
53.721017804,385.0
53.799799499,365.0
53.878581194,403.0
53.957362889,344.0
54.036144584,311.0
54.114926279,388.0
54.193707974,383.0
54.272489669,389.0
54.351271365,393.0
54.430053060,414.0
54.508834755,428.0
54.587616450,388.0
54.666398145,373.0
54.745179840,391.0
54.823961535,365.0
54.902743230,367.0
54.981524925,406.0
55.060306620,349.0
55.139088315,373.0
55.217870010,369.0
55.296651705,367.0
55.375433400,365.0
55.454215095,375.0
55.532996790,365.0
55.611778485,352.0
55.690560180,383.0
55.769341875,404.0
55.848123570,341.0
55.926905265,393.0
56.005686960,376.0
56.084468655,366.0
56.163250350,353.0
56.242032045,352.0
56.320813740,349.0
56.399595435,342.0
56.478377130,372.0
56.557158825,346.0
56.635940520,387.0
56.714722215,382.0
56.793503910,343.0
56.872285605,332.0
56.951067300,368.0
57.029848995,339.0
57.108630690,330.0
57.187412385,353.0
57.266194080,340.0
57.344975775,385.0
57.423757470,316.0
57.502539165,371.0
57.581320860,375.0
57.660102555,371.0
57.738884251,349.0
57.817665946,329.0
57.896447641,372.0
57.975229336,334.0
58.054011031,352.0
58.132792726,338.0
58.211574421,382.0
58.290356116,358.0
58.369137811,349.0
58.447919506,336.0
58.526701201,353.0
58.605482896,383.0
58.684264591,338.0
58.763046286,362.0
58.841827981,358.0
58.920609676,355.0
58.999391371,340.0
59.078173066,357.0
59.156954761,345.0
59.235736456,320.0
59.314518151,342.0
59.393299846,340.0
59.472081541,344.0
59.550863236,346.0
59.629644931,327.0
59.708426626,321.0
59.787208321,327.0
59.865990016,361.0
59.944771711,322.0
60.023553406,337.0
60.102335101,340.0
60.181116796,315.0
60.259898491,314.0
60.338680186,336.0
60.417461881,363.0
60.496243576,329.0
60.575025271,334.0
60.653806966,366.0
60.732588661,371.0
60.811370356,298.0
60.890152051,355.0
60.968933746,327.0
61.047715441,328.0
61.126497137,336.0
61.205278832,347.0
61.284060527,356.0
61.362842222,374.0
61.441623917,311.0
61.520405612,314.0
61.599187307,321.0
61.677969002,349.0
61.756750697,338.0
61.835532392,355.0
61.914314087,315.0
61.993095782,318.0
62.071877477,337.0
62.150659172,333.0
62.229440867,295.0
62.308222562,315.0
62.387004257,314.0
62.465785952,311.0
62.544567647,332.0
62.623349342,312.0
62.702131037,290.0
62.780912732,301.0
62.859694427,365.0
62.938476122,327.0
63.017257817,331.0
63.096039512,303.0
63.174821207,336.0
63.253602902,311.0
63.332384597,355.0
63.411166292,325.0
63.489947987,363.0
63.568729682,298.0
63.647511377,310.0
63.726293072,283.0
63.805074767,317.0
63.883856462,317.0
63.962638157,282.0
64.041419852,321.0
64.120201547,305.0
64.198983242,326.0
64.277764937,332.0
64.356546632,296.0
64.435328327,269.0
64.514110023,344.0
64.592891718,300.0
64.671673413,313.0
64.750455108,319.0
64.829236803,276.0
64.908018498,341.0
64.986800193,277.0
65.065581888,309.0
65.144363583,334.0
65.223145278,285.0
65.301926973,321.0
65.380708668,281.0
65.459490363,279.0
65.538272058,273.0
65.617053753,288.0
65.695835448,311.0
65.774617143,339.0
65.853398838,311.0
65.932180533,329.0
66.010962228,308.0
66.089743923,305.0
66.168525618,270.0
66.247307313,270.0
66.326089008,296.0
66.404870703,297.0
66.483652398,272.0
66.562434093,329.0
66.641215788,291.0
66.719997483,331.0
66.798779178,306.0
66.877560873,296.0
66.956342568,300.0
67.035124263,289.0
67.113905958,320.0
67.192687653,305.0
67.271469348,289.0
67.350251043,266.0
67.429032738,295.0
67.507814433,284.0
67.586596128,310.0
67.665377823,312.0
67.744159518,269.0
67.822941213,296.0
67.901722909,256.0
67.980504604,297.0
68.059286299,285.0
68.138067994,314.0
68.216849689,305.0
68.295631384,279.0
68.374413079,357.0
68.453194774,303.0
68.531976469,276.0
68.610758164,265.0
68.689539859,300.0
68.768321554,280.0
68.847103249,254.0
68.925884944,260.0
69.004666639,282.0
69.083448334,288.0
69.162230029,270.0
69.241011724,295.0
69.319793419,295.0
69.398575114,282.0
69.477356809,277.0
69.556138504,286.0
69.634920199,287.0
69.713701894,281.0
69.792483589,264.0
69.871265284,322.0
69.950046979,277.0
70.028828674,277.0
70.107610369,288.0
70.186392064,316.0
70.265173759,293.0
70.343955454,291.0
70.422737149,292.0
70.501518844,278.0
70.580300539,278.0
70.659082234,259.0
70.737863929,272.0
70.816645624,263.0
70.895427319,245.0
70.974209014,283.0
71.052990709,256.0
71.131772404,278.0
71.210554099,256.0
71.289335794,285.0
71.368117490,249.0
71.446899185,275.0
71.525680880,295.0
71.604462575,269.0
71.683244270,297.0
71.762025965,268.0
71.840807660,229.0
71.919589355,253.0
71.998371050,263.0
72.077152745,272.0
72.155934440,252.0
72.234716135,279.0
72.313497830,283.0
72.392279525,295.0
72.471061220,272.0
72.549842915,246.0
72.628624610,256.0
72.707406305,237.0
72.786188000,282.0
72.864969695,304.0
72.943751390,259.0
73.022533085,250.0
73.101314780,274.0
73.180096475,273.0
73.258878170,262.0
73.337659865,277.0
73.416441560,277.0
73.495223255,268.0
73.574004950,271.0
73.652786645,260.0
73.731568340,272.0
73.810350035,251.0
73.889131730,264.0
73.967913425,246.0
74.046695120,263.0
74.125476815,281.0
74.204258510,274.0
74.283040205,250.0
74.361821900,261.0
74.440603595,268.0
74.519385290,264.0
74.598166985,273.0
74.676948680,263.0
74.755730376,242.0
74.834512071,269.0
74.913293766,290.0
74.992075461,248.0
75.070857156,260.0
75.149638851,270.0
75.228420546,257.0
75.307202241,263.0
75.385983936,280.0
75.464765631,250.0
75.543547326,289.0
75.622329021,285.0
75.701110716,265.0
75.779892411,282.0
75.858674106,254.0
75.937455801,241.0
76.016237496,249.0
76.095019191,280.0
76.173800886,286.0
76.252582581,249.0
76.331364276,251.0
76.410145971,262.0
76.488927666,251.0
76.567709361,239.0
76.646491056,272.0
76.725272751,273.0
76.804054446,239.0
76.882836141,269.0
76.961617836,265.0
77.040399531,276.0
77.119181226,224.0
77.197962921,270.0
77.276744616,274.0
77.355526311,236.0
77.434308006,236.0
77.513089701,231.0
77.591871396,254.0
77.670653091,282.0
77.749434786,261.0
77.828216481,267.0
77.906998176,253.0
77.985779871,274.0
78.064561566,255.0
78.143343262,245.0
78.222124957,290.0
78.300906652,257.0
78.379688347,244.0
78.458470042,279.0
78.537251737,272.0
78.616033432,286.0
78.694815127,264.0
78.773596822,276.0
78.852378517,242.0
78.931160212,265.0
79.009941907,251.0
79.088723602,268.0
79.167505297,261.0
79.246286992,260.0
79.325068687,250.0
79.403850382,237.0
79.482632077,242.0
79.561413772,234.0
79.640195467,240.0
79.718977162,257.0
79.797758857,249.0
79.876540552,236.0
79.955322247,266.0
80.034103942,245.0
80.112885637,273.0
80.191667332,248.0
80.270449027,246.0
80.349230722,254.0
80.428012417,232.0
80.506794112,262.0
80.585575807,250.0
80.664357502,250.0
80.743139197,249.0
80.821920892,216.0
80.900702587,256.0
80.979484282,242.0
81.058265977,237.0
81.137047672,245.0
81.215829367,248.0
81.294611062,246.0
81.373392757,234.0
81.452174452,271.0
81.530956148,248.0
81.609737843,243.0
81.688519538,215.0
81.767301233,247.0
81.846082928,241.0
81.924864623,216.0
82.003646318,248.0
82.082428013,233.0
82.161209708,213.0
82.239991403,236.0
82.318773098,255.0
82.397554793,255.0
82.476336488,242.0
82.555118183,253.0
82.633899878,244.0
82.712681573,240.0
82.791463268,234.0
82.870244963,228.0
82.949026658,251.0
83.027808353,216.0
83.106590048,223.0
83.185371743,232.0
83.264153438,226.0
83.342935133,236.0
83.421716828,241.0
83.500498523,217.0
83.579280218,235.0
83.658061913,200.0
83.736843608,224.0
83.815625303,227.0
83.894406998,237.0
83.973188693,228.0
84.051970388,224.0
84.130752083,223.0
84.209533778,231.0
84.288315473,235.0
84.367097168,245.0
84.445878863,197.0
84.524660558,205.0
84.603442253,221.0
84.682223948,220.0
84.761005643,198.0
84.839787338,217.0
84.918569034,206.0
84.997350729,242.0
85.076132424,226.0
85.154914119,206.0
85.233695814,247.0
85.312477509,225.0
85.391259204,213.0
85.470040899,218.0
85.548822594,205.0
85.627604289,221.0
85.706385984,235.0
85.785167679,238.0
85.863949374,214.0
85.942731069,237.0
86.021512764,239.0
86.100294459,207.0
86.179076154,243.0
86.257857849,222.0
86.336639544,239.0
86.415421239,262.0
86.494202934,230.0
86.572984629,229.0
86.651766324,228.0
86.730548019,207.0
86.809329714,229.0
86.888111409,211.0
86.966893104,220.0
87.045674799,233.0
87.124456494,207.0
87.203238189,222.0
87.282019884,210.0
87.360801579,210.0
87.439583274,209.0
87.518364969,203.0
87.597146664,223.0
87.675928359,210.0
87.754710054,224.0
87.833491749,210.0
87.912273444,233.0
87.991055139,235.0
88.069836834,207.0
88.148618529,244.0
88.227400224,207.0
88.306181920,225.0
88.384963615,218.0
88.463745310,213.0
88.542527005,201.0
88.621308700,205.0
88.700090395,227.0
88.778872090,221.0
88.857653785,220.0
88.936435480,236.0
89.015217175,197.0
89.093998870,210.0
89.172780565,190.0
89.251562260,245.0
89.330343955,215.0
89.409125650,206.0
89.487907345,228.0
89.566689040,212.0
89.645470735,218.0
89.724252430,222.0
89.803034125,219.0
89.881815820,218.0
89.960597515,206.0
89.986858080,217.0