File: 2017007296/7296-b3#.csv
[Measurement conditions]
Sample identification,
Comment - 1,"Configuration=Stage for flat samples/holders, Owner=User-1, Creation date=3/27/2015 11:56:23 AM"
Comment - 2,"Goniometer=Theta/Theta; Minimum step size 2Theta:0.0001; Minimum step size Omega:0.0001"
Comment - 3,"Sample stage=Stage for flat samples/holders"
Comment - 4,"Diffractometer system=EMPYREAN"
Comment - 5,"Measurement program=C:\PANalytical\Data Collector\Programs\Powder - Copy.xrdmp, Identifier={BEEA10DD-8FD6-4721-8940-4FBC5A4262A1}"
Comment - 6,"Fine Calibration Offset for 2Theta = -0.0130 deg"
Comment - 7,"Fine Calibration Offset for Omega = -0.0070 deg"
Anode material,Cu
K-Alpha1 wavelength,1.5405980
K-Alpha2 wavelength,1.5444260
Ratio K-Alpha2/K-Alpha1,0.500
Divergence slit,Fixed,0.38mm
Monochromator used,NO
Generator voltage, 40
Tube current, 35
File date and time,24/Jul/2017 16:40
Unit cell,
h k l, 0 0 0
Scan axis,Gonio
Scan range,5.020799997,89.999988363
Scan step size,0.0262606
No. of points, 3236
Scan type,CONTINUOUS
Time per step,18.615
[Scan points]
Angle,Intensity
5.033930280,2021.0
5.112711975,2060.0
5.191493670,1998.0
5.270275365,2047.0
5.349057060,2007.0
5.427838755,2042.0
5.506620450,2053.0
5.585402145,1936.0
5.664183840,1948.0
5.742965535,1994.0
5.821747230,2005.0
5.900528925,1906.0
5.979310620,1937.0
6.058092315,1913.0
6.136874010,1868.0
6.215655705,1917.0
6.294437400,1941.0
6.373219095,1876.0
6.452000790,1866.0
6.530782485,1879.0
6.609564180,1955.0
6.688345875,1932.0
6.767127571,1862.0
6.845909266,1795.0
6.924690961,1845.0
7.003472656,1827.0
7.082254351,1801.0
7.161036046,1919.0
7.239817741,1805.0
7.318599436,1809.0
7.397381131,1859.0
7.476162826,1901.0
7.554944521,1870.0
7.633726216,1772.0
7.712507911,1775.0
7.791289606,1812.0
7.870071301,1703.0
7.948852996,1761.0
8.027634691,1719.0
8.106416386,1744.0
8.185198081,1694.0
8.263979776,1732.0
8.342761471,1705.0
8.421543166,1804.0
8.500324861,1728.0
8.579106556,1690.0
8.657888251,1639.0
8.736669946,1681.0
8.815451641,1615.0
8.894233336,1685.0
8.973015031,1680.0
9.051796726,1656.0
9.130578421,1746.0
9.209360116,1684.0
9.288141811,1650.0
9.366923506,1634.0
9.445705201,1592.0
9.524486896,1597.0
9.603268591,1652.0
9.682050286,1676.0
9.760831981,1674.0
9.839613676,1640.0
9.918395371,1667.0
9.997177066,1686.0
10.075958761,1648.0
10.154740457,1681.0
10.233522152,1619.0
10.312303847,1696.0
10.391085542,1589.0
10.469867237,1628.0
10.548648932,1640.0
10.627430627,1684.0
10.706212322,1633.0
10.784994017,1654.0
10.863775712,1638.0
10.942557407,1631.0
11.021339102,1691.0
11.100120797,1593.0
11.178902492,1628.0
11.257684187,1645.0
11.336465882,1595.0
11.415247577,1647.0
11.494029272,1592.0
11.572810967,1651.0
11.651592662,1549.0
11.730374357,1602.0
11.809156052,1620.0
11.887937747,1614.0
11.966719442,1673.0
12.045501137,1588.0
12.124282832,1610.0
12.203064527,1588.0
12.281846222,1650.0
12.360627917,1649.0
12.439409612,1566.0
12.518191307,1736.0
12.596973002,1706.0
12.675754697,1718.0
12.754536392,1665.0
12.833318087,1703.0
12.912099782,1683.0
12.990881477,1735.0
13.069663172,1739.0
13.148444867,1749.0
13.227226562,1764.0
13.306008257,1728.0
13.384789952,1800.0
13.463571647,1880.0
13.542353343,1816.0
13.621135038,1687.0
13.699916733,1798.0
13.778698428,1781.0
13.857480123,1882.0
13.936261818,1862.0
14.015043513,1866.0
14.093825208,1865.0
14.172606903,1933.0
14.251388598,1880.0
14.330170293,1848.0
14.408951988,1981.0
14.487733683,1900.0
14.566515378,1996.0
14.645297073,1928.0
14.724078768,1879.0
14.802860463,1841.0
14.881642158,1944.0
14.960423853,1873.0
15.039205548,1900.0
15.117987243,1766.0
15.196768938,1882.0
15.275550633,1722.0
15.354332328,1632.0
15.433114023,1564.0
15.511895718,1510.0
15.590677413,1446.0
15.669459108,1422.0
15.748240803,1351.0
15.827022498,1363.0
15.905804193,1249.0
15.984585888,1120.0
16.063367583,1177.0
16.142149278,1143.0
16.220930973,1135.0
16.299712668,1093.0
16.378494363,1083.0
16.457276058,1031.0
16.536057753,1036.0
16.614839448,1042.0
16.693621143,1054.0
16.772402838,897.0
16.851184533,951.0
16.929966229,919.0
17.008747924,994.0
17.087529619,915.0
17.166311314,961.0
17.245093009,848.0
17.323874704,892.0
17.402656399,867.0
17.481438094,882.0
17.560219789,925.0
17.639001484,885.0
17.717783179,851.0
17.796564874,870.0
17.875346569,834.0
17.954128264,851.0
18.032909959,873.0
18.111691654,832.0
18.190473349,821.0
18.269255044,880.0
18.348036739,827.0
18.426818434,830.0
18.505600129,816.0
18.584381824,882.0
18.663163519,817.0
18.741945214,845.0
18.820726909,863.0
18.899508604,755.0
18.978290299,825.0
19.057071994,835.0
19.135853689,818.0
19.214635384,782.0
19.293417079,824.0
19.372198774,789.0
19.450980469,826.0
19.529762164,830.0
19.608543859,800.0
19.687325554,816.0
19.766107249,833.0
19.844888944,801.0
19.923670639,816.0
20.002452334,738.0
20.081234029,784.0
20.160015724,754.0
20.238797419,831.0
20.317579114,825.0
20.396360810,823.0
20.475142505,811.0
20.553924200,785.0
20.632705895,769.0
20.711487590,785.0
20.790269285,823.0
20.869050980,824.0
20.947832675,821.0
21.026614370,776.0
21.105396065,780.0
21.184177760,762.0
21.262959455,837.0
21.341741150,782.0
21.420522845,796.0
21.499304540,793.0
21.578086235,837.0
21.656867930,790.0
21.735649625,750.0
21.814431320,767.0
21.893213015,749.0
21.971994710,795.0
22.050776405,812.0
22.129558100,836.0
22.208339795,779.0
22.287121490,821.0
22.365903185,808.0
22.444684880,855.0
22.523466575,791.0
22.602248270,783.0
22.681029965,775.0
22.759811660,756.0
22.838593355,735.0
22.917375050,865.0
22.996156745,779.0
23.074938440,797.0
23.153720135,788.0
23.232501830,777.0
23.311283525,790.0
23.390065220,812.0
23.468846915,885.0
23.547628610,818.0
23.626410305,848.0
23.705192000,773.0
23.783973696,750.0
23.862755391,800.0
23.941537086,811.0
24.020318781,821.0
24.099100476,811.0
24.177882171,760.0
24.256663866,797.0
24.335445561,854.0
24.414227256,781.0
24.493008951,813.0
24.571790646,780.0
24.650572341,847.0
24.729354036,816.0
24.808135731,850.0
24.886917426,806.0
24.965699121,844.0
25.044480816,805.0
25.123262511,832.0
25.202044206,850.0
25.280825901,817.0
25.359607596,798.0
25.438389291,790.0
25.517170986,832.0
25.595952681,826.0
25.674734376,849.0
25.753516071,803.0
25.832297766,835.0
25.911079461,855.0
25.989861156,848.0
26.068642851,806.0
26.147424546,857.0
26.226206241,857.0
26.304987936,846.0
26.383769631,859.0
26.462551326,808.0
26.541333021,866.0
26.620114716,783.0
26.698896411,797.0
26.777678106,821.0
26.856459801,800.0
26.935241496,838.0
27.014023191,811.0
27.092804886,809.0
27.171586582,765.0
27.250368277,830.0
27.329149972,868.0
27.407931667,868.0
27.486713362,856.0
27.565495057,795.0
27.644276752,803.0
27.723058447,820.0
27.801840142,830.0
27.880621837,776.0
27.959403532,825.0
28.038185227,826.0
28.116966922,817.0
28.195748617,762.0
28.274530312,871.0
28.353312007,769.0
28.432093702,843.0
28.510875397,788.0
28.589657092,808.0
28.668438787,867.0
28.747220482,808.0
28.826002177,854.0
28.904783872,822.0
28.983565567,809.0
29.062347262,884.0
29.141128957,819.0
29.219910652,807.0
29.298692347,796.0
29.377474042,801.0
29.456255737,833.0
29.535037432,801.0
29.613819127,796.0
29.692600822,849.0
29.771382517,862.0
29.850164212,798.0
29.928945907,808.0
30.007727602,812.0
30.086509297,841.0
30.165290992,830.0
30.244072687,810.0
30.322854382,744.0
30.401636077,791.0
30.480417772,758.0
30.559199468,800.0
30.637981163,783.0
30.716762858,790.0
30.795544553,748.0
30.874326248,755.0
30.953107943,781.0
31.031889638,722.0
31.110671333,787.0
31.189453028,771.0
31.268234723,680.0
31.347016418,778.0
31.425798113,735.0
31.504579808,698.0
31.583361503,719.0
31.662143198,751.0
31.740924893,693.0
31.819706588,694.0
31.898488283,737.0
31.977269978,720.0
32.056051673,726.0
32.134833368,665.0
32.213615063,749.0
32.292396758,641.0
32.371178453,680.0
32.449960148,673.0
32.528741843,691.0
32.607523538,723.0
32.686305233,703.0
32.765086928,695.0
32.843868623,657.0
32.922650318,675.0
33.001432013,615.0
33.080213708,666.0
33.158995403,642.0
33.237777098,673.0
33.316558793,647.0
33.395340488,651.0
33.474122183,685.0
33.552903878,605.0
33.631685573,678.0
33.710467268,588.0
33.789248963,669.0
33.868030658,653.0
33.946812354,626.0
34.025594049,630.0
34.104375744,612.0
34.183157439,614.0
34.261939134,630.0
34.340720829,620.0
34.419502524,640.0
34.498284219,622.0
34.577065914,620.0
34.655847609,660.0
34.734629304,637.0
34.813410999,687.0
34.892192694,621.0
34.970974389,616.0
35.049756084,675.0
35.128537779,625.0
35.207319474,651.0
35.286101169,628.0
35.364882864,643.0
35.443664559,617.0
35.522446254,688.0
35.601227949,657.0
35.680009644,648.0
35.758791339,626.0
35.837573034,662.0
35.916354729,628.0
35.995136424,626.0
36.073918119,623.0
36.152699814,660.0
36.231481509,654.0
36.310263204,713.0
36.389044899,636.0
36.467826594,644.0
36.546608289,678.0
36.625389984,663.0
36.704171679,645.0
36.782953374,654.0
36.861735069,650.0
36.940516764,675.0
37.019298459,632.0
37.098080154,687.0
37.176861849,686.0
37.255643544,716.0
37.334425240,601.0
37.413206935,732.0
37.491988630,693.0
37.570770325,727.0
37.649552020,707.0
37.728333715,691.0
37.807115410,700.0
37.885897105,674.0
37.964678800,685.0
38.043460495,681.0
38.122242190,747.0
38.201023885,751.0
38.279805580,714.0
38.358587275,743.0
38.437368970,770.0
38.516150665,777.0
38.594932360,807.0
38.673714055,813.0
38.752495750,790.0
38.831277445,746.0
38.910059140,805.0
38.988840835,865.0
39.067622530,840.0
39.146404225,854.0
39.225185920,936.0
39.303967615,926.0
39.382749310,973.0
39.461531005,1013.0
39.540312700,995.0
39.619094395,1034.0
39.697876090,1098.0
39.776657785,1159.0
39.855439480,1290.0
39.934221175,1360.0
40.013002870,1383.0
40.091784565,1437.0
40.170566260,1610.0
40.249347955,1730.0
40.328129650,1750.0
40.406911345,1848.0
40.485693040,1941.0
40.564474735,1954.0
40.643256430,1899.0
40.722038126,2031.0
40.800819821,1935.0
40.879601516,1891.0
40.958383211,1943.0
41.037164906,2003.0
41.115946601,1951.0
41.194728296,1944.0
41.273509991,1838.0
41.352291686,1916.0
41.431073381,1847.0
41.509855076,1742.0
41.588636771,1751.0
41.667418466,1799.0
41.746200161,1733.0
41.824981856,1677.0
41.903763551,1701.0
41.982545246,1745.0
42.061326941,1597.0
42.140108636,1668.0
42.218890331,1652.0
42.297672026,1661.0
42.376453721,1618.0
42.455235416,1539.0
42.534017111,1529.0
42.612798806,1507.0
42.691580501,1527.0
42.770362196,1477.0
42.849143891,1461.0
42.927925586,1374.0
43.006707281,1415.0
43.085488976,1414.0
43.164270671,1306.0
43.243052366,1303.0
43.321834061,1249.0
43.400615756,1304.0
43.479397451,1283.0
43.558179146,1196.0
43.636960841,1191.0
43.715742536,1230.0
43.794524231,1151.0
43.873305926,1188.0
43.952087621,1089.0
44.030869316,1092.0
44.109651011,1079.0
44.188432707,1034.0
44.267214402,1074.0
44.345996097,1006.0
44.424777792,983.0
44.503559487,998.0
44.582341182,1006.0
44.661122877,916.0
44.739904572,911.0
44.818686267,954.0
44.897467962,884.0
44.976249657,902.0
45.055031352,886.0
45.133813047,844.0
45.212594742,922.0
45.291376437,767.0
45.370158132,843.0
45.448939827,792.0
45.527721522,799.0
45.606503217,765.0
45.685284912,781.0
45.764066607,775.0
45.842848302,785.0
45.921629997,777.0
46.000411692,775.0
46.079193387,692.0
46.157975082,723.0
46.236756777,710.0
46.315538472,710.0
46.394320167,757.0
46.473101862,748.0
46.551883557,644.0
46.630665252,723.0
46.709446947,635.0
46.788228642,659.0
46.867010337,656.0
46.945792032,660.0
47.024573727,624.0
47.103355422,639.0
47.182137117,619.0
47.260918812,625.0
47.339700507,562.0
47.418482202,612.0
47.497263897,617.0
47.576045593,604.0
47.654827288,589.0
47.733608983,583.0
47.812390678,638.0
47.891172373,526.0
47.969954068,556.0
48.048735763,526.0
48.127517458,563.0
48.206299153,529.0
48.285080848,549.0
48.363862543,510.0
48.442644238,547.0
48.521425933,481.0
48.600207628,528.0
48.678989323,522.0
48.757771018,469.0
48.836552713,521.0
48.915334408,460.0
48.994116103,419.0
49.072897798,453.0
49.151679493,477.0
49.230461188,494.0
49.309242883,445.0
49.388024578,487.0
49.466806273,485.0
49.545587968,435.0
49.624369663,473.0
49.703151358,439.0
49.781933053,421.0
49.860714748,444.0
49.939496443,441.0
50.018278138,431.0
50.097059833,470.0
50.175841528,422.0
50.254623223,430.0
50.333404918,438.0
50.412186613,416.0
50.490968308,424.0
50.569750003,488.0
50.648531698,386.0
50.727313393,407.0
50.806095088,413.0
50.884876783,411.0
50.963658479,382.0
51.042440174,423.0
51.121221869,429.0
51.200003564,351.0
51.278785259,422.0
51.357566954,359.0
51.436348649,388.0
51.515130344,387.0
51.593912039,409.0
51.672693734,426.0
51.751475429,421.0
51.830257124,405.0
51.909038819,385.0
51.987820514,360.0
52.066602209,386.0
52.145383904,370.0
52.224165599,366.0
52.302947294,405.0
52.381728989,417.0
52.460510684,394.0
52.539292379,403.0
52.618074074,379.0
52.696855769,387.0
52.775637464,399.0
52.854419159,350.0
52.933200854,366.0
53.011982549,377.0
53.090764244,326.0
53.169545939,351.0
53.248327634,353.0
53.327109329,342.0
53.405891024,337.0
53.484672719,391.0
53.563454414,365.0
53.642236109,344.0
53.721017804,384.0
53.799799499,325.0
53.878581194,358.0
53.957362889,370.0
54.036144584,379.0
54.114926279,391.0
54.193707974,339.0
54.272489669,371.0
54.351271365,343.0
54.430053060,313.0
54.508834755,365.0
54.587616450,360.0
54.666398145,336.0
54.745179840,384.0
54.823961535,394.0
54.902743230,361.0
54.981524925,384.0
55.060306620,373.0
55.139088315,353.0
55.217870010,347.0
55.296651705,355.0
55.375433400,359.0
55.454215095,324.0
55.532996790,378.0
55.611778485,330.0
55.690560180,326.0
55.769341875,389.0
55.848123570,361.0
55.926905265,351.0
56.005686960,367.0
56.084468655,340.0
56.163250350,357.0
56.242032045,330.0
56.320813740,356.0
56.399595435,349.0
56.478377130,327.0
56.557158825,341.0
56.635940520,350.0
56.714722215,351.0
56.793503910,313.0
56.872285605,321.0
56.951067300,348.0
57.029848995,339.0
57.108630690,314.0
57.187412385,314.0
57.266194080,331.0
57.344975775,349.0
57.423757470,315.0
57.502539165,359.0
57.581320860,337.0
57.660102555,327.0
57.738884251,323.0
57.817665946,318.0
57.896447641,369.0
57.975229336,359.0
58.054011031,308.0
58.132792726,313.0
58.211574421,335.0
58.290356116,339.0
58.369137811,331.0
58.447919506,351.0
58.526701201,343.0
58.605482896,346.0
58.684264591,317.0
58.763046286,356.0
58.841827981,380.0
58.920609676,345.0
58.999391371,317.0
59.078173066,300.0
59.156954761,341.0
59.235736456,322.0
59.314518151,327.0
59.393299846,322.0
59.472081541,303.0
59.550863236,332.0
59.629644931,381.0
59.708426626,328.0
59.787208321,320.0
59.865990016,285.0
59.944771711,301.0
60.023553406,320.0
60.102335101,337.0
60.181116796,323.0
60.259898491,324.0
60.338680186,321.0
60.417461881,352.0
60.496243576,349.0
60.575025271,318.0
60.653806966,345.0
60.732588661,335.0
60.811370356,329.0
60.890152051,317.0
60.968933746,315.0
61.047715441,292.0
61.126497137,354.0
61.205278832,303.0
61.284060527,353.0
61.362842222,318.0
61.441623917,303.0
61.520405612,316.0
61.599187307,322.0
61.677969002,337.0
61.756750697,321.0
61.835532392,356.0
61.914314087,301.0
61.993095782,311.0
62.071877477,304.0
62.150659172,338.0
62.229440867,293.0
62.308222562,296.0
62.387004257,334.0
62.465785952,312.0
62.544567647,314.0
62.623349342,330.0
62.702131037,334.0
62.780912732,299.0
62.859694427,342.0
62.938476122,264.0
63.017257817,304.0
63.096039512,308.0
63.174821207,299.0
63.253602902,294.0
63.332384597,322.0
63.411166292,309.0
63.489947987,345.0
63.568729682,296.0
63.647511377,302.0
63.726293072,317.0
63.805074767,306.0
63.883856462,286.0
63.962638157,317.0
64.041419852,318.0
64.120201547,314.0
64.198983242,332.0
64.277764937,285.0
64.356546632,290.0
64.435328327,313.0
64.514110023,270.0
64.592891718,296.0
64.671673413,281.0
64.750455108,304.0
64.829236803,310.0
64.908018498,286.0
64.986800193,256.0
65.065581888,326.0
65.144363583,293.0
65.223145278,301.0
65.301926973,281.0
65.380708668,254.0
65.459490363,277.0
65.538272058,292.0
65.617053753,258.0
65.695835448,331.0
65.774617143,297.0
65.853398838,312.0
65.932180533,288.0
66.010962228,283.0
66.089743923,267.0
66.168525618,296.0
66.247307313,293.0
66.326089008,307.0
66.404870703,274.0
66.483652398,309.0
66.562434093,264.0
66.641215788,296.0
66.719997483,269.0
66.798779178,278.0
66.877560873,284.0
66.956342568,297.0
67.035124263,287.0
67.113905958,279.0
67.192687653,299.0
67.271469348,245.0
67.350251043,282.0
67.429032738,281.0
67.507814433,294.0
67.586596128,287.0
67.665377823,294.0
67.744159518,287.0
67.822941213,276.0
67.901722909,262.0
67.980504604,269.0
68.059286299,279.0
68.138067994,275.0
68.216849689,294.0
68.295631384,271.0
68.374413079,272.0
68.453194774,263.0
68.531976469,272.0
68.610758164,296.0
68.689539859,278.0
68.768321554,249.0
68.847103249,269.0
68.925884944,265.0
69.004666639,263.0
69.083448334,240.0
69.162230029,259.0
69.241011724,238.0
69.319793419,277.0
69.398575114,303.0
69.477356809,253.0
69.556138504,286.0
69.634920199,289.0
69.713701894,259.0
69.792483589,293.0
69.871265284,286.0
69.950046979,270.0
70.028828674,281.0
70.107610369,276.0
70.186392064,281.0
70.265173759,274.0
70.343955454,280.0
70.422737149,307.0
70.501518844,295.0
70.580300539,273.0
70.659082234,259.0
70.737863929,283.0
70.816645624,274.0
70.895427319,276.0
70.974209014,284.0
71.052990709,297.0
71.131772404,293.0
71.210554099,264.0
71.289335794,290.0
71.368117490,276.0
71.446899185,307.0
71.525680880,310.0
71.604462575,285.0
71.683244270,258.0
71.762025965,314.0
71.840807660,305.0
71.919589355,278.0
71.998371050,305.0
72.077152745,317.0
72.155934440,311.0
72.234716135,311.0
72.313497830,360.0
72.392279525,321.0
72.471061220,313.0
72.549842915,368.0
72.628624610,397.0
72.707406305,387.0
72.786188000,386.0
72.864969695,369.0
72.943751390,439.0
73.022533085,404.0
73.101314780,412.0
73.180096475,422.0
73.258878170,465.0
73.337659865,448.0
73.416441560,428.0
73.495223255,437.0
73.574004950,440.0
73.652786645,449.0
73.731568340,407.0
73.810350035,451.0
73.889131730,369.0
73.967913425,416.0
74.046695120,382.0
74.125476815,364.0
74.204258510,329.0
74.283040205,378.0
74.361821900,354.0
74.440603595,334.0
74.519385290,296.0
74.598166985,337.0
74.676948680,330.0
74.755730376,316.0
74.834512071,321.0
74.913293766,319.0
74.992075461,298.0
75.070857156,338.0
75.149638851,339.0
75.228420546,303.0
75.307202241,303.0
75.385983936,289.0
75.464765631,277.0
75.543547326,314.0
75.622329021,268.0
75.701110716,269.0
75.779892411,257.0
75.858674106,276.0
75.937455801,269.0
76.016237496,299.0
76.095019191,292.0
76.173800886,241.0
76.252582581,299.0
76.331364276,280.0
76.410145971,264.0
76.488927666,262.0
76.567709361,256.0
76.646491056,285.0
76.725272751,256.0
76.804054446,270.0
76.882836141,262.0
76.961617836,262.0
77.040399531,298.0
77.119181226,280.0
77.197962921,279.0
77.276744616,266.0
77.355526311,247.0
77.434308006,259.0
77.513089701,272.0
77.591871396,263.0
77.670653091,259.0
77.749434786,269.0
77.828216481,240.0
77.906998176,270.0
77.985779871,281.0
78.064561566,262.0
78.143343262,270.0
78.222124957,254.0
78.300906652,260.0
78.379688347,256.0
78.458470042,265.0
78.537251737,216.0
78.616033432,242.0
78.694815127,219.0
78.773596822,265.0
78.852378517,248.0
78.931160212,232.0
79.009941907,251.0
79.088723602,263.0
79.167505297,256.0
79.246286992,268.0
79.325068687,266.0
79.403850382,238.0
79.482632077,259.0
79.561413772,260.0
79.640195467,249.0
79.718977162,264.0
79.797758857,275.0
79.876540552,235.0
79.955322247,221.0
80.034103942,268.0
80.112885637,234.0
80.191667332,244.0
80.270449027,244.0
80.349230722,240.0
80.428012417,260.0
80.506794112,235.0
80.585575807,231.0
80.664357502,236.0
80.743139197,239.0
80.821920892,253.0
80.900702587,218.0
80.979484282,251.0
81.058265977,245.0
81.137047672,288.0
81.215829367,224.0
81.294611062,262.0
81.373392757,239.0
81.452174452,246.0
81.530956148,247.0
81.609737843,242.0
81.688519538,248.0
81.767301233,248.0
81.846082928,229.0
81.924864623,255.0
82.003646318,265.0
82.082428013,213.0
82.161209708,253.0
82.239991403,231.0
82.318773098,259.0
82.397554793,250.0
82.476336488,249.0
82.555118183,239.0
82.633899878,255.0
82.712681573,232.0
82.791463268,234.0
82.870244963,228.0
82.949026658,244.0
83.027808353,246.0
83.106590048,224.0
83.185371743,233.0
83.264153438,208.0
83.342935133,223.0
83.421716828,287.0
83.500498523,192.0
83.579280218,263.0
83.658061913,225.0
83.736843608,259.0
83.815625303,231.0
83.894406998,231.0
83.973188693,219.0
84.051970388,220.0
84.130752083,231.0
84.209533778,235.0
84.288315473,223.0
84.367097168,251.0
84.445878863,260.0
84.524660558,246.0
84.603442253,193.0
84.682223948,238.0
84.761005643,251.0
84.839787338,244.0
84.918569034,232.0
84.997350729,237.0
85.076132424,233.0
85.154914119,235.0
85.233695814,267.0
85.312477509,268.0
85.391259204,233.0
85.470040899,227.0
85.548822594,221.0
85.627604289,247.0
85.706385984,204.0
85.785167679,215.0
85.863949374,240.0
85.942731069,230.0
86.021512764,227.0
86.100294459,241.0
86.179076154,227.0
86.257857849,256.0
86.336639544,233.0
86.415421239,236.0
86.494202934,215.0
86.572984629,218.0
86.651766324,270.0
86.730548019,219.0
86.809329714,250.0
86.888111409,263.0
86.966893104,286.0
87.045674799,265.0
87.124456494,243.0
87.203238189,240.0
87.282019884,304.0
87.360801579,229.0
87.439583274,253.0
87.518364969,231.0
87.597146664,276.0
87.675928359,265.0
87.754710054,269.0
87.833491749,248.0
87.912273444,257.0
87.991055139,270.0
88.069836834,265.0
88.148618529,297.0
88.227400224,248.0
88.306181920,240.0
88.384963615,252.0
88.463745310,257.0
88.542527005,258.0
88.621308700,236.0
88.700090395,244.0
88.778872090,233.0
88.857653785,261.0
88.936435480,263.0
89.015217175,266.0
89.093998870,262.0
89.172780565,248.0
89.251562260,250.0
89.330343955,214.0
89.409125650,234.0
89.487907345,269.0
89.566689040,227.0
89.645470735,253.0
89.724252430,235.0
89.803034125,255.0
89.881815820,250.0
89.960597515,247.0
89.986858080,229.0