File: 2017007296/7296-a5#.csv
[Measurement conditions]
Sample identification,
Comment - 1,"Configuration=Stage for flat samples/holders, Owner=User-1, Creation date=3/27/2015 11:56:23 AM"
Comment - 2,"Goniometer=Theta/Theta; Minimum step size 2Theta:0.0001; Minimum step size Omega:0.0001"
Comment - 3,"Sample stage=Stage for flat samples/holders"
Comment - 4,"Diffractometer system=EMPYREAN"
Comment - 5,"Measurement program=C:\PANalytical\Data Collector\Programs\Powder - Copy.xrdmp, Identifier={BEEA10DD-8FD6-4721-8940-4FBC5A4262A1}"
Comment - 6,"Fine Calibration Offset for 2Theta = -0.0130 deg"
Comment - 7,"Fine Calibration Offset for Omega = -0.0070 deg"
Anode material,Cu
K-Alpha1 wavelength,1.5405980
K-Alpha2 wavelength,1.5444260
Ratio K-Alpha2/K-Alpha1,0.500
Divergence slit,Fixed,0.38mm
Monochromator used,NO
Generator voltage, 40
Tube current, 35
File date and time,24/Jul/2017 16:20
Unit cell,
h k l, 0 0 0
Scan axis,Gonio
Scan range,5.020799997,89.999988363
Scan step size,0.0262606
No. of points, 3236
Scan type,CONTINUOUS
Time per step,18.615
[Scan points]
Angle,Intensity
5.033930280,1034.0
5.112711975,1117.0
5.191493670,1066.0
5.270275365,1104.0
5.349057060,1046.0
5.427838755,1080.0
5.506620450,1128.0
5.585402145,1024.0
5.664183840,1042.0
5.742965535,970.0
5.821747230,1003.0
5.900528925,1035.0
5.979310620,1011.0
6.058092315,961.0
6.136874010,993.0
6.215655705,1082.0
6.294437400,1062.0
6.373219095,1032.0
6.452000790,1024.0
6.530782485,1020.0
6.609564180,940.0
6.688345875,1021.0
6.767127571,991.0
6.845909266,985.0
6.924690961,993.0
7.003472656,1022.0
7.082254351,999.0
7.161036046,926.0
7.239817741,988.0
7.318599436,987.0
7.397381131,944.0
7.476162826,935.0
7.554944521,954.0
7.633726216,979.0
7.712507911,940.0
7.791289606,953.0
7.870071301,923.0
7.948852996,924.0
8.027634691,871.0
8.106416386,912.0
8.185198081,905.0
8.263979776,874.0
8.342761471,914.0
8.421543166,862.0
8.500324861,855.0
8.579106556,837.0
8.657888251,847.0
8.736669946,851.0
8.815451641,814.0
8.894233336,880.0
8.973015031,920.0
9.051796726,843.0
9.130578421,836.0
9.209360116,894.0
9.288141811,837.0
9.366923506,778.0
9.445705201,880.0
9.524486896,826.0
9.603268591,851.0
9.682050286,811.0
9.760831981,839.0
9.839613676,769.0
9.918395371,803.0
9.997177066,838.0
10.075958761,842.0
10.154740457,802.0
10.233522152,838.0
10.312303847,795.0
10.391085542,780.0
10.469867237,829.0
10.548648932,695.0
10.627430627,761.0
10.706212322,807.0
10.784994017,802.0
10.863775712,817.0
10.942557407,776.0
11.021339102,772.0
11.100120797,733.0
11.178902492,796.0
11.257684187,712.0
11.336465882,787.0
11.415247577,753.0
11.494029272,800.0
11.572810967,711.0
11.651592662,769.0
11.730374357,775.0
11.809156052,813.0
11.887937747,750.0
11.966719442,725.0
12.045501137,754.0
12.124282832,787.0
12.203064527,785.0
12.281846222,743.0
12.360627917,732.0
12.439409612,723.0
12.518191307,685.0
12.596973002,755.0
12.675754697,778.0
12.754536392,772.0
12.833318087,733.0
12.912099782,743.0
12.990881477,734.0
13.069663172,768.0
13.148444867,750.0
13.227226562,756.0
13.306008257,754.0
13.384789952,762.0
13.463571647,772.0
13.542353343,772.0
13.621135038,692.0
13.699916733,755.0
13.778698428,731.0
13.857480123,806.0
13.936261818,744.0
14.015043513,739.0
14.093825208,764.0
14.172606903,731.0
14.251388598,757.0
14.330170293,746.0
14.408951988,726.0
14.487733683,714.0
14.566515378,712.0
14.645297073,743.0
14.724078768,724.0
14.802860463,735.0
14.881642158,733.0
14.960423853,687.0
15.039205548,664.0
15.117987243,659.0
15.196768938,676.0
15.275550633,621.0
15.354332328,622.0
15.433114023,625.0
15.511895718,635.0
15.590677413,600.0
15.669459108,638.0
15.748240803,543.0
15.827022498,559.0
15.905804193,531.0
15.984585888,522.0
16.063367583,543.0
16.142149278,508.0
16.220930973,500.0
16.299712668,539.0
16.378494363,517.0
16.457276058,473.0
16.536057753,475.0
16.614839448,476.0
16.693621143,472.0
16.772402838,480.0
16.851184533,507.0
16.929966229,464.0
17.008747924,449.0
17.087529619,485.0
17.166311314,473.0
17.245093009,435.0
17.323874704,460.0
17.402656399,473.0
17.481438094,458.0
17.560219789,466.0
17.639001484,466.0
17.717783179,448.0
17.796564874,409.0
17.875346569,445.0
17.954128264,443.0
18.032909959,461.0
18.111691654,427.0
18.190473349,434.0
18.269255044,437.0
18.348036739,421.0
18.426818434,470.0
18.505600129,448.0
18.584381824,471.0
18.663163519,445.0
18.741945214,378.0
18.820726909,446.0
18.899508604,394.0
18.978290299,404.0
19.057071994,390.0
19.135853689,399.0
19.214635384,398.0
19.293417079,441.0
19.372198774,428.0
19.450980469,431.0
19.529762164,444.0
19.608543859,445.0
19.687325554,416.0
19.766107249,420.0
19.844888944,403.0
19.923670639,428.0
20.002452334,408.0
20.081234029,420.0
20.160015724,402.0
20.238797419,417.0
20.317579114,423.0
20.396360810,416.0
20.475142505,444.0
20.553924200,420.0
20.632705895,441.0
20.711487590,439.0
20.790269285,446.0
20.869050980,400.0
20.947832675,474.0
21.026614370,419.0
21.105396065,438.0
21.184177760,455.0
21.262959455,467.0
21.341741150,443.0
21.420522845,451.0
21.499304540,446.0
21.578086235,440.0
21.656867930,469.0
21.735649625,477.0
21.814431320,425.0
21.893213015,459.0
21.971994710,439.0
22.050776405,490.0
22.129558100,499.0
22.208339795,411.0
22.287121490,446.0
22.365903185,459.0
22.444684880,457.0
22.523466575,447.0
22.602248270,468.0
22.681029965,458.0
22.759811660,464.0
22.838593355,508.0
22.917375050,484.0
22.996156745,422.0
23.074938440,486.0
23.153720135,459.0
23.232501830,447.0
23.311283525,474.0
23.390065220,478.0
23.468846915,515.0
23.547628610,519.0
23.626410305,506.0
23.705192000,509.0
23.783973696,499.0
23.862755391,487.0
23.941537086,496.0
24.020318781,521.0
24.099100476,521.0
24.177882171,491.0
24.256663866,528.0
24.335445561,485.0
24.414227256,491.0
24.493008951,514.0
24.571790646,558.0
24.650572341,517.0
24.729354036,537.0
24.808135731,519.0
24.886917426,542.0
24.965699121,482.0
25.044480816,491.0
25.123262511,481.0
25.202044206,553.0
25.280825901,547.0
25.359607596,504.0
25.438389291,533.0
25.517170986,512.0
25.595952681,525.0
25.674734376,537.0
25.753516071,581.0
25.832297766,559.0
25.911079461,580.0
25.989861156,510.0
26.068642851,517.0
26.147424546,614.0
26.226206241,586.0
26.304987936,615.0
26.383769631,514.0
26.462551326,557.0
26.541333021,547.0
26.620114716,528.0
26.698896411,518.0
26.777678106,546.0
26.856459801,595.0
26.935241496,535.0
27.014023191,577.0
27.092804886,580.0
27.171586582,565.0
27.250368277,583.0
27.329149972,578.0
27.407931667,526.0
27.486713362,553.0
27.565495057,578.0
27.644276752,579.0
27.723058447,555.0
27.801840142,574.0
27.880621837,604.0
27.959403532,535.0
28.038185227,579.0
28.116966922,585.0
28.195748617,575.0
28.274530312,647.0
28.353312007,589.0
28.432093702,601.0
28.510875397,588.0
28.589657092,567.0
28.668438787,576.0
28.747220482,554.0
28.826002177,584.0
28.904783872,644.0
28.983565567,613.0
29.062347262,642.0
29.141128957,599.0
29.219910652,625.0
29.298692347,580.0
29.377474042,587.0
29.456255737,592.0
29.535037432,574.0
29.613819127,610.0
29.692600822,589.0
29.771382517,596.0
29.850164212,561.0
29.928945907,594.0
30.007727602,585.0
30.086509297,604.0
30.165290992,606.0
30.244072687,560.0
30.322854382,601.0
30.401636077,565.0
30.480417772,598.0
30.559199468,628.0
30.637981163,610.0
30.716762858,589.0
30.795544553,637.0
30.874326248,620.0
30.953107943,568.0
31.031889638,604.0
31.110671333,579.0
31.189453028,590.0
31.268234723,525.0
31.347016418,587.0
31.425798113,591.0
31.504579808,587.0
31.583361503,547.0
31.662143198,584.0
31.740924893,594.0
31.819706588,533.0
31.898488283,556.0
31.977269978,537.0
32.056051673,547.0
32.134833368,557.0
32.213615063,565.0
32.292396758,598.0
32.371178453,571.0
32.449960148,533.0
32.528741843,626.0
32.607523538,551.0
32.686305233,528.0
32.765086928,531.0
32.843868623,529.0
32.922650318,527.0
33.001432013,563.0
33.080213708,580.0
33.158995403,595.0
33.237777098,541.0
33.316558793,541.0
33.395340488,558.0
33.474122183,519.0
33.552903878,546.0
33.631685573,528.0
33.710467268,496.0
33.789248963,536.0
33.868030658,516.0
33.946812354,574.0
34.025594049,575.0
34.104375744,543.0
34.183157439,552.0
34.261939134,467.0
34.340720829,530.0
34.419502524,524.0
34.498284219,520.0
34.577065914,545.0
34.655847609,565.0
34.734629304,549.0
34.813410999,496.0
34.892192694,523.0
34.970974389,479.0
35.049756084,514.0
35.128537779,552.0
35.207319474,519.0
35.286101169,508.0
35.364882864,489.0
35.443664559,479.0
35.522446254,516.0
35.601227949,496.0
35.680009644,496.0
35.758791339,526.0
35.837573034,497.0
35.916354729,497.0
35.995136424,465.0
36.073918119,520.0
36.152699814,495.0
36.231481509,582.0
36.310263204,536.0
36.389044899,474.0
36.467826594,538.0
36.546608289,495.0
36.625389984,455.0
36.704171679,480.0
36.782953374,517.0
36.861735069,494.0
36.940516764,505.0
37.019298459,520.0
37.098080154,517.0
37.176861849,518.0
37.255643544,542.0
37.334425240,483.0
37.413206935,485.0
37.491988630,464.0
37.570770325,526.0
37.649552020,515.0
37.728333715,518.0
37.807115410,491.0
37.885897105,550.0
37.964678800,517.0
38.043460495,531.0
38.122242190,483.0
38.201023885,520.0
38.279805580,561.0
38.358587275,542.0
38.437368970,612.0
38.516150665,544.0
38.594932360,517.0
38.673714055,518.0
38.752495750,564.0
38.831277445,583.0
38.910059140,609.0
38.988840835,582.0
39.067622530,641.0
39.146404225,552.0
39.225185920,637.0
39.303967615,674.0
39.382749310,642.0
39.461531005,663.0
39.540312700,726.0
39.619094395,723.0
39.697876090,741.0
39.776657785,817.0
39.855439480,782.0
39.934221175,881.0
40.013002870,896.0
40.091784565,928.0
40.170566260,983.0
40.249347955,1070.0
40.328129650,1009.0
40.406911345,1051.0
40.485693040,1077.0
40.564474735,1062.0
40.643256430,1111.0
40.722038126,1080.0
40.800819821,1040.0
40.879601516,1085.0
40.958383211,996.0
41.037164906,1053.0
41.115946601,1014.0
41.194728296,1033.0
41.273509991,1088.0
41.352291686,1026.0
41.431073381,1043.0
41.509855076,1027.0
41.588636771,1057.0
41.667418466,994.0
41.746200161,1009.0
41.824981856,959.0
41.903763551,992.0
41.982545246,955.0
42.061326941,929.0
42.140108636,890.0
42.218890331,902.0
42.297672026,878.0
42.376453721,873.0
42.455235416,867.0
42.534017111,867.0
42.612798806,818.0
42.691580501,812.0
42.770362196,806.0
42.849143891,876.0
42.927925586,776.0
43.006707281,817.0
43.085488976,803.0
43.164270671,786.0
43.243052366,772.0
43.321834061,775.0
43.400615756,720.0
43.479397451,758.0
43.558179146,738.0
43.636960841,721.0
43.715742536,698.0
43.794524231,737.0
43.873305926,698.0
43.952087621,738.0
44.030869316,625.0
44.109651011,662.0
44.188432707,696.0
44.267214402,656.0
44.345996097,640.0
44.424777792,651.0
44.503559487,656.0
44.582341182,604.0
44.661122877,613.0
44.739904572,629.0
44.818686267,574.0
44.897467962,555.0
44.976249657,535.0
45.055031352,609.0
45.133813047,581.0
45.212594742,603.0
45.291376437,546.0
45.370158132,543.0
45.448939827,561.0
45.527721522,605.0
45.606503217,569.0
45.685284912,538.0
45.764066607,533.0
45.842848302,514.0
45.921629997,568.0
46.000411692,511.0
46.079193387,517.0
46.157975082,501.0
46.236756777,460.0
46.315538472,513.0
46.394320167,515.0
46.473101862,497.0
46.551883557,479.0
46.630665252,462.0
46.709446947,442.0
46.788228642,490.0
46.867010337,523.0
46.945792032,493.0
47.024573727,450.0
47.103355422,418.0
47.182137117,442.0
47.260918812,472.0
47.339700507,446.0
47.418482202,434.0
47.497263897,429.0
47.576045593,465.0
47.654827288,439.0
47.733608983,480.0
47.812390678,423.0
47.891172373,410.0
47.969954068,472.0
48.048735763,429.0
48.127517458,458.0
48.206299153,404.0
48.285080848,390.0
48.363862543,369.0
48.442644238,409.0
48.521425933,403.0
48.600207628,399.0
48.678989323,406.0
48.757771018,357.0
48.836552713,348.0
48.915334408,368.0
48.994116103,383.0
49.072897798,405.0
49.151679493,353.0
49.230461188,371.0
49.309242883,381.0
49.388024578,338.0
49.466806273,389.0
49.545587968,371.0
49.624369663,368.0
49.703151358,353.0
49.781933053,360.0
49.860714748,415.0
49.939496443,407.0
50.018278138,378.0
50.097059833,342.0
50.175841528,361.0
50.254623223,374.0
50.333404918,396.0
50.412186613,358.0
50.490968308,375.0
50.569750003,349.0
50.648531698,325.0
50.727313393,364.0
50.806095088,313.0
50.884876783,332.0
50.963658479,398.0
51.042440174,345.0
51.121221869,351.0
51.200003564,353.0
51.278785259,383.0
51.357566954,365.0
51.436348649,328.0
51.515130344,347.0
51.593912039,365.0
51.672693734,338.0
51.751475429,334.0
51.830257124,312.0
51.909038819,332.0
51.987820514,334.0
52.066602209,332.0
52.145383904,329.0
52.224165599,341.0
52.302947294,321.0
52.381728989,354.0
52.460510684,312.0
52.539292379,340.0
52.618074074,346.0
52.696855769,344.0
52.775637464,326.0
52.854419159,338.0
52.933200854,320.0
53.011982549,331.0
53.090764244,340.0
53.169545939,335.0
53.248327634,319.0
53.327109329,289.0
53.405891024,310.0
53.484672719,340.0
53.563454414,348.0
53.642236109,320.0
53.721017804,306.0
53.799799499,342.0
53.878581194,321.0
53.957362889,320.0
54.036144584,352.0
54.114926279,322.0
54.193707974,336.0
54.272489669,339.0
54.351271365,336.0
54.430053060,326.0
54.508834755,322.0
54.587616450,343.0
54.666398145,320.0
54.745179840,326.0
54.823961535,317.0
54.902743230,307.0
54.981524925,311.0
55.060306620,324.0
55.139088315,315.0
55.217870010,332.0
55.296651705,320.0
55.375433400,301.0
55.454215095,289.0
55.532996790,306.0
55.611778485,304.0
55.690560180,333.0
55.769341875,335.0
55.848123570,293.0
55.926905265,327.0
56.005686960,315.0
56.084468655,316.0
56.163250350,317.0
56.242032045,330.0
56.320813740,307.0
56.399595435,321.0
56.478377130,287.0
56.557158825,281.0
56.635940520,292.0
56.714722215,301.0
56.793503910,320.0
56.872285605,330.0
56.951067300,315.0
57.029848995,323.0
57.108630690,319.0
57.187412385,286.0
57.266194080,328.0
57.344975775,320.0
57.423757470,336.0
57.502539165,314.0
57.581320860,308.0
57.660102555,305.0
57.738884251,307.0
57.817665946,324.0
57.896447641,323.0
57.975229336,313.0
58.054011031,319.0
58.132792726,307.0
58.211574421,311.0
58.290356116,306.0
58.369137811,310.0
58.447919506,283.0
58.526701201,308.0
58.605482896,313.0
58.684264591,325.0
58.763046286,289.0
58.841827981,346.0
58.920609676,320.0
58.999391371,285.0
59.078173066,289.0
59.156954761,292.0
59.235736456,295.0
59.314518151,274.0
59.393299846,286.0
59.472081541,310.0
59.550863236,290.0
59.629644931,275.0
59.708426626,340.0
59.787208321,328.0
59.865990016,290.0
59.944771711,317.0
60.023553406,288.0
60.102335101,302.0
60.181116796,277.0
60.259898491,313.0
60.338680186,309.0
60.417461881,282.0
60.496243576,276.0
60.575025271,281.0
60.653806966,299.0
60.732588661,320.0
60.811370356,267.0
60.890152051,293.0
60.968933746,305.0
61.047715441,261.0
61.126497137,273.0
61.205278832,288.0
61.284060527,298.0
61.362842222,303.0
61.441623917,274.0
61.520405612,283.0
61.599187307,307.0
61.677969002,287.0
61.756750697,299.0
61.835532392,285.0
61.914314087,286.0
61.993095782,304.0
62.071877477,254.0
62.150659172,297.0
62.229440867,279.0
62.308222562,315.0
62.387004257,297.0
62.465785952,264.0
62.544567647,281.0
62.623349342,289.0
62.702131037,283.0
62.780912732,280.0
62.859694427,278.0
62.938476122,300.0
63.017257817,312.0
63.096039512,261.0
63.174821207,300.0
63.253602902,310.0
63.332384597,276.0
63.411166292,252.0
63.489947987,286.0
63.568729682,292.0
63.647511377,299.0
63.726293072,273.0
63.805074767,260.0
63.883856462,264.0
63.962638157,253.0
64.041419852,264.0
64.120201547,322.0
64.198983242,273.0
64.277764937,274.0
64.356546632,272.0
64.435328327,273.0
64.514110023,267.0
64.592891718,273.0
64.671673413,277.0
64.750455108,255.0
64.829236803,291.0
64.908018498,293.0
64.986800193,290.0
65.065581888,303.0
65.144363583,270.0
65.223145278,254.0
65.301926973,275.0
65.380708668,257.0
65.459490363,251.0
65.538272058,275.0
65.617053753,253.0
65.695835448,234.0
65.774617143,282.0
65.853398838,256.0
65.932180533,267.0
66.010962228,270.0
66.089743923,278.0
66.168525618,291.0
66.247307313,231.0
66.326089008,291.0
66.404870703,256.0
66.483652398,268.0
66.562434093,301.0
66.641215788,297.0
66.719997483,269.0
66.798779178,275.0
66.877560873,265.0
66.956342568,241.0
67.035124263,237.0
67.113905958,251.0
67.192687653,276.0
67.271469348,266.0
67.350251043,249.0
67.429032738,302.0
67.507814433,264.0
67.586596128,240.0
67.665377823,245.0
67.744159518,258.0
67.822941213,262.0
67.901722909,237.0
67.980504604,267.0
68.059286299,267.0
68.138067994,275.0
68.216849689,237.0
68.295631384,250.0
68.374413079,245.0
68.453194774,266.0
68.531976469,247.0
68.610758164,239.0
68.689539859,234.0
68.768321554,251.0
68.847103249,249.0
68.925884944,271.0
69.004666639,285.0
69.083448334,229.0
69.162230029,290.0
69.241011724,248.0
69.319793419,252.0
69.398575114,244.0
69.477356809,223.0
69.556138504,229.0
69.634920199,262.0
69.713701894,240.0
69.792483589,267.0
69.871265284,240.0
69.950046979,249.0
70.028828674,261.0
70.107610369,239.0
70.186392064,222.0
70.265173759,229.0
70.343955454,241.0
70.422737149,217.0
70.501518844,241.0
70.580300539,267.0
70.659082234,263.0
70.737863929,241.0
70.816645624,237.0
70.895427319,268.0
70.974209014,263.0
71.052990709,260.0
71.131772404,257.0
71.210554099,254.0
71.289335794,246.0
71.368117490,226.0
71.446899185,247.0
71.525680880,234.0
71.604462575,288.0
71.683244270,233.0
71.762025965,264.0
71.840807660,260.0
71.919589355,275.0
71.998371050,287.0
72.077152745,278.0
72.155934440,246.0
72.234716135,261.0
72.313497830,267.0
72.392279525,275.0
72.471061220,253.0
72.549842915,237.0
72.628624610,273.0
72.707406305,304.0
72.786188000,249.0
72.864969695,281.0
72.943751390,291.0
73.022533085,330.0
73.101314780,313.0
73.180096475,303.0
73.258878170,291.0
73.337659865,308.0
73.416441560,310.0
73.495223255,300.0
73.574004950,303.0
73.652786645,292.0
73.731568340,306.0
73.810350035,277.0
73.889131730,287.0
73.967913425,289.0
74.046695120,297.0
74.125476815,263.0
74.204258510,256.0
74.283040205,257.0
74.361821900,275.0
74.440603595,277.0
74.519385290,272.0
74.598166985,260.0
74.676948680,271.0
74.755730376,264.0
74.834512071,263.0
74.913293766,205.0
74.992075461,227.0
75.070857156,246.0
75.149638851,255.0
75.228420546,272.0
75.307202241,262.0
75.385983936,240.0
75.464765631,248.0
75.543547326,218.0
75.622329021,233.0
75.701110716,194.0
75.779892411,244.0
75.858674106,222.0
75.937455801,239.0
76.016237496,241.0
76.095019191,204.0
76.173800886,233.0
76.252582581,260.0
76.331364276,247.0
76.410145971,239.0
76.488927666,232.0
76.567709361,222.0
76.646491056,241.0
76.725272751,235.0
76.804054446,230.0
76.882836141,231.0
76.961617836,225.0
77.040399531,235.0
77.119181226,254.0
77.197962921,218.0
77.276744616,199.0
77.355526311,239.0
77.434308006,237.0
77.513089701,239.0
77.591871396,197.0
77.670653091,192.0
77.749434786,209.0
77.828216481,225.0
77.906998176,251.0
77.985779871,201.0
78.064561566,248.0
78.143343262,216.0
78.222124957,205.0
78.300906652,210.0
78.379688347,208.0
78.458470042,219.0
78.537251737,234.0
78.616033432,233.0
78.694815127,210.0
78.773596822,195.0
78.852378517,215.0
78.931160212,218.0
79.009941907,189.0
79.088723602,240.0
79.167505297,208.0
79.246286992,223.0
79.325068687,218.0
79.403850382,173.0
79.482632077,233.0
79.561413772,221.0
79.640195467,198.0
79.718977162,175.0
79.797758857,194.0
79.876540552,194.0
79.955322247,217.0
80.034103942,198.0
80.112885637,224.0
80.191667332,224.0
80.270449027,224.0
80.349230722,203.0
80.428012417,232.0
80.506794112,226.0
80.585575807,202.0
80.664357502,223.0
80.743139197,190.0
80.821920892,176.0
80.900702587,210.0
80.979484282,240.0
81.058265977,199.0
81.137047672,196.0
81.215829367,217.0
81.294611062,226.0
81.373392757,217.0
81.452174452,218.0
81.530956148,199.0
81.609737843,199.0
81.688519538,197.0
81.767301233,199.0
81.846082928,213.0
81.924864623,193.0
82.003646318,241.0
82.082428013,209.0
82.161209708,206.0
82.239991403,215.0
82.318773098,201.0
82.397554793,190.0
82.476336488,212.0
82.555118183,227.0
82.633899878,222.0
82.712681573,212.0
82.791463268,208.0
82.870244963,201.0
82.949026658,220.0
83.027808353,177.0
83.106590048,204.0
83.185371743,204.0
83.264153438,199.0
83.342935133,187.0
83.421716828,189.0
83.500498523,205.0
83.579280218,177.0
83.658061913,174.0
83.736843608,213.0
83.815625303,230.0
83.894406998,221.0
83.973188693,226.0
84.051970388,216.0
84.130752083,203.0
84.209533778,200.0
84.288315473,228.0
84.367097168,190.0
84.445878863,209.0
84.524660558,192.0
84.603442253,198.0
84.682223948,191.0
84.761005643,181.0
84.839787338,222.0
84.918569034,197.0
84.997350729,209.0
85.076132424,206.0
85.154914119,196.0
85.233695814,205.0
85.312477509,193.0
85.391259204,182.0
85.470040899,194.0
85.548822594,188.0
85.627604289,180.0
85.706385984,180.0
85.785167679,199.0
85.863949374,188.0
85.942731069,196.0
86.021512764,203.0
86.100294459,188.0
86.179076154,196.0
86.257857849,202.0
86.336639544,200.0
86.415421239,187.0
86.494202934,211.0
86.572984629,193.0
86.651766324,165.0
86.730548019,183.0
86.809329714,207.0
86.888111409,210.0
86.966893104,202.0
87.045674799,188.0
87.124456494,173.0
87.203238189,186.0
87.282019884,202.0
87.360801579,181.0
87.439583274,211.0
87.518364969,204.0
87.597146664,170.0
87.675928359,202.0
87.754710054,211.0
87.833491749,184.0
87.912273444,187.0
87.991055139,186.0
88.069836834,172.0
88.148618529,192.0
88.227400224,194.0
88.306181920,194.0
88.384963615,190.0
88.463745310,195.0
88.542527005,223.0
88.621308700,181.0
88.700090395,216.0
88.778872090,198.0
88.857653785,224.0
88.936435480,208.0
89.015217175,192.0
89.093998870,184.0
89.172780565,192.0
89.251562260,203.0
89.330343955,219.0
89.409125650,196.0
89.487907345,210.0
89.566689040,189.0
89.645470735,202.0
89.724252430,195.0
89.803034125,212.0
89.881815820,194.0
89.960597515,198.0
89.986858080,194.0