File: 2017007296/7296-a3#.csv
[Measurement conditions]
Sample identification,
Comment - 1,"Configuration=Stage for flat samples/holders, Owner=User-1, Creation date=3/27/2015 11:56:23 AM"
Comment - 2,"Goniometer=Theta/Theta; Minimum step size 2Theta:0.0001; Minimum step size Omega:0.0001"
Comment - 3,"Sample stage=Stage for flat samples/holders"
Comment - 4,"Diffractometer system=EMPYREAN"
Comment - 5,"Measurement program=C:\PANalytical\Data Collector\Programs\Powder - Copy.xrdmp, Identifier={BEEA10DD-8FD6-4721-8940-4FBC5A4262A1}"
Comment - 6,"Fine Calibration Offset for 2Theta = -0.0130 deg"
Comment - 7,"Fine Calibration Offset for Omega = -0.0070 deg"
Anode material,Cu
K-Alpha1 wavelength,1.5405980
K-Alpha2 wavelength,1.5444260
Ratio K-Alpha2/K-Alpha1,0.500
Divergence slit,Fixed,0.38mm
Monochromator used,NO
Generator voltage, 40
Tube current, 35
File date and time,24/Jul/2017 16:07
Unit cell,
h k l, 0 0 0
Scan axis,Gonio
Scan range,5.020799997,89.999988363
Scan step size,0.0262606
No. of points, 3236
Scan type,CONTINUOUS
Time per step,18.615
[Scan points]
Angle,Intensity
5.033930280,1242.0
5.112711975,1214.0
5.191493670,1211.0
5.270275365,1267.0
5.349057060,1225.0
5.427838755,1227.0
5.506620450,1205.0
5.585402145,1146.0
5.664183840,1222.0
5.742965535,1200.0
5.821747230,1236.0
5.900528925,1224.0
5.979310620,1190.0
6.058092315,1183.0
6.136874010,1247.0
6.215655705,1297.0
6.294437400,1194.0
6.373219095,1189.0
6.452000790,1207.0
6.530782485,1293.0
6.609564180,1222.0
6.688345875,1308.0
6.767127571,1258.0
6.845909266,1257.0
6.924690961,1221.0
7.003472656,1302.0
7.082254351,1266.0
7.161036046,1313.0
7.239817741,1306.0
7.318599436,1230.0
7.397381131,1292.0
7.476162826,1248.0
7.554944521,1349.0
7.633726216,1328.0
7.712507911,1280.0
7.791289606,1216.0
7.870071301,1340.0
7.948852996,1298.0
8.027634691,1218.0
8.106416386,1276.0
8.185198081,1284.0
8.263979776,1305.0
8.342761471,1358.0
8.421543166,1292.0
8.500324861,1290.0
8.579106556,1292.0
8.657888251,1268.0
8.736669946,1340.0
8.815451641,1273.0
8.894233336,1372.0
8.973015031,1348.0
9.051796726,1300.0
9.130578421,1328.0
9.209360116,1294.0
9.288141811,1349.0
9.366923506,1306.0
9.445705201,1338.0
9.524486896,1208.0
9.603268591,1239.0
9.682050286,1295.0
9.760831981,1250.0
9.839613676,1264.0
9.918395371,1296.0
9.997177066,1247.0
10.075958761,1265.0
10.154740457,1310.0
10.233522152,1243.0
10.312303847,1246.0
10.391085542,1252.0
10.469867237,1277.0
10.548648932,1262.0
10.627430627,1234.0
10.706212322,1232.0
10.784994017,1179.0
10.863775712,1248.0
10.942557407,1190.0
11.021339102,1194.0
11.100120797,1194.0
11.178902492,1263.0
11.257684187,1228.0
11.336465882,1209.0
11.415247577,1238.0
11.494029272,1199.0
11.572810967,1204.0
11.651592662,1209.0
11.730374357,1218.0
11.809156052,1148.0
11.887937747,1229.0
11.966719442,1121.0
12.045501137,1223.0
12.124282832,1150.0
12.203064527,1178.0
12.281846222,1119.0
12.360627917,1187.0
12.439409612,1129.0
12.518191307,1151.0
12.596973002,1117.0
12.675754697,1220.0
12.754536392,1138.0
12.833318087,1234.0
12.912099782,1123.0
12.990881477,1170.0
13.069663172,1232.0
13.148444867,1188.0
13.227226562,1276.0
13.306008257,1194.0
13.384789952,1162.0
13.463571647,1140.0
13.542353343,1245.0
13.621135038,1192.0
13.699916733,1157.0
13.778698428,1239.0
13.857480123,1209.0
13.936261818,1303.0
14.015043513,1262.0
14.093825208,1204.0
14.172606903,1196.0
14.251388598,1226.0
14.330170293,1215.0
14.408951988,1310.0
14.487733683,1292.0
14.566515378,1216.0
14.645297073,1190.0
14.724078768,1205.0
14.802860463,1204.0
14.881642158,1194.0
14.960423853,1162.0
15.039205548,1165.0
15.117987243,1155.0
15.196768938,1152.0
15.275550633,1133.0
15.354332328,1177.0
15.433114023,1122.0
15.511895718,1100.0
15.590677413,1114.0
15.669459108,1114.0
15.748240803,1009.0
15.827022498,1000.0
15.905804193,1079.0
15.984585888,936.0
16.063367583,985.0
16.142149278,986.0
16.220930973,947.0
16.299712668,949.0
16.378494363,973.0
16.457276058,937.0
16.536057753,918.0
16.614839448,922.0
16.693621143,952.0
16.772402838,923.0
16.851184533,936.0
16.929966229,919.0
17.008747924,904.0
17.087529619,881.0
17.166311314,900.0
17.245093009,883.0
17.323874704,879.0
17.402656399,935.0
17.481438094,911.0
17.560219789,855.0
17.639001484,841.0
17.717783179,867.0
17.796564874,869.0
17.875346569,868.0
17.954128264,859.0
18.032909959,853.0
18.111691654,873.0
18.190473349,846.0
18.269255044,883.0
18.348036739,870.0
18.426818434,902.0
18.505600129,842.0
18.584381824,881.0
18.663163519,894.0
18.741945214,860.0
18.820726909,839.0
18.899508604,875.0
18.978290299,847.0
19.057071994,816.0
19.135853689,856.0
19.214635384,848.0
19.293417079,865.0
19.372198774,846.0
19.450980469,865.0
19.529762164,833.0
19.608543859,869.0
19.687325554,860.0
19.766107249,895.0
19.844888944,826.0
19.923670639,866.0
20.002452334,850.0
20.081234029,832.0
20.160015724,883.0
20.238797419,835.0
20.317579114,863.0
20.396360810,822.0
20.475142505,859.0
20.553924200,863.0
20.632705895,830.0
20.711487590,836.0
20.790269285,849.0
20.869050980,883.0
20.947832675,788.0
21.026614370,833.0
21.105396065,878.0
21.184177760,850.0
21.262959455,837.0
21.341741150,868.0
21.420522845,853.0
21.499304540,872.0
21.578086235,862.0
21.656867930,853.0
21.735649625,808.0
21.814431320,893.0
21.893213015,858.0
21.971994710,907.0
22.050776405,868.0
22.129558100,824.0
22.208339795,864.0
22.287121490,835.0
22.365903185,850.0
22.444684880,829.0
22.523466575,857.0
22.602248270,902.0
22.681029965,837.0
22.759811660,867.0
22.838593355,777.0
22.917375050,826.0
22.996156745,864.0
23.074938440,832.0
23.153720135,887.0
23.232501830,875.0
23.311283525,840.0
23.390065220,838.0
23.468846915,864.0
23.547628610,792.0
23.626410305,872.0
23.705192000,912.0
23.783973696,853.0
23.862755391,856.0
23.941537086,848.0
24.020318781,856.0
24.099100476,882.0
24.177882171,819.0
24.256663866,781.0
24.335445561,826.0
24.414227256,849.0
24.493008951,861.0
24.571790646,815.0
24.650572341,847.0
24.729354036,898.0
24.808135731,848.0
24.886917426,796.0
24.965699121,823.0
25.044480816,748.0
25.123262511,861.0
25.202044206,834.0
25.280825901,837.0
25.359607596,818.0
25.438389291,790.0
25.517170986,805.0
25.595952681,879.0
25.674734376,806.0
25.753516071,759.0
25.832297766,856.0
25.911079461,793.0
25.989861156,772.0
26.068642851,800.0
26.147424546,764.0
26.226206241,779.0
26.304987936,785.0
26.383769631,843.0
26.462551326,770.0
26.541333021,788.0
26.620114716,796.0
26.698896411,802.0
26.777678106,770.0
26.856459801,743.0
26.935241496,797.0
27.014023191,790.0
27.092804886,770.0
27.171586582,762.0
27.250368277,741.0
27.329149972,771.0
27.407931667,755.0
27.486713362,778.0
27.565495057,788.0
27.644276752,799.0
27.723058447,757.0
27.801840142,732.0
27.880621837,757.0
27.959403532,733.0
28.038185227,762.0
28.116966922,745.0
28.195748617,758.0
28.274530312,680.0
28.353312007,713.0
28.432093702,789.0
28.510875397,742.0
28.589657092,726.0
28.668438787,696.0
28.747220482,738.0
28.826002177,740.0
28.904783872,702.0
28.983565567,736.0
29.062347262,738.0
29.141128957,733.0
29.219910652,678.0
29.298692347,740.0
29.377474042,679.0
29.456255737,718.0
29.535037432,722.0
29.613819127,705.0
29.692600822,672.0
29.771382517,750.0
29.850164212,677.0
29.928945907,730.0
30.007727602,697.0
30.086509297,718.0
30.165290992,674.0
30.244072687,708.0
30.322854382,698.0
30.401636077,712.0
30.480417772,633.0
30.559199468,683.0
30.637981163,703.0
30.716762858,713.0
30.795544553,640.0
30.874326248,628.0
30.953107943,664.0
31.031889638,656.0
31.110671333,700.0
31.189453028,715.0
31.268234723,660.0
31.347016418,687.0
31.425798113,632.0
31.504579808,633.0
31.583361503,674.0
31.662143198,639.0
31.740924893,672.0
31.819706588,627.0
31.898488283,677.0
31.977269978,679.0
32.056051673,629.0
32.134833368,653.0
32.213615063,642.0
32.292396758,662.0
32.371178453,590.0
32.449960148,632.0
32.528741843,595.0
32.607523538,607.0
32.686305233,614.0
32.765086928,588.0
32.843868623,618.0
32.922650318,584.0
33.001432013,553.0
33.080213708,605.0
33.158995403,554.0
33.237777098,547.0
33.316558793,570.0
33.395340488,574.0
33.474122183,557.0
33.552903878,532.0
33.631685573,585.0
33.710467268,575.0
33.789248963,524.0
33.868030658,577.0
33.946812354,543.0
34.025594049,566.0
34.104375744,566.0
34.183157439,546.0
34.261939134,535.0
34.340720829,532.0
34.419502524,535.0
34.498284219,570.0
34.577065914,556.0
34.655847609,515.0
34.734629304,512.0
34.813410999,571.0
34.892192694,467.0
34.970974389,505.0
35.049756084,485.0
35.128537779,502.0
35.207319474,546.0
35.286101169,483.0
35.364882864,533.0
35.443664559,479.0
35.522446254,536.0
35.601227949,509.0
35.680009644,499.0
35.758791339,506.0
35.837573034,499.0
35.916354729,523.0
35.995136424,535.0
36.073918119,512.0
36.152699814,440.0
36.231481509,497.0
36.310263204,463.0
36.389044899,486.0
36.467826594,511.0
36.546608289,514.0
36.625389984,534.0
36.704171679,453.0
36.782953374,516.0
36.861735069,511.0
36.940516764,525.0
37.019298459,475.0
37.098080154,491.0
37.176861849,512.0
37.255643544,461.0
37.334425240,473.0
37.413206935,506.0
37.491988630,492.0
37.570770325,501.0
37.649552020,515.0
37.728333715,465.0
37.807115410,471.0
37.885897105,478.0
37.964678800,479.0
38.043460495,505.0
38.122242190,471.0
38.201023885,537.0
38.279805580,511.0
38.358587275,427.0
38.437368970,496.0
38.516150665,474.0
38.594932360,495.0
38.673714055,502.0
38.752495750,497.0
38.831277445,456.0
38.910059140,519.0
38.988840835,503.0
39.067622530,495.0
39.146404225,532.0
39.225185920,473.0
39.303967615,520.0
39.382749310,543.0
39.461531005,541.0
39.540312700,540.0
39.619094395,570.0
39.697876090,534.0
39.776657785,561.0
39.855439480,554.0
39.934221175,578.0
40.013002870,607.0
40.091784565,611.0
40.170566260,661.0
40.249347955,681.0
40.328129650,669.0
40.406911345,747.0
40.485693040,729.0
40.564474735,644.0
40.643256430,758.0
40.722038126,718.0
40.800819821,661.0
40.879601516,768.0
40.958383211,696.0
41.037164906,691.0
41.115946601,693.0
41.194728296,699.0
41.273509991,677.0
41.352291686,688.0
41.431073381,712.0
41.509855076,662.0
41.588636771,641.0
41.667418466,650.0
41.746200161,677.0
41.824981856,664.0
41.903763551,679.0
41.982545246,665.0
42.061326941,693.0
42.140108636,711.0
42.218890331,635.0
42.297672026,647.0
42.376453721,601.0
42.455235416,599.0
42.534017111,640.0
42.612798806,649.0
42.691580501,612.0
42.770362196,633.0
42.849143891,618.0
42.927925586,583.0
43.006707281,560.0
43.085488976,553.0
43.164270671,530.0
43.243052366,522.0
43.321834061,599.0
43.400615756,566.0
43.479397451,540.0
43.558179146,520.0
43.636960841,559.0
43.715742536,501.0
43.794524231,505.0
43.873305926,530.0
43.952087621,503.0
44.030869316,516.0
44.109651011,549.0
44.188432707,492.0
44.267214402,526.0
44.345996097,477.0
44.424777792,503.0
44.503559487,484.0
44.582341182,448.0
44.661122877,487.0
44.739904572,465.0
44.818686267,447.0
44.897467962,412.0
44.976249657,446.0
45.055031352,431.0
45.133813047,450.0
45.212594742,400.0
45.291376437,451.0
45.370158132,494.0
45.448939827,458.0
45.527721522,418.0
45.606503217,423.0
45.685284912,434.0
45.764066607,438.0
45.842848302,407.0
45.921629997,493.0
46.000411692,459.0
46.079193387,431.0
46.157975082,403.0
46.236756777,428.0
46.315538472,432.0
46.394320167,417.0
46.473101862,374.0
46.551883557,417.0
46.630665252,377.0
46.709446947,403.0
46.788228642,428.0
46.867010337,388.0
46.945792032,390.0
47.024573727,375.0
47.103355422,405.0
47.182137117,440.0
47.260918812,388.0
47.339700507,407.0
47.418482202,394.0
47.497263897,389.0
47.576045593,388.0
47.654827288,351.0
47.733608983,377.0
47.812390678,371.0
47.891172373,364.0
47.969954068,356.0
48.048735763,360.0
48.127517458,342.0
48.206299153,329.0
48.285080848,383.0
48.363862543,342.0
48.442644238,361.0
48.521425933,340.0
48.600207628,335.0
48.678989323,351.0
48.757771018,342.0
48.836552713,313.0
48.915334408,353.0
48.994116103,350.0
49.072897798,352.0
49.151679493,313.0
49.230461188,338.0
49.309242883,355.0
49.388024578,345.0
49.466806273,318.0
49.545587968,312.0
49.624369663,325.0
49.703151358,318.0
49.781933053,308.0
49.860714748,310.0
49.939496443,337.0
50.018278138,311.0
50.097059833,357.0
50.175841528,328.0
50.254623223,314.0
50.333404918,352.0
50.412186613,316.0
50.490968308,308.0
50.569750003,322.0
50.648531698,302.0
50.727313393,304.0
50.806095088,346.0
50.884876783,325.0
50.963658479,299.0
51.042440174,332.0
51.121221869,330.0
51.200003564,283.0
51.278785259,311.0
51.357566954,324.0
51.436348649,304.0
51.515130344,319.0
51.593912039,325.0
51.672693734,317.0
51.751475429,289.0
51.830257124,282.0
51.909038819,329.0
51.987820514,300.0
52.066602209,315.0
52.145383904,270.0
52.224165599,306.0
52.302947294,291.0
52.381728989,277.0
52.460510684,287.0
52.539292379,323.0
52.618074074,301.0
52.696855769,313.0
52.775637464,277.0
52.854419159,281.0
52.933200854,277.0
53.011982549,298.0
53.090764244,345.0
53.169545939,305.0
53.248327634,314.0
53.327109329,305.0
53.405891024,306.0
53.484672719,288.0
53.563454414,297.0
53.642236109,296.0
53.721017804,312.0
53.799799499,301.0
53.878581194,295.0
53.957362889,288.0
54.036144584,312.0
54.114926279,289.0
54.193707974,321.0
54.272489669,314.0
54.351271365,301.0
54.430053060,282.0
54.508834755,284.0
54.587616450,279.0
54.666398145,322.0
54.745179840,268.0
54.823961535,285.0
54.902743230,273.0
54.981524925,303.0
55.060306620,287.0
55.139088315,266.0
55.217870010,280.0
55.296651705,285.0
55.375433400,296.0
55.454215095,304.0
55.532996790,312.0
55.611778485,272.0
55.690560180,295.0
55.769341875,289.0
55.848123570,335.0
55.926905265,273.0
56.005686960,297.0
56.084468655,313.0
56.163250350,334.0
56.242032045,265.0
56.320813740,282.0
56.399595435,323.0
56.478377130,274.0
56.557158825,315.0
56.635940520,268.0
56.714722215,276.0
56.793503910,280.0
56.872285605,246.0
56.951067300,313.0
57.029848995,280.0
57.108630690,276.0
57.187412385,266.0
57.266194080,287.0
57.344975775,337.0
57.423757470,276.0
57.502539165,283.0
57.581320860,302.0
57.660102555,299.0
57.738884251,263.0
57.817665946,285.0
57.896447641,273.0
57.975229336,263.0
58.054011031,301.0
58.132792726,276.0
58.211574421,293.0
58.290356116,264.0
58.369137811,293.0
58.447919506,301.0
58.526701201,275.0
58.605482896,298.0
58.684264591,254.0
58.763046286,272.0
58.841827981,285.0
58.920609676,301.0
58.999391371,265.0
59.078173066,256.0
59.156954761,248.0
59.235736456,261.0
59.314518151,279.0
59.393299846,273.0
59.472081541,290.0
59.550863236,273.0
59.629644931,256.0
59.708426626,284.0
59.787208321,282.0
59.865990016,270.0
59.944771711,258.0
60.023553406,266.0
60.102335101,283.0
60.181116796,274.0
60.259898491,257.0
60.338680186,276.0
60.417461881,271.0
60.496243576,270.0
60.575025271,281.0
60.653806966,266.0
60.732588661,279.0
60.811370356,288.0
60.890152051,258.0
60.968933746,276.0
61.047715441,248.0
61.126497137,273.0
61.205278832,273.0
61.284060527,272.0
61.362842222,263.0
61.441623917,246.0
61.520405612,271.0
61.599187307,294.0
61.677969002,256.0
61.756750697,265.0
61.835532392,268.0
61.914314087,288.0
61.993095782,263.0
62.071877477,272.0
62.150659172,274.0
62.229440867,288.0
62.308222562,274.0
62.387004257,257.0
62.465785952,297.0
62.544567647,286.0
62.623349342,271.0
62.702131037,238.0
62.780912732,263.0
62.859694427,258.0
62.938476122,228.0
63.017257817,276.0
63.096039512,262.0
63.174821207,260.0
63.253602902,261.0
63.332384597,266.0
63.411166292,261.0
63.489947987,302.0
63.568729682,242.0
63.647511377,246.0
63.726293072,249.0
63.805074767,245.0
63.883856462,277.0
63.962638157,257.0
64.041419852,282.0
64.120201547,258.0
64.198983242,257.0
64.277764937,270.0
64.356546632,270.0
64.435328327,281.0
64.514110023,270.0
64.592891718,265.0
64.671673413,260.0
64.750455108,273.0
64.829236803,258.0
64.908018498,257.0
64.986800193,277.0
65.065581888,266.0
65.144363583,246.0
65.223145278,283.0
65.301926973,257.0
65.380708668,270.0
65.459490363,253.0
65.538272058,261.0
65.617053753,238.0
65.695835448,259.0
65.774617143,249.0
65.853398838,245.0
65.932180533,260.0
66.010962228,257.0
66.089743923,249.0
66.168525618,280.0
66.247307313,247.0
66.326089008,229.0
66.404870703,260.0
66.483652398,250.0
66.562434093,255.0
66.641215788,261.0
66.719997483,255.0
66.798779178,234.0
66.877560873,254.0
66.956342568,235.0
67.035124263,262.0
67.113905958,220.0
67.192687653,242.0
67.271469348,236.0
67.350251043,248.0
67.429032738,252.0
67.507814433,243.0
67.586596128,240.0
67.665377823,242.0
67.744159518,234.0
67.822941213,248.0
67.901722909,244.0
67.980504604,235.0
68.059286299,227.0
68.138067994,262.0
68.216849689,247.0
68.295631384,245.0
68.374413079,207.0
68.453194774,254.0
68.531976469,236.0
68.610758164,231.0
68.689539859,244.0
68.768321554,264.0
68.847103249,230.0
68.925884944,241.0
69.004666639,221.0
69.083448334,213.0
69.162230029,223.0
69.241011724,239.0
69.319793419,239.0
69.398575114,236.0
69.477356809,216.0
69.556138504,229.0
69.634920199,210.0
69.713701894,234.0
69.792483589,247.0
69.871265284,224.0
69.950046979,230.0
70.028828674,209.0
70.107610369,237.0
70.186392064,212.0
70.265173759,249.0
70.343955454,228.0
70.422737149,239.0
70.501518844,233.0
70.580300539,200.0
70.659082234,228.0
70.737863929,231.0
70.816645624,227.0
70.895427319,226.0
70.974209014,210.0
71.052990709,217.0
71.131772404,234.0
71.210554099,240.0
71.289335794,210.0
71.368117490,202.0
71.446899185,196.0
71.525680880,252.0
71.604462575,197.0
71.683244270,210.0
71.762025965,226.0
71.840807660,216.0
71.919589355,229.0
71.998371050,235.0
72.077152745,226.0
72.155934440,241.0
72.234716135,233.0
72.313497830,230.0
72.392279525,218.0
72.471061220,239.0
72.549842915,251.0
72.628624610,228.0
72.707406305,215.0
72.786188000,234.0
72.864969695,230.0
72.943751390,230.0
73.022533085,255.0
73.101314780,256.0
73.180096475,256.0
73.258878170,239.0
73.337659865,256.0
73.416441560,246.0
73.495223255,257.0
73.574004950,222.0
73.652786645,242.0
73.731568340,224.0
73.810350035,240.0
73.889131730,218.0
73.967913425,232.0
74.046695120,256.0
74.125476815,235.0
74.204258510,222.0
74.283040205,233.0
74.361821900,240.0
74.440603595,222.0
74.519385290,212.0
74.598166985,202.0
74.676948680,247.0
74.755730376,229.0
74.834512071,217.0
74.913293766,225.0
74.992075461,192.0
75.070857156,215.0
75.149638851,208.0
75.228420546,218.0
75.307202241,211.0
75.385983936,203.0
75.464765631,220.0
75.543547326,192.0
75.622329021,221.0
75.701110716,211.0
75.779892411,211.0
75.858674106,194.0
75.937455801,207.0
76.016237496,203.0
76.095019191,225.0
76.173800886,216.0
76.252582581,214.0
76.331364276,212.0
76.410145971,225.0
76.488927666,192.0
76.567709361,196.0
76.646491056,200.0
76.725272751,216.0
76.804054446,210.0
76.882836141,194.0
76.961617836,211.0
77.040399531,193.0
77.119181226,199.0
77.197962921,224.0
77.276744616,196.0
77.355526311,214.0
77.434308006,197.0
77.513089701,188.0
77.591871396,220.0
77.670653091,200.0
77.749434786,218.0
77.828216481,202.0
77.906998176,223.0
77.985779871,203.0
78.064561566,187.0
78.143343262,190.0
78.222124957,193.0
78.300906652,203.0
78.379688347,186.0
78.458470042,196.0
78.537251737,208.0
78.616033432,212.0
78.694815127,210.0
78.773596822,220.0
78.852378517,210.0
78.931160212,195.0
79.009941907,196.0
79.088723602,194.0
79.167505297,180.0
79.246286992,182.0
79.325068687,203.0
79.403850382,187.0
79.482632077,194.0
79.561413772,219.0
79.640195467,198.0
79.718977162,204.0
79.797758857,196.0
79.876540552,211.0
79.955322247,195.0
80.034103942,236.0
80.112885637,176.0
80.191667332,169.0
80.270449027,195.0
80.349230722,176.0
80.428012417,197.0
80.506794112,202.0
80.585575807,207.0
80.664357502,184.0
80.743139197,215.0
80.821920892,173.0
80.900702587,205.0
80.979484282,185.0
81.058265977,215.0
81.137047672,183.0
81.215829367,181.0
81.294611062,175.0
81.373392757,213.0
81.452174452,200.0
81.530956148,178.0
81.609737843,184.0
81.688519538,198.0
81.767301233,201.0
81.846082928,205.0
81.924864623,193.0
82.003646318,175.0
82.082428013,183.0
82.161209708,181.0
82.239991403,196.0
82.318773098,189.0
82.397554793,171.0
82.476336488,180.0
82.555118183,146.0
82.633899878,189.0
82.712681573,173.0
82.791463268,174.0
82.870244963,191.0
82.949026658,183.0
83.027808353,181.0
83.106590048,169.0
83.185371743,176.0
83.264153438,193.0
83.342935133,181.0
83.421716828,184.0
83.500498523,167.0
83.579280218,183.0
83.658061913,191.0
83.736843608,164.0
83.815625303,177.0
83.894406998,174.0
83.973188693,171.0
84.051970388,167.0
84.130752083,167.0
84.209533778,163.0
84.288315473,195.0
84.367097168,167.0
84.445878863,182.0
84.524660558,176.0
84.603442253,170.0
84.682223948,171.0
84.761005643,187.0
84.839787338,198.0
84.918569034,203.0
84.997350729,182.0
85.076132424,185.0
85.154914119,153.0
85.233695814,192.0
85.312477509,164.0
85.391259204,170.0
85.470040899,147.0
85.548822594,177.0
85.627604289,162.0
85.706385984,168.0
85.785167679,153.0
85.863949374,199.0
85.942731069,167.0
86.021512764,178.0
86.100294459,140.0
86.179076154,178.0
86.257857849,170.0
86.336639544,188.0
86.415421239,165.0
86.494202934,200.0
86.572984629,148.0
86.651766324,173.0
86.730548019,163.0
86.809329714,159.0
86.888111409,157.0
86.966893104,191.0
87.045674799,177.0
87.124456494,197.0
87.203238189,171.0
87.282019884,167.0
87.360801579,181.0
87.439583274,155.0
87.518364969,176.0
87.597146664,169.0
87.675928359,139.0
87.754710054,149.0
87.833491749,181.0
87.912273444,150.0
87.991055139,180.0
88.069836834,195.0
88.148618529,167.0
88.227400224,182.0
88.306181920,185.0
88.384963615,185.0
88.463745310,182.0
88.542527005,168.0
88.621308700,181.0
88.700090395,152.0
88.778872090,179.0
88.857653785,163.0
88.936435480,187.0
89.015217175,166.0
89.093998870,190.0
89.172780565,162.0
89.251562260,152.0
89.330343955,162.0
89.409125650,183.0
89.487907345,190.0
89.566689040,171.0
89.645470735,154.0
89.724252430,153.0
89.803034125,161.0
89.881815820,164.0
89.960597515,169.0
89.986858080,137.0