File: 2017007296/7296-b1#.csv
[Measurement conditions]
Sample identification,
Comment - 1,"Configuration=Stage for flat samples/holders, Owner=User-1, Creation date=3/27/2015 11:56:23 AM"
Comment - 2,"Goniometer=Theta/Theta; Minimum step size 2Theta:0.0001; Minimum step size Omega:0.0001"
Comment - 3,"Sample stage=Stage for flat samples/holders"
Comment - 4,"Diffractometer system=EMPYREAN"
Comment - 5,"Measurement program=C:\PANalytical\Data Collector\Programs\Powder - Copy.xrdmp, Identifier={BEEA10DD-8FD6-4721-8940-4FBC5A4262A1}"
Comment - 6,"Fine Calibration Offset for 2Theta = -0.0130 deg"
Comment - 7,"Fine Calibration Offset for Omega = -0.0070 deg"
Anode material,Cu
K-Alpha1 wavelength,1.5405980
K-Alpha2 wavelength,1.5444260
Ratio K-Alpha2/K-Alpha1,0.500
Divergence slit,Fixed,0.38mm
Monochromator used,NO
Generator voltage, 40
Tube current, 35
File date and time,24/Jul/2017 16:27
Unit cell,
h k l, 0 0 0
Scan axis,Gonio
Scan range,5.020799997,89.999988363
Scan step size,0.0262606
No. of points, 3236
Scan type,CONTINUOUS
Time per step,18.615
[Scan points]
Angle,Intensity
5.033930280,2069.0
5.112711975,2017.0
5.191493670,1927.0
5.270275365,1997.0
5.349057060,1892.0
5.427838755,2008.0
5.506620450,1951.0
5.585402145,1899.0
5.664183840,1953.0
5.742965535,1941.0
5.821747230,1932.0
5.900528925,1895.0
5.979310620,1947.0
6.058092315,1883.0
6.136874010,1894.0
6.215655705,1881.0
6.294437400,1833.0
6.373219095,1920.0
6.452000790,1860.0
6.530782485,2012.0
6.609564180,1845.0
6.688345875,1916.0
6.767127571,1885.0
6.845909266,1903.0
6.924690961,1842.0
7.003472656,1929.0
7.082254351,1855.0
7.161036046,1905.0
7.239817741,1941.0
7.318599436,1857.0
7.397381131,1905.0
7.476162826,1809.0
7.554944521,1964.0
7.633726216,1922.0
7.712507911,1974.0
7.791289606,1831.0
7.870071301,1920.0
7.948852996,1871.0
8.027634691,1986.0
8.106416386,1999.0
8.185198081,2054.0
8.263979776,2060.0
8.342761471,2072.0
8.421543166,2147.0
8.500324861,2066.0
8.579106556,2085.0
8.657888251,2152.0
8.736669946,2243.0
8.815451641,2318.0
8.894233336,2255.0
8.973015031,2323.0
9.051796726,2428.0
9.130578421,2253.0
9.209360116,2398.0
9.288141811,2341.0
9.366923506,2273.0
9.445705201,2272.0
9.524486896,2187.0
9.603268591,2188.0
9.682050286,2074.0
9.760831981,2025.0
9.839613676,2027.0
9.918395371,1973.0
9.997177066,1944.0
10.075958761,1903.0
10.154740457,1930.0
10.233522152,1891.0
10.312303847,1759.0
10.391085542,1852.0
10.469867237,1836.0
10.548648932,1863.0
10.627430627,1814.0
10.706212322,1750.0
10.784994017,1789.0
10.863775712,1759.0
10.942557407,1826.0
11.021339102,1678.0
11.100120797,1752.0
11.178902492,1814.0
11.257684187,1691.0
11.336465882,1726.0
11.415247577,1706.0
11.494029272,1774.0
11.572810967,1770.0
11.651592662,1733.0
11.730374357,1784.0
11.809156052,1698.0
11.887937747,1807.0
11.966719442,1790.0
12.045501137,1668.0
12.124282832,1743.0
12.203064527,1705.0
12.281846222,1757.0
12.360627917,1744.0
12.439409612,1709.0
12.518191307,1691.0
12.596973002,1698.0
12.675754697,1725.0
12.754536392,1758.0
12.833318087,1688.0
12.912099782,1770.0
12.990881477,1778.0
13.069663172,1781.0
13.148444867,1728.0
13.227226562,1671.0
13.306008257,1793.0
13.384789952,1768.0
13.463571647,1770.0
13.542353343,1704.0
13.621135038,1856.0
13.699916733,1755.0
13.778698428,1730.0
13.857480123,1766.0
13.936261818,1706.0
14.015043513,1729.0
14.093825208,1807.0
14.172606903,1789.0
14.251388598,1710.0
14.330170293,1827.0
14.408951988,1761.0
14.487733683,1799.0
14.566515378,1770.0
14.645297073,1822.0
14.724078768,1809.0
14.802860463,1797.0
14.881642158,1796.0
14.960423853,1678.0
15.039205548,1655.0
15.117987243,1713.0
15.196768938,1570.0
15.275550633,1633.0
15.354332328,1561.0
15.433114023,1520.0
15.511895718,1461.0
15.590677413,1375.0
15.669459108,1450.0
15.748240803,1292.0
15.827022498,1303.0
15.905804193,1250.0
15.984585888,1313.0
16.063367583,1197.0
16.142149278,1155.0
16.220930973,1124.0
16.299712668,1106.0
16.378494363,1127.0
16.457276058,1108.0
16.536057753,1111.0
16.614839448,1063.0
16.693621143,1086.0
16.772402838,1085.0
16.851184533,1039.0
16.929966229,1039.0
17.008747924,976.0
17.087529619,1031.0
17.166311314,1043.0
17.245093009,1038.0
17.323874704,927.0
17.402656399,968.0
17.481438094,915.0
17.560219789,971.0
17.639001484,940.0
17.717783179,993.0
17.796564874,926.0
17.875346569,920.0
17.954128264,887.0
18.032909959,928.0
18.111691654,947.0
18.190473349,908.0
18.269255044,872.0
18.348036739,922.0
18.426818434,929.0
18.505600129,940.0
18.584381824,973.0
18.663163519,908.0
18.741945214,928.0
18.820726909,846.0
18.899508604,899.0
18.978290299,938.0
19.057071994,898.0
19.135853689,928.0
19.214635384,895.0
19.293417079,854.0
19.372198774,874.0
19.450980469,884.0
19.529762164,906.0
19.608543859,915.0
19.687325554,869.0
19.766107249,892.0
19.844888944,837.0
19.923670639,901.0
20.002452334,837.0
20.081234029,923.0
20.160015724,949.0
20.238797419,860.0
20.317579114,882.0
20.396360810,920.0
20.475142505,893.0
20.553924200,966.0
20.632705895,860.0
20.711487590,966.0
20.790269285,851.0
20.869050980,885.0
20.947832675,913.0
21.026614370,861.0
21.105396065,961.0
21.184177760,863.0
21.262959455,900.0
21.341741150,920.0
21.420522845,954.0
21.499304540,850.0
21.578086235,883.0
21.656867930,897.0
21.735649625,847.0
21.814431320,819.0
21.893213015,911.0
21.971994710,853.0
22.050776405,917.0
22.129558100,878.0
22.208339795,852.0
22.287121490,853.0
22.365903185,889.0
22.444684880,871.0
22.523466575,859.0
22.602248270,894.0
22.681029965,863.0
22.759811660,846.0
22.838593355,841.0
22.917375050,908.0
22.996156745,853.0
23.074938440,874.0
23.153720135,865.0
23.232501830,852.0
23.311283525,904.0
23.390065220,887.0
23.468846915,877.0
23.547628610,921.0
23.626410305,888.0
23.705192000,943.0
23.783973696,889.0
23.862755391,923.0
23.941537086,869.0
24.020318781,903.0
24.099100476,879.0
24.177882171,939.0
24.256663866,880.0
24.335445561,828.0
24.414227256,860.0
24.493008951,943.0
24.571790646,926.0
24.650572341,934.0
24.729354036,864.0
24.808135731,861.0
24.886917426,871.0
24.965699121,906.0
25.044480816,919.0
25.123262511,867.0
25.202044206,913.0
25.280825901,944.0
25.359607596,912.0
25.438389291,915.0
25.517170986,945.0
25.595952681,817.0
25.674734376,917.0
25.753516071,899.0
25.832297766,898.0
25.911079461,904.0
25.989861156,876.0
26.068642851,951.0
26.147424546,901.0
26.226206241,891.0
26.304987936,856.0
26.383769631,856.0
26.462551326,957.0
26.541333021,909.0
26.620114716,835.0
26.698896411,925.0
26.777678106,867.0
26.856459801,886.0
26.935241496,847.0
27.014023191,888.0
27.092804886,867.0
27.171586582,854.0
27.250368277,945.0
27.329149972,859.0
27.407931667,873.0
27.486713362,831.0
27.565495057,930.0
27.644276752,877.0
27.723058447,859.0
27.801840142,863.0
27.880621837,866.0
27.959403532,877.0
28.038185227,812.0
28.116966922,873.0
28.195748617,847.0
28.274530312,854.0
28.353312007,818.0
28.432093702,864.0
28.510875397,900.0
28.589657092,907.0
28.668438787,849.0
28.747220482,862.0
28.826002177,963.0
28.904783872,825.0
28.983565567,842.0
29.062347262,821.0
29.141128957,852.0
29.219910652,784.0
29.298692347,861.0
29.377474042,833.0
29.456255737,862.0
29.535037432,874.0
29.613819127,860.0
29.692600822,839.0
29.771382517,817.0
29.850164212,762.0
29.928945907,877.0
30.007727602,844.0
30.086509297,824.0
30.165290992,853.0
30.244072687,871.0
30.322854382,869.0
30.401636077,820.0
30.480417772,850.0
30.559199468,820.0
30.637981163,793.0
30.716762858,830.0
30.795544553,790.0
30.874326248,837.0
30.953107943,752.0
31.031889638,791.0
31.110671333,812.0
31.189453028,769.0
31.268234723,821.0
31.347016418,826.0
31.425798113,771.0
31.504579808,775.0
31.583361503,797.0
31.662143198,708.0
31.740924893,789.0
31.819706588,793.0
31.898488283,709.0
31.977269978,792.0
32.056051673,805.0
32.134833368,763.0
32.213615063,733.0
32.292396758,715.0
32.371178453,722.0
32.449960148,772.0
32.528741843,739.0
32.607523538,701.0
32.686305233,722.0
32.765086928,713.0
32.843868623,716.0
32.922650318,719.0
33.001432013,726.0
33.080213708,728.0
33.158995403,708.0
33.237777098,749.0
33.316558793,723.0
33.395340488,729.0
33.474122183,689.0
33.552903878,692.0
33.631685573,718.0
33.710467268,674.0
33.789248963,687.0
33.868030658,693.0
33.946812354,655.0
34.025594049,638.0
34.104375744,691.0
34.183157439,684.0
34.261939134,682.0
34.340720829,711.0
34.419502524,664.0
34.498284219,724.0
34.577065914,688.0
34.655847609,655.0
34.734629304,654.0
34.813410999,651.0
34.892192694,671.0
34.970974389,662.0
35.049756084,682.0
35.128537779,688.0
35.207319474,701.0
35.286101169,698.0
35.364882864,649.0
35.443664559,675.0
35.522446254,690.0
35.601227949,675.0
35.680009644,695.0
35.758791339,717.0
35.837573034,625.0
35.916354729,646.0
35.995136424,647.0
36.073918119,675.0
36.152699814,649.0
36.231481509,672.0
36.310263204,692.0
36.389044899,668.0
36.467826594,689.0
36.546608289,617.0
36.625389984,590.0
36.704171679,646.0
36.782953374,671.0
36.861735069,677.0
36.940516764,669.0
37.019298459,635.0
37.098080154,676.0
37.176861849,654.0
37.255643544,659.0
37.334425240,684.0
37.413206935,645.0
37.491988630,720.0
37.570770325,676.0
37.649552020,656.0
37.728333715,676.0
37.807115410,656.0
37.885897105,688.0
37.964678800,727.0
38.043460495,669.0
38.122242190,650.0
38.201023885,649.0
38.279805580,719.0
38.358587275,733.0
38.437368970,718.0
38.516150665,667.0
38.594932360,662.0
38.673714055,720.0
38.752495750,699.0
38.831277445,693.0
38.910059140,763.0
38.988840835,713.0
39.067622530,688.0
39.146404225,799.0
39.225185920,773.0
39.303967615,731.0
39.382749310,730.0
39.461531005,834.0
39.540312700,881.0
39.619094395,852.0
39.697876090,886.0
39.776657785,907.0
39.855439480,919.0
39.934221175,974.0
40.013002870,1020.0
40.091784565,1074.0
40.170566260,1116.0
40.249347955,1171.0
40.328129650,1231.0
40.406911345,1268.0
40.485693040,1360.0
40.564474735,1387.0
40.643256430,1289.0
40.722038126,1281.0
40.800819821,1293.0
40.879601516,1308.0
40.958383211,1336.0
41.037164906,1302.0
41.115946601,1368.0
41.194728296,1330.0
41.273509991,1318.0
41.352291686,1260.0
41.431073381,1271.0
41.509855076,1282.0
41.588636771,1289.0
41.667418466,1209.0
41.746200161,1223.0
41.824981856,1188.0
41.903763551,1200.0
41.982545246,1276.0
42.061326941,1211.0
42.140108636,1223.0
42.218890331,1205.0
42.297672026,1210.0
42.376453721,1176.0
42.455235416,1168.0
42.534017111,1171.0
42.612798806,1163.0
42.691580501,1105.0
42.770362196,1056.0
42.849143891,1079.0
42.927925586,1045.0
43.006707281,1065.0
43.085488976,1016.0
43.164270671,991.0
43.243052366,967.0
43.321834061,969.0
43.400615756,999.0
43.479397451,996.0
43.558179146,938.0
43.636960841,874.0
43.715742536,973.0
43.794524231,849.0
43.873305926,836.0
43.952087621,818.0
44.030869316,821.0
44.109651011,846.0
44.188432707,826.0
44.267214402,757.0
44.345996097,754.0
44.424777792,780.0
44.503559487,795.0
44.582341182,760.0
44.661122877,783.0
44.739904572,724.0
44.818686267,732.0
44.897467962,696.0
44.976249657,713.0
45.055031352,683.0
45.133813047,740.0
45.212594742,684.0
45.291376437,654.0
45.370158132,671.0
45.448939827,628.0
45.527721522,652.0
45.606503217,645.0
45.685284912,678.0
45.764066607,676.0
45.842848302,598.0
45.921629997,650.0
46.000411692,664.0
46.079193387,589.0
46.157975082,612.0
46.236756777,603.0
46.315538472,606.0
46.394320167,611.0
46.473101862,569.0
46.551883557,571.0
46.630665252,551.0
46.709446947,569.0
46.788228642,541.0
46.867010337,519.0
46.945792032,519.0
47.024573727,566.0
47.103355422,542.0
47.182137117,518.0
47.260918812,518.0
47.339700507,544.0
47.418482202,543.0
47.497263897,515.0
47.576045593,496.0
47.654827288,503.0
47.733608983,515.0
47.812390678,526.0
47.891172373,490.0
47.969954068,439.0
48.048735763,498.0
48.127517458,419.0
48.206299153,483.0
48.285080848,483.0
48.363862543,468.0
48.442644238,459.0
48.521425933,473.0
48.600207628,454.0
48.678989323,404.0
48.757771018,406.0
48.836552713,460.0
48.915334408,469.0
48.994116103,443.0
49.072897798,453.0
49.151679493,435.0
49.230461188,415.0
49.309242883,424.0
49.388024578,411.0
49.466806273,422.0
49.545587968,412.0
49.624369663,435.0
49.703151358,419.0
49.781933053,424.0
49.860714748,373.0
49.939496443,427.0
50.018278138,468.0
50.097059833,407.0
50.175841528,405.0
50.254623223,379.0
50.333404918,420.0
50.412186613,412.0
50.490968308,359.0
50.569750003,396.0
50.648531698,390.0
50.727313393,356.0
50.806095088,379.0
50.884876783,378.0
50.963658479,383.0
51.042440174,379.0
51.121221869,407.0
51.200003564,365.0
51.278785259,370.0
51.357566954,384.0
51.436348649,409.0
51.515130344,363.0
51.593912039,374.0
51.672693734,407.0
51.751475429,361.0
51.830257124,340.0
51.909038819,369.0
51.987820514,386.0
52.066602209,375.0
52.145383904,369.0
52.224165599,348.0
52.302947294,372.0
52.381728989,381.0
52.460510684,349.0
52.539292379,348.0
52.618074074,391.0
52.696855769,332.0
52.775637464,376.0
52.854419159,346.0
52.933200854,378.0
53.011982549,373.0
53.090764244,363.0
53.169545939,328.0
53.248327634,359.0
53.327109329,338.0
53.405891024,368.0
53.484672719,303.0
53.563454414,365.0
53.642236109,352.0
53.721017804,367.0
53.799799499,348.0
53.878581194,366.0
53.957362889,357.0
54.036144584,317.0
54.114926279,361.0
54.193707974,353.0
54.272489669,353.0
54.351271365,361.0
54.430053060,357.0
54.508834755,357.0
54.587616450,332.0
54.666398145,354.0
54.745179840,381.0
54.823961535,322.0
54.902743230,334.0
54.981524925,344.0
55.060306620,305.0
55.139088315,331.0
55.217870010,314.0
55.296651705,344.0
55.375433400,352.0
55.454215095,368.0
55.532996790,337.0
55.611778485,328.0
55.690560180,351.0
55.769341875,357.0
55.848123570,373.0
55.926905265,351.0
56.005686960,335.0
56.084468655,321.0
56.163250350,355.0
56.242032045,318.0
56.320813740,351.0
56.399595435,382.0
56.478377130,307.0
56.557158825,335.0
56.635940520,332.0
56.714722215,338.0
56.793503910,366.0
56.872285605,302.0
56.951067300,331.0
57.029848995,329.0
57.108630690,340.0
57.187412385,323.0
57.266194080,339.0
57.344975775,327.0
57.423757470,347.0
57.502539165,375.0
57.581320860,343.0
57.660102555,299.0
57.738884251,328.0
57.817665946,366.0
57.896447641,345.0
57.975229336,312.0
58.054011031,319.0
58.132792726,317.0
58.211574421,326.0
58.290356116,326.0
58.369137811,340.0
58.447919506,334.0
58.526701201,356.0
58.605482896,323.0
58.684264591,339.0
58.763046286,328.0
58.841827981,340.0
58.920609676,314.0
58.999391371,331.0
59.078173066,322.0
59.156954761,335.0
59.235736456,332.0
59.314518151,299.0
59.393299846,327.0
59.472081541,323.0
59.550863236,347.0
59.629644931,337.0
59.708426626,324.0
59.787208321,325.0
59.865990016,309.0
59.944771711,334.0
60.023553406,353.0
60.102335101,301.0
60.181116796,304.0
60.259898491,334.0
60.338680186,303.0
60.417461881,303.0
60.496243576,324.0
60.575025271,332.0
60.653806966,306.0
60.732588661,305.0
60.811370356,291.0
60.890152051,290.0
60.968933746,309.0
61.047715441,283.0
61.126497137,308.0
61.205278832,302.0
61.284060527,293.0
61.362842222,286.0
61.441623917,329.0
61.520405612,308.0
61.599187307,297.0
61.677969002,326.0
61.756750697,320.0
61.835532392,280.0
61.914314087,282.0
61.993095782,331.0
62.071877477,339.0
62.150659172,285.0
62.229440867,289.0
62.308222562,329.0
62.387004257,329.0
62.465785952,317.0
62.544567647,331.0
62.623349342,327.0
62.702131037,317.0
62.780912732,313.0
62.859694427,293.0
62.938476122,266.0
63.017257817,272.0
63.096039512,303.0
63.174821207,287.0
63.253602902,287.0
63.332384597,302.0
63.411166292,316.0
63.489947987,302.0
63.568729682,312.0
63.647511377,301.0
63.726293072,278.0
63.805074767,292.0
63.883856462,303.0
63.962638157,269.0
64.041419852,297.0
64.120201547,293.0
64.198983242,285.0
64.277764937,308.0
64.356546632,318.0
64.435328327,280.0
64.514110023,272.0
64.592891718,276.0
64.671673413,275.0
64.750455108,306.0
64.829236803,307.0
64.908018498,304.0
64.986800193,284.0
65.065581888,309.0
65.144363583,281.0
65.223145278,285.0
65.301926973,282.0
65.380708668,276.0
65.459490363,293.0
65.538272058,248.0
65.617053753,289.0
65.695835448,308.0
65.774617143,296.0
65.853398838,271.0
65.932180533,259.0
66.010962228,262.0
66.089743923,267.0
66.168525618,281.0
66.247307313,249.0
66.326089008,291.0
66.404870703,239.0
66.483652398,290.0
66.562434093,278.0
66.641215788,264.0
66.719997483,278.0
66.798779178,286.0
66.877560873,268.0
66.956342568,308.0
67.035124263,253.0
67.113905958,278.0
67.192687653,288.0
67.271469348,273.0
67.350251043,268.0
67.429032738,258.0
67.507814433,268.0
67.586596128,292.0
67.665377823,295.0
67.744159518,305.0
67.822941213,285.0
67.901722909,314.0
67.980504604,284.0
68.059286299,262.0
68.138067994,252.0
68.216849689,273.0
68.295631384,261.0
68.374413079,283.0
68.453194774,234.0
68.531976469,262.0
68.610758164,247.0
68.689539859,264.0
68.768321554,284.0
68.847103249,275.0
68.925884944,309.0
69.004666639,245.0
69.083448334,275.0
69.162230029,276.0
69.241011724,280.0
69.319793419,256.0
69.398575114,249.0
69.477356809,283.0
69.556138504,241.0
69.634920199,256.0
69.713701894,265.0
69.792483589,254.0
69.871265284,234.0
69.950046979,283.0
70.028828674,288.0
70.107610369,240.0
70.186392064,270.0
70.265173759,256.0
70.343955454,278.0
70.422737149,262.0
70.501518844,253.0
70.580300539,253.0
70.659082234,254.0
70.737863929,241.0
70.816645624,293.0
70.895427319,231.0
70.974209014,279.0
71.052990709,239.0
71.131772404,277.0
71.210554099,276.0
71.289335794,252.0
71.368117490,283.0
71.446899185,268.0
71.525680880,259.0
71.604462575,274.0
71.683244270,249.0
71.762025965,282.0
71.840807660,281.0
71.919589355,284.0
71.998371050,317.0
72.077152745,300.0
72.155934440,287.0
72.234716135,310.0
72.313497830,283.0
72.392279525,301.0
72.471061220,294.0
72.549842915,291.0
72.628624610,302.0
72.707406305,281.0
72.786188000,317.0
72.864969695,342.0
72.943751390,339.0
73.022533085,292.0
73.101314780,313.0
73.180096475,317.0
73.258878170,341.0
73.337659865,348.0
73.416441560,347.0
73.495223255,361.0
73.574004950,372.0
73.652786645,323.0
73.731568340,352.0
73.810350035,316.0
73.889131730,350.0
73.967913425,307.0
74.046695120,326.0
74.125476815,328.0
74.204258510,305.0
74.283040205,322.0
74.361821900,264.0
74.440603595,289.0
74.519385290,309.0
74.598166985,276.0
74.676948680,285.0
74.755730376,304.0
74.834512071,260.0
74.913293766,247.0
74.992075461,280.0
75.070857156,274.0
75.149638851,287.0
75.228420546,262.0
75.307202241,277.0
75.385983936,280.0
75.464765631,249.0
75.543547326,286.0
75.622329021,303.0
75.701110716,217.0
75.779892411,235.0
75.858674106,284.0
75.937455801,268.0
76.016237496,281.0
76.095019191,247.0
76.173800886,280.0
76.252582581,261.0
76.331364276,292.0
76.410145971,267.0
76.488927666,258.0
76.567709361,264.0
76.646491056,253.0
76.725272751,265.0
76.804054446,268.0
76.882836141,281.0
76.961617836,262.0
77.040399531,224.0
77.119181226,271.0
77.197962921,263.0
77.276744616,265.0
77.355526311,250.0
77.434308006,251.0
77.513089701,263.0
77.591871396,273.0
77.670653091,235.0
77.749434786,254.0
77.828216481,268.0
77.906998176,249.0
77.985779871,262.0
78.064561566,252.0
78.143343262,280.0
78.222124957,230.0
78.300906652,252.0
78.379688347,248.0
78.458470042,263.0
78.537251737,229.0
78.616033432,304.0
78.694815127,259.0
78.773596822,260.0
78.852378517,249.0
78.931160212,232.0
79.009941907,246.0
79.088723602,285.0
79.167505297,240.0
79.246286992,227.0
79.325068687,214.0
79.403850382,251.0
79.482632077,254.0
79.561413772,222.0
79.640195467,247.0
79.718977162,213.0
79.797758857,250.0
79.876540552,229.0
79.955322247,233.0
80.034103942,240.0
80.112885637,233.0
80.191667332,189.0
80.270449027,222.0
80.349230722,228.0
80.428012417,237.0
80.506794112,218.0
80.585575807,259.0
80.664357502,250.0
80.743139197,219.0
80.821920892,229.0
80.900702587,235.0
80.979484282,253.0
81.058265977,239.0
81.137047672,232.0
81.215829367,223.0
81.294611062,222.0
81.373392757,234.0
81.452174452,237.0
81.530956148,197.0
81.609737843,214.0
81.688519538,255.0
81.767301233,215.0
81.846082928,201.0
81.924864623,212.0
82.003646318,229.0
82.082428013,223.0
82.161209708,220.0
82.239991403,279.0
82.318773098,224.0
82.397554793,234.0
82.476336488,250.0
82.555118183,231.0
82.633899878,225.0
82.712681573,223.0
82.791463268,221.0
82.870244963,220.0
82.949026658,247.0
83.027808353,232.0
83.106590048,246.0
83.185371743,223.0
83.264153438,242.0
83.342935133,199.0
83.421716828,234.0
83.500498523,222.0
83.579280218,224.0
83.658061913,241.0
83.736843608,212.0
83.815625303,224.0
83.894406998,223.0
83.973188693,243.0
84.051970388,226.0
84.130752083,198.0
84.209533778,218.0
84.288315473,249.0
84.367097168,208.0
84.445878863,191.0
84.524660558,219.0
84.603442253,217.0
84.682223948,215.0
84.761005643,230.0
84.839787338,207.0
84.918569034,259.0
84.997350729,218.0
85.076132424,230.0
85.154914119,228.0
85.233695814,195.0
85.312477509,223.0
85.391259204,238.0
85.470040899,225.0
85.548822594,219.0
85.627604289,209.0
85.706385984,220.0
85.785167679,225.0
85.863949374,227.0
85.942731069,211.0
86.021512764,208.0
86.100294459,225.0
86.179076154,214.0
86.257857849,228.0
86.336639544,224.0
86.415421239,228.0
86.494202934,234.0
86.572984629,210.0
86.651766324,221.0
86.730548019,224.0
86.809329714,192.0
86.888111409,221.0
86.966893104,242.0
87.045674799,215.0
87.124456494,245.0
87.203238189,216.0
87.282019884,200.0
87.360801579,255.0
87.439583274,222.0
87.518364969,233.0
87.597146664,229.0
87.675928359,246.0
87.754710054,224.0
87.833491749,217.0
87.912273444,235.0
87.991055139,234.0
88.069836834,194.0
88.148618529,211.0
88.227400224,246.0
88.306181920,226.0
88.384963615,228.0
88.463745310,226.0
88.542527005,211.0
88.621308700,228.0
88.700090395,218.0
88.778872090,209.0
88.857653785,257.0
88.936435480,215.0
89.015217175,225.0
89.093998870,232.0
89.172780565,204.0
89.251562260,214.0
89.330343955,208.0
89.409125650,214.0
89.487907345,231.0
89.566689040,200.0
89.645470735,228.0
89.724252430,236.0
89.803034125,220.0
89.881815820,212.0
89.960597515,208.0
89.986858080,211.0